Workbook

Sheet Main
A1: Tech | I1: Capital Structure = relative proportions of debt, equity, and other securities that a firm has outstanding
B2: BBAI | E2: AAPL | H2: AMZN | K2: IBM | N2: ALRM | Q2: T | U2: AFRM
B4: P | C4: 7.29 | E4: P | F4: 273.94 | G4: 46058 | H4: P | I4: 246.21 | K4: P | L4: 287 | N4: P | O4: 52.3 | Q4: P | R4: 27.06 | U4: P | V4: 78.18 | W4: Q3FY25
B5: S/O | C5: 252.3414 | E5: S/O | F5: =AAPL!O18 -> 14748.158 | G5: Q126 | H5: S/O | I5: =AMZN!M32 -> 10674 | J5: Q225 | K5: S/O | L5: 927.26 | M5: Q125 | N5: S/O | O5: 49.646 | P5: Q125 | Q5: S/O | R5: 7178.183 | S5: Q125 | U5: S/O | V5: 324.05397
B6: MC | C6: =C5*C4 -> 1839.5688 | E6: MC | F6: =F5*F4 -> 4040110.4 | H6: MC | I6: =I5*I4 -> 2628045.5 | K6: MC | L6: =L5*L4 -> 266123.62 | N6: MC | O6: =O5*O4 -> 2596.4858 | Q6: MC | R6: =R5*R4 -> 194241.63 | U6: MC | V6: 25292.412
B7: Cash | C7: 107.61 | E7: Cash | F7: =+AAPL!O68 -> 144795 | G7: Q126 | H7: Cash | I7: =AMZN!M50+AMZN!M51 -> 94197 | J7: Q225 | K7: Cash | L7: =13947+644 -> 14591 | M7: Q125 | N7: Cash | O7: 1220.701 | P7: Q125 | Q7: Cash | R7: =3298+295 -> 3593 | S7: Q125 | U7: Cash | V7: 2131.318 | W7: Q3FY25
B8: Debt | C8: =0.818+100.588 -> 101.406 | E8: Debt | F8: =+AAPL!O79 -> 90509 | G8: Q126 | H8: Debt | I8: =AMZN!M63 -> 50742 | J8: Q225 | K8: Debt (+Lease) | L8: =49884+5089+2655+768 -> 58396 | M8: Q125 | N8: Debt (+Lease) | O8: =983.477+65.534+7.7 -> 1056.711 | P8: Q125 | Q8: Debt (+Lease) | R8: =5089+118443+17391 -> 140923 | S8: Q125 | U8: Debt | V8: 7322.642 | W8: Q3FY25
B10: EV | C10: =C6-C7+C8 -> 1833.3648 | E10: EV | F10: =F6-F7+F8 -> 3985824.4 | H10: EV | I10: =I6-I7+I8 -> 2584590.5 | K10: EV | L10: =L6-L7+L8 -> 309928.62 | N10: EV | O10: =O6-O7+O8 -> 2432.4958 | Q10: EV | R10: =R6-R7+R8 -> 331571.63 | U10: EV | V10: 30483.736
E11: EV/P | F11: =F10/AAPL!V17 -> 35.584541 | H11: EV/P | I11: =I10/AMZN!AA31 -> 34.288394
B13: MSFT | E13: META | H13: GOOGL | K13: BIDU | N13: GTLB | Q13: BABA
B15: P | C15: 525.99 | E15: P | F15: 667.1 | G15: 46058 | H15: P | I15: 331.71 | J15: 46058 | K15: P | L15: 141.31 | N15: P | O15: 46.95 | Q15: P | R15: 190.08
B16: S/O | C16: =+MSFT!AQ42 -> 7434 | D16: Q126 | E16: S/O | F16: =+META!N20 -> 2525 | G16: Q126 | H16: S/O | I16: =+GOOGL!N15 -> 12073 | J16: Q425 | K16: S/O | L16: 344 | N16: S/O | O16: =144.6+19.4 -> 164 | Q16: S/O | R16: 2311 | S16: Q425
B17: MC | C17: =C16*C15 -> 3910209.7 | E17: MC | F17: =F16*F15 -> 1684427.5 | H17: MC | I17: =I16*I15 -> 4004734.8 | K17: MC | L17: =L16*L15 -> 48610.64 | N17: MC | O17: =O16*O15 -> 7699.8 | Q17: MC | R17: =R16*R15 -> 439274.88
B18: Cash | C18: =+MSFT!AQ64 -> 113477 | D18: Q126 | E18: Cash | F18: =+META!N34 -> 109116 | G18: Q126 | H18: Cash | I18: =+GOOGL!N35 -> 195530 | J18: Q425 | K18: Cash | L18: =BIDU!K38 -> 36674 | N18: Cash | O18: =764.728+264.565 -> 1029.293 | Q18: Cash | R18: 51582 | S18: Q425
B19: Debt | C19: =+MSFT!AQ75 -> 43208 | D19: Q126 | E19: Debt | F19: =+META!N45 -> 58744 | G19: Q126 | H19: Debt | I19: =+GOOGL!N49 -> 46547 | J19: Q425 | K19: Debt | L19: =BIDU!K50+BIDU!K53+BIDU!K54 -> 10868 | N19: Debt | O19: 0 | Q19: Debt | R19: 31792 | S19: Q425
B21: EV | C21: =C17-C18+C19 -> 3839940.7 | E21: EV | F21: =F17-F18+F19 -> 1634055.5 | H21: EV | I21: =I17-I18+I19 -> 3855751.8 | K21: EV | L21: =L17-L18+L19 -> 22804.64 | N21: EV | O21: =O17-O18+O19 -> 6670.507 | Q21: EV | R21: =R17-R18+R19 -> 419484.88
B22: EV/P | C22: =C21/MSFT!BE41 -> 37.708585 | E22: EV/P | F22: =F21/META!W19 -> 27.023922 | H22: EV/P | I22: =I21/GOOGL!AA14 -> 29.17267 | L22: 3600 | Q22: EV/P | R22: =+R21/15234 -> 27.536096
L23: =L21/L22 -> 6.3346222
B25: Discount rate = Risk free rate (Estimated Inflation / US Government Bond) + Risk Premium (Opportunity Cost / Risk)
B26: A Company is worth the discounted sum of its cash flows from today until eternity.
C29: Buy/Price | D29: Sell/Price | E29: Years | F29: Cash return | G29: IRR - Internal rate of return.
B30: Short-Term | C30: 10 | D30: 12 | E30: 0.04 | F30: =D30/C30-1 -> 0.2 | G30: =RATE(E30,0,-C30,D30) -> 94.396217 | H30: =_xlfn.FORMULATEXT(G30) -> =RATE(E30,0,-C30,D30)
B31: Long-Term | C31: 10 | D31: 20 | E31: 2 | F31: =D31/C31-1 -> 1 | G31: =RATE(E31,0,-C31,D31) -> 0.41421356
B35: Discounting fast growing company. 1:40:00 - Facebook
B36: https://www.youtube.com/watch?v=gsrEfnsUXOE
D40: Warren Buffet's Financial Statements Rules of Thumb
D41: METRIC | F41: EQUATION | H41: THRESHOLD
B42: INCOME STATEMENT | D42: Gross Margin | F42: Gross Profit Revenue | H42: >40%
D44: SG&A Margin | F44: SG&A Gross Profit | H44: <30%
D46: R&D Margin | F46: R&D Gross Profit | H46: <30%
D48: Depreciation Margin | F48: Depreciation Gross Profit | H48: <10%
D50: Interest Margin | F50: Interest Operating Income | H50: <15%
D52: Tax Margin | F52: Taxes Pre-Tax Income | H52: Corporate Tax Rate
D54: Net Income Margin | F54: Net Income Revenue | H54: >20%
D56: EPS Growth | F56: Year 2 EPS Year 1 EPS | H56: Positive & Growing
B58: BALANCE SHEET | D58: Cash & Debt | F58: Cash > Debt | H58: Cash>Debt
D59: Adjusted Debt to Equity | F59: Total Liabilities Shareholder Equity + Treasury Stock | H59: Below 0.80
D62: Preferred Stock | F62: NONE | H62: NONE
D63: Retained Earnings | F63: Yr 2 Retained Earnings Yr 1 Retained Earnings | H63: Consistent Growth
D65: Treasury Stock | F65: Treasury Stock > 1 | H65: Exists
...

Sheet GOOGL
A1: Main
C2: Q123 | D2: Q223 | E2: Q323 | F2: Q423 | G2: Q124 | H2: Q224 | I2: Q324 | J2: Q424 | K2: Q125 | L2: Q225 | M2: Q325 | N2: Q425 | O2: Q126 | P2: Q226 | Q2: Q326 | R2: Q426 | S2: Q127 | T2: Q227 | U2: Q327 | V2: Q427 | X2: 2022 | Y2: 2023 | Z2: 2024 | AA2: 2025 | AB2: 2026 | AC2: 2027 | AD2: 2028 | AE2: 2029 | AF2: 2030 | AG2: 2031 | AH2: 2032 | AI2: 2033 | AJ2: 2034 | AK2: 2035 | AL2: 2036 | AM2: 2037 | AN2: 2038 | AO2: 2039 | AP2: 2040 | AQ2: 2041 | AR2: 2042 | AS2: 2043 | AT2: 2044 | AU2: 2045 | AV2: =+AU2+1 -> 2046 | AW2: =+AV2+1 -> 2047 | AX2: =+AW2+1 -> 2048 | AY2: =+AX2+1 -> 2049 | AZ2: =+AY2+1 -> 2050 | BA2: =+AZ2+1 -> 2051 | BB2: =+BA2+1 -> 2052 | BC2: =+BB2+1 -> 2053 | ... YT2: =+YS2+1 -> 2668
B3: Revenue | C3: 69787 | D3: 74604 | E3: 76693 | F3: 86310 | G3: 80539 | H3: 84742 | I3: 88268 | J3: 96469 | K3: 90234 | L3: 96428 | M3: 102346 | N3: 113828 | O3: 100950 | P3: 107080 | Q3: 110600 | R3: 120480 | S3: 105010 | T3: 109580 | U3: =Q3*(1+0.1) -> 121660 | V3: =R3*(1+0.1) -> 132528 | X3: 282836 | Y3: 307394 | Z3: 350018 | AA3: =SUM(K3:N3) -> 402836 | AB3: =SUM(O3:R3) -> 439110 | AC3: =SUM(S3:V3) -> 468778 | AD3: =AC3*(1+AD188) -> 496136.27 | AE3: =AD3*(1+AE188) -> 530102.06 | AF3: =AE3*(1+AF188) -> 572389.21 | AG3: =AF3*(1+AG188) -> 599462.55 | AH3: =AG3*(1+AH188) -> 629634.62 | AI3: =AH3*(1+AI188) -> 663285.68 | AJ3: =AI3*(1+AJ188) -> 724766.26 | AK3: =AJ3*(1+AK188) -> 766755.24 | AL3: =AK3*1.02 -> 782090.34 | AM3: =AL3*1.02 -> 797732.15 | AN3: =AM3*1.02 -> 813686.79 | AO3: =AN3*1.02 -> 829960.53 | AP3: =AO3*1.02 -> 846559.74 | AQ3: =AP3*1.02 -> 863490.93 | AR3: =AQ3*1.02 -> 880760.75 | AS3: =AR3*1.02 -> 898375.97 | ... AU3: =AT3*1.02 -> 934670.36
B4: COGS | C4: 30612 | D4: 31916 | E4: 33229 | F4: 37575 | G4: 33712 | H4: 35507 | I4: 36474 | J4: 40613 | K4: 36361 | L4: 39039 | M4: 41369 | N4: 45766 | O4: =O3-O5 -> 40588.236 | P4: =P3-P5 -> 43052.88 | Q4: =Q3-Q5 -> 44468.141 | R4: =R3-R5 -> 48440.521 | S4: =S3-S5 -> 42220.611 | T4: =T3-T5 -> 44058.037 | U4: =U3-U5 -> 48914.956 | V4: =V3-V5 -> 53284.574 | X4: 126203 | Y4: 133332 | Z4: 146306 | AA4: =SUM(K4:N4) -> 162535 | AB4: =SUM(O4:R4) -> 176549.78 | AC4: =SUM(S4:V4) -> 188478.18
B5: Gross Profit | C5: =C3-C4 -> 39175 | D5: =D3-D4 -> 42688 | E5: =E3-E4 -> 43464 | F5: =F3-F4 -> 48735 | G5: =G3-G4 -> 46827 | H5: =H3-H4 -> 49235 | I5: =I3-I4 -> 51794 | J5: =J3-J4 -> 55856 | ... N5: =N3-N4 -> 68062 | O5: =O3*N20 -> 60361.764 | P5: =P3*O20 -> 64027.12 | Q5: =Q3*P20 -> 66131.859 | R5: =R3*Q20 -> 72039.479 | S5: =S3*R20 -> 62789.389 | T5: =T3*S20 -> 65521.963 | U5: =U3*T20 -> 72745.044 | V5: =V3*U20 -> 79243.426 | X5: =X3-X4 -> 156633 | Y5: =Y3-Y4 -> 174062 | Z5: =Z3-Z4 -> 203712 | AA5: =AA3-AA4 -> 240301 | AB5: =AB3-AB4 -> 262560.22 | AC5: =SUM(S5:V5) -> 280299.82
B6: R&D | C6: 11468 | D6: 10588 | E6: 11258 | F6: 12113 | G6: 11903 | H6: 11860 | I6: 12447 | J6: 13116 | K6: 13556 | L6: 13808 | M6: 15151 | N6: 18572 | O6: =O5*N25 -> 16470.845 | P6: =P5*O25 -> 17471.007 | Q6: =Q5*P25 -> 18045.325 | R6: =R5*Q25 -> 19657.33 | S6: =S5*R25 -> 17133.269 | T6: =T5*S25 -> 17878.903 | U6: =U5*T25 -> 19849.857 | V6: =V5*U25 -> 21623.063 | X6: 39500 | Y6: 45427 | Z6: 49326 | AA6: =SUM(K6:N6) -> 61087 | AB6: =SUM(O6:R6) -> 71644.507 | AC6: =SUM(S6:V6) -> 76485.092
B7: S&M | C7: 6533 | D7: 6781 | E7: 6884 | F7: 7719 | G7: 6426 | H7: 6792 | I7: 7227 | J7: 7363 | K7: 6172 | L7: 7101 | M7: 7205 | N7: 8215 | O7: =O5*N26 -> 7285.591 | P7: =P5*O26 -> 7727.9949 | Q7: =Q5*P26 -> 7982.0343 | R7: =R5*Q26 -> 8695.0768 | S7: =S5*R26 -> 7578.6024 | T7: =T5*S26 -> 7908.4206 | U7: =U5*T26 -> 8780.2377 | V7: =V5*U26 -> 9564.5845 | X7: 26567 | Y7: 27917 | Z7: 27808 | AA7: =SUM(K7:N7) -> 28693 | AB7: =SUM(O7:R7) -> 31690.697 | AC7: =SUM(S7:V7) -> 33831.845
B8: G&A | C8: 3759 | D8: 3481 | E8: 3979 | F8: 5206 | G8: 3026 | H8: 3158 | I8: 3599 | J8: 4405 | K8: 3539 | L8: 5209 | M8: 7393 | N8: 5341 | O8: =O5*N27 -> 4736.7427 | P8: =P5*O27 -> 5024.3726 | Q8: =Q5*P27 -> 5189.5368 | R8: =R5*Q27 -> 5653.123 | S8: =S5*R27 -> 4927.2447 | T8: =T5*S27 -> 5141.6767 | U8: =U5*T27 -> 5708.4905 | V8: =V5*U27 -> 6218.4353 | X8: 15724 | Y8: 16425 | Z8: 14188 | AA8: =SUM(K8:N8) -> 21482 | AB8: =SUM(O8:R8) -> 20603.775 | AC8: =SUM(S8:V8) -> 21995.847
B9: Operating expenses | C9: =SUM(C6:C8) -> 21760 | D9: =SUM(D6:D8) -> 20850 | E9: =SUM(E6:E8) -> 22121 | F9: =SUM(F6:F8) -> 25038 | G9: =SUM(G6:G8) -> 21355 | H9: =SUM(H6:H8) -> 21810 | I9: =SUM(I6:I8) -> 23273 | J9: =SUM(J6:J8) -> 24884 | ... V9: =SUM(V6:V8) -> 37406.083 | X9: =SUM(X6:X8) -> 81791 | Y9: =SUM(Y6:Y8) -> 89769 | Z9: =SUM(Z6:Z8) -> 91322 | AA9: =SUM(AA6:AA8) -> 111262 | AB9: =SUM(AB6:AB8) -> 123938.98 | AC9: =SUM(S9:V9) -> 132312.78
B10: Operating Income | C10: =C5-C9 -> 17415 | D10: =D5-D9 -> 21838 | E10: =E5-E9 -> 21343 | F10: =F5-F9 -> 23697 | G10: =G5-G9 -> 25472 | H10: =H5-H9 -> 27425 | I10: =I5-I9 -> 28521 | J10: =J5-J9 -> 30972 | ... V10: =V5-V9 -> 41837.344 | X10: =X5-X9 -> 74842 | Y10: =Y5-Y9 -> 84293 | Z10: =Z5-Z9 -> 112390 | AA10: =AA5-AA9 -> 129039 | AB10: =AB5-AB9 -> 138621.24 | AC10: =SUM(S10:V10) -> 147987.04
B11: Interest income | C11: 790 | D11: 65 | E11: -146 | F11: 715 | G11: 2843 | H11: 126 | I11: 3185 | J11: 1271 | K11: 11183 | L11: 2662 | M11: 12759 | N11: 3183 | O11: =O12-O10 -> 3444.668 | P11: =P12-P10 -> 3642.0378 | Q11: =Q12-Q10 -> 3326.0009 | R11: =R12-R10 -> 3664.8464 | S11: =S12-S10 -> 6042.4975 | T11: =T12-T10 -> 6804.628 | U11: =U12-U10 -> 3658.601 | V11: =V12-V10 -> 4031.3311 | X11: -3514 | Y11: 1424 | Z11: 7425 | AA11: =SUM(K11:N11) -> 29787 | AB11: =SUM(O11:R11) -> 14077.553 | AC11: =SUM(S11:V11) -> 20537.058
B12: Pre Tax Income | C12: =C10+C11 -> 18205 | D12: =D10+D11 -> 21903 | E12: =E10+E11 -> 21197 | F12: =F10+F11 -> 24412 | G12: =G10+G11 -> 28315 | H12: =H10+H11 -> 27551 | I12: =I10+I11 -> 31706 | J12: =J10+J11 -> 32243 | ... N12: =N10+N11 -> 39117 | O12: =O14/0.83 -> 35313.253 | P12: =P14/0.83 -> 37445.783 | Q12: =Q14/0.83 -> 38240.964 | R12: =R14/0.83 -> 41698.795 | S12: =S14/0.83 -> 39192.771 | T12: =T14/0.83 -> 41397.59 | U12: =U14/0.83 -> 42065.06 | V12: =V14/0.83 -> 45868.675 | X12: =X10+X11 -> 71328 | Y12: =Y10+Y11 -> 85717 | Z12: =Z10+Z11 -> 119815 | AA12: =AA10+AA11 -> 158826 | AB12: =AB10+AB11 -> 152698.8 | AC12: =SUM(S12:V12) -> 168524.1
B13: Taxes | C13: 3154 | D13: 3535 | E13: 1508 | F13: 3725 | G13: 4653 | H13: 3932 | I13: 5405 | J13: 5707 | K13: 7249 | L13: 5737 | M13: 9008 | N13: 4662 | O13: =O12*0.17 -> 6003.253 | P13: =P12*0.17 -> 6365.7831 | Q13: =Q12*0.17 -> 6500.9639 | R13: =R12*0.17 -> 7088.7952 | S13: =S12*0.17 -> 6662.7711 | T13: =T12*0.17 -> 7037.5904 | U13: =U12*0.17 -> 7151.0602 | V13: =V12*0.17 -> 7797.6747 | X13: 11356 | Y13: 11922 | Z13: 19697 | AA13: =SUM(K13:N13) -> 26656 | AB13: =SUM(O13:R13) -> 25958.795 | AC13: =SUM(S13:V13) -> 28649.096
B14: Net Income | C14: =C12-C13 -> 15051 | D14: =D12-D13 -> 18368 | E14: =E12-E13 -> 19689 | F14: =F12-F13 -> 20687 | G14: =G12-G13 -> 23662 | H14: =H12-H13 -> 23619 | I14: =I12-I13 -> 26301 | J14: =J12-J13 -> 26536 | ... N14: =N12-N13 -> 34455 | O14: 29310 | P14: 31080 | Q14: 31740 | R14: 34610 | S14: 32530 | T14: 34360 | U14: =Q14*1.1 -> 34914 | V14: =R14*1.1 -> 38071 | X14: =X12-X13 -> 59972 | Y14: =Y12-Y13 -> 73795 | Z14: =Z12-Z13 -> 100118 | AA14: =AA12-AA13 -> 132170 | AB14: =AB12-AB13 -> 126740 | AC14: =SUM(S14:V14) -> 139875 | AD14: =AD3*AC22 -> 148038.22 | AE14: =AE3*AD22 -> 158173.01 | AF14: =AF3*AE22 -> 170790.74 | AG14: =AG3*AF22 -> 178868.94 | AH14: =AH3*AG22 -> 187871.75 | AI14: =AI3*AH22 -> 197912.62 | AJ14: =AJ3*AI22 -> 216257.34 | AK14: =AK3*AJ22 -> 228786.1 | ... AU14: =AU3*AT22 -> 278888.98 | AV14: =AU14*(1+$AX$22) -> 276100.09 | AW14: =AV14*(1+$AX$22) -> 273339.08 | AX14: =AW14*(1+$AX$22) -> 270605.69 | AY14: =AX14*(1+$AX$22) -> 267899.64 | AZ14: =AY14*(1+$AX$22) -> 265220.64 | BA14: =AZ14*(1+$AX$22) -> 262568.43 | BB14: =BA14*(1+$AX$22) -> 259942.75 | BC14: =BB14*(1+$AX$22) -> 257343.32 | ... YT14: =YS14*(1+$AX$22) -> 532.30137
B15: SE | C15: 12781 | D15: 12668 | E15: 12541 | F15: 12488 | G15: 12415 | H15: 12343 | I15: 12264 | J15: 12228 | K15: =5820+856+5459 -> 12135 | L15: =5817+847+5430 -> 12094 | M15: =5818+5407+842 -> 12067 | N15: 12073 | X15: 12849 | Y15: 12460 | Z15: 12211 | AA15: =Z15*0.98 -> 11966.78 | AB15: =AA15*0.98 -> 11727.444 | AC15: =AB15*0.98 -> 11492.896 | AD15: =AC15*0.98 -> 11263.038 | AE15: =AD15*0.98 -> 11037.777 | AF15: =AE15*0.98 -> 10817.021 | AG15: =AF15*0.98 -> 10600.681 | AH15: =AG15*0.98 -> 10388.667 | ... AU15: =AT15*0.98 -> 7989.1177
B16: EPS | C16: =C14/C15 -> 1.1776074 | D16: =D14/D15 -> 1.4499526 | E16: =E14/E15 -> 1.5699705 | F16: =F14/F15 -> 1.6565503 | G16: =G14/G15 -> 1.9059203 | H16: =H14/H15 -> 1.9135542 | I16: =I14/I15 -> 2.1445695 | J16: =J14/J15 -> 2.1701014 | ... N16: =N14/N15 -> 2.8538888 | X16: =X14/X15 -> 4.6674449 | Y16: =Y14/Y15 -> 5.9225522 | Z16: =Z14/Z15 -> 8.1990009 | AA16: =AA14/AA15 -> 11.044742 | AB16: =AB14/AB15 -> 10.807129 | AC16: =AC14/AC15 -> 12.170562 | AD16: =AD14/AD15 -> 13.143721 | AE16: =AE14/AE15 -> 14.330151 | ... AU16: =AU14/AU15 -> 34.908608
B20: Gross Margin | C20: =C5/C3 -> 0.56135097 | D20: =D5/D3 -> 0.57219452 | E20: =E5/E3 -> 0.56672708 | F20: =F5/F3 -> 0.56465068 | G20: =G5/G3 -> 0.58142018 | H20: =H5/H3 -> 0.5809988 | I20: =I5/I3 -> 0.58678117 | J20: =J5/J3 -> 0.57900465 | ... V20: =V5/V3 -> 0.59793724 | X20: =X5/X3 -> 0.55379443 | Y20: =Y5/Y3 -> 0.56625048 | Z20: =Z5/Z3 -> 0.58200435 | AA20: =AA5/AA3 -> 0.59652315 | AB20: =AB5/AB3 -> 0.59793724 | AC20: =AC5/AC3 -> 0.59793724
B21: Operating Margin | C21: =C10/C3 -> 0.24954504 | D21: =D10/D3 -> 0.29271889 | E21: =E10/E3 -> 0.27829137 | F21: =F10/F3 -> 0.27455683 | G21: =G10/G3 -> 0.31626914 | H21: =H10/H3 -> 0.32362937 | I21: =I10/I3 -> 0.32311823 | J21: =J10/J3 -> 0.32105651 | ... V21: =V10/V3 -> 0.31568683 | X21: =X10/X3 -> 0.26461271 | Y21: =Y10/Y3 -> 0.2742181 | Z21: =Z10/Z3 -> 0.32109777 | AA21: =AA10/AA3 -> 0.32032639 | AB21: =AB10/AB3 -> 0.31568683 | AC21: =AC10/AC3 -> 0.31568683
B22: Net Margin | C22: =C14/C3 -> 0.21567054 | D22: =D14/D3 -> 0.24620664 | E22: =E14/E3 -> 0.25672486 | F22: =F14/F3 -> 0.23968254 | G22: =G14/G3 -> 0.29379555 | H22: =H14/H3 -> 0.27871658 | I22: =I14/I3 -> 0.29796755 | J22: =J14/J3 -> 0.27507282 | ... N22: =N14/N3 -> 0.30269354 | X22: =X14/X3 -> 0.21203807 | Y22: =Y14/Y3 -> 0.24006649 | Z22: =Z14/Z3 -> 0.28603672 | AA22: =AA14/AA3 -> 0.32809878 | AB22: =AB14/AB3 -> 0.28862927 | AC22: =AC14/AC3 -> 0.29838218 | AD22: =AD14/AD3 -> 0.29838218 | AE22: =AE14/AE3 -> 0.29838218 | ... AU22: =AU14/AU3 -> 0.29838218 | AW22: Maturity | AX22: -0.01
AW23: Discount | AX23: 0.06
B24: Tax Margin | C24: =C13/C12 -> 0.17324911 | D24: =D13/D12 -> 0.16139342 | E24: =E13/E12 -> 0.071142143 | F24: =F13/F12 -> 0.15258889 | G24: =G13/G12 -> 0.16432986 | H24: =H13/H12 -> 0.14271714 | I24: =I13/I12 -> 0.17047247 | J24: =J13/J12 -> 0.17699966 | ... V24: =V13/V12 -> 0.17 | X24: =X13/X12 -> 0.15920817 | Y24: =Y13/Y12 -> 0.1390856 | Z24: =Z13/Z12 -> 0.16439511 | AA24: =AA13/AA12 -> 0.16783146 | AB24: =AB13/AB12 -> 0.17 | AC24: =AC13/AC12 -> 0.17 | AW24: NPV | AX24: =NPV(AX23,AB14:YT14)+AA14+L34 -> 3778612.7
B25: R&D Margin | G25: =G6/G5 -> 0.25419096 | H25: =H6/H5 -> 0.24088555 | I25: =I6/I5 -> 0.24031741 | J25: =J6/J5 -> 0.2348181 | K25: =K6/K5 -> 0.25162883 | L25: =L6/L5 -> 0.2406036 | M25: =M6/M5 -> 0.24847073 | N25: =N6/N5 -> 0.27286885 | ... V25: =V6/V5 -> 0.27286885 | X25: =X6/X5 -> 0.25218185 | Y25: =Y6/Y5 -> 0.26098172 | Z25: =Z6/Z5 -> 0.24213596 | AA25: =AA6/AA5 -> 0.25421034 | AB25: =AB6/AB5 -> 0.27286885 | AC25: =AC6/AC5 -> 0.27286885 | AW25: Share | AX25: =AX24/Main!I16 -> 312.98042
B26: S&M Margin | G26: =G7/G5 -> 0.13722852 | H26: =H7/H5 -> 0.13795064 | I26: =I7/I5 -> 0.13953354 | J26: =J7/J5 -> 0.13182111 | K26: =K7/K5 -> 0.11456574 | L26: =L7/L5 -> 0.12373451 | M26: =M7/M5 -> 0.11815931 | N26: =N7/N5 -> 0.12069877 | ... V26: =V7/V5 -> 0.12069877 | AW26: Current | AX26: =Main!I15 -> 331.71
B27: G&A Margin | G27: =(G8)/G5 -> 0.064620838 | H27: =(H8)/H5 -> 0.064141363 | I27: =(I8)/I5 -> 0.069486813 | J27: =(J8)/J5 -> 0.078863506 | K27: =(K8)/K5 -> 0.065691534 | L27: =(L8)/L5 -> 0.090766523 | M27: =(M8)/M5 -> 0.12124244 | N27: =(N8)/N5 -> 0.078472569 | ... V27: =(V8)/V5 -> 0.078472569 | X27: =(X8)/X5 -> 0.10038753 | Y27: =(Y8)/Y5 -> 0.094362928 | Z27: =(Z8)/Z5 -> 0.069647345 | AA27: =(AA8)/AA5 -> 0.089396216 | AB27: =(AB8)/AB5 -> 0.078472569 | AC27: =(AC8)/AC5 -> 0.078472569 | AW27: Return | AX27: =AX25/AX26-1 -> -0.056463705
B28: Interest Margin | G28: =G11/G10 -> 0.11161275 | H28: =H11/H10 -> 0.0045943482 | I28: =I11/I10 -> 0.1116721 | J28: =J11/J10 -> 0.041037066 | K28: =K11/K10 -> 0.36538587 | L28: =L11/L10 -> 0.085126795 | M28: =M11/M10 -> 0.40857564 | N28: =N11/N10 -> 0.088579062 | ... V28: =V11/V10 -> 0.096357242 | X28: =X11/X10 -> -0.046952246 | Y28: =Y11/Y10 -> 0.016893455 | Z28: =Z11/Z10 -> 0.066064596 | AA28: =AA11/AA10 -> 0.23083719 | AB28: =AB11/AB10 -> 0.10155408 | AC28: =AC11/AC10 -> 0.13877606
B30: Revenue y/y | G30: =G3/C3-1 -> 0.15406881 | H30: =H3/D3-1 -> 0.13589084 | I30: =I3/E3-1 -> 0.15092642 | J30: =J3/F3-1 -> 0.11770363 | K30: =K3/G3-1 -> 0.12037646 | L30: =L3/H3-1 -> 0.13790092 | M30: =M3/I3-1 -> 0.15949155 | N30: =N3/J3-1 -> 0.17994382 | ... V30: =V3/R3-1 -> 0.1 | Y30: =Y3/X3-1 -> 0.086827702 | Z30: =Z3/Y3-1 -> 0.13866243 | AA30: =AA3/Z3-1 -> 0.15090081 | AB30: =AB3/AA3-1 -> 0.09004657 | AC30: =AC3/AB3-1 -> 0.067563936
B31: EPS y/y | Y31: =Y16/X16-1 -> 0.2689067 | Z31: =Z16/Y16-1 -> 0.38436955 | AA31: =AA16/Z16-1 -> 0.34708391 | AB31: =AB16/AA16-1 -> -0.021513728 | AC31: =AC16/AB16-1 -> 0.12616058 | AD31: =AD16/AC16-1 -> 0.079960018 | AE31: =AE16/AD16-1 -> 0.090265937 | AF31: =AF16/AE16-1 -> 0.10180786 | ... AK31: =AK16/AJ16-1 -> 0.079525004
B32: S/O | Y32: =Y15/X15-1 -> -0.03027473 | Z32: =Z15/Y15-1 -> -0.019983949 | AA32: =AA15/Z15-1 -> -0.02 | AB32: =AB15/AA15-1 -> -0.02 | AC32: =AC15/AB15-1 -> -0.02
B34: Net Cash | C34: =C35-C49 -> 0 | D34: =D35-D49 -> 0 | E34: =E35-E49 -> 0 | F34: =F35-F49 -> 130054 | G34: =G35-G49 -> 128856 | H34: =H35-H49 -> 121659 | I34: =I35-I49 -> 117110 | J34: =J35-J49 -> 122756 | ... O34: =O35-O49 -> 0 | Y34: =Y35-Y49 -> 130054 | Z34: =Z35-Z49 -> 122756 | AA34: =AA35-AA49 -> 148983
B35: Cash | F35: =24048+86868+31008 -> 141924 | G35: =24493+83597+33994 -> 142084 | H35: =27225+73500+34172 -> 134897 | I35: =19959+73271+36177 -> 129407 | J35: =23466+72191+37982 -> 133639 | K35: =23264+72064+51029 -> 146357 | L35: =21036+74112+52574 -> 147722 | M35: =23090+75406+63800 -> 162296 | N35: =126843+68687 -> 195530 | Y35: =24048+86868+31008 -> 141924 | Z35: =23466+72191+37982 -> 133639 | AA35: =126843+68687 -> 195530
B36: A/R | F36: 47964 | G36: 44552 | H36: 47087 | I36: 49104 | J36: 52340 | K36: 51000 | L36: 55048 | M36: 57148 | N36: 62886 | Y36: 47964 | Z36: 52340 | AA36: 62886
B37: OCA | F37: 12650 | G37: 12829 | H37: 14183 | I37: 15207 | J37: 15714 | K37: 15724 | L37: 16020 | M37: 18303 | N37: 13309 | Y37: 12650 | Z37: 15714 | AA37: 13309
B38: D/R taxes | F38: 12169 | G38: 11687 | H38: 14958 | I38: 15915 | J38: 17180 | K38: 18386 | L38: 19289 | M38: 10331 | N38: 9113 | Y38: 12169 | Z38: 17180 | AA38: 9113
B39: PP&A | F39: 134345 | G39: 143182 | H39: 151155 | I39: 161270 | J39: 171036 | K39: 185062 | L39: 203231 | M39: 223787 | N39: 246597 | Y39: 134345 | Z39: 171036 | AA39: 246597
B40: Lease ROU | F40: 14091 | G40: 13768 | H40: 13606 | I40: 13561 | J40: 13588 | K40: 13722 | L40: 14255 | M40: 14524 | N40: 15221 | Y40: 14091 | Z40: 13588 | AA40: 15221
B41: Goodwill | F41: 29198 | G41: 29183 | H41: 29185 | I41: 31935 | J41: 31885 | K41: 32173 | L41: 32335 | M41: 33269 | N41: 33380 | Y41: 29198 | Z41: 31885 | AA41: 33380
B42: ONCA | F42: 10051 | G42: 10065 | H42: 9699 | I42: 13867 | J42: 14874 | K42: 12950 | L42: 14153 | M42: 16811 | N42: 16245 | Y42: 10051 | Z42: 14874 | AA42: 16245
B43: Total Assets | C43: =SUM(C35:C42) -> 0 | D43: =SUM(D35:D42) -> 0 | E43: =SUM(E35:E42) -> 0 | F43: =SUM(F35:F42) -> 402392 | G43: =SUM(G35:G42) -> 407350 | H43: =SUM(H35:H42) -> 414770 | I43: =SUM(I35:I42) -> 430266 | J43: =SUM(J35:J42) -> 450256 | ... O43: =SUM(O35:O42) -> 0 | Y43: =SUM(Y35:Y42) -> 402392 | Z43: =SUM(Z35:Z42) -> 450256 | AA43: =SUM(AA35:AA42) -> 592281
B44: A/P | F44: 7493 | G44: 6198 | H44: 6092 | I44: 7049 | J44: 7987 | K44: 8497 | L44: 8347 | M44: 10546 | N44: 12200 | Y44: 7493 | Z44: 7987 | AA44: 12200
B45: Wages | F45: 15140 | G45: 9703 | H45: 11373 | I45: 12908 | J45: 15069 | K45: 9984 | L45: 12168 | M45: 13944 | N45: 17546 | Y45: 15140 | Z45: 15069 | AA45: 17546
...

Sheet META
A1: Main
C2: Q123 | D2: Q223 | E2: Q323 | F2: Q423 | G2: Q124 | H2: Q224 | I2: Q324 | J2: Q424 | K2: Q125 | L2: Q225 | M2: Q325 | N2: Q425 | O2: Q126 | P2: Q226 | Q2: Q326 | R2: Q426 | T2: 2022 | U2: 2023 | V2: 2024 | W2: 2025 | X2: 2026 | Y2: 2027 | Z2: 2028 | AA2: 2029 | AB2: 2030 | AC2: 2031 | AD2: 2032 | AE2: 2033 | AF2: 2034 | AG2: 2035 | AH2: 2036 | AI2: 2037 | AJ2: 2038 | AK2: 2039 | AL2: 2040 | AM2: 2041 | AN2: 2042 | AO2: 2043 | AP2: 2044 | AQ2: 2045 | AR2: 2046 | AS2: 2047 | AT2: 2048 | AU2: 2049 | AV2: 2050 | AW2: 2051 | AX2: 2052 | AY2: 2053 | AZ2: 2054 | BA2: 2055 | BB2: 2056 | BC2: 2057 | BD2: 2058 | BE2: 2059 | BF2: 2060 | BG2: 2061 | BH2: 2062 | BI2: 2063 | BJ2: 2064 | BK2: 2065 | BL2: 2066 | BM2: 2067 | BN2: 2068 | BO2: 2069 | BP2: 2070 | BQ2: 2071 | BR2: 2072 | BS2: 2073 | BT2: 2074 | BU2: 2075 | BV2: 2076 | BW2: 2077 | BX2: 2078 | BY2: 2079 | BZ2: 2080 | CA2: 2081 | CB2: 2082 | CC2: 2083 | CD2: 2084 | CE2: 2085 | CF2: 2086 | CG2: 2087 | CH2: 2088 | CI2: 2089 | CJ2: 2090 | CK2: 2091 | CL2: 2092 | CM2: 2093 | CN2: 2094 | CO2: 2095 | CP2: 2096 | CQ2: 2097 | CR2: 2098 | CS2: 2099 | CT2: 2100 | CU2: 2101 | CV2: 2102 | CW2: 2103 | CX2: 2104 | CY2: 2105 | CZ2: 2106 | DA2: 2107 | DB2: 2108 | DC2: 2109 | DD2: 2110 | DE2: 2111 | DF2: 2112 | DG2: 2113 | DH2: 2114 | DI2: 2115 | DJ2: 2116 | DK2: 2117 | DL2: 2118 | DM2: 2119 | DN2: 2120 | DO2: 2121 | DP2: 2122 | DQ2: 2123 | DR2: 2124 | DS2: 2125 | DT2: 2126 | DU2: 2127 | DV2: 2128 | DW2: 2129 | DX2: 2130 | DY2: 2131 | DZ2: 2132 | EA2: 2133 | EB2: 2134 | EC2: 2135 | ED2: 2136 | EE2: 2137 | EF2: 2138 | EG2: 2139 | EH2: 2140 | EI2: 2141 | EJ2: 2142 | EK2: 2143 | EL2: 2144 | EM2: 2145 | EN2: 2146 | EO2: 2147 | EP2: 2148 | EQ2: 2149 | ER2: 2150 | ES2: 2151 | ET2: 2152 | EU2: 2153 | EV2: 2154 | EW2: 2155 | EX2: 2156 | EY2: 2157 | EZ2: 2158 | FA2: 2159 | FB2: 2160 | FC2: 2161 | FD2: 2162 | FE2: 2163 | FF2: 2164 | FG2: 2165 | FH2: 2166 | FI2: 2167 | FJ2: 2168 | FK2: 2169 | FL2: 2170 | FM2: 2171 | FN2: 2172 | FO2: 2173 | FP2: 2174 | FQ2: 2175 | FR2: 2176 | FS2: 2177 | FT2: 2178 | FU2: 2179 | FV2: 2180 | FW2: 2181 | FX2: 2182 | FY2: 2183 | FZ2: 2184 | GA2: 2185 | GB2: 2186 | GC2: 2187 | GD2: 2188 | GE2: 2189 | GF2: 2190
B3: DAP | C3: 3020 | D3: 3070 | E3: 3140 | F3: 3190 | G3: 3240 | H3: 3270 | I3: 3290 | J3: 3350 | N3: 3580 | U3: 3190 | V3: 3350 | W3: =V3*1.015 -> 3400.25 | X3: =W3*1.015 -> 3451.2537 | Y3: =X3*1.015 -> 3503.0226 | Z3: =Y3*1.015 -> 3555.5679 | AA3: =Z3*1.015 -> 3608.9014 | AB3: =AA3*1.015 -> 3663.0349 | AC3: =AB3*1.015 -> 3717.9805 | AD3: =AC3*1.015 -> 3773.7502
B4: Avg rev per user | C4: =C8/C3 -> 9.4850993 | D4: =D8/D3 -> 10.423127 | E4: =E8/E3 -> 10.874522 | F4: =F8/F3 -> 12.573981 | G4: =G8/G3 -> 11.251543 | H4: =H8/H3 -> 11.948318 | I4: =I8/I3 -> 12.337082 | J4: =J8/J3 -> 14.443284 | N4: =N8/N3 -> 16.729888 | O4: =O8/O3 -> #DIV/0! | P4: =P8/P3 -> #DIV/0! | Q4: =Q8/Q3 -> #DIV/0! | R4: =R8/R3 -> #DIV/0! | U4: =U8/I3 -> 41.003343 | V4: =V8/J3 -> 49.104478 | W4: =V4*1.2 -> 58.925373 | X4: =W4*1.2 -> 70.710448 | Y4: =X4*1.2 -> 84.852537 | Z4: =Y4*1.2 -> 101.82304 | AA4: =Z4*1.1 -> 112.00535 | AB4: =AA4*1.1 -> 123.20588 | AC4: =AB4*1.1 -> 135.52647 | AD4: =AC4*1.1 -> 149.07912
B5: DAP growth | G5: =G3/C3-1 -> 0.072847682 | H5: =H3/D3-1 -> 0.06514658 | I5: =I3/E3-1 -> 0.047770701 | J5: =J3/F3-1 -> 0.05015674 | N5: =N3/J3-1 -> 0.068656716 | O5: =O3/K3-1 -> #DIV/0! | P5: =P3/L3-1 -> #DIV/0! | Q5: =Q3/M3-1 -> #DIV/0! | R5: =R3/N3-1 -> -1 | V5: =V3/U3-1 -> 0.05015674
B6: ARPU growth | G6: =G4/C4-1 -> 0.18623357 | H6: =H4/D4-1 -> 0.14632758 | I6: =I4/E4-1 -> 0.13449416 | J6: =J4/F4-1 -> 0.14866432 | N6: =N4/J4-1 -> 0.15831612 | O6: =O4/K4-1 -> #DIV/0! | P6: =P4/L4-1 -> #DIV/0! | Q6: =Q4/M4-1 -> #DIV/0! | R6: =R4/N4-1 -> #DIV/0! | V6: =V4/U4-1 -> 0.19757253
B8: Revenue | C8: 28645 | D8: 31999 | E8: 34146 | F8: 40111 | G8: 36455 | H8: 39071 | I8: 40589 | J8: 48385 | K8: 42314 | L8: 47516 | M8: 51242 | N8: 59893 | T8: 116609 | U8: =SUM(C8:F8) -> 134901 | V8: =SUM(G8:J8) -> 164500 | W8: =SUM(K8:N8) -> 200965 | X8: 213430 | Y8: =Y4*Y3 -> 297240.35 | Z8: =Z4*Z3 -> 362038.75 | AA8: =AA4*AA3 -> 404216.26 | AB8: =AB4*AB3 -> 451307.46 | AC8: =AC4*AC3 -> 503884.78 | AD8: =AD4*AD3 -> 562587.35
B9: COGS | C9: 6108 | D9: 5945 | E9: 6210 | F9: 7695 | G9: 6640 | H9: 7308 | I9: 7375 | J9: 8839 | K9: 7572 | L9: 8491 | M9: 9206 | N9: 10905 | T9: 25249 | U9: =SUM(C9:F9) -> 25958 | V9: =SUM(G9:J9) -> 30162 | W9: =SUM(K9:N9) -> 36174
B10: Gross Profit | C10: =C8-C9 -> 22537 | D10: =D8-D9 -> 26054 | E10: =E8-E9 -> 27936 | F10: =F8-F9 -> 32416 | G10: =G8-G9 -> 29815 | H10: =H8-H9 -> 31763 | I10: =I8-I9 -> 33214 | J10: =J8-J9 -> 39546 | ... R10: =R8-R9 -> 0 | T10: =T8-T9 -> 91360 | U10: =U8-U9 -> 108943 | V10: =V8-V9 -> 134338 | W10: =W8-W9 -> 164791 | X10: =X8-X9 -> 213430
B11: R&D | C11: 9381 | D11: 9344 | E11: 9241 | F11: 10517 | G11: 9978 | H11: 10537 | I11: 11177 | J11: 12180 | K11: 12150 | L11: 12942 | M11: 15144 | N11: 17136 | T11: 35338 | U11: =SUM(C11:F11) -> 38483 | V11: =SUM(G11:J11) -> 43872 | W11: =SUM(K11:N11) -> 57372
B12: M&S | C12: 3044 | D12: 3154 | E12: 2877 | F12: 3226 | G12: 2564 | H12: 2721 | I12: 2822 | J12: 3240 | K12: 2757 | L12: 2979 | M12: 2845 | N12: 3410 | T12: 15262 | U12: =SUM(C12:F12) -> 12301 | V12: =SUM(G12:J12) -> 11347 | W12: =SUM(K12:N12) -> 11991
B13: G&A | C13: 2885 | D13: 4164 | E13: 2070 | F13: 2289 | G13: 3455 | H13: 3658 | I13: 1865 | J13: 761 | K13: 2280 | L13: 2663 | M13: 3512 | N13: 3697 | T13: 11816 | U13: =SUM(C13:F13) -> 11408 | V13: =SUM(G13:J13) -> 9739 | W13: =SUM(K13:N13) -> 12152
B14: Operating Expenses | C14: =SUM(C11:C13) -> 15310 | D14: =SUM(D11:D13) -> 16662 | E14: =SUM(E11:E13) -> 14188 | F14: =SUM(F11:F13) -> 16032 | G14: =SUM(G11:G13) -> 15997 | H14: =SUM(H11:H13) -> 16916 | I14: =SUM(I11:I13) -> 15864 | J14: =SUM(J11:J13) -> 16181 | ... R14: =SUM(R11:R13) -> 0 | T14: =SUM(T11:T13) -> 62416 | U14: =SUM(U11:U13) -> 62192 | V14: =SUM(V11:V13) -> 64958 | W14: =SUM(W11:W13) -> 81515 | X14: =SUM(X11:X13) -> 0
B15: Operating Income | C15: =C10-C14 -> 7227 | D15: =D10-D14 -> 9392 | E15: =E10-E14 -> 13748 | F15: =F10-F14 -> 16384 | G15: =G10-G14 -> 13818 | H15: =H10-H14 -> 14847 | I15: =I10-I14 -> 17350 | J15: =J10-J14 -> 23365 | ... R15: =R10-R14 -> 0 | T15: =T10-T14 -> 28944 | U15: =U10-U14 -> 46751 | V15: =V10-V14 -> 69380 | W15: =W10-W14 -> 83276 | X15: =X10-X14 -> 213430
B16: Interest income | C16: 80 | D16: -99 | E16: 272 | F16: 424 | G16: 365 | H16: 259 | I16: 472 | J16: 188 | K16: 827 | L16: 93 | M16: 1128 | N16: 609 | T16: -125 | U16: =SUM(C16:F16) -> 677 | V16: =SUM(G16:J16) -> 1284 | W16: =SUM(K16:N16) -> 2657
B17: Pre-Tax Income | C17: =C15+C16 -> 7307 | D17: =D15+D16 -> 9293 | E17: =E15+E16 -> 14020 | F17: =F15+F16 -> 16808 | G17: =G15+G16 -> 14183 | H17: =H15+H16 -> 15106 | I17: =I15+I16 -> 17822 | J17: =J15+J16 -> 23553 | ... R17: =R15+R16 -> 0 | T17: =T15+T16 -> 28819 | U17: =U15+U16 -> 47428 | V17: =V15+V16 -> 70664 | W17: =W15+W16 -> 85933 | X17: =X15+X16 -> 213430
B18: Taxes | C18: 1598 | D18: 1505 | E18: 2437 | F18: 2791 | G18: 1814 | H18: 1641 | I18: 2134 | J18: 2715 | K18: 1738 | L18: 2197 | M18: 18945 | N18: 2586 | T18: 5619 | U18: =SUM(C18:F18) -> 8331 | V18: =SUM(G18:J18) -> 8304 | W18: =SUM(K18:N18) -> 25466
B19: Net Income | C19: =C17-C18 -> 5709 | D19: =D17-D18 -> 7788 | E19: =E17-E18 -> 11583 | F19: =F17-F18 -> 14017 | G19: =G17-G18 -> 12369 | H19: =H17-H18 -> 13465 | I19: =I17-I18 -> 15688 | J19: =J17-J18 -> 20838 | ... R19: =R17-R18 -> 0 | T19: =T17-T18 -> 23200 | U19: =U17-U18 -> 39097 | V19: =V17-V18 -> 62360 | W19: =W17-W18 -> 60467 | X19: =X17-X18 -> 213430 | Y19: =Y8*0.4 -> 118896.14 | Z19: =Z8*0.4 -> 144815.5 | AA19: =AA8*0.35 -> 141475.69 | AB19: =AB8*0.35 -> 157957.61 | AC19: =AC8*0.35 -> 176359.67 | AD19: =AD8*0.35 -> 196905.57 | AE19: =AD19*(1-$AG$30) -> 189029.35 | AF19: =AE19*(1-$AG$30) -> 181468.18 | AG19: =AF19*(1-$AG$30) -> 174209.45 | AH19: =AG19*(1-$AG$30) -> 167241.07 | AI19: =AH19*(1-$AG$30) -> 160551.43 | AJ19: =AI19*(1-$AG$30) -> 154129.37 | AK19: =AJ19*(1-$AG$30) -> 147964.2 | AL19: =AK19*(1-$AG$30) -> 142045.63 | ... GF19: =GE19*(1-$AG$30) -> 311.25249
B20: S/O | C20: 2587 | D20: 2568 | E20: 2576 | F20: 2566 | G20: 2545 | H20: 2534 | I20: 2529 | J20: 2529 | K20: 2527 | L20: 2518 | M20: 2517 | N20: 2525 | T20: 2687 | U20: 2574 | V20: 2534 | W20: =+N20 -> 2525
B21: EPS | C21: =C19/C20 -> 2.2068032 | D21: =D19/D20 -> 3.0327103 | E21: =E19/E20 -> 4.4965062 | F21: =F19/F20 -> 5.4625877 | G21: =G19/G20 -> 4.8601179 | H21: =H19/H20 -> 5.3137332 | I21: =I19/I20 -> 6.2032424 | J21: =J19/J20 -> 8.2396204 | ... R21: =R19/R20 -> #DIV/0! | T21: =T19/T20 -> 8.6341645 | U21: =U19/U20 -> 15.1892 | V21: =V19/V20 -> 24.609313 | W21: =W19/W20 -> 23.947327 | X21: =X19/X20 -> #DIV/0!
B23: Gross Margin | C23: =C10/C8 -> 0.78676907 | D23: =D10/D8 -> 0.81421294 | E23: =E10/E8 -> 0.8181339 | F23: =F10/F8 -> 0.80815736 | G23: =G10/G8 -> 0.81785763 | H23: =H10/H8 -> 0.8129559 | I23: =I10/I8 -> 0.81830052 | J23: =J10/J8 -> 0.81731942 | ... R23: =R10/R8 -> #DIV/0! | T23: =T10/T8 -> 0.78347297 | U23: =U10/U8 -> 0.80757741 | V23: =V10/V8 -> 0.81664438 | W23: =W10/W8 -> 0.81999851 | X23: =X10/X8 -> 1
B24: Operating Margin | C24: =C15/C8 -> 0.25229534 | D24: =D15/D8 -> 0.29350917 | E24: =E15/E8 -> 0.40262403 | F24: =F15/F8 -> 0.40846651 | G24: =G15/G8 -> 0.37904266 | H24: =H15/H8 -> 0.38000051 | I24: =I15/I8 -> 0.42745571 | J24: =J15/J8 -> 0.48289759 | ... R24: =R15/R8 -> #DIV/0! | T24: =T15/T8 -> 0.24821412 | U24: =U15/U8 -> 0.34655785 | V24: =V15/V8 -> 0.42176292 | W24: =W15/W8 -> 0.41438061 | X24: =X15/X8 -> 1
B25: Net Margin | C25: =C19/C8 -> 0.1993018 | D25: =D19/D8 -> 0.24338261 | E25: =E19/E8 -> 0.33921982 | F25: =F19/F8 -> 0.34945526 | G25: =G19/G8 -> 0.33929502 | H25: =H19/H8 -> 0.34462901 | I25: =I19/I8 -> 0.38650866 | J25: =J19/J8 -> 0.43067066 | ... R25: =R19/R8 -> #DIV/0! | T25: =T19/T8 -> 0.19895548 | U25: =U19/U8 -> 0.28981994 | V25: =V19/V8 -> 0.37908815 | W25: =W19/W8 -> 0.30088324 | X25: =X19/X8 -> 1
B26: Tax Margin | C26: =C18/C17 -> 0.2186944 | D26: =D18/D17 -> 0.16194985 | E26: =E18/E17 -> 0.17382311 | F26: =F18/F17 -> 0.16605188 | G26: =G18/G17 -> 0.1278996 | H26: =H18/H17 -> 0.10863233 | I26: =I18/I17 -> 0.11973965 | J26: =J18/J17 -> 0.11527194 | ... R26: =R18/R17 -> #DIV/0! | T26: =T18/T17 -> 0.19497554 | U26: =U18/U17 -> 0.17565573 | V26: =V18/V17 -> 0.11751387 | W26: =W18/W17 -> 0.29634715 | X26: =X18/X17 -> 0
B27: SG&A Margin | C27: =(C12+C13)/C10 -> 0.26307849 | D27: =(D12+D13)/D10 -> 0.28087818 | E27: =(E12+E13)/E10 -> 0.17708333 | F27: =(F12+F13)/F10 -> 0.17013203 | G27: =(G12+G13)/G10 -> 0.20187825 | H27: =(H12+H13)/H10 -> 0.20083116 | I27: =(I12+I13)/I10 -> 0.14111519 | J27: =(J12+J13)/J10 -> 0.10117332 | ... R27: =(R12+R13)/R10 -> #DIV/0! | T27: =(T12+T13)/T10 -> 0.29638792 | U27: =(U12+U13)/U10 -> 0.21762757 | V27: =(V12+V13)/V10 -> 0.15696229 | W27: =(W12+W13)/W10 -> 0.14650679 | X27: =(X12+X13)/X10 -> 0 | AF27: Change | AG27: =#REF!/Main!F15-1 -> #REF!
B28: R&D Margin | C28: =C11/C10 -> 0.41624884 | D28: =D11/D10 -> 0.35863975 | E28: =E11/E10 -> 0.33079181 | F28: =F11/F10 -> 0.32443855 | G28: =G11/G10 -> 0.33466376 | H28: =H11/H10 -> 0.33173819 | I28: =I11/I10 -> 0.33651472 | J28: =J11/J10 -> 0.30799575 | ... R28: =R11/R10 -> #DIV/0! | T28: =T11/T10 -> 0.38679947 | U28: =U11/U10 -> 0.35323977 | V28: =V11/V10 -> 0.32657923 | W28: =W11/W10 -> 0.34815008 | X28: =X11/X10 -> 0
B30: Revenue y/y | G30: =G8/C8-1 -> 0.27264793 | H30: =H8/D8-1 -> 0.22100691 | I30: =I8/E8-1 -> 0.18868974 | J30: =J8/F8-1 -> 0.20627758 | K30: =K8/G8-1 -> 0.16071869 | L30: =L8/H8-1 -> 0.21614497 | M30: =M8/I8-1 -> 0.26246027 | N30: =N8/J8-1 -> 0.23784231 | ... R30: =R8/N8-1 -> -1 | U30: =U8/T8-1 -> 0.15686611 | V30: =V8/U8-1 -> 0.21941275 | W30: =W8/V8-1 -> 0.22167173 | X30: =X8/W8-1 -> 0.062025726 | AF30: Maturity | AG30: 0.04
AF31: Discount Rate | AG31: 0.0775
B33: Net Cash | F33: =F34-F45 -> 53159 | G33: =G34-G45 -> 45951 | H33: =H34-H45 -> 45898 | I33: =I34-I45 -> 48148 | J33: =J34-J45 -> 55059 | K33: =K34-K45 -> 47569 | L33: =L34-L45 -> 40227 | M33: =M34-M45 -> 40688 | ... P33: =P34-P45 -> 0 | U33: =U34-U45 -> 53159 | V33: =V34-V45 -> 55059 | W33: =W34-W45 -> 50372 | X33: =X34-X45 -> 0 | Y33: =Y34-Y45 -> 0
B34: Cash | F34: =41862+23541+6141 -> 71544 | G34: =32307+25813+6218 -> 64338 | H34: =32045+26035+6207 -> 64287 | I34: =43852+27048+6071 -> 76971 | J34: =43889+33926+6070 -> 83885 | K34: =28750+41480+6168 -> 76398 | L34: =12005+35066+21988 -> 69059 | M34: =10187+34261+25074 -> 69522 | N34: =35873+45719+27524 -> 109116 | U34: =41862+23541+6141 -> 71544 | V34: =43889+33926+6070 -> 83885 | W34: =35873+45719+27524 -> 109116
B35: A/R | F35: 16169 | G35: 13430 | H35: 14505 | I35: 14700 | J35: 16994 | K35: 14514 | L35: 16561 | M35: 17297 | N35: 19769 | U35: 16169 | V35: 16994 | W35: 19769
B36: Prepaids | F36: 3793 | G36: 3780 | H36: 3846 | I36: 5467 | J36: 5236 | K36: 5483 | L36: 9981 | M36: 11373 | N36: 7361 | U36: 3793 | V36: 5236 | W36: 7361
B37: PP&A | F37: 96587 | G37: 98908 | H37: 102959 | I37: 112162 | J37: 121346 | K37: 133567 | L37: 147039 | M37: 160270 | N37: 176400 | U37: 96587 | V37: 121346 | W37: 176400
B38: Lease ROU | F38: 13294 | G38: 13555 | H38: 14058 | I38: 14812 | J38: 14922 | K38: 15505 | L38: 15662 | M38: 17372 | N38: 20404 | U38: 13294 | V38: 14922 | W38: 20404
B39: Goodwill | F39: 20654 | G39: 20654 | H39: 20654 | I39: 20654 | J39: 20654 | K39: 20654 | L39: 20654 | M39: 21158 | N39: 24534 | U39: 20654 | V39: 20654 | W39: 24534
B40: Other assets | F40: 7582 | G40: 8179 | H40: 9929 | I40: 11642 | J40: 13017 | K40: 14092 | L40: 15788 | M40: 6852 | N40: 8437 | U40: 7582 | V40: 13017 | W40: 8437
B41: Total Assets | F41: =SUM(F34:F40) -> 229623 | G41: =SUM(G34:G40) -> 222844 | H41: =SUM(H34:H40) -> 230238 | I41: =SUM(I34:I40) -> 256408 | J41: =SUM(J34:J40) -> 276054 | K41: =SUM(K34:K40) -> 280213 | L41: =SUM(L34:L40) -> 294744 | M41: =SUM(M34:M40) -> 303844 | ... P41: =SUM(P34:P40) -> 0 | U41: =SUM(U34:U40) -> 229623 | V41: =SUM(V34:V40) -> 276054 | W41: =SUM(W34:W40) -> 366021 | X41: =SUM(X34:X40) -> 0 | Y41: =SUM(Y34:Y40) -> 0
B42: A/P | F42: 4849 | G42: 3785 | H42: 3173 | I42: 7656 | J42: 7687 | K42: 8512 | L42: 10271 | M42: 7798 | N42: 8894 | U42: 4849 | V42: 7687 | W42: 8894
B43: Lease | F43: =1623+17226 -> 18849 | G43: =1676+17570 -> 19246 | H43: =1917+17685 -> 19602 | I43: =2016+18208 -> 20224 | J43: =1942+18292 -> 20234 | K43: =1976+18714 -> 20690 | L43: =1977+18751 -> 20728 | M43: =2113+20113 -> 22226 | N43: =2213+22940 -> 25153 | U43: =1623+17226 -> 18849 | V43: =1942+18292 -> 20234 | W43: =2213+22940 -> 25153
B44: OCL | F44: 25488 | G44: 22640 | H44: 21914 | I44: 23658 | J44: 23967 | K44: 23402 | L44: 25057 | M44: 27047 | N44: 30729 | U44: 25488 | V44: 23967 | W44: 30729
...

Sheet MSFT
A1: Main | AD1: 44742 | AF1: 44926 | AH1: 45107 | AJ1: 45291 | AL1: 45473 | AN1: 45657
C2: Q116 | D2: Q216 | E2: Q316 | F2: Q416 | G2: Q117 | H2: Q217 | I2: Q317 | J2: Q417 | K2: Q118 | L2: Q218 | M2: Q318 | N2: Q418 | O2: Q119 | P2: Q219 | Q2: Q319 | R2: Q419 | S2: Q120 | T2: Q220 | U2: Q320 | V2: Q420 | W2: Q121 | X2: Q221 | Y2: Q321 | Z2: Q421 | AA2: Q122 | AB2: Q222 | AC2: Q322 | AD2: Q422 | AE2: Q123 | AF2: Q223 | AG2: Q323 | AH2: Q423 | AI2: Q124 | AJ2: Q224 | AK2: Q324 | AL2: Q424 | AM2: Q125 | AN2: Q225 | AO2: Q325 | AP2: Q425 | AQ2: Q126 | AR2: Q226 | AS2: Q326 | AV2: FY16 | AW2: FY17 | AX2: FY18 | AY2: FY19 | AZ2: FY20 | BA2: FY21 | BB2: FY22 | BC2: FY23 | BD2: FY24 | BE2: FY25 | BF2: FY26 | BG2: FY27 | BH2: FY28 | BI2: FY29 | BJ2: FY30 | BK2: FY31 | BL2: FY32 | BM2: FY33 | BN2: FY34 | BO2: FY35 | BP2: FY36 | BQ2: FY37 | BR2: FY38 | BS2: FY39 | BT2: FY40 | BU2: FY41 | BV2: FY42 | BW2: FY43 | BX2: FY44 | BY2: FY45 | BZ2: FY46 | CA2: FY47 | CB2: FY48 | CC2: FY49 | CD2: FY50 | CE2: FY51 | CF2: FY52 | CG2: FY53 | CH2: FY54 | CI2: FY55 | CJ2: FY56 | CK2: FY57 | CL2: FY58 | CM2: FY59 | CN2: FY60 | CO2: FY61 | CP2: FY62 | CQ2: FY63 | CR2: FY64 | CS2: FY65 | CT2: FY66 | CU2: FY67 | CV2: FY68 | CW2: FY69 | CX2: FY70 | CY2: FY71 | CZ2: FY72 | DA2: FY73 | DB2: FY74 | DC2: FY75 | DD2: FY76 | DE2: FY77 | DF2: FY78 | DG2: FY79 | DH2: FY80 | DI2: FY81 | DJ2: FY82 | DK2: FY83 | DL2: FY84 | DM2: FY85 | DN2: FY86 | DO2: FY87 | DP2: FY88 | DQ2: FY89 | DR2: FY90 | DS2: FY91 | DT2: FY92 | DU2: FY93 | DV2: FY94 | DW2: FY95 | DX2: FY96 | DY2: FY97 | DZ2: FY98 | EA2: FY99 | EB2: FY100 | EC2: FY101 | ED2: FY102 | EE2: FY103 | EF2: FY104 | EG2: FY105 | EH2: FY106 | EI2: FY107 | EJ2: FY108 | EK2: FY109 | EL2: FY110 | EM2: FY111 | EN2: FY112 | EO2: FY113 | EP2: FY114 | EQ2: FY115 | ER2: FY116 | ES2: FY117 | ET2: FY118 | EU2: FY119 | EV2: FY120 | EW2: FY121 | EX2: FY122 | EY2: FY123 | EZ2: FY124 | FA2: FY125 | FB2: FY126 | FC2: FY127 | FD2: FY128 | FE2: FY129 | FF2: FY130 | FG2: FY131 | FH2: FY132 | FI2: FY133 | FJ2: FY134 | FK2: FY135 | FL2: FY136 | FM2: FY137 | FN2: FY138 | FO2: FY139 | FP2: FY140 | FQ2: FY141 | FR2: FY142 | FS2: FY143 | FT2: FY144 | FU2: FY145 | FV2: FY146 | FW2: FY147 | FX2: FY148 | FY2: FY149 | FZ2: FY150 | GA2: FY151 | GB2: FY152 | GC2: FY153 | GD2: FY154 | GE2: FY155 | GF2: FY156 | GG2: FY157 | GH2: FY158 | GI2: FY159 | GJ2: FY160 | GK2: FY161 | GL2: FY162 | GM2: FY163 | GN2: FY164 | GO2: FY165 | GP2: FY166 | GQ2: FY167 | GR2: FY168 | GS2: FY169 | GT2: FY170 | GU2: FY171 | GV2: FY172 | GW2: FY173 | GX2: FY174 | GY2: FY175 | GZ2: FY176 | HA2: FY177 | HB2: FY178 | HC2: FY179 | HD2: FY180 | HE2: FY181 | HF2: FY182 | HG2: FY183 | HH2: FY184 | HI2: FY185 | HJ2: FY186 | HK2: FY187 | HL2: FY188 | HM2: FY189 | HN2: FY190 | HO2: FY191 | HP2: FY192 | HQ2: FY193 | HR2: FY194 | HS2: FY195 | HT2: FY196 | HU2: FY197 | HV2: FY198 | HW2: FY199 | HX2: FY200 | HY2: FY201 | HZ2: FY202 | IA2: FY203 | IB2: FY204 | IC2: FY205 | ID2: FY206 | IE2: FY207 | IF2: FY208 | IG2: FY209 | IH2: FY210 | II2: FY211 | IJ2: FY212 | IK2: FY213 | IL2: FY214 | IM2: FY215 | IN2: FY216 | IO2: FY217 | IP2: FY218 | IQ2: FY219 | IR2: FY220 | IS2: FY221 | IT2: FY222 | IU2: FY223 | IV2: FY224 | IW2: FY225 | IX2: FY226 | IY2: FY227 | IZ2: FY228 | JA2: FY229 | JB2: FY230 | JC2: FY231 | JD2: FY232 | JE2: FY233 | JF2: FY234 | JG2: FY235 | JH2: FY236 | JI2: FY237 | JJ2: FY238 | JK2: FY239 | JL2: FY240 | JM2: FY241 | JN2: FY242 | JO2: FY243 | JP2: FY244 | JQ2: FY245 | JR2: FY246 | JS2: FY247 | JT2: FY248 | JU2: FY249 | JV2: FY250 | JW2: FY251 | JX2: FY252 | JY2: FY253 | JZ2: FY254 | KA2: FY255 | KB2: FY256 | KC2: FY257 | KD2: FY258 | KE2: FY259 | KF2: FY260 | KG2: FY261 | KH2: FY262 | KI2: FY263 | KJ2: FY264 | KK2: FY265 | KL2: FY266 | KM2: FY267 | KN2: FY268 | KO2: FY269 | KP2: FY270 | KQ2: FY271 | KR2: FY272 | KS2: FY273 | KT2: FY274 | KU2: FY275 | KV2: FY276 | KW2: FY277 | KX2: FY278 | KY2: FY279 | KZ2: FY280 | LA2: FY281 | LB2: FY282 | LC2: FY283 | LD2: FY284 | LE2: FY285 | LF2: FY286 | LG2: FY287 | LH2: FY288 | LI2: FY289 | LJ2: FY290 | LK2: FY291 | LL2: FY292 | LM2: FY293 | LN2: FY294 | LO2: FY295 | LP2: FY296 | LQ2: FY297 | LR2: FY298 | LS2: FY299 | LT2: FY300 | LU2: FY301 | LV2: FY302 | LW2: FY303 | LX2: FY304 | LY2: FY305 | LZ2: FY306 | MA2: FY307 | MB2: FY308 | MC2: FY309 | MD2: FY310 | ME2: FY311 | MF2: FY312 | MG2: FY313 | MH2: FY314 | MI2: FY315 | MJ2: FY316 | MK2: FY317 | ML2: FY318 | MM2: FY319 | MN2: FY320 | MO2: FY321 | MP2: FY322 | MQ2: FY323 | MR2: FY324 | MS2: FY325 | MT2: FY326 | MU2: FY327 | MV2: FY328 | MW2: FY329 | MX2: FY330 | MY2: FY331 | MZ2: FY332 | NA2: FY333 | NB2: FY334 | NC2: FY335 | ND2: FY336 | NE2: FY337 | NF2: FY338 | NG2: FY339 | NH2: FY340 | NI2: FY341 | NJ2: FY342 | NK2: FY343 | NL2: FY344 | NM2: FY345 | NN2: FY346 | NO2: FY347 | NP2: FY348 | NQ2: FY349 | NR2: FY350 | NS2: FY351 | NT2: FY352 | NU2: FY353 | NV2: FY354 | NW2: FY355 | NX2: FY356 | NY2: FY357 | NZ2: FY358 | OA2: FY359 | OB2: FY360 | OC2: FY361 | OD2: FY362 | OE2: FY363 | OF2: FY364 | OG2: FY365 | OH2: FY366 | OI2: FY367 | OJ2: FY368 | OK2: FY369 | OL2: FY370 | OM2: FY371 | ON2: FY372 | OO2: FY373 | OP2: FY374 | OQ2: FY375 | OR2: FY376 | OS2: FY377 | OT2: FY378 | OU2: FY379 | OV2: FY380 | OW2: FY381 | OX2: FY382 | OY2: FY383 | OZ2: FY384 | PA2: FY385 | PB2: FY386 | PC2: FY387 | PD2: FY388 | PE2: FY389 | PF2: FY390 | PG2: FY391 | PH2: FY392 | PI2: FY393 | PJ2: FY394 | PK2: FY395 | PL2: FY396 | PM2: FY397 | PN2: FY398 | PO2: FY399 | PP2: FY400 | PQ2: FY401 | PR2: FY402 | PS2: FY403 | PT2: FY404 | PU2: FY405 | PV2: FY406 | PW2: FY407 | PX2: FY408 | PY2: FY409 | PZ2: FY410 | QA2: FY411 | QB2: FY412 | QC2: FY413 | QD2: FY414 | QE2: FY415 | QF2: FY416 | QG2: FY417 | QH2: FY418 | QI2: FY419 | QJ2: FY420 | QK2: FY421 | QL2: FY422 | QM2: FY423 | QN2: FY424 | QO2: FY425 | QP2: FY426 | QQ2: FY427 | QR2: FY428 | QS2: FY429 | QT2: FY430 | QU2: FY431 | QV2: FY432 | QW2: FY433 | QX2: FY434 | QY2: FY435 | QZ2: FY436 | RA2: FY437 | RB2: FY438 | RC2: FY439 | RD2: FY440 | RE2: FY441 | RF2: FY442 | RG2: FY443 | RH2: FY444 | RI2: FY445 | RJ2: FY446 | RK2: FY447 | RL2: FY448 | RM2: FY449 | RN2: FY450 | RO2: FY451 | RP2: FY452 | RQ2: FY453 | RR2: FY454 | RS2: FY455 | RT2: FY456 | RU2: FY457 | RV2: FY458 | RW2: FY459 | RX2: FY460 | RY2: FY461 | RZ2: FY462 | SA2: FY463 | SB2: FY464 | SC2: FY465 | SD2: FY466 | SE2: FY467 | SF2: FY468 | SG2: FY469 | SH2: FY470 | SI2: FY471 | SJ2: FY472 | SK2: FY473 | SL2: FY474 | SM2: FY475 | SN2: FY476 | SO2: FY477 | SP2: FY478 | SQ2: FY479 | SR2: FY480 | SS2: FY481 | ST2: FY482 | SU2: FY483 | SV2: FY484 | SW2: FY485 | SX2: FY486 | SY2: FY487 | SZ2: FY488 | TA2: FY489
B3: Server and cloud | AE3: 14948 | AF3: 16012 | AG3: 16187 | AH3: 17860 | AI3: 18062 | AJ3: 19597 | AK3: 20266 | AL3: 21903 | AM3: 22155 | AN3: 23641 | AO3: 24761 | AP3: 27878 | AQ3: 28872 | AR3: 30865 | BC3: 65007 | BD3: 79828 | BE3: =SUM(AM3:AP3) -> 98435
B4: MS 365 Commercial and cloud | AE4: 15502 | AF4: 15774 | AG4: 17195 | AH4: 18478 | AI4: 18044 | AJ4: 18321 | AK4: 19712 | AL4: 20892 | AM4: 20449 | AN4: 21117 | AO4: 21883 | AP4: 24318 | AQ4: 23966 | AR4: 24524 | BC4: 66949 | BD4: 76969 | BE4: =SUM(AM4:AP4) -> 87767
B5: Gaming | AE5: 3610 | AF5: 4758 | AG5: 3607 | AH5: 3491 | AI5: 3919 | AJ5: 7111 | AK5: 5451 | AL5: 5022 | AM5: 5621 | AN5: 6581 | AO5: 5721 | AP5: 5532 | AQ5: 5508 | AR5: 5958 | BB5: 16230 | BC5: 15466 | BD5: 21503 | BE5: =SUM(AM5:AP5) -> 23455
B6: LinkedIn | AE6: 3628 | AF6: 3833 | AG6: 3659 | AH6: 3869 | AI6: 3913 | AJ6: 4195 | AK6: 4013 | AL6: 4251 | AM6: 4292 | AN6: 4587 | AO6: 4311 | AP6: 4622 | AQ6: 4714 | AR6: 5082 | BB6: 13631 | BC6: 14989 | BD6: 16372 | BE6: =SUM(AM6:AP6) -> 17812
B7: Windows and Devices | AE7: 4593 | AF7: 4219 | AG7: 4040 | AH7: 4295 | AI7: 4340 | AJ7: 4363 | AK7: 4098 | AL7: 4225 | AM7: 4329 | AN7: 4512 | AO7: 4144 | AP7: 4329 | AQ7: 4551 | AR7: 4479 | BB7: =24732+7306 -> 32038 | BC7: 17147 | BD7: 17026 | BE7: =SUM(AM7:AP7) -> 17314
B8: Search and news ads | AE8: 2913 | AF8: 3209 | AG8: 3034 | AH8: 2969 | AI8: 3018 | AJ8: 3168 | AK8: 3055 | AL8: 3065 | AM8: 3225 | AN8: 3558 | AO8: 3504 | AP8: 3591 | AQ8: 3697 | AR8: 3812 | BB8: 11526 | BC8: 12125 | BD8: 12306 | BE8: =SUM(AM8:AP8) -> 13878
B9: Enterprise | AE9: 1929 | AF9: 1907 | AG9: 2047 | AH9: 2017 | AI9: 1944 | AJ9: 1917 | AK9: 1861 | AL9: 1872 | AM9: 1928 | AN9: 1892 | AO9: 1929 | AP9: 2136 | AQ9: 2204 | AR9: 2305 | BB9: 7605 | BC9: 7900 | BD9: 7594 | BE9: =SUM(AM9:AP9) -> 7885
B10: Dynamics and cloud | AE10: 1345 | AF10: 1391 | AG10: 1484 | AH10: 1576 | AI10: 1626 | AJ10: 1659 | AK10: 1740 | AL10: 1806 | AM10: 1849 | AN10: 1913 | AO10: 1946 | AP10: 1994 | AQ10: 2136 | AR10: 2204 | BB10: 4687 | BC10: 5796 | BD10: 6831 | BE10: =SUM(AM10:AP10) -> 7702
B11: MS 365 Consumer and cloud | AE11: 1599 | AF11: 1605 | AG11: 1586 | AH11: 1627 | AI11: 1643 | AJ11: 1679 | AK11: 1648 | AL11: 1678 | AM11: 1727 | AN11: 1821 | AO11: 1821 | AP11: 2035 | AQ11: 2022 | AR11: 2038 | BC11: 6417 | BD11: 6648 | BE11: =SUM(AM11:AP11) -> 7404
B12: Other | AE12: 55 | AF12: 39 | AG12: 18 | AH12: 7 | AI12: 8 | AJ12: 10 | AK12: 14 | AL12: 13 | AM12: 10 | AN12: 10 | AO12: 46 | AP12: 6 | AQ12: 3 | AR12: 6 | BB12: 45 | BC12: 119 | BD12: 45 | BE12: =SUM(AM12:AP12) -> 72
AX13: =SUM(AX3:AX12) -> 0 | AY13: =SUM(AY3:AY12) -> 0 | AZ13: =SUM(AZ3:AZ12) -> 0 | BA13: =SUM(BA3:BA12) -> 0 | BB13: =SUM(BB3:BB12) -> 85762 | BC13: =SUM(BC3:BC12) -> 211915 | BD13: =SUM(BD3:BD12) -> 245122 | BE13: =SUM(BE3:BE12) -> 281724
B14: Y/Y stats
B15: Server and cloud | AI15: =AI3/AE3-1 -> 0.20832218 | AJ15: =AJ3/AF3-1 -> 0.22389458 | AK15: =AK3/AG3-1 -> 0.25199234 | AL15: =AL3/AH3-1 -> 0.22637178 | AM15: =AM3/AI3-1 -> 0.22660835 | AN15: =AN3/AJ3-1 -> 0.20635812 | AO15: =AO3/AK3-1 -> 0.22180006 | AP15: =AP3/AL3-1 -> 0.27279368 | ... AR15: =AR3/AN3-1 -> 0.30557083 | BD15: =BD3/BC3-1 -> 0.22799083 | BE15: =BE3/BD3-1 -> 0.23308864
B16: MS 365 Commercial and cloud | AI16: =AI4/AE4-1 -> 0.16397884 | AJ16: =AJ4/AF4-1 -> 0.16146824 | AK16: =AK4/AG4-1 -> 0.14637976 | AL16: =AL4/AH4-1 -> 0.13064184 | AM16: =AM4/AI4-1 -> 0.1332853 | AN16: =AN4/AJ4-1 -> 0.15261176 | AO16: =AO4/AK4-1 -> 0.11013596 | AP16: =AP4/AL4-1 -> 0.16398621 | ... AR16: =AR4/AN4-1 -> 0.16133921 | BD16: =BD4/BC4-1 -> 0.14966616 | BE16: =BE4/BD4-1 -> 0.14029025
B17: Gaming | AI17: =AI5/AE5-1 -> 0.085595568 | AJ17: =AJ5/AF5-1 -> 0.49453552 | AK17: =AK5/AG5-1 -> 0.51122817 | AL17: =AL5/AH5-1 -> 0.43855629 | AM17: =AM5/AI5-1 -> 0.43429446 | AN17: =AN5/AJ5-1 -> -0.074532415 | AO17: =AO5/AK5-1 -> 0.049532196 | AP17: =AP5/AL5-1 -> 0.10155317 | ... AR17: =AR5/AN5-1 -> -0.094666464 | BD17: =BD5/BC5-1 -> 0.3903401 | BE17: =BE5/BD5-1 -> 0.090778031
B18: LinkedIn | AI18: =AI6/AE6-1 -> 0.078555678 | AJ18: =AJ6/AF6-1 -> 0.094442995 | AK18: =AK6/AG6-1 -> 0.096747745 | AL18: =AL6/AH6-1 -> 0.098733523 | AM18: =AM6/AI6-1 -> 0.096856632 | AN18: =AN6/AJ6-1 -> 0.093444577 | AO18: =AO6/AK6-1 -> 0.074258659 | AP18: =AP6/AL6-1 -> 0.087273583 | ... AR18: =AR6/AN6-1 -> 0.10791367 | BD18: =BD6/BC6-1 -> 0.092267663 | BE18: =BE6/BD6-1 -> 0.087955045
B19: Windows and Devices | AI19: =AI7/AE7-1 -> -0.055083823 | AJ19: =AJ7/AF7-1 -> 0.034131311 | AK19: =AK7/AG7-1 -> 0.014356436 | AL19: =AL7/AH7-1 -> -0.016298021 | AM19: =AM7/AI7-1 -> -0.0025345622 | AN19: =AN7/AJ7-1 -> 0.034150814 | AO19: =AO7/AK7-1 -> 0.011224988 | AP19: =AP7/AL7-1 -> 0.024615385 | ... AR19: =AR7/AN7-1 -> -0.0073138298 | BD19: =BD7/BC7-1 -> -0.007056628 | BE19: =BE7/BD7-1 -> 0.016915306
B20: Search and news ads | AI20: =AI8/AE8-1 -> 0.036045314 | AJ20: =AJ8/AF8-1 -> -0.012776566 | AK20: =AK8/AG8-1 -> 0.0069215557 | AL20: =AL8/AH8-1 -> 0.032334119 | AM20: =AM8/AI8-1 -> 0.068588469 | AN20: =AN8/AJ8-1 -> 0.12310606 | AO20: =AO8/AK8-1 -> 0.14697218 | AP20: =AP8/AL8-1 -> 0.17161501 | ... AR20: =AR8/AN8-1 -> 0.07138842 | BD20: =BD8/BC8-1 -> 0.014927835 | BE20: =BE8/BD8-1 -> 0.12774256
B21: Enterprise | AI21: =AI9/AE9-1 -> 0.0077760498 | AJ21: =AJ9/AF9-1 -> 0.0052438385 | AK21: =AK9/AG9-1 -> -0.09086468 | AL21: =AL9/AH9-1 -> -0.071888944 | AM21: =AM9/AI9-1 -> -0.0082304527 | AN21: =AN9/AJ9-1 -> -0.01304121 | AO21: =AO9/AK9-1 -> 0.036539495 | AP21: =AP9/AL9-1 -> 0.14102564 | ... AR21: =AR9/AN9-1 -> 0.21828753 | BD21: =BD9/BC9-1 -> -0.038734177 | BE21: =BE9/BD9-1 -> 0.038319726
B22: Dynamics and cloud | AI22: =AI10/AE10-1 -> 0.20892193 | AJ22: =AJ10/AF10-1 -> 0.19266715 | AK22: =AK10/AG10-1 -> 0.17250674 | AL22: =AL10/AH10-1 -> 0.14593909 | AM22: =AM10/AI10-1 -> 0.13714637 | AN22: =AN10/AJ10-1 -> 0.15310428 | AO22: =AO10/AK10-1 -> 0.1183908 | AP22: =AP10/AL10-1 -> 0.10409745 | ... AR22: =AR10/AN10-1 -> 0.15211709 | BD22: =BD10/BC10-1 -> 0.17857143 | BE22: =BE10/BD10-1 -> 0.12750695
B23: MS 365 Consumer and cloud | AI23: =AI11/AE11-1 -> 0.027517198 | AJ23: =AJ11/AF11-1 -> 0.046105919 | AK23: =AK11/AG11-1 -> 0.039092055 | AL23: =AL11/AH11-1 -> 0.031346036 | AM23: =AM11/AI11-1 -> 0.051125989 | AN23: =AN11/AJ11-1 -> 0.084574151 | AO23: =AO11/AK11-1 -> 0.10497573 | AP23: =AP11/AL11-1 -> 0.21275328 | ... AR23: =AR11/AN11-1 -> 0.11916529 | BD23: =BD11/BC11-1 -> 0.03599813 | BE23: =BE11/BD11-1 -> 0.11371841
B26: Product | C26: 15750 | D26: 19431 | E26: 15307 | F26: 16848 | G26: 14968 | H26: 18273 | I26: 14513 | J26: 16057 | K26: 14298 | L26: 17926 | M26: 15114 | N26: 17159 | O26: 17299 | P26: 16219 | Q26: 15448 | R26: 17103 | S26: 15768 | T26: 18255 | U26: 15871 | V26: 18147 | W26: 15803 | X26: 19460 | Y26: 16873 | Z26: 18938 | AA26: 16631 | AB26: 20779 | AC26: 17366 | AD26: 17956 | AE26: 15741 | AF26: 16517 | AG26: 15588 | AH26: 16853 | AI26: 15535 | AJ26: 18941 | AK26: 17080 | AL26: 13217 | AM26: 15272 | AN26: 16219 | AO26: 15319 | AP26: 17136 | AQ26: 15922 | AR26: 16451 | AV26: 67336 | AW26: 63811 | AX26: 64497 | AY26: 66069 | AZ26: 68041 | BA26: 71074 | BB26: 72732 | BC26: 64699 | BD26: 64773 | BE26: =AM26+AN26+AO26+AP26 -> 63946
B27: Service and Other | C27: 5160 | D27: 5822 | E27: 6210 | F27: 6626 | G27: 6960 | H27: 7553 | I27: 8699 | J27: 9548 | K27: 10240 | L27: 10992 | M27: 11705 | N27: 12926 | O27: 11785 | P27: 16252 | Q27: 15123 | R27: 16614 | S27: 17287 | T27: 18651 | U27: 19150 | V27: 19886 | W27: 21351 | X27: 23616 | Y27: 24833 | Z27: 27214 | AA27: 28686 | AB27: 30949 | AC27: 31994 | AD27: 33909 | AE27: 34381 | AF27: 36230 | AG27: 37269 | AH27: 39336 | AI27: 40982 | AJ27: 43079 | AK27: 44778 | AL27: 51510 | AM27: 50313 | AN27: 53413 | AO27: 54747 | AP27: 59305 | AQ27: 61751 | AR27: 64822 | AV27: 23818 | AW27: 32760 | AX27: 45863 | AY27: 59774 | AZ27: 74974 | BA27: 97014 | BB27: 125538 | BC27: 147216 | BD27: 180349 | BE27: =AM27+AN27+AO27+AP27 -> 217778
B28: Revenue | C28: =SUM(C26:C27) -> 20910 | D28: =SUM(D26:D27) -> 25253 | E28: =SUM(E26:E27) -> 21517 | F28: =SUM(F26:F27) -> 23474 | G28: =SUM(G26:G27) -> 21928 | H28: =SUM(H26:H27) -> 25826 | I28: =SUM(I26:I27) -> 23212 | J28: =SUM(J26:J27) -> 25605 | ... AR28: =SUM(AR26:AR27) -> 81273 | AV28: =SUM(AV26:AV27) -> 91154 | AW28: =SUM(AW26:AW27) -> 96571 | AX28: =SUM(AX26:AX27) -> 110360 | AY28: =SUM(AY26:AY27) -> 125843 | AZ28: =SUM(AZ26:AZ27) -> 143015 | BA28: =SUM(BA26:BA27) -> 168088 | BB28: =SUM(BB26:BB27) -> 198270 | BC28: =SUM(BC26:BC27) -> 211915 | BD28: =SUM(BD26:BD27) -> 245122 | BE28: =AM28+AN28+AO28+AP28 -> 281724 | BF28: =BE28*1.13 -> 318348.12 | BG28: =BF28*1.1 -> 350182.93 | BH28: =BG28*1.1 -> 385201.23
B29: Product COGS | C29: 4035 | D29: 6268 | E29: 3801 | F29: 3776 | G29: 3581 | H29: 5378 | I29: 3075 | J29: 3141 | K29: 2980 | L29: 5498 | M29: 3425 | N29: 3517 | O29: 3649 | P29: 5885 | Q29: 3441 | R29: 3298 | S29: 3305 | T29: 4966 | U29: 3376 | V29: 4370 | W29: 3597 | X29: 6058 | Y29: 4277 | Z29: 4287 | AA29: 3792 | AB29: 6331 | AC29: 4584 | AD29: 4357 | AE29: 4302 | AF29: 5690 | AG29: 3941 | AH29: 3871 | AI29: 3531 | AJ29: 5964 | AK29: 4339 | AL29: 1438 | AM29: 3294 | AN29: 3856 | AO29: 3037 | AP29: 3314 | AQ29: 2922 | AR29: 3505 | AV29: 17880 | AW29: 15175 | AX29: 15420 | AY29: 16273 | AZ29: 16017 | BA29: 18219 | BB29: 19064 | BC29: 17804 | BD29: 15272 | BE29: =AM29+AN29+AO29+AP29 -> 13501
B30: Services COGS | C30: 3172 | D30: 3604 | E30: 3921 | F30: 4203 | G30: 4263 | H30: 4523 | I30: 4985 | J30: 5315 | K30: 5298 | L30: 5566 | M30: 5844 | N30: 6225 | O30: 6256 | P30: 6538 | Q30: 6729 | R30: 7114 | S30: 7101 | T30: 7392 | U30: 7599 | V30: 7969 | W30: 7405 | X30: 8136 | Y30: 8768 | Z30: 9704 | AA30: 9854 | AB30: 10629 | AC30: 11031 | AD30: 12072 | AE30: 11150 | AF30: 11798 | AG30: 12187 | AH30: 12924 | AI30: 12771 | AJ30: 13659 | AK30: 14166 | AL30: 18246 | AM30: 16805 | AN30: 17943 | AO30: 18882 | AP30: 20700 | AQ30: 21121 | AR30: 22473 | AV30: 14900 | AW30: 19086 | AX30: 22933 | AY30: 26637 | AZ30: 30061 | BA30: 34013 | BB30: 43586 | BC30: 48059 | BD30: 58842 | BE30: =AM30+AN30+AO30+AP30 -> 74330
B31: COGS | C31: =SUM(C29:C30) -> 7207 | D31: =SUM(D29:D30) -> 9872 | E31: =SUM(E29:E30) -> 7722 | F31: =SUM(F29:F30) -> 7979 | G31: =SUM(G29:G30) -> 7844 | H31: =SUM(H29:H30) -> 9901 | I31: =SUM(I29:I30) -> 8060 | J31: =SUM(J29:J30) -> 8456 | ... AR31: =SUM(AR29:AR30) -> 25978 | AV31: =SUM(AV29:AV30) -> 32780 | AW31: =SUM(AW29:AW30) -> 34261 | AX31: =SUM(AX29:AX30) -> 38353 | AY31: =SUM(AY29:AY30) -> 42910 | AZ31: =SUM(AZ29:AZ30) -> 46078 | BA31: =SUM(BA29:BA30) -> 52232 | BB31: =SUM(BB29:BB30) -> 62650 | BC31: =SUM(BC29:BC30) -> 65863 | ... BE31: =SUM(BE29:BE30) -> 87831
B32: Gross Profit | C32: =C28-C31 -> 13703 | D32: =D28-D31 -> 15381 | E32: =E28-E31 -> 13795 | F32: =F28-F31 -> 15495 | G32: =G28-G31 -> 14084 | H32: =H28-H31 -> 15925 | I32: =I28-I31 -> 15152 | J32: =J28-J31 -> 17149 | ... AR32: =AR28-AR31 -> 55295 | AV32: =AV28-AV31 -> 58374 | AW32: =AW28-AW31 -> 62310 | AX32: =AX28-AX31 -> 72007 | AY32: =AY28-AY31 -> 82933 | AZ32: =AZ28-AZ31 -> 96937 | BA32: =BA28-BA31 -> 115856 | BB32: =BB28-BB31 -> 135620 | BC32: =BC28-BC31 -> 146052 | ... BE32: =BE28-BE31 -> 193893 | BF32: =BF28*0.7 -> 222843.68 | BG32: =BG28*0.7 -> 245128.05 | BH32: =BH28*0.7 -> 269640.86
B33: R&D | C33: 2962 | D33: 2900 | E33: 2980 | F33: 3146 | G33: 3106 | H33: 3062 | I33: 3355 | J33: 3514 | K33: 3574 | L33: 3504 | M33: 3715 | N33: 3933 | O33: 3977 | P33: 4070 | Q33: 4316 | R33: 4513 | S33: 4565 | T33: 4603 | U33: 4887 | V33: 5214 | W33: 4926 | X33: 4899 | Y33: 5204 | Z33: 5687 | AA33: 5599 | AB33: 5758 | AC33: 6306 | AD33: 6849 | AE33: 6628 | AF33: 6844 | AG33: 6984 | AH33: 6739 | AI33: 6659 | AJ33: 7142 | AK33: 7653 | AL33: 805 | AM33: 7544 | AN33: 7917 | AO33: 8198 | AP33: 8829 | AQ33: 8146 | AR33: 8504 | AV33: 11988 | AW33: 13037 | AX33: 14726 | AY33: 16876 | AZ33: 19269 | BA33: 20716 | BB33: 24512 | BC33: 27195 | BD33: 29510 | BE33: =AM33+AN33+AO33+AP33 -> 32488
B34: S&M | C34: 3341 | D34: 3954 | E34: 3398 | F34: 3942 | G34: 3218 | H34: 4079 | I34: 3872 | J34: 4292 | K34: 3812 | L34: 4562 | M34: 4335 | N34: 4760 | O34: 4098 | P34: 4588 | Q34: 4565 | R34: 4962 | S34: 4337 | T34: 4933 | U34: 4911 | V34: 5417 | W34: 4231 | X34: 4947 | Y34: 5082 | Z34: 5857 | AA34: 4547 | AB34: 5379 | AC34: 5595 | AD34: 6304 | AE34: 5126 | AF34: 5679 | AG34: 5750 | AH34: 6204 | AI34: 5187 | AJ34: 6246 | AK34: 6207 | AL34: 6816 | AM34: 5717 | AN34: 6440 | AO34: 6212 | AP34: 7285 | AQ34: 5717 | AR34: 6584 | AV34: 14635 | AW34: 15461 | AX34: 17469 | AY34: 18213 | AZ34: 19598 | BA34: 20117 | BB34: 21825 | BC34: 22759 | BD34: 24456 | BE34: =AM34+AN34+AO34+AP34 -> 25654
B35: G&A | C35: 1084 | D35: 1038 | E35: 1140 | F35: =1301+1110 -> 2411 | G35: 1045 | H35: 879 | I35: 1202 | J35: =1355+306 -> 1661 | K35: 1166 | L35: 1109 | M35: 1208 | N35: 1271 | O35: 1149 | P35: 1132 | Q35: 1179 | R35: 1425 | S35: 1061 | T35: 1121 | U35: 1273 | V35: 1656 | W35: 1119 | X35: 1139 | Y35: 1327 | Z35: 1522 | AA35: 1287 | AB35: 1384 | AC35: 1480 | AD35: 1749 | AE35: 1398 | AF35: 2337 | AG35: 1643 | AH35: 2197 | AI35: 1474 | AJ35: 1977 | AK35: 1912 | AL35: 2246 | AM35: 1673 | AN35: 1823 | AO35: 1737 | AP35: 1990 | AQ35: 1806 | AR35: 1932 | AV35: =4563+1110 -> 5673 | AW35: =4481+306 -> 4787 | AX35: 4754 | AY35: 4885 | AZ35: 5111 | BA35: 5107 | BB35: 5900 | BC35: 7575 | BD35: 7609 | BE35: =AM35+AN35+AO35+AP35 -> 7223
B36: Operating Expenses | C36: =SUM(C33:C35) -> 7387 | D36: =SUM(D33:D35) -> 7892 | E36: =SUM(E33:E35) -> 7518 | F36: =SUM(F33:F35) -> 9499 | G36: =SUM(G33:G35) -> 7369 | H36: =SUM(H33:H35) -> 8020 | I36: =SUM(I33:I35) -> 8429 | J36: =SUM(J33:J35) -> 9467 | ... AR36: =SUM(AR33:AR35) -> 17020 | AV36: =SUM(AV33:AV35) -> 32296 | AW36: =SUM(AW33:AW35) -> 33285 | AX36: =SUM(AX33:AX35) -> 36949 | AY36: =SUM(AY33:AY35) -> 39974 | AZ36: =SUM(AZ33:AZ35) -> 43978 | BA36: =SUM(BA33:BA35) -> 45940 | BB36: =SUM(BB33:BB35) -> 52237 | BC36: =SUM(BC33:BC35) -> 57529 | ... BE36: =SUM(BE33:BE35) -> 65365 | BF36: =BE36*1.05 -> 68633.25 | BG36: =BF36*1.05 -> 72064.913 | BH36: =BG36*1.05 -> 75668.158
B37: Operating Income | C37: =C32-C36 -> 6316 | D37: =D32-D36 -> 7489 | E37: =E32-E36 -> 6277 | F37: =F32-F36 -> 5996 | G37: =G32-G36 -> 6715 | H37: =H32-H36 -> 7905 | I37: =I32-I36 -> 6723 | J37: =J32-J36 -> 7682 | ... AR37: =AR32-AR36 -> 38275 | AV37: =AV32-AV36 -> 26078 | AW37: =AW32-AW36 -> 29025 | AX37: =AX32-AX36 -> 35058 | AY37: =AY32-AY36 -> 42959 | AZ37: =AZ32-AZ36 -> 52959 | BA37: =BA32-BA36 -> 69916 | BB37: =BB32-BB36 -> 83383 | BC37: =BC32-BC36 -> 88523 | ... BH37: =BH32-BH36 -> 193972.7
B38: Other expenses | C38: -295 | D38: -176 | E38: -212 | F38: 244 | G38: 112 | H38: 117 | I38: 371 | J38: 276 | K38: 276 | L38: 490 | M38: 349 | N38: 301 | O38: 266 | P38: 127 | Q38: 145 | R38: 191 | S38: 0 | T38: 194 | U38: -132 | V38: 15 | W38: 248 | X38: 440 | Y38: 188 | Z38: 310 | AA38: 286 | AB38: 268 | AC38: -174 | AD38: -47 | AE38: 54 | AF38: -60 | AG38: 321 | AH38: 473 | AI38: 389 | AJ38: -506 | AK38: -854 | AL38: -675 | AM38: -283 | AN38: -2288 | AO38: -623 | AP38: -1707 | AQ38: -3660 | AR38: 9971 | AV38: -439 | AW38: 876 | AX38: 1416 | AY38: 729 | AZ38: 77 | BA38: 1186 | BB38: 333 | BC38: 788 | BD38: -1646 | BE38: =AM38+AN38+AO38+AP38 -> -4901 | BF38: =BE38*(1+$BL$45) -> -4950.01 | BG38: =BF38*(1+$BL$45) -> -4999.5101 | BH38: =BG38*(1+$BL$45) -> -5049.5052
B39: Pre-Tax Income | C39: =C37+C38 -> 6021 | D39: =D37+D38 -> 7313 | E39: =E37+E38 -> 6065 | F39: =F37+F38 -> 6240 | G39: =G37+G38 -> 6827 | H39: =H37+H38 -> 8022 | I39: =I37+I38 -> 7094 | J39: =J37+J38 -> 7958 | ... AR39: =AR37+AR38 -> 48246 | AV39: =AV37+AV38 -> 25639 | AW39: =AW37+AW38 -> 29901 | AX39: =AX37+AX38 -> 36474 | AY39: =AY37+AY38 -> 43688 | AZ39: =AZ37+AZ38 -> 53036 | BA39: =BA37+BA38 -> 71102 | BB39: =BB37+BB38 -> 83716 | BC39: =BC37+BC38 -> 89311 | ... BH39: =BH37+BH38 -> 188923.19
B40: Taxes | C40: 952 | D40: 1375 | E40: 1760 | F40: 1013 | G40: 1160 | H40: 1755 | I40: 1608 | J40: -111 | K40: 1408 | L40: 15471 | M40: 1217 | N40: 1807 | O40: 1397 | P40: 1965 | Q40: 1677 | R40: -591 | S40: 2008 | T40: 2436 | U40: 2091 | V40: 2220 | W40: 2231 | X40: 2874 | Y40: 1779 | Z40: 2947 | AA40: 19 | AB40: 3750 | AC40: 3462 | AD40: 3747 | AE40: 4016 | AF40: 3914 | AG40: 4374 | AH40: 4646 | AI40: 4993 | AJ40: 4656 | AK40: 4788 | AL40: 2514 | AM40: 5602 | AN40: 5257 | AO40: 5553 | AP40: 5383 | AQ40: 6554 | AR40: 9788 | AV40: 5100 | AW40: 4412 | AX40: 19903 | AY40: 4448 | AZ40: 8755 | BA40: 9831 | BB40: 10978 | BC40: 16950 | BD40: 19651 | BE40: =AM40+AN40+AO40+AP40 -> 21795
