Workbook

Sheet Model
B2: FY | C2: 39813 | D2: 40178 | E2: 40543 | F2: 40908 | G2: 41274 | H2: 41639 | I2: 42004 | J2: 42369 | K2: 42735 | L2: 43100 | M2: 43465 | N2: 43830 | O2: 44196 | P2: 44561 | Q2: 44926 | R2: 45291 | S2: 45657 | T2: 46022
B3: Revenue | C3: 60420 | D3: 58437 | E3: 62484 | F3: 69943 | G3: 73723 | H3: 77849 | I3: 86833 | J3: 93580 | K3: 91154 | L3: 96571 | M3: 110360 | N3: 125843 | O3: 143015 | P3: 168088 | Q3: 198270 | R3: 211915 | S3: 245122 | T3: 281724
B4: COGS | C4: 11598 | D4: 12155 | E4: 12395 | F4: 15577 | G4: 17530 | H4: 20385 | I4: 27078 | J4: 33038 | K4: 32780 | L4: 34261 | M4: 38353 | N4: 42910 | O4: 46078 | P4: 52232 | Q4: 62650 | R4: 65863 | S4: 74114 | T4: 87831
B5: Gross Profit | C5: =+C3-C4 -> 48822 | D5: =+D3-D4 -> 46282 | E5: =+E3-E4 -> 50089 | F5: =+F3-F4 -> 54366 | G5: =+G3-G4 -> 56193 | H5: =+H3-H4 -> 57464 | I5: =+I3-I4 -> 59755 | J5: =+J3-J4 -> 60542 | ... T5: =+T3-T4 -> 193893
B6: R&D Expense | C6: 8164 | D6: 9010 | E6: 8714 | F6: 9043 | G6: 9811 | H6: 10411 | I6: 11381 | J6: 12046 | K6: 11988 | L6: 13037 | M6: 14726 | N6: 16876 | O6: 19269 | P6: 20716 | Q6: 24512 | R6: 27195 | S6: 29510 | T6: 32488
B7: S&M Expense | C7: 13260 | D7: 12879 | E7: 13214 | F7: 13940 | G7: 20050 | H7: 15276 | I7: 15811 | J7: 25724 | K7: 15745 | L7: 15767 | M7: 17469 | N7: 18213 | O7: 19598 | P7: 20117 | Q7: 21825 | R7: 22759 | S7: 24456 | T7: 25654
B8: G&A Expense | C8: 5127 | D8: 4030 | E8: 4063 | F8: 4222 | G8: 4569 | H8: 5013 | I8: 4677 | J8: 4611 | K8: 4563 | L8: 4481 | M8: 4754 | N8: 4885 | O8: 5111 | P8: 5107 | Q8: 5900 | R8: 7575 | S8: 7609 | T8: 7223
B9: Operating Expenses | C9: =SUM(C6:C8) -> 26551 | D9: =SUM(D6:D8) -> 25919 | E9: =SUM(E6:E8) -> 25991 | F9: =SUM(F6:F8) -> 27205 | G9: =SUM(G6:G8) -> 34430 | H9: =SUM(H6:H8) -> 30700 | I9: =SUM(I6:I8) -> 31869 | J9: =SUM(J6:J8) -> 42381 | ... T9: =SUM(T6:T8) -> 65365
B10: Operating Income | C10: =C5-C9 -> 22271 | D10: =D5-D9 -> 20363 | E10: =E5-E9 -> 24098 | F10: =F5-F9 -> 27161 | G10: =G5-G9 -> 21763 | H10: =H5-H9 -> 26764 | I10: =I5-I9 -> 27886 | J10: =J5-J9 -> 18161 | ... T10: =T5-T9 -> 128528
B11: Other Income | C11: 1543 | D11: -542 | E11: 915 | F11: 910 | G11: 504 | H11: 288 | I11: 61 | J11: 346 | K11: -439 | L11: 876 | M11: 1416 | N11: 729 | O11: 77 | P11: 1186 | Q11: 333 | R11: 788 | S11: -1646 | T11: -4901
B12: Pretax Income | C12: =C10+C11 -> 23814 | D12: =D10+D11 -> 19821 | E12: =E10+E11 -> 25013 | F12: =F10+F11 -> 28071 | G12: =G10+G11 -> 22267 | H12: =H10+H11 -> 27052 | I12: =I10+I11 -> 27947 | J12: =J10+J11 -> 18507 | ... T12: =T10+T11 -> 123627
B13: Income Taxes | C13: 6133 | D13: 5252 | E13: 6253 | F13: 4921 | G13: 5289 | H13: 5189 | I13: 5746 | J13: 6314 | K13: 5100 | L13: 4412 | M13: 19903 | N13: 4448 | O13: 8755 | P13: 9831 | Q13: 10978 | R13: 16950 | S13: 19651 | T13: 21795
B14: Net Income | C14: =C12-C13 -> 17681 | D14: =D12-D13 -> 14569 | E14: =E12-E13 -> 18760 | F14: =F12-F13 -> 23150 | G14: =G12-G13 -> 16978 | H14: =H12-H13 -> 21863 | I14: =I12-I13 -> 22201 | J14: =J12-J13 -> 12193 | ... T14: =T12-T13 -> 101832
B15: S/O Basic | C15: 9328 | D15: 8945 | E15: 8813 | F15: 8490 | G15: 8396 | H15: 8375 | I15: 8299 | J15: 8177 | K15: 7925 | L15: 7746 | M15: 7700 | N15: 7673 | O15: 7610 | P15: 7547 | Q15: 7496 | R15: 7446 | S15: 7435 | T15: 7432
B16: EPS | C16: =C14/C15 -> 1.895476 | D16: =D14/D15 -> 1.6287311 | E16: =E14/E15 -> 2.1286736 | F16: =F14/F15 -> 2.7267373 | G16: =G14/G15 -> 2.0221534 | H16: =H14/H15 -> 2.6105075 | I16: =I14/I15 -> 2.6751416 | J16: =J14/J15 -> 1.4911337 | ... T16: =T14/T15 -> 13.70183
B18: Effective tax rate | C18: =C13/C12 -> 0.25753758 | D18: =D13/D12 -> 0.26497149 | E18: =E13/E12 -> 0.24999001 | F18: =F13/F12 -> 0.17530548 | G18: =G13/G12 -> 0.23752638 | H18: =H13/H12 -> 0.19181576 | I18: =I13/I12 -> 0.20560346 | J18: =J13/J12 -> 0.34116821 | ... T18: =T13/T12 -> 0.17629644
B20: % Growth | D20: =D3/C3-1 -> -0.032820258 | E20: =E3/D3-1 -> 0.069254068 | F20: =F3/E3-1 -> 0.11937456 | G20: =G3/F3-1 -> 0.054044007 | H20: =H3/G3-1 -> 0.055966252 | I20: =I3/H3-1 -> 0.1154029 | J20: =J3/I3-1 -> 0.077700874 | K20: =K3/J3-1 -> -0.025924343 | ... T20: =T3/S3-1 -> 0.14932156
B24: Net Cash | C24: =C25+C26-C39-C45 -> 23661.999 | D24: =D25+D26-D39-D45 -> 24017 | E24: =E25+E26-E39-E45 -> 30849 | F24: =F25+F26-F39-F45 -> 40851 | G24: =G25+G26-G39-G45 -> 51096 | H24: =H25+H26-H39-H45 -> 61422 | I24: =I25+I26-I39-I45 -> 63064 | J24: =J25+J26-J39-J45 -> 61234 | ... T24: =T25+T26-T39-T45 -> 51414
B25: Cash & Equivalents | C25: 10339 | D25: 6076 | E25: 5505 | F25: 9610 | G25: 6938 | H25: 3804 | I25: 8669 | J25: 5595 | K25: 6510 | L25: 7663 | M25: 11946 | N25: 11356 | O25: 13576 | P25: 14224 | Q25: 13931 | R25: 34704 | S25: 18315 | T25: 30242
B26: Short Term Investments | C26: 13323 | D26: 25371 | E26: 31283 | F26: 43162 | G26: 56102 | H26: 73218 | I26: 77040 | J26: 90931 | K26: 106730 | L26: 125318 | M26: 121822 | N26: 122463 | O26: 122951 | P26: 116110 | Q26: 90826 | R26: 76558 | S26: 57228 | T26: 64323
B27: Accounts Receivable | C27: 13589 | D27: 11192 | E27: 13014 | F27: 14987 | G27: 15780 | H27: 17486 | I27: 19544 | J27: 17908 | K27: 18277 | L27: 22431 | M27: 26481 | N27: 29524 | O27: 32011 | P27: 38043 | Q27: 44261 | R27: 48688 | S27: 56924 | T27: 69905
B28: Inventory | C28: 985 | D28: 717 | E28: 740 | F28: 1372 | G28: 1137 | H28: 1938 | I28: 2660 | J28: 2902 | K28: 2251 | L28: 2181 | M28: 2662 | N28: 2063 | O28: 1895 | P28: 2636 | Q28: 3742 | R28: 2500 | S28: 1246 | T28: 938
B29: Other Current Assets | C29: 5006 | D29: 5924 | E29: 5134 | F29: 5787 | G29: 5127 | H29: 5020 | I29: 6333 | J29: 5461 | K29: 5892 | L29: 5103 | M29: 6751 | N29: 10146 | O29: 11482 | P29: 13393 | Q29: 16924 | R29: 21807 | S29: 26021 | T29: 25723
B30: Current Assets | C30: =SUM(C25:C29) -> 43242 | D30: =SUM(D25:D29) -> 49280 | E30: =SUM(E25:E29) -> 55676 | F30: =SUM(F25:F29) -> 74918 | G30: =SUM(G25:G29) -> 85084 | H30: =SUM(H25:H29) -> 101466 | I30: =SUM(I25:I29) -> 114246 | J30: =SUM(J25:J29) -> 122797 | ... T30: =SUM(T25:T29) -> 191131
B31: PP&E | C31: 6242 | D31: 7535 | E31: 7630 | F31: 8162 | G31: 8269 | H31: 9991 | I31: 13011 | J31: 14731 | K31: 18356 | L31: 23734 | M31: 29460 | N31: 36477 | O31: 44151 | P31: 59715 | Q31: 74398 | R31: 95641 | S31: 135591 | T31: 204966
B32: Long Term Investments | C32: 6588 | D32: 4933 | E32: 7754 | F32: 10865 | G32: 9776 | H32: 10844 | I32: 14597 | J32: 12053 | K32: 10431 | L32: 6023 | M32: 1862 | N32: 2649 | O32: 2965 | P32: 5984 | Q32: 6891 | R32: 9879 | S32: 14600 | T32: 15405
B33: Goodwill | C33: 12108 | D33: 12503 | E33: 12394 | F33: 12581 | G33: 13452 | H33: 14655 | I33: 20127 | J33: 16939 | K33: 17872 | L33: 35122 | M33: 35683 | N33: 42026 | O33: 43351 | P33: 49711 | Q33: 67524 | R33: 67886 | S33: 119220 | T33: 119509
B34: Intangible assets | C34: 1973 | D34: 1759 | E34: 1158 | F34: 744 | G34: 3170 | H34: 3083 | I34: 6981 | J34: 4835 | K34: 3733 | L34: 10106 | M34: 8053 | N34: 7750 | O34: 7038 | P34: 7800 | Q34: 11298 | R34: 9366 | S34: 27597 | T34: 22604
B35: Other Noncurrent Assets | C35: 2640 | D35: 1878 | E35: 1501 | F35: 1434 | G35: 1520 | H35: 2392 | I35: 3422 | J35: 3117 | K35: 3416 | L35: 12631 | M35: 14128 | N35: 22102 | O35: 21891 | P35: 26163 | Q35: 35045 | R35: 44947 | S35: 55421 | T35: 65388
B36: Noncurrent Assets | C36: =SUM(C31:C35) -> 29551 | D36: =SUM(D31:D35) -> 28608 | E36: =SUM(E31:E35) -> 30437 | F36: =SUM(F31:F35) -> 33786 | G36: =SUM(G31:G35) -> 36187 | H36: =SUM(H31:H35) -> 40965 | I36: =SUM(I31:I35) -> 58138 | J36: =SUM(J31:J35) -> 51675 | ... T36: =SUM(T31:T35) -> 427872
B37: Total Assets | C37: =C30+C36 -> 72793 | D37: =D30+D36 -> 77888 | E37: =E30+E36 -> 86113 | F37: =F30+F36 -> 108704 | G37: =G30+G36 -> 121271 | H37: =H30+H36 -> 142431 | I37: =I30+I36 -> 172384 | J37: =J30+J36 -> 174472 | ... T37: =T30+T36 -> 619003
B38: Accounts Payable | C38: 4034 | D38: 3324 | E38: 4025 | F38: 4197 | G38: 4175 | H38: 4828 | I38: 7432 | J38: 6591 | K38: 6898 | L38: 7390 | M38: 8617 | N38: 9382 | O38: 12530 | P38: 15163 | Q38: 19000 | R38: 18095 | S38: 21996 | T38: 27724
B39: Short Term Debt | C39: 0 | D39: 3684 | E39: 1000 | F39: 0 | G39: 1231 | H39: 2999 | I39: 2000 | J39: 7484 | K39: 12904 | L39: 10121 | M39: 3998 | N39: 5516 | O39: 3749 | P39: 8072 | Q39: 2749 | R39: 5247 | S39: 8942 | T39: 2999
B40: Accrued compensation | C40: 2934 | D40: 3156 | E40: 3283 | F40: 3575 | G40: 3875 | H40: 4117 | I40: 4797 | J40: 5096 | K40: 5264 | L40: 5819 | M40: 6103 | N40: 6830 | O40: 7874 | P40: 10057 | Q40: 10661 | R40: 11009 | S40: 12564 | T40: 13709
B41: Income taxes | C41: 3248 | D41: 725 | E41: 1074 | F41: 580 | G41: 789 | H41: 592 | I41: 782 | J41: 606 | K41: 580 | L41: 718 | M41: 2121 | N41: 5665 | O41: 2130 | P41: 2174 | Q41: 4067 | R41: 4152 | S41: 5017 | T41: 7211
B42: Current Deferred Revenue | C42: 13397 | D42: 13003 | E42: 13652 | F42: 15722 | G42: 18653 | H42: 20639 | I42: 23150 | J42: 23223 | K42: 27468 | L42: 24013 | M42: 28905 | N42: 32676 | O42: 36000 | P42: 41525 | Q42: 45538 | R42: 50901 | S42: 57582 | T42: 64555
B43: Other Current Liabilities | C43: 6273 | D43: 3142 | E43: 3113 | F43: 4700 | G43: 3965 | H43: 4242 | I43: 7464 | J43: 6647 | K43: 6243 | L43: 7684 | M43: 8744 | N43: 9351 | O43: 10027 | P43: 11666 | Q43: 13067 | R43: 14745 | S43: 19185 | T43: 25020
B44: Current Liabilities | C44: =SUM(C38:C43) -> 29886 | D44: =SUM(D38:D43) -> 27034 | E44: =SUM(E38:E43) -> 26147 | F44: =SUM(F38:F43) -> 28774 | G44: =SUM(G38:G43) -> 32688 | H44: =SUM(H38:H43) -> 37417 | I44: =SUM(I38:I43) -> 45625 | J44: =SUM(J38:J43) -> 49647 | ... T44: =SUM(T38:T43) -> 141218
B45: Long Term Debt | C45: 0.001 | D45: 3746 | E45: 4939 | F45: 11921 | G45: 10713 | H45: 12601 | I45: 20645 | J45: 27808 | K45: 40557 | L45: 76073 | M45: 72242 | N45: 66662 | O45: 59578 | P45: 50074 | Q45: 47032 | R45: 41990 | S45: 42688 | T45: 40152
B46: Long Term Deferred Revenue | C46: 1900 | D46: 1281 | E46: 1178 | F46: 1398 | G46: 1406 | H46: 1760 | I46: 2008 | J46: 2095 | K46: 6441 | L46: 10377 | M46: 3815 | N46: 4530 | O46: 3180 | P46: 2616 | Q46: 2870 | R46: 2912 | S46: 2602 | T46: 2710
...

Sheet Segments
B2: FY | C2: 42735 | D2: 43100 | E2: 43465 | F2: 43830 | G2: 44196 | H2: 44561 | I2: 44926 | J2: 45291 | K2: 45657 | L2: 2025
A3: Server & Cloud (Pre-FY25) | B3: Server Products and Cloud Services Revenue (Pre-FY2025) | C3: 19062 | D3: 21649 | E3: 26129 | F3: 32622 | G3: 41379 | H3: 52589 | I3: 67350 | J3: 79970 | K3: 97726 | L3: 114163.69
A4: Office | B4: Office Products and Cloud Services | C4: 23868 | D4: 25573 | E4: 28316 | F4: 31769 | G4: 35316 | H4: 39872 | I4: 44970 | J4: 48848 | K4: 54875 | L4: 64105.073
A5: Windows | B5: Windows | C5: 17548 | D5: 18593 | E5: 19518 | F5: 20395 | G5: 21510 | H5: 22488 | I5: 24732 | J5: 21507 | K5: 23244 | L5: 27153.682
A6: Gaming | B6: Gaming | C6: 9202 | D6: 9051 | E6: 10353 | F6: 11386 | G6: 11575 | H6: 15370 | I6: 16230 | J6: 15466 | K6: 21503 | L6: 23455
A7: Search & Ads | B7: Search and News Advertising | C7: 5428 | D7: 6219 | E7: 7012 | F7: 7628 | G7: 8524 | H7: 9267 | I7: 11526 | J7: 12125 | K7: 12306 | L7: 13878
A8: Enterprise Services | B8: Enterprise and Partner Services | C8: 5659 | D8: 5542 | E8: 5846 | F8: 6124 | G8: 6409 | H8: 6943 | I8: 7605 | J8: 7900 | K8: 7594 | L8: 7885
A9: Devices | B9: Devices | C9: 7888 | D9: 5062 | E9: 5134 | F9: 6095 | G9: 6457 | H9: 7143 | I9: 7306 | J9: 5521 | K9: 4706 | L9: 5497.5576
A10: Other Products (Pre-FY23) | B10: Other Product Revenue (Pre-FY2023) | C10: 2499 | D10: 2611 | E10: 2793 | F10: 3070 | G10: 3768 | H10: 4479 | I10: 5291 | J10: 0 | K10: 0 | L10: 0
A11: LinkedIn | B11: LinkedIn | C11: 0 | D11: 2271 | E11: 5259 | F11: 6754 | G11: 8077 | H11: 10289 | I11: 13631 | J11: 14989 | K11: 16372 | L11: 17812
A12: Dynamics | B12: Dynamics Products and Cloud Services | C12: 0 | D12: 0 | E12: 0 | F12: 0 | G12: 0 | H12: 3754 | I12: 4687 | J12: 5796 | K12: 6831 | L12: 7702
A13: Other Products (Post-FY22) | B13: Other Product Revenue (Post-FY2022) | C13: 0 | D13: 0 | E13: 0 | F13: 0 | G13: 0 | H13: 373 | I13: 233 | J13: 119 | K13: 45 | L13: 72
A14: Other | B14: Other | C14: 0 | D14: 0 | E14: 0 | F14: 0 | G14: 0 | H14: -4479 | I14: -5291 | J14: -155846 | K14: -180551 | L14: =-SUM(L15:L18) -> -210920
A15: Server & Cloud (Post-FY24) | B15: Server Products and Cloud Services Revenue (Post-FY2024) | C15: 0 | D15: 0 | E15: 0 | F15: 0 | G15: 0 | H15: 0 | I15: 0 | J15: 65007 | K15: 79828 | L15: 98435
A16: M365 Commercial | B16: Microsoft 365 Commercial Products and Cloud Services | C16: 0 | D16: 0 | E16: 0 | F16: 0 | G16: 0 | H16: 0 | I16: 0 | J16: 66949 | K16: 76969 | L16: 87767
A17: Windows & Devices | B17: Windows and Devices | C17: 0 | D17: 0 | E17: 0 | F17: 0 | G17: 0 | H17: 0 | I17: 0 | J17: 17147 | K17: 17026 | L17: 17314
A18: M365 Consumer | B18: Microsoft 365 Consumer Products and Cloud Services | C18: 0 | D18: 0 | E18: 0 | F18: 0 | G18: 0 | H18: 0 | I18: 0 | J18: 6417 | K18: 6648 | L18: 7404
B19: Total Revenue by Product | C19: =SUM(C3:C18) -> 91154 | D19: =SUM(D3:D18) -> 96571 | E19: =SUM(E3:E18) -> 110360 | F19: =SUM(F3:F18) -> 125843 | G19: =SUM(G3:G18) -> 143015 | H19: =SUM(H3:H18) -> 168088 | I19: =SUM(I3:I18) -> 198270 | J19: =SUM(J3:J18) -> 211915 | ... L19: =SUM(L3:L18) -> 281724 | N19: =L19/C19 -> 3.0906378
A21: Other | C21: =C10+C13 -> 2499 | D21: =D10+D13 -> 2611 | E21: =E10+E13 -> 2793 | F21: =F10+F13 -> 3070 | G21: =G10+G13 -> 3768 | H21: =H10+H13 -> 4852 | I21: =I10+I13 -> 5524 | J21: =J10+J13 -> 119 | ... L21: =L10+L13 -> 72
B23: Growth Y/Y | N23: CAGR
B24: Server & Cloud (Pre-FY25) | D24: =D3/C3-1 -> 0.13571504 | E24: =E3/D3-1 -> 0.20693796 | F24: =F3/E3-1 -> 0.24849784 | G24: =G3/F3-1 -> 0.26843848 | H24: =H3/G3-1 -> 0.27091037 | I24: =I3/H3-1 -> 0.28068608 | J24: =J3/I3-1 -> 0.18737936 | K24: =K3/J3-1 -> 0.22203326 | L24: =L3/K3-1 -> 0.16820178 | N24: =(L3/C3)^(1/10)-1 -> 0.19601314
B25: Office | D25: =D4/C4-1 -> 0.071434557 | E25: =E4/D4-1 -> 0.10726156 | F25: =F4/E4-1 -> 0.12194519 | G25: =G4/F4-1 -> 0.11164972 | H25: =H4/G4-1 -> 0.12900668 | I25: =I4/H4-1 -> 0.12785915 | J25: =J4/I4-1 -> 0.086235268 | K25: =K4/J4-1 -> 0.12338274 | L25: =L4/K4-1 -> 0.16820178 | N25: =(L4/C4)^(1/10)-1 -> 0.10384384
B26: Windows | D26: =D5/C5-1 -> 0.059550946 | E26: =E5/D5-1 -> 0.049749906 | F26: =F5/E5-1 -> 0.044932882 | G26: =G5/F5-1 -> 0.054670262 | H26: =H5/G5-1 -> 0.045467225 | I26: =I5/H5-1 -> 0.099786553 | J26: =J5/I5-1 -> -0.13039787 | K26: =K5/J5-1 -> 0.080764402 | L26: =L5/K5-1 -> 0.16820178 | N26: =(L5/C5)^(1/10)-1 -> 0.044624267
B27: Gaming | D27: =D6/C6-1 -> -0.016409476 | E27: =E6/D6-1 -> 0.14385151 | F27: =F6/E6-1 -> 0.099777842 | G27: =G6/F6-1 -> 0.016599333 | H27: =H6/G6-1 -> 0.32786177 | I27: =I6/H6-1 -> 0.055953155 | J27: =J6/I6-1 -> -0.047073321 | K27: =K6/J6-1 -> 0.3903401 | L27: =L6/K6-1 -> 0.090778031 | N27: =(L6/C6)^(1/10)-1 -> 0.098083386
B28: Search & Ads | D28: =D7/C7-1 -> 0.14572587 | E28: =E7/D7-1 -> 0.12751246 | F28: =F7/E7-1 -> 0.087849401 | G28: =G7/F7-1 -> 0.11746198 | H28: =H7/G7-1 -> 0.08716565 | I28: =I7/H7-1 -> 0.24376821 | J28: =J7/I7-1 -> 0.05196946 | K28: =K7/J7-1 -> 0.014927835 | L28: =L7/K7-1 -> 0.12774256 | N28: =(L7/C7)^(1/10)-1 -> 0.098420689
B29: Enterprise Services | D29: =D8/C8-1 -> -0.020675031 | E29: =E8/D8-1 -> 0.054853843 | F29: =F8/E8-1 -> 0.047553883 | G29: =G8/F8-1 -> 0.04653821 | H29: =H8/G8-1 -> 0.083320331 | I29: =I8/H8-1 -> 0.095347832 | J29: =J8/I8-1 -> 0.03879027 | K29: =K8/J8-1 -> -0.038734177 | L29: =L8/K8-1 -> 0.038319726 | N29: =(L8/C8)^(1/10)-1 -> 0.033727811
B30: Devices | D30: =D9/C9-1 -> -0.35826572 | E30: =E9/D9-1 -> 0.014223627 | F30: =F9/E9-1 -> 0.18718348 | G30: =G9/F9-1 -> 0.059392945 | H30: =H9/G9-1 -> 0.10624129 | I30: =I9/H9-1 -> 0.022819544 | J30: =J9/I9-1 -> -0.24431974 | K30: =K9/J9-1 -> -0.14761819 | L30: =L9/K9-1 -> 0.16820178 | N30: =(L9/C9)^(1/10)-1 -> -0.035459898
B31: LinkedIn | D31: =D11/C11-1 -> #DIV/0! | E31: =E11/D11-1 -> 1.3157199 | F31: =F11/E11-1 -> 0.28427458 | G31: =G11/F11-1 -> 0.19588392 | H31: =H11/G11-1 -> 0.27386406 | I31: =I11/H11-1 -> 0.32481291 | J31: =J11/I11-1 -> 0.099625853 | K31: =K11/J11-1 -> 0.092267663 | L31: =L11/K11-1 -> 0.087955045 | N31: =(L11/C11)^(1/10)-1 -> #DIV/0!
B32: Dynamics | D32: =D12/C12-1 -> #DIV/0! | E32: =E12/D12-1 -> #DIV/0! | F32: =F12/E12-1 -> #DIV/0! | G32: =G12/F12-1 -> #DIV/0! | H32: =H12/G12-1 -> #DIV/0! | I32: =I12/H12-1 -> 0.2485349 | J32: =J12/I12-1 -> 0.23661191 | K32: =K12/J12-1 -> 0.17857143 | L32: =L12/K12-1 -> 0.12750695 | N32: =(L12/C12)^(1/10)-1 -> #DIV/0!
B33: Total Revenue | D33: =D19/C19-1 -> 0.059426904 | E33: =E19/D19-1 -> 0.14278614 | F33: =F19/E19-1 -> 0.1402954 | G33: =G19/F19-1 -> 0.13645574 | H33: =H19/G19-1 -> 0.17531727 | I33: =I19/H19-1 -> 0.17956071 | J33: =J19/I19-1 -> 0.068820296 | K33: =K19/J19-1 -> 0.15669962 | L33: =L19/K19-1 -> 0.14932156 | N33: =(L19/C19)^(1/10)-1 -> 0.11945029
B36: % of total Revenue
B37: Server & Cloud | C37: =C3/C$19 -> 0.20911863 | D37: =D3/D$19 -> 0.22417703 | E37: =E3/E$19 -> 0.23676151 | F37: =F3/F$19 -> 0.25922777 | G37: =G3/G$19 -> 0.28933329 | H37: =H3/H$19 -> 0.31286588 | I37: =I3/I$19 -> 0.3396883 | J37: =J3/J$19 -> 0.37736828 | ... L37: =L3/L$19 -> 0.40523238
B38: Office | C38: =C4/C$19 -> 0.2618426 | D38: =D4/D$19 -> 0.26481035 | E38: =E4/E$19 -> 0.25657847 | F38: =F4/F$19 -> 0.25244948 | G38: =G4/G$19 -> 0.24693913 | H38: =H4/H$19 -> 0.23720908 | I38: =I4/I$19 -> 0.22681192 | J38: =J4/J$19 -> 0.23050751 | ... L38: =L4/L$19 -> 0.22754566
B39: Windows | C39: =C5/C$19 -> 0.19250938 | D39: =D5/D$19 -> 0.19253192 | E39: =E5/E$19 -> 0.17685756 | F39: =F5/F$19 -> 0.16206702 | G39: =G5/G$19 -> 0.1504038 | H39: =H5/H$19 -> 0.13378706 | I39: =I5/I$19 -> 0.12473899 | J39: =J5/J$19 -> 0.1014888 | ... L39: =L5/L$19 -> 0.096383987
B40: Gaming | C40: =C6/C$19 -> 0.10095004 | D40: =D6/D$19 -> 0.093723789 | E40: =E6/E$19 -> 0.093811163 | F40: =F6/F$19 -> 0.090477818 | G40: =G6/G$19 -> 0.080935566 | H40: =H6/H$19 -> 0.091440198 | I40: =I6/I$19 -> 0.081858072 | J40: =J6/J$19 -> 0.072982092 | ... L40: =L6/L$19 -> 0.083255243
B41: Search & Ads | C41: =C7/C$19 -> 0.059547579 | D41: =D7/D$19 -> 0.064398215 | E41: =E7/E$19 -> 0.063537514 | F41: =F7/F$19 -> 0.060615211 | G41: =G7/G$19 -> 0.05960214 | H41: =H7/H$19 -> 0.055131836 | I41: =I7/I$19 -> 0.058132849 | J41: =J7/J$19 -> 0.057216337 | ... L41: =L7/L$19 -> 0.049260979
B42: Enterprise Services | C42: =C8/C$19 -> 0.062081752 | D42: =D8/D$19 -> 0.057387829 | E42: =E8/E$19 -> 0.052972091 | F42: =F8/F$19 -> 0.048663811 | G42: =G8/G$19 -> 0.044813481 | H42: =H8/H$19 -> 0.041305745 | I42: =I8/I$19 -> 0.038356786 | J42: =J8/J$19 -> 0.037279098 | ... L42: =L8/L$19 -> 0.027988386
B43: Devices | C43: =C9/C$19 -> 0.086534875 | D43: =D9/D$19 -> 0.052417392 | E43: =E9/E$19 -> 0.046520478 | F43: =F9/F$19 -> 0.048433365 | G43: =G9/G$19 -> 0.04514911 | H43: =H9/H$19 -> 0.042495598 | I43: =I9/I$19 -> 0.036848742 | J43: =J9/J$19 -> 0.026052899 | ... L43: =L9/L$19 -> 0.019513984
B44: LinkedIn | C44: =C11/C$19 -> 0 | D44: =D11/D$19 -> 0.023516377 | E44: =E11/E$19 -> 0.047653135 | F44: =F11/F$19 -> 0.053670049 | G44: =G11/G$19 -> 0.056476593 | H44: =H11/H$19 -> 0.061211984 | I44: =I11/I$19 -> 0.068749685 | J44: =J11/J$19 -> 0.070731189 | ... L44: =L11/L$19 -> 0.063225
B45: Dynamics | C45: =C12/C$19 -> 0 | D45: =D12/D$19 -> 0 | E45: =E12/E$19 -> 0 | F45: =F12/F$19 -> 0 | G45: =G12/G$19 -> 0 | H45: =H12/H$19 -> 0.02233354 | I45: =I12/I$19 -> 0.023639482 | J45: =J12/J$19 -> 0.027350589 | ... L45: =L12/L$19 -> 0.027338814
...

Sheet Forecast
A1: Timeline | B1: Total Revenue | C1: Forecast(Total Revenue) | D1: Lower Confidence Bound(Total Revenue) | E1: Upper Confidence Bound(Total Revenue) | F1: Shade base | G1: Column1 | H1: shade gap
A2: 42735 | B2: 91154
A3: 43100 | B3: 96571 | I3: 386708.12 | J3: 412754.55 | K3: 438800.99 | L3: 464847.42 | M3: 490893.86 | N3: 516940.29 | O3: 542986.73 | P3: 569033.16 | Q3: 595079.6 | R3: 621126.03 | S3: 647172.47 | T3: 673218.9 | U3: 699265.34 | V3: 725311.77 | W3: 751358.21 | X3: 777404.64 | Y3: 803451.08 | Z3: 829497.51 | AA3: 855543.94 | AB3: 881590.38 | AC3: 907636.81 | AD3: 933683.25 | AE3: 959729.68
A4: 43465 | B4: 110360 | I4: 407158.26 | J4: 454562.15 | K4: 505996.05 | L4: 561400.47 | M4: 620586.12 | N4: 683218.09 | O4: 748804.5 | P4: 816691.05 | Q4: 886062.83 | R4: 926205.34 | S4: 966347.84 | T4: 1006490.3 | U4: 1046632.9 | V4: 1086775.4 | W4: 1126917.9 | X4: 1167060.4 | Y4: 1207202.9 | Z4: 1247345.4 | AA4: 1287487.9 | AB4: 1327630.4 | AC4: 1367772.9 | AD4: 1407915.4 | AE4: 1448057.9
A5: 43830 | B5: 125843 | I5: 363386.9 | J5: 387727.29 | K5: 411399.15 | L5: 434119.27 | M5: 455610.31 | N5: 474441.81 | O5: 491555.66 | P5: 511709.77 | Q5: 531667.98 | R5: 551432.98 | S5: 571007.47 | T5: 590394.13 | U5: 609595.63 | V5: 628614.63 | W5: 647453.78 | X5: 666115.7 | Y5: 684602.99 | Z5: 702918.24 | AA5: 721064 | AB5: 739042.81 | AC5: 756857.19 | AD5: 774509.61 | AE5: 792002.54
A6: 44196 | B6: 143015
A7: 44561 | B7: 172567
A8: 44926 | B8: 203561
A9: 45291 | B9: 212241
A10: 45657 | B10: 245202
A11: 46022 | B11: 281724
A12: 46387 | B12: 321869.75 | C12: 321869.75 | D12: 306730.09 | E12: 321446.93 | F12: =MIN(Table1[[#This Row],[Lower Confidence Bound(Total Revenue)]:[Upper Confidence Bound(Total Revenue)]])-Table1[[#This Row],[Column1]] -> 291590.43 | G12: 15139.663 | H12: =MAX(Table1[[#This Row],[Upper Confidence Bound(Total Revenue)]],Table1[[#This Row],[Lower Confidence Bound(Total Revenue)]])-Table1[[#This Row],[Shade base]]-Table1[[#This Row],[Column1]] -> 14716.841
A13: 46752 | C13: 360661.68 | D13: 335779.11 | E13: 363732.74 | F13: =MIN(Table1[[#This Row],[Lower Confidence Bound(Total Revenue)]:[Upper Confidence Bound(Total Revenue)]]) -> 335779.11 | G13: 24882.57 | H13: =MAX(Table1[[#This Row],[Upper Confidence Bound(Total Revenue)]],Table1[[#This Row],[Lower Confidence Bound(Total Revenue)]])-Table1[[#This Row],[Shade base]]-Table1[[#This Row],[Column1]] -> 3071.0542
A14: 47118 | C14: 386708.12 | D14: 363386.9 | E14: 407158.26 | F14: =MIN(Table1[[#This Row],[Lower Confidence Bound(Total Revenue)]:[Upper Confidence Bound(Total Revenue)]]) -> 363386.9 | G14: 23321.222 | H14: =MAX(Table1[[#This Row],[Upper Confidence Bound(Total Revenue)]],Table1[[#This Row],[Lower Confidence Bound(Total Revenue)]])-Table1[[#This Row],[Shade base]]-Table1[[#This Row],[Column1]] -> 20450.14
A15: 47483 | C15: 412754.55 | D15: 387727.29 | E15: 454562.15 | F15: =MIN(Table1[[#This Row],[Lower Confidence Bound(Total Revenue)]:[Upper Confidence Bound(Total Revenue)]]) -> 387727.29 | G15: 25027.262 | H15: =MAX(Table1[[#This Row],[Upper Confidence Bound(Total Revenue)]],Table1[[#This Row],[Lower Confidence Bound(Total Revenue)]])-Table1[[#This Row],[Shade base]]-Table1[[#This Row],[Column1]] -> 41807.602
A16: 47848 | C16: 438800.99 | D16: 411399.15 | E16: 505996.05 | F16: =MIN(Table1[[#This Row],[Lower Confidence Bound(Total Revenue)]:[Upper Confidence Bound(Total Revenue)]]) -> 411399.15 | G16: 27401.835 | H16: =MAX(Table1[[#This Row],[Upper Confidence Bound(Total Revenue)]],Table1[[#This Row],[Lower Confidence Bound(Total Revenue)]])-Table1[[#This Row],[Shade base]]-Table1[[#This Row],[Column1]] -> 67195.06
A17: 48213 | C17: 464847.42 | D17: 434119.27 | E17: 561400.47 | F17: =MIN(Table1[[#This Row],[Lower Confidence Bound(Total Revenue)]:[Upper Confidence Bound(Total Revenue)]]) -> 434119.27 | G17: 30728.156 | H17: =MAX(Table1[[#This Row],[Upper Confidence Bound(Total Revenue)]],Table1[[#This Row],[Lower Confidence Bound(Total Revenue)]])-Table1[[#This Row],[Shade base]]-Table1[[#This Row],[Column1]] -> 96553.043
A18: 48579 | C18: 490893.86 | D18: 455610.31 | E18: 620586.12 | F18: =MIN(Table1[[#This Row],[Lower Confidence Bound(Total Revenue)]:[Upper Confidence Bound(Total Revenue)]]) -> 455610.31 | G18: 35283.545 | H18: =MAX(Table1[[#This Row],[Upper Confidence Bound(Total Revenue)]],Table1[[#This Row],[Lower Confidence Bound(Total Revenue)]])-Table1[[#This Row],[Shade base]]-Table1[[#This Row],[Column1]] -> 129692.26
A19: 48944 | C19: 516940.29 | D19: 474441.81 | E19: 683218.09 | F19: =MIN(Table1[[#This Row],[Lower Confidence Bound(Total Revenue)]:[Upper Confidence Bound(Total Revenue)]]) -> 474441.81 | G19: 42498.482 | H19: =MAX(Table1[[#This Row],[Upper Confidence Bound(Total Revenue)]],Table1[[#This Row],[Lower Confidence Bound(Total Revenue)]])-Table1[[#This Row],[Shade base]]-Table1[[#This Row],[Column1]] -> 166277.8
A20: 49309 | C20: 542986.73 | D20: 491555.66 | E20: 748804.5 | F20: =MIN(Table1[[#This Row],[Lower Confidence Bound(Total Revenue)]:[Upper Confidence Bound(Total Revenue)]]) -> 491555.66 | G20: 51431.067 | H20: =MAX(Table1[[#This Row],[Upper Confidence Bound(Total Revenue)]],Table1[[#This Row],[Lower Confidence Bound(Total Revenue)]])-Table1[[#This Row],[Shade base]]-Table1[[#This Row],[Column1]] -> 205817.77
A21: 49674 | C21: 569033.16 | D21: 511709.77 | E21: 816691.05 | F21: =MIN(Table1[[#This Row],[Lower Confidence Bound(Total Revenue)]:[Upper Confidence Bound(Total Revenue)]]) -> 511709.77 | G21: 57323.391 | H21: =MAX(Table1[[#This Row],[Upper Confidence Bound(Total Revenue)]],Table1[[#This Row],[Lower Confidence Bound(Total Revenue)]])-Table1[[#This Row],[Shade base]]-Table1[[#This Row],[Column1]] -> 247657.89
A22: 50040 | C22: 595079.6 | D22: 531667.98 | E22: 886062.83 | F22: =MIN(Table1[[#This Row],[Lower Confidence Bound(Total Revenue)]:[Upper Confidence Bound(Total Revenue)]]) -> 531667.98 | G22: 63411.617 | H22: =MAX(Table1[[#This Row],[Upper Confidence Bound(Total Revenue)]],Table1[[#This Row],[Lower Confidence Bound(Total Revenue)]])-Table1[[#This Row],[Shade base]]-Table1[[#This Row],[Column1]] -> 290983.24
A23: 50405 | C23: 621126.03 | D23: 551432.98 | E23: 926205.34 | F23: =MIN(Table1[[#This Row],[Lower Confidence Bound(Total Revenue)]:[Upper Confidence Bound(Total Revenue)]]) -> 551432.98 | G23: 69693.051 | H23: =MAX(Table1[[#This Row],[Upper Confidence Bound(Total Revenue)]],Table1[[#This Row],[Lower Confidence Bound(Total Revenue)]])-Table1[[#This Row],[Shade base]]-Table1[[#This Row],[Column1]] -> 305079.31
A24: 50770 | C24: 647172.47 | D24: 571007.47 | E24: 966347.84 | F24: =MIN(Table1[[#This Row],[Lower Confidence Bound(Total Revenue)]:[Upper Confidence Bound(Total Revenue)]]) -> 571007.47 | G24: 76164.998 | H24: =MAX(Table1[[#This Row],[Upper Confidence Bound(Total Revenue)]],Table1[[#This Row],[Lower Confidence Bound(Total Revenue)]])-Table1[[#This Row],[Shade base]]-Table1[[#This Row],[Column1]] -> 319175.38
... A36: 55153 | C36: 959729.68 | D36: 792002.54 | E36: 1448057.9 | F36: =MIN(Table1[[#This Row],[Lower Confidence Bound(Total Revenue)]:[Upper Confidence Bound(Total Revenue)]]) -> 792002.54 | G36: 167727.14 | H36: =MAX(Table1[[#This Row],[Upper Confidence Bound(Total Revenue)]],Table1[[#This Row],[Lower Confidence Bound(Total Revenue)]])-Table1[[#This Row],[Shade base]]-Table1[[#This Row],[Column1]] -> 488328.22

Sheet DCF
B2: FY | C2: 42735 | D2: 43100 | E2: 43465 | F2: 43830 | G2: 44196 | H2: 44561 | I2: 44926 | J2: 45291 | K2: 45657 | L2: 46022 | M2: 46387 | N2: 46752 | O2: 47118 | P2: 47483 | Q2: 47848 | R2: 48213 | S2: 48579 | T2: 48944 | U2: 49309 | V2: 49674 | W2: 50040 | X2: 50405 | Y2: 50770 | Z2: 51135 | AA2: 51501 | AB2: 51866 | AC2: 52231 | AD2: 52596 | AE2: 52962 | AF2: 53327 | AG2: 53692 | AH2: 54057 | AI2: 54423 | AJ2: 54788 | AK2: 55153 | AL2: 55518 | AM2: 55884 | AN2: 56249 | AO2: 56614 | AP2: 56979 | AQ2: 57345 | AR2: 57710 | AS2: 58075 | AT2: 58440 | AU2: 58806 | AV2: 59171 | AW2: 59536 | AX2: 59901 | AY2: 60267 | AZ2: 60632 | BA2: 60997 | BB2: 61362 | BC2: 61728 | BD2: 62093 | BE2: 62458 | BF2: 62823 | BG2: 63189 | BH2: 63554 | BI2: 63919 | BJ2: 64284 | BK2: 64650 | BL2: 65015 | BM2: 65380 | BN2: 65745 | BO2: 66111 | BP2: 66476 | BQ2: 66841 | BR2: 67206 | BS2: 67572 | BT2: 67937 | BU2: 68302 | BV2: 68667 | BW2: 69033 | BX2: 69398 | BY2: 69763 | BZ2: 70128 | CA2: 70494 | CB2: 70859 | CC2: 71224 | CD2: 71589 | CE2: 71955 | CF2: 72320 | CG2: 72685 | CH2: 73050 | CI2: 73415
B3: BASE CASE (Linear growth)
A4: Server & Cloud | B4: Server Products and Cloud Services Revenue (Pre-FY2025) | C4: 19062 | D4: 21649 | E4: 26129 | F4: 32622 | G4: 41379 | H4: 52589 | I4: 67350 | J4: 79970 | K4: 97726 | L4: 114163.69 | M4: =L4*(1+Segments!AG76+0.1) -> 137419.25 | N4: =M4*(1+Segments!AH76+0.08) -> 161324.66 | O4: =N4*(1+Segments!AI76) -> 175180.75 | P4: =O4*(1+Segments!AJ76) -> 189036.85 | Q4: =P4*(1+Segments!AK76) -> 202892.95 | R4: =Q4*(1+Segments!AL76) -> 216749.05 | S4: =R4*(1+Segments!AM76) -> 230605.15 | T4: =S4*(1+Segments!AN76) -> 244461.25 | U4: =T4*(1+Segments!AO76) -> 258317.35 | V4: =U4*(1+Segments!AP76) -> 272173.45 | ... CI4: =CH4*(1+Segments!DC76) -> 1172819.9
A5: Office | B5: Office Products and Cloud Services | C5: 23868 | D5: 25573 | E5: 28316 | F5: 31769 | G5: 35316 | H5: 39872 | I5: 44970 | J5: 48848 | K5: 54875 | L5: 64105.073 | M5: =L5*(1+Segments!AG77+0.05) -> 71994.545 | N5: =M5*(1+Segments!AH77+0.04) -> 79776.807 | O5: =N5*(1+Segments!AI77) -> 84862.885 | P5: =O5*(1+Segments!AJ77) -> 89948.963 | Q5: =P5*(1+Segments!AK77) -> 95035.041 | R5: =Q5*(1+Segments!AL77) -> 100121.12 | S5: =R5*(1+Segments!AM77) -> 105207.2 | T5: =S5*(1+Segments!AN77) -> 110293.28 | U5: =T5*(1+Segments!AO77) -> 115379.35 | V5: =U5*(1+Segments!AP77) -> 120465.43 | ... CI5: =CH5*(1+Segments!DC77) -> 451060.5
A6: Windows | B6: Windows | C6: 17548 | D6: 18593 | E6: 19518 | F6: 20395 | G6: 21510 | H6: 22488 | I6: 24732 | J6: 21507 | K6: 23244 | L6: 27153.682 | M6: =L6*(1+Segments!AG78) -> 28073.759 | N6: =M6*(1+Segments!AH78) -> 28993.835 | O6: =N6*(1+Segments!AI78) -> 29913.912 | P6: =O6*(1+Segments!AJ78) -> 30833.988 | Q6: =P6*(1+Segments!AK78) -> 31754.064 | R6: =Q6*(1+Segments!AL78) -> 32674.141 | S6: =R6*(1+Segments!AM78) -> 33594.217 | T6: =S6*(1+Segments!AN78) -> 34514.294 | ... CI6: =CH6*(1+Segments!DC78) -> 96159.414
A7: Gaming | B7: Gaming | C7: 9202 | D7: 9051 | E7: 10353 | F7: 11386 | G7: 11575 | H7: 15370 | I7: 16230 | J7: 15466 | K7: 21503 | L7: 23455 | M7: =L7*(1+Segments!AG79+0.05) -> 26347.829 | N7: =M7*(1+Segments!AH79) -> 28148.036 | O7: =N7*(1+Segments!AI79) -> 29948.243 | P7: =O7*(1+Segments!AJ79) -> 31748.451 | Q7: =P7*(1+Segments!AK79) -> 33548.658 | R7: =Q7*(1+Segments!AL79) -> 35348.865 | S7: =R7*(1+Segments!AM79) -> 37149.072 | T7: =S7*(1+Segments!AN79) -> 38949.279 | U7: =T7*(1+Segments!AO79) -> 40749.486 | ... CI7: =CH7*(1+Segments!DC79) -> 159563.15
A8: Search & Ads | B8: Search and News Advertising | C8: 5428 | D8: 6219 | E8: 7012 | F8: 7628 | G8: 8524 | H8: 9267 | I8: 11526 | J8: 12125 | K8: 12306 | L8: 13878 | M8: =L8*(1+Segments!AG80) -> 14842.337 | N8: =M8*(1+Segments!AH80) -> 15806.674 | O8: =N8*(1+Segments!AI80) -> 16771.011 | P8: =O8*(1+Segments!AJ80) -> 17735.348 | Q8: =P8*(1+Segments!AK80) -> 18699.686 | R8: =Q8*(1+Segments!AL80) -> 19664.023 | S8: =R8*(1+Segments!AM80) -> 20628.36 | T8: =S8*(1+Segments!AN80) -> 21592.697 | ... CI8: =CH8*(1+Segments!DC80) -> 86203.283
A9: Enterprise Services | B9: Enterprise and Partner Services | C9: 5659 | D9: 5542 | E9: 5846 | F9: 6124 | G9: 6409 | H9: 6943 | I9: 7605 | J9: 7900 | K9: 7594 | L9: 7885 | M9: =L9*(1+Segments!AG81) -> 8177.7238 | N9: =M9*(1+Segments!AH81) -> 8470.4477 | O9: =N9*(1+Segments!AI81) -> 8763.1715 | P9: =O9*(1+Segments!AJ81) -> 9055.8953 | Q9: =P9*(1+Segments!AK81) -> 9348.6191 | R9: =Q9*(1+Segments!AL81) -> 9641.343 | S9: =R9*(1+Segments!AM81) -> 9934.0668 | T9: =S9*(1+Segments!AN81) -> 10226.791 | ... CI9: =CH9*(1+Segments!DC81) -> 29839.287
A10: Devices | B10: Devices | C10: 7888 | D10: 5062 | E10: 5134 | F10: 6095 | G10: 6457 | H10: 7143 | I10: 7306 | J10: 5521 | K10: 4706 | L10: 5497.5576 | M10: =L10*(1+Segments!AG82) -> 5573.8917 | N10: =M10*(1+Segments!AH82) -> 5650.2257 | O10: =N10*(1+Segments!AI82) -> 5726.5598 | P10: =O10*(1+Segments!AJ82) -> 5802.8939 | Q10: =P10*(1+Segments!AK82) -> 5879.228 | R10: =Q10*(1+Segments!AL82) -> 5955.562 | S10: =R10*(1+Segments!AM82) -> 6031.8961 | T10: =S10*(1+Segments!AN82) -> 6108.2302 | ... CI10: =CH10*(1+Segments!DC82) -> 11222.613
B11: Other Product Revenue (Pre-FY2023) | C11: 2499 | D11: 2611 | E11: 2793 | F11: 3070 | G11: 3768 | H11: 4479 | I11: 5291 | J11: 0 | K11: 0 | L11: 0 | M11: =L11*(1+Segments!AG83) -> 0 | N11: =M11*(1+Segments!AH83) -> 0 | O11: =N11*(1+Segments!AI83) -> 0 | P11: =O11*(1+Segments!AJ83) -> 0 | Q11: =P11*(1+Segments!AK83) -> 0 | R11: =Q11*(1+Segments!AL83) -> 0 | S11: =R11*(1+Segments!AM83) -> 0 | T11: =S11*(1+Segments!AN83) -> 0 | ... CI11: =CH11*(1+Segments!DC83) -> 0
A12: LinkedIn | B12: LinkedIn | C12: 0 | D12: 2271 | E12: 5259 | F12: 6754 | G12: 8077 | H12: 10289 | I12: 13631 | J12: 14989 | K12: 16372 | L12: 17812 | M12: =L12*(1+Segments!AG84+0.05) -> 20625.023 | N12: =M12*(1+Segments!AH84) -> 22634.204 | O12: =N12*(1+Segments!AI84) -> 24643.385 | P12: =O12*(1+Segments!AJ84) -> 26652.566 | Q12: =P12*(1+Segments!AK84) -> 28661.747 | R12: =Q12*(1+Segments!AL84) -> 30670.928 | S12: =R12*(1+Segments!AM84) -> 32680.109 | T12: =S12*(1+Segments!AN84) -> 34689.29 | U12: =T12*(1+Segments!AO84) -> 36698.471 | ... CI12: =CH12*(1+Segments!DC84) -> 169304.41
A13: Dynamics | B13: Dynamics Products and Cloud Services | C13: 0 | D13: 0 | E13: 0 | F13: 0 | G13: 0 | H13: 3754 | I13: 4687 | J13: 5796 | K13: 6831 | L13: 7702 | M13: =L13*(1+Segments!AG85) -> 8743.3984 | N13: =M13*(1+Segments!AH85) -> 9784.7967 | O13: =N13*(1+Segments!AI85) -> 10826.195 | P13: =O13*(1+Segments!AJ85) -> 11867.593 | Q13: =P13*(1+Segments!AK85) -> 12908.992 | R13: =Q13*(1+Segments!AL85) -> 13950.39 | S13: =R13*(1+Segments!AM85) -> 14991.789 | T13: =S13*(1+Segments!AN85) -> 16033.187 | ... CI13: =CH13*(1+Segments!DC85) -> 85806.877
B14: Other Product Revenue (Post-FY2022) | C14: 0 | D14: 0 | E14: 0 | F14: 0 | G14: 0 | H14: 373 | I14: 233 | J14: 119 | K14: 45 | L14: 72 | M14: =L14*(1+Segments!AG86) -> 72 | N14: =M14*(1+Segments!AH86) -> 72 | O14: =N14*(1+Segments!AI86) -> 72 | P14: =O14*(1+Segments!AJ86) -> 72 | Q14: =P14*(1+Segments!AK86) -> 72 | R14: =Q14*(1+Segments!AL86) -> 72 | S14: =R14*(1+Segments!AM86) -> 72 | T14: =S14*(1+Segments!AN86) -> 72 | ... CI14: =CH14*(1+Segments!DC86) -> 72
B15: Total Revenue | C15: =SUM(C4:C14) -> 91154 | D15: =SUM(D4:D14) -> 96571 | E15: =SUM(E4:E14) -> 110360 | F15: =SUM(F4:F14) -> 125843 | G15: =SUM(G4:G14) -> 143015 | H15: =SUM(H4:H14) -> 172567 | I15: =SUM(I4:I14) -> 203561 | J15: =SUM(J4:J14) -> 212241 | ... CI15: =SUM(CI4:CI14) -> 2262051.4
B16: % Growth | D16: =D15/C15-1 -> 0.059426904 | E16: =E15/D15-1 -> 0.14278614 | F16: =F15/E15-1 -> 0.1402954 | G16: =G15/F15-1 -> 0.13645574 | H16: =H15/G15-1 -> 0.20663567 | I16: =I15/H15-1 -> 0.1796056 | J16: =J15/I15-1 -> 0.042640781 | K16: =K15/J15-1 -> 0.15529987 | ... CI16: =CI15/CH15-1 -> 0.011648648
B17: COGS | C17: 32780 | D17: 34261 | E17: 38353 | F17: 42910 | G17: 46078 | H17: 52232 | I17: 62650 | J17: 65863 | K17: 74114 | L17: 87831 | M17: =M15*(L18-0.001) -> 100025.07 | N17: =N15*(M18-0.001) -> 111719.49 | O17: =O15*(N18-0.001) -> 119400.99 | P17: =P15*(O18-0.001) -> 127030.4 | Q17: =Q15*(P18-0.001) -> 134607.72 | R17: =R15*(Q18-0.001) -> 142132.95 | S17: =S15*(R18-0.001) -> 149606.08 | T17: =T15*(S18-0.001) -> 157027.11 | ... CI17: =CI15*(CH18-0.001) -> 535569.12
B18: % of Revenue | C18: =C17/C$15 -> 0.35961121 | D18: =D17/D$15 -> 0.35477524 | E18: =E17/E$15 -> 0.34752628 | F18: =F17/F$15 -> 0.34098043 | G18: =G17/G$15 -> 0.32218998 | H18: =H17/H$15 -> 0.30267664 | I18: =I17/I$15 -> 0.30777015 | J18: =J17/J$15 -> 0.31032176 | ... CI18: =CI17/CI$15 -> 0.23676258
B19: Operating expenses | C19: 32296 | D19: 33285 | E19: 36949 | F19: 39974 | G19: 43978 | H19: 45940 | I19: 52237 | J19: 57529 | K19: 61575 | L19: 65365 | M19: =M15*L20 -> 74679.532 | N19: =N15*M20 -> 83679.952 | O19: =O15*N20 -> 89723.191 | P19: =P15*O20 -> 95766.429 | Q19: =Q15*P20 -> 101809.67 | R19: =R15*Q20 -> 107852.9 | S19: =S15*R20 -> 113896.14 | T19: =T15*S20 -> 119939.38 | ... CI19: =CI15*CH20 -> 524836.33
B20: % of Revenue | C20: =C19/C$15 -> 0.35430151 | D20: =D19/D$15 -> 0.34466869 | E20: =E19/E$15 -> 0.33480428 | F20: =F19/F$15 -> 0.31764977 | G20: =G19/G$15 -> 0.30750621 | H20: =H19/H$15 -> 0.26621544 | I20: =I19/I$15 -> 0.25661595 | J20: =J19/J$15 -> 0.27105507 | ... CI20: =CI19/CI$15 -> 0.23201786
B21: Net interest & other expenses | C21: -439 | D21: 876 | E21: 1416 | F21: 729 | G21: 77 | H21: 1186 | I21: 333 | J21: 788 | K21: -1646 | L21: -4901 | M21: =M15*$L$22 -> -5599.394 | N21: =N15*$L$22 -> -6274.2362 | O21: =O15*$L$22 -> -6727.3519 | P21: =P15*$L$22 -> -7180.4676 | Q21: =Q15*$L$22 -> -7633.5834 | R21: =R15*$L$22 -> -8086.6991 | S21: =S15*$L$22 -> -8539.8148 | T21: =T15*$L$22 -> -8992.9306 | ... CI21: =CI15*$L$22 -> -39351.685
B22: % of Revenue | C22: =C21/C$15 -> -0.0048160256 | D22: =D21/D$15 -> 0.0090710462 | E22: =E21/E$15 -> 0.012830736 | F22: =F21/F$15 -> 0.0057929325 | G22: =G21/G$15 -> 0.00053840506 | H22: =H21/H$15 -> 0.0068726929 | I22: =I21/I$15 -> 0.0016358733 | J22: =J21/J$15 -> 0.0037127605 | ... CI22: =CI21/CI$15 -> -0.017396459
B23: Taxes | C23: 5100 | D23: 4412 | E23: 19903 | F23: 4448 | G23: 8755 | H23: 9831 | I23: 10978 | J23: 16950 | K23: 19651 | L23: 21795 | M23: =+(M15-M17-M19+M21)*M24 -> 24957.538 | N23: =+(N15-N17-N19+N21)*N24 -> 28029.019 | O23: =+(O15-O17-O19+O21)*O24 -> 30121.407 | P23: =+(P15-P17-P19+P21)*P24 -> 32222.979 | Q23: =+(Q15-Q17-Q19+Q21)*Q24 -> 34333.735 | R23: =+(R15-R17-R19+R21)*R24 -> 36453.674 | S23: =+(S15-S17-S19+S21)*S24 -> 38582.797 | T23: =+(T15-T17-T19+T21)*T24 -> 40721.104 | ... CI23: =+(CI15-CI17-CI19+CI21)*CI24 -> 204908.34
B24: Tax rate | C24: =C23/(C15-C17-C19+C21) -> 0.19891571 | D24: =D23/(D15-D17-D19+D21) -> 0.14755359 | E24: =E23/(E15-E17-E19+E21) -> 0.54567637 | F24: =F23/(F15-F17-F19+F21) -> 0.10181285 | G24: =G23/(G15-G17-G19+G21) -> 0.16507655 | H24: =H23/(H15-H17-H19+H21) -> 0.13007237 | I24: =I23/(I15-I17-I19+I21) -> 0.12333861 | J24: =J23/(J15-J17-J19+J21) -> 0.18909602 | ... L24: =L23/(L15-L17-L19+L21) -> 0.17629644 | M24: 0.17629644 | N24: 0.17629644 | O24: 0.17629644 | P24: 0.17629644 | Q24: 0.17629644 | R24: 0.17629644 | S24: 0.17629644 | T24: 0.17629644 | U24: 0.17629644 | V24: 0.17629644 | W24: 0.17629644 | X24: 0.17629644 | Y24: 0.17629644 | Z24: 0.17629644 | AA24: 0.17629644 | AB24: 0.17629644 | AC24: 0.17629644 | AD24: 0.17629644 | AE24: 0.17629644 | AF24: 0.17629644 | AG24: 0.17629644 | AH24: 0.17629644 | AI24: 0.17629644 | AJ24: 0.17629644 | AK24: 0.17629644 | AL24: 0.17629644 | AM24: 0.17629644 | AN24: 0.17629644 | AO24: 0.17629644 | AP24: 0.17629644 | AQ24: 0.17629644 | AR24: 0.17629644 | AS24: 0.17629644 | AT24: 0.17629644 | AU24: 0.17629644 | AV24: 0.17629644 | AW24: 0.17629644 | AX24: 0.17629644 | AY24: 0.17629644 | AZ24: 0.17629644 | BA24: 0.17629644 | BB24: 0.17629644 | BC24: 0.17629644 | BD24: 0.17629644 | BE24: 0.17629644 | BF24: 0.17629644 | BG24: 0.17629644 | BH24: 0.17629644 | BI24: 0.17629644 | BJ24: 0.17629644 | BK24: 0.17629644 | BL24: 0.17629644 | BM24: 0.17629644 | BN24: 0.17629644 | BO24: 0.17629644 | BP24: 0.17629644 | BQ24: 0.17629644 | BR24: 0.17629644 | BS24: 0.17629644 | BT24: 0.17629644 | BU24: 0.17629644 | BV24: 0.17629644 | BW24: 0.17629644 | BX24: 0.17629644 | BY24: 0.17629644 | BZ24: 0.17629644 | CA24: 0.17629644 | CB24: 0.17629644 | CC24: 0.17629644 | CD24: 0.17629644 | CE24: 0.17629644 | CF24: 0.17629644 | CG24: 0.17629644 | CH24: 0.17629644 | CI24: 0.17629644
B25: Net Income | C25: 20539 | D25: 25489 | E25: 16571 | F25: 39240 | G25: 44281 | H25: 61271 | I25: 72738 | J25: 72361 | K25: 88136 | L25: 101832 | M25: =+(M15-M17-M19+M21-M23) -> 116608.22 | N25: =+(N15-N17-N19+N21-N23) -> 130958.98 | O25: =+(O15-O17-O19+O21-O23) -> 140735.17 | P25: =+(P15-P17-P19+P21-P23) -> 150554.27 | Q25: =+(Q15-Q17-Q19+Q21-Q23) -> 160416.28 | R25: =+(R15-R17-R19+R21-R23) -> 170321.2 | S25: =+(S15-S17-S19+S21-S23) -> 180269.03 | T25: =+(T15-T17-T19+T21-T23) -> 190259.76 | ... CI25: =+(CI15-CI17-CI19+CI21-CI23) -> 957385.94
B26: % Margin | C26: =C25/C15 -> 0.22532198 | D26: =D25/D15 -> 0.26394052 | E26: =E25/E15 -> 0.15015404 | F26: =F25/F15 -> 0.31181711 | G26: =G25/G15 -> 0.30962486 | H26: =H25/H15 -> 0.3550563 | I26: =I25/I15 -> 0.35732778 | J26: =J25/J15 -> 0.3409379 | ... CI26: =CI25/CI15 -> 0.42323792
F28: 2026-2035 CAGR
E29: Base Case | N29: Discount | O29: =+WACC!D16 -> 0.081629526
E30: Revenue | F30: =(V15/M15)^(1/10)-1 -> 0.058633763 | N30: NPV | O30: =NPV(O29,M25:CI25) -> 2981729.3
E31: Cloud | F31: =(V4/M4)^(1/10)-1 -> 0.070729626 | N31: Net cash | O31: =Model!$T$24 -> 51414
E32: Office | F32: =(V5/M5)^(1/10)-1 -> 0.052825232
E33: Windows | F33: =(V6/M6)^(1/10)-1 -> 0.026185083
E34: Gaming | F34: =(V7/M7)^(1/10)-1 -> 0.049095825
E35: Best Case | N35: Fair value | O35: =O30+O31 -> 3033143.3
E36: Revenue | F36: =(V60/M60)^(1/10)-1 -> 0.097728276 | N36: S/O | O36: =Model!$T$15 -> 7432
E37: Cloud | F37: =(V49/M49)^(1/10)-1 -> 0.14265552 | N37: Fair price | O37: =O35/O36 -> 408.11939
E38: Office | F38: =(V50/M50)^(1/10)-1 -> 0.052825232
E39: Windows | F39: =(V51/M51)^(1/10)-1 -> 0.026185083
E40: Gaming | F40: =(V52/M52)^(1/10)-1 -> 0.049095825
E41: Worst Case | N41: Stock price | O41: 418.79
E42: Revenue | F42: =(V98/M98)^(1/10)-1 -> 0.052511216 | N42: Downside | O42: =O37/O41-1 -> -0.02547962
...

Sheet Model2
A1: Main | AD1: 44742 | AF1: 44926 | AH1: 45107 | AJ1: 45291 | AL1: 45473 | AN1: 45657
C2: Q116 | D2: Q216 | E2: Q316 | F2: Q416 | G2: Q117 | H2: Q217 | I2: Q317 | J2: Q417 | K2: Q118 | L2: Q218 | M2: Q318 | N2: Q418 | O2: Q119 | P2: Q219 | Q2: Q319 | R2: Q419 | S2: Q120 | T2: Q220 | U2: Q320 | V2: Q420 | W2: Q121 | X2: Q221 | Y2: Q321 | Z2: Q421 | AA2: Q122 | AB2: Q222 | AC2: Q322 | AD2: Q422 | AE2: Q123 | AF2: Q223 | AG2: Q323 | AH2: Q423 | AI2: Q124 | AJ2: Q224 | AK2: Q324 | AL2: Q424 | AM2: Q125 | AN2: Q225 | AO2: Q325 | AP2: Q425 | AQ2: Q126 | AR2: Q226 | AS2: Q326 | AV2: FY16 | AW2: FY17 | AX2: FY18 | AY2: FY19 | AZ2: FY20 | BA2: FY21 | BB2: FY22 | BC2: FY23 | BD2: FY24 | BE2: FY25 | BF2: FY26 | BG2: FY27 | BH2: FY28 | BI2: FY29 | BJ2: FY30 | BK2: FY31 | BL2: FY32 | BM2: FY33 | BN2: FY34 | BO2: FY35 | BP2: FY36 | BQ2: FY37 | BR2: FY38 | BS2: FY39 | BT2: FY40 | BU2: FY41 | BV2: FY42 | BW2: FY43 | BX2: FY44 | BY2: FY45 | BZ2: FY46 | CA2: FY47 | CB2: FY48 | CC2: FY49 | CD2: FY50 | CE2: FY51 | CF2: FY52 | CG2: FY53 | CH2: FY54 | CI2: FY55 | CJ2: FY56 | CK2: FY57 | CL2: FY58 | CM2: FY59 | CN2: FY60 | CO2: FY61 | CP2: FY62 | CQ2: FY63 | CR2: FY64 | CS2: FY65 | CT2: FY66 | CU2: FY67 | CV2: FY68 | CW2: FY69 | CX2: FY70 | CY2: FY71 | CZ2: FY72 | DA2: FY73 | DB2: FY74 | DC2: FY75 | DD2: FY76 | DE2: FY77 | DF2: FY78 | DG2: FY79 | DH2: FY80 | DI2: FY81 | DJ2: FY82 | DK2: FY83 | DL2: FY84 | DM2: FY85 | DN2: FY86 | DO2: FY87 | DP2: FY88 | DQ2: FY89 | DR2: FY90 | DS2: FY91 | DT2: FY92 | DU2: FY93 | DV2: FY94 | DW2: FY95 | DX2: FY96 | DY2: FY97 | DZ2: FY98 | EA2: FY99 | EB2: FY100 | EC2: FY101 | ED2: FY102 | EE2: FY103 | EF2: FY104 | EG2: FY105 | EH2: FY106 | EI2: FY107 | EJ2: FY108 | EK2: FY109 | EL2: FY110 | EM2: FY111 | EN2: FY112 | EO2: FY113 | EP2: FY114 | EQ2: FY115 | ER2: FY116 | ES2: FY117 | ET2: FY118 | EU2: FY119 | EV2: FY120 | EW2: FY121 | EX2: FY122 | EY2: FY123 | EZ2: FY124 | FA2: FY125 | FB2: FY126 | FC2: FY127 | FD2: FY128 | FE2: FY129 | FF2: FY130 | FG2: FY131 | FH2: FY132 | FI2: FY133 | FJ2: FY134 | FK2: FY135 | FL2: FY136 | FM2: FY137 | FN2: FY138 | FO2: FY139 | FP2: FY140 | FQ2: FY141 | FR2: FY142 | FS2: FY143 | FT2: FY144 | FU2: FY145 | FV2: FY146 | FW2: FY147 | FX2: FY148 | FY2: FY149 | FZ2: FY150 | GA2: FY151 | GB2: FY152 | GC2: FY153 | GD2: FY154 | GE2: FY155 | GF2: FY156 | GG2: FY157 | GH2: FY158 | GI2: FY159 | GJ2: FY160 | GK2: FY161 | GL2: FY162 | GM2: FY163 | GN2: FY164 | GO2: FY165 | GP2: FY166 | GQ2: FY167 | GR2: FY168 | GS2: FY169 | GT2: FY170 | GU2: FY171 | GV2: FY172 | GW2: FY173 | GX2: FY174 | GY2: FY175 | GZ2: FY176 | HA2: FY177 | HB2: FY178 | HC2: FY179 | HD2: FY180 | HE2: FY181 | HF2: FY182 | HG2: FY183 | HH2: FY184 | HI2: FY185 | HJ2: FY186 | HK2: FY187 | HL2: FY188 | HM2: FY189 | HN2: FY190 | HO2: FY191 | HP2: FY192 | HQ2: FY193 | HR2: FY194 | HS2: FY195 | HT2: FY196 | HU2: FY197 | HV2: FY198 | HW2: FY199 | HX2: FY200 | HY2: FY201 | HZ2: FY202 | IA2: FY203 | IB2: FY204 | IC2: FY205 | ID2: FY206 | IE2: FY207 | IF2: FY208 | IG2: FY209 | IH2: FY210 | II2: FY211 | IJ2: FY212 | IK2: FY213 | IL2: FY214 | IM2: FY215 | IN2: FY216 | IO2: FY217 | IP2: FY218 | IQ2: FY219 | IR2: FY220 | IS2: FY221 | IT2: FY222 | IU2: FY223 | IV2: FY224 | IW2: FY225 | IX2: FY226 | IY2: FY227 | IZ2: FY228 | JA2: FY229 | JB2: FY230 | JC2: FY231 | JD2: FY232 | JE2: FY233 | JF2: FY234 | JG2: FY235 | JH2: FY236 | JI2: FY237 | JJ2: FY238 | JK2: FY239 | JL2: FY240 | JM2: FY241 | JN2: FY242 | JO2: FY243 | JP2: FY244 | JQ2: FY245 | JR2: FY246 | JS2: FY247 | JT2: FY248 | JU2: FY249 | JV2: FY250 | JW2: FY251 | JX2: FY252 | JY2: FY253 | JZ2: FY254 | KA2: FY255 | KB2: FY256 | KC2: FY257 | KD2: FY258 | KE2: FY259 | KF2: FY260 | KG2: FY261 | KH2: FY262 | KI2: FY263 | KJ2: FY264 | KK2: FY265 | KL2: FY266 | KM2: FY267 | KN2: FY268 | KO2: FY269 | KP2: FY270 | KQ2: FY271 | KR2: FY272 | KS2: FY273 | KT2: FY274 | KU2: FY275 | KV2: FY276 | KW2: FY277 | KX2: FY278 | KY2: FY279 | KZ2: FY280 | LA2: FY281 | LB2: FY282 | LC2: FY283 | LD2: FY284 | LE2: FY285 | LF2: FY286 | LG2: FY287 | LH2: FY288 | LI2: FY289 | LJ2: FY290 | LK2: FY291 | LL2: FY292 | LM2: FY293 | LN2: FY294 | LO2: FY295 | LP2: FY296 | LQ2: FY297 | LR2: FY298 | LS2: FY299 | LT2: FY300 | LU2: FY301 | LV2: FY302 | LW2: FY303 | LX2: FY304 | LY2: FY305 | LZ2: FY306 | MA2: FY307 | MB2: FY308 | MC2: FY309 | MD2: FY310 | ME2: FY311 | MF2: FY312 | MG2: FY313 | MH2: FY314 | MI2: FY315 | MJ2: FY316 | MK2: FY317 | ML2: FY318 | MM2: FY319 | MN2: FY320 | MO2: FY321 | MP2: FY322 | MQ2: FY323 | MR2: FY324 | MS2: FY325 | MT2: FY326 | MU2: FY327 | MV2: FY328 | MW2: FY329 | MX2: FY330 | MY2: FY331 | MZ2: FY332 | NA2: FY333 | NB2: FY334 | NC2: FY335 | ND2: FY336 | NE2: FY337 | NF2: FY338 | NG2: FY339 | NH2: FY340 | NI2: FY341 | NJ2: FY342 | NK2: FY343 | NL2: FY344 | NM2: FY345 | NN2: FY346 | NO2: FY347 | NP2: FY348 | NQ2: FY349 | NR2: FY350 | NS2: FY351 | NT2: FY352 | NU2: FY353 | NV2: FY354 | NW2: FY355 | NX2: FY356 | NY2: FY357 | NZ2: FY358 | OA2: FY359 | OB2: FY360 | OC2: FY361 | OD2: FY362 | OE2: FY363 | OF2: FY364 | OG2: FY365 | OH2: FY366 | OI2: FY367 | OJ2: FY368 | OK2: FY369 | OL2: FY370 | OM2: FY371 | ON2: FY372 | OO2: FY373 | OP2: FY374 | OQ2: FY375 | OR2: FY376 | OS2: FY377 | OT2: FY378 | OU2: FY379 | OV2: FY380 | OW2: FY381 | OX2: FY382 | OY2: FY383 | OZ2: FY384 | PA2: FY385 | PB2: FY386 | PC2: FY387 | PD2: FY388 | PE2: FY389 | PF2: FY390 | PG2: FY391 | PH2: FY392 | PI2: FY393 | PJ2: FY394 | PK2: FY395 | PL2: FY396 | PM2: FY397 | PN2: FY398 | PO2: FY399 | PP2: FY400 | PQ2: FY401 | PR2: FY402 | PS2: FY403 | PT2: FY404 | PU2: FY405 | PV2: FY406 | PW2: FY407 | PX2: FY408 | PY2: FY409 | PZ2: FY410 | QA2: FY411 | QB2: FY412 | QC2: FY413 | QD2: FY414 | QE2: FY415 | QF2: FY416 | QG2: FY417 | QH2: FY418 | QI2: FY419 | QJ2: FY420 | QK2: FY421 | QL2: FY422 | QM2: FY423 | QN2: FY424 | QO2: FY425 | QP2: FY426 | QQ2: FY427 | QR2: FY428 | QS2: FY429 | QT2: FY430 | QU2: FY431 | QV2: FY432 | QW2: FY433 | QX2: FY434 | QY2: FY435 | QZ2: FY436 | RA2: FY437 | RB2: FY438 | RC2: FY439 | RD2: FY440 | RE2: FY441 | RF2: FY442 | RG2: FY443 | RH2: FY444 | RI2: FY445 | RJ2: FY446 | RK2: FY447 | RL2: FY448 | RM2: FY449 | RN2: FY450 | RO2: FY451 | RP2: FY452 | RQ2: FY453 | RR2: FY454 | RS2: FY455 | RT2: FY456 | RU2: FY457 | RV2: FY458 | RW2: FY459 | RX2: FY460 | RY2: FY461 | RZ2: FY462 | SA2: FY463 | SB2: FY464 | SC2: FY465 | SD2: FY466 | SE2: FY467 | SF2: FY468 | SG2: FY469 | SH2: FY470 | SI2: FY471 | SJ2: FY472 | SK2: FY473 | SL2: FY474 | SM2: FY475 | SN2: FY476 | SO2: FY477 | SP2: FY478 | SQ2: FY479 | SR2: FY480 | SS2: FY481 | ST2: FY482 | SU2: FY483 | SV2: FY484 | SW2: FY485 | SX2: FY486 | SY2: FY487 | SZ2: FY488 | TA2: FY489
B3: Server and cloud | AE3: 14948 | AF3: 16012 | AG3: 16187 | AH3: 17860 | AI3: 18062 | AJ3: 19597 | AK3: 20266 | AL3: 21903 | AM3: 22155 | AN3: 23641 | AO3: 24761 | AP3: 27878 | AQ3: 28872 | AR3: 30865 | BC3: 65007 | BD3: 79828 | BE3: =SUM(AM3:AP3) -> 98435
B4: MS 365 Commercial and cloud | AE4: 15502 | AF4: 15774 | AG4: 17195 | AH4: 18478 | AI4: 18044 | AJ4: 18321 | AK4: 19712 | AL4: 20892 | AM4: 20449 | AN4: 21117 | AO4: 21883 | AP4: 24318 | AQ4: 23966 | AR4: 24524 | BC4: 66949 | BD4: 76969 | BE4: =SUM(AM4:AP4) -> 87767
B5: Gaming | AE5: 3610 | AF5: 4758 | AG5: 3607 | AH5: 3491 | AI5: 3919 | AJ5: 7111 | AK5: 5451 | AL5: 5022 | AM5: 5621 | AN5: 6581 | AO5: 5721 | AP5: 5532 | AQ5: 5508 | AR5: 5958 | BB5: 16230 | BC5: 15466 | BD5: 21503 | BE5: =SUM(AM5:AP5) -> 23455
B6: LinkedIn | AE6: 3628 | AF6: 3833 | AG6: 3659 | AH6: 3869 | AI6: 3913 | AJ6: 4195 | AK6: 4013 | AL6: 4251 | AM6: 4292 | AN6: 4587 | AO6: 4311 | AP6: 4622 | AQ6: 4714 | AR6: 5082 | BB6: 13631 | BC6: 14989 | BD6: 16372 | BE6: =SUM(AM6:AP6) -> 17812
B7: Windows and Devices | AE7: 4593 | AF7: 4219 | AG7: 4040 | AH7: 4295 | AI7: 4340 | AJ7: 4363 | AK7: 4098 | AL7: 4225 | AM7: 4329 | AN7: 4512 | AO7: 4144 | AP7: 4329 | AQ7: 4551 | AR7: 4479 | BB7: =24732+7306 -> 32038 | BC7: 17147 | BD7: 17026 | BE7: =SUM(AM7:AP7) -> 17314
B8: Search and news ads | AE8: 2913 | AF8: 3209 | AG8: 3034 | AH8: 2969 | AI8: 3018 | AJ8: 3168 | AK8: 3055 | AL8: 3065 | AM8: 3225 | AN8: 3558 | AO8: 3504 | AP8: 3591 | AQ8: 3697 | AR8: 3812 | BB8: 11526 | BC8: 12125 | BD8: 12306 | BE8: =SUM(AM8:AP8) -> 13878
B9: Enterprise | AE9: 1929 | AF9: 1907 | AG9: 2047 | AH9: 2017 | AI9: 1944 | AJ9: 1917 | AK9: 1861 | AL9: 1872 | AM9: 1928 | AN9: 1892 | AO9: 1929 | AP9: 2136 | AQ9: 2204 | AR9: 2305 | BB9: 7605 | BC9: 7900 | BD9: 7594 | BE9: =SUM(AM9:AP9) -> 7885
B10: Dynamics and cloud | AE10: 1345 | AF10: 1391 | AG10: 1484 | AH10: 1576 | AI10: 1626 | AJ10: 1659 | AK10: 1740 | AL10: 1806 | AM10: 1849 | AN10: 1913 | AO10: 1946 | AP10: 1994 | AQ10: 2136 | AR10: 2204 | BB10: 4687 | BC10: 5796 | BD10: 6831 | BE10: =SUM(AM10:AP10) -> 7702
B11: MS 365 Consumer and cloud | AE11: 1599 | AF11: 1605 | AG11: 1586 | AH11: 1627 | AI11: 1643 | AJ11: 1679 | AK11: 1648 | AL11: 1678 | AM11: 1727 | AN11: 1821 | AO11: 1821 | AP11: 2035 | AQ11: 2022 | AR11: 2038 | BC11: 6417 | BD11: 6648 | BE11: =SUM(AM11:AP11) -> 7404
B12: Other | AE12: 55 | AF12: 39 | AG12: 18 | AH12: 7 | AI12: 8 | AJ12: 10 | AK12: 14 | AL12: 13 | AM12: 10 | AN12: 10 | AO12: 46 | AP12: 6 | AQ12: 3 | AR12: 6 | BB12: 45 | BC12: 119 | BD12: 45 | BE12: =SUM(AM12:AP12) -> 72
AX13: =SUM(AX3:AX12) -> 0 | AY13: =SUM(AY3:AY12) -> 0 | AZ13: =SUM(AZ3:AZ12) -> 0 | BA13: =SUM(BA3:BA12) -> 0 | BB13: =SUM(BB3:BB12) -> 85762 | BC13: =SUM(BC3:BC12) -> 211915 | BD13: =SUM(BD3:BD12) -> 245122 | BE13: =SUM(BE3:BE12) -> 281724
B14: Y/Y stats
B15: Server and cloud | AI15: =AI3/AE3-1 -> 0.20832218 | AJ15: =AJ3/AF3-1 -> 0.22389458 | AK15: =AK3/AG3-1 -> 0.25199234 | AL15: =AL3/AH3-1 -> 0.22637178 | AM15: =AM3/AI3-1 -> 0.22660835 | AN15: =AN3/AJ3-1 -> 0.20635812 | AO15: =AO3/AK3-1 -> 0.22180006 | AP15: =AP3/AL3-1 -> 0.27279368 | ... AR15: =AR3/AN3-1 -> 0.30557083 | BD15: =BD3/BC3-1 -> 0.22799083 | BE15: =BE3/BD3-1 -> 0.23308864
B16: MS 365 Commercial and cloud | AI16: =AI4/AE4-1 -> 0.16397884 | AJ16: =AJ4/AF4-1 -> 0.16146824 | AK16: =AK4/AG4-1 -> 0.14637976 | AL16: =AL4/AH4-1 -> 0.13064184 | AM16: =AM4/AI4-1 -> 0.1332853 | AN16: =AN4/AJ4-1 -> 0.15261176 | AO16: =AO4/AK4-1 -> 0.11013596 | AP16: =AP4/AL4-1 -> 0.16398621 | ... AR16: =AR4/AN4-1 -> 0.16133921 | BD16: =BD4/BC4-1 -> 0.14966616 | BE16: =BE4/BD4-1 -> 0.14029025
B17: Gaming | AI17: =AI5/AE5-1 -> 0.085595568 | AJ17: =AJ5/AF5-1 -> 0.49453552 | AK17: =AK5/AG5-1 -> 0.51122817 | AL17: =AL5/AH5-1 -> 0.43855629 | AM17: =AM5/AI5-1 -> 0.43429446 | AN17: =AN5/AJ5-1 -> -0.074532415 | AO17: =AO5/AK5-1 -> 0.049532196 | AP17: =AP5/AL5-1 -> 0.10155317 | ... AR17: =AR5/AN5-1 -> -0.094666464 | BD17: =BD5/BC5-1 -> 0.3903401 | BE17: =BE5/BD5-1 -> 0.090778031
B18: LinkedIn | AI18: =AI6/AE6-1 -> 0.078555678 | AJ18: =AJ6/AF6-1 -> 0.094442995 | AK18: =AK6/AG6-1 -> 0.096747745 | AL18: =AL6/AH6-1 -> 0.098733523 | AM18: =AM6/AI6-1 -> 0.096856632 | AN18: =AN6/AJ6-1 -> 0.093444577 | AO18: =AO6/AK6-1 -> 0.074258659 | AP18: =AP6/AL6-1 -> 0.087273583 | ... AR18: =AR6/AN6-1 -> 0.10791367 | BD18: =BD6/BC6-1 -> 0.092267663 | BE18: =BE6/BD6-1 -> 0.087955045
B19: Windows and Devices | AI19: =AI7/AE7-1 -> -0.055083823 | AJ19: =AJ7/AF7-1 -> 0.034131311 | AK19: =AK7/AG7-1 -> 0.014356436 | AL19: =AL7/AH7-1 -> -0.016298021 | AM19: =AM7/AI7-1 -> -0.0025345622 | AN19: =AN7/AJ7-1 -> 0.034150814 | AO19: =AO7/AK7-1 -> 0.011224988 | AP19: =AP7/AL7-1 -> 0.024615385 | ... AR19: =AR7/AN7-1 -> -0.0073138298 | BD19: =BD7/BC7-1 -> -0.007056628 | BE19: =BE7/BD7-1 -> 0.016915306
B20: Search and news ads | AI20: =AI8/AE8-1 -> 0.036045314 | AJ20: =AJ8/AF8-1 -> -0.012776566 | AK20: =AK8/AG8-1 -> 0.0069215557 | AL20: =AL8/AH8-1 -> 0.032334119 | AM20: =AM8/AI8-1 -> 0.068588469 | AN20: =AN8/AJ8-1 -> 0.12310606 | AO20: =AO8/AK8-1 -> 0.14697218 | AP20: =AP8/AL8-1 -> 0.17161501 | ... AR20: =AR8/AN8-1 -> 0.07138842 | BD20: =BD8/BC8-1 -> 0.014927835 | BE20: =BE8/BD8-1 -> 0.12774256
B21: Enterprise | AI21: =AI9/AE9-1 -> 0.0077760498 | AJ21: =AJ9/AF9-1 -> 0.0052438385 | AK21: =AK9/AG9-1 -> -0.09086468 | AL21: =AL9/AH9-1 -> -0.071888944 | AM21: =AM9/AI9-1 -> -0.0082304527 | AN21: =AN9/AJ9-1 -> -0.01304121 | AO21: =AO9/AK9-1 -> 0.036539495 | AP21: =AP9/AL9-1 -> 0.14102564 | ... AR21: =AR9/AN9-1 -> 0.21828753 | BD21: =BD9/BC9-1 -> -0.038734177 | BE21: =BE9/BD9-1 -> 0.038319726
B22: Dynamics and cloud | AI22: =AI10/AE10-1 -> 0.20892193 | AJ22: =AJ10/AF10-1 -> 0.19266715 | AK22: =AK10/AG10-1 -> 0.17250674 | AL22: =AL10/AH10-1 -> 0.14593909 | AM22: =AM10/AI10-1 -> 0.13714637 | AN22: =AN10/AJ10-1 -> 0.15310428 | AO22: =AO10/AK10-1 -> 0.1183908 | AP22: =AP10/AL10-1 -> 0.10409745 | ... AR22: =AR10/AN10-1 -> 0.15211709 | BD22: =BD10/BC10-1 -> 0.17857143 | BE22: =BE10/BD10-1 -> 0.12750695
B23: MS 365 Consumer and cloud | AI23: =AI11/AE11-1 -> 0.027517198 | AJ23: =AJ11/AF11-1 -> 0.046105919 | AK23: =AK11/AG11-1 -> 0.039092055 | AL23: =AL11/AH11-1 -> 0.031346036 | AM23: =AM11/AI11-1 -> 0.051125989 | AN23: =AN11/AJ11-1 -> 0.084574151 | AO23: =AO11/AK11-1 -> 0.10497573 | AP23: =AP11/AL11-1 -> 0.21275328 | ... AR23: =AR11/AN11-1 -> 0.11916529 | BD23: =BD11/BC11-1 -> 0.03599813 | BE23: =BE11/BD11-1 -> 0.11371841
B26: Product | C26: 15750 | D26: 19431 | E26: 15307 | F26: 16848 | G26: 14968 | H26: 18273 | I26: 14513 | J26: 16057 | K26: 14298 | L26: 17926 | M26: 15114 | N26: 17159 | O26: 17299 | P26: 16219 | Q26: 15448 | R26: 17103 | S26: 15768 | T26: 18255 | U26: 15871 | V26: 18147 | W26: 15803 | X26: 19460 | Y26: 16873 | Z26: 18938 | AA26: 16631 | AB26: 20779 | AC26: 17366 | AD26: 17956 | AE26: 15741 | AF26: 16517 | AG26: 15588 | AH26: 16853 | AI26: 15535 | AJ26: 18941 | AK26: 17080 | AL26: 13217 | AM26: 15272 | AN26: 16219 | AO26: 15319 | AP26: 17136 | AQ26: 15922 | AR26: 16451 | AV26: 67336 | AW26: 63811 | AX26: 64497 | AY26: 66069 | AZ26: 68041 | BA26: 71074 | BB26: 72732 | BC26: 64699 | BD26: 64773 | BE26: =AM26+AN26+AO26+AP26 -> 63946
B27: Service and Other | C27: 5160 | D27: 5822 | E27: 6210 | F27: 6626 | G27: 6960 | H27: 7553 | I27: 8699 | J27: 9548 | K27: 10240 | L27: 10992 | M27: 11705 | N27: 12926 | O27: 11785 | P27: 16252 | Q27: 15123 | R27: 16614 | S27: 17287 | T27: 18651 | U27: 19150 | V27: 19886 | W27: 21351 | X27: 23616 | Y27: 24833 | Z27: 27214 | AA27: 28686 | AB27: 30949 | AC27: 31994 | AD27: 33909 | AE27: 34381 | AF27: 36230 | AG27: 37269 | AH27: 39336 | AI27: 40982 | AJ27: 43079 | AK27: 44778 | AL27: 51510 | AM27: 50313 | AN27: 53413 | AO27: 54747 | AP27: 59305 | AQ27: 61751 | AR27: 64822 | AV27: 23818 | AW27: 32760 | AX27: 45863 | AY27: 59774 | AZ27: 74974 | BA27: 97014 | BB27: 125538 | BC27: 147216 | BD27: 180349 | BE27: =AM27+AN27+AO27+AP27 -> 217778
B28: Revenue | C28: =SUM(C26:C27) -> 20910 | D28: =SUM(D26:D27) -> 25253 | E28: =SUM(E26:E27) -> 21517 | F28: =SUM(F26:F27) -> 23474 | G28: =SUM(G26:G27) -> 21928 | H28: =SUM(H26:H27) -> 25826 | I28: =SUM(I26:I27) -> 23212 | J28: =SUM(J26:J27) -> 25605 | ... AR28: =SUM(AR26:AR27) -> 81273 | AV28: =SUM(AV26:AV27) -> 91154 | AW28: =SUM(AW26:AW27) -> 96571 | AX28: =SUM(AX26:AX27) -> 110360 | AY28: =SUM(AY26:AY27) -> 125843 | AZ28: =SUM(AZ26:AZ27) -> 143015 | BA28: =SUM(BA26:BA27) -> 168088 | BB28: =SUM(BB26:BB27) -> 198270 | BC28: =SUM(BC26:BC27) -> 211915 | BD28: =SUM(BD26:BD27) -> 245122 | BE28: =AM28+AN28+AO28+AP28 -> 281724 | BF28: =BE28*1.13 -> 318348.12 | BG28: =BF28*1.1 -> 350182.93 | BH28: =BG28*1.1 -> 385201.23
B29: Product COGS | C29: 4035 | D29: 6268 | E29: 3801 | F29: 3776 | G29: 3581 | H29: 5378 | I29: 3075 | J29: 3141 | K29: 2980 | L29: 5498 | M29: 3425 | N29: 3517 | O29: 3649 | P29: 5885 | Q29: 3441 | R29: 3298 | S29: 3305 | T29: 4966 | U29: 3376 | V29: 4370 | W29: 3597 | X29: 6058 | Y29: 4277 | Z29: 4287 | AA29: 3792 | AB29: 6331 | AC29: 4584 | AD29: 4357 | AE29: 4302 | AF29: 5690 | AG29: 3941 | AH29: 3871 | AI29: 3531 | AJ29: 5964 | AK29: 4339 | AL29: 1438 | AM29: 3294 | AN29: 3856 | AO29: 3037 | AP29: 3314 | AQ29: 2922 | AR29: 3505 | AV29: 17880 | AW29: 15175 | AX29: 15420 | AY29: 16273 | AZ29: 16017 | BA29: 18219 | BB29: 19064 | BC29: 17804 | BD29: 15272 | BE29: =AM29+AN29+AO29+AP29 -> 13501
B30: Services COGS | C30: 3172 | D30: 3604 | E30: 3921 | F30: 4203 | G30: 4263 | H30: 4523 | I30: 4985 | J30: 5315 | K30: 5298 | L30: 5566 | M30: 5844 | N30: 6225 | O30: 6256 | P30: 6538 | Q30: 6729 | R30: 7114 | S30: 7101 | T30: 7392 | U30: 7599 | V30: 7969 | W30: 7405 | X30: 8136 | Y30: 8768 | Z30: 9704 | AA30: 9854 | AB30: 10629 | AC30: 11031 | AD30: 12072 | AE30: 11150 | AF30: 11798 | AG30: 12187 | AH30: 12924 | AI30: 12771 | AJ30: 13659 | AK30: 14166 | AL30: 18246 | AM30: 16805 | AN30: 17943 | AO30: 18882 | AP30: 20700 | AQ30: 21121 | AR30: 22473 | AV30: 14900 | AW30: 19086 | AX30: 22933 | AY30: 26637 | AZ30: 30061 | BA30: 34013 | BB30: 43586 | BC30: 48059 | BD30: 58842 | BE30: =AM30+AN30+AO30+AP30 -> 74330
B31: COGS | C31: =SUM(C29:C30) -> 7207 | D31: =SUM(D29:D30) -> 9872 | E31: =SUM(E29:E30) -> 7722 | F31: =SUM(F29:F30) -> 7979 | G31: =SUM(G29:G30) -> 7844 | H31: =SUM(H29:H30) -> 9901 | I31: =SUM(I29:I30) -> 8060 | J31: =SUM(J29:J30) -> 8456 | ... AR31: =SUM(AR29:AR30) -> 25978 | AV31: =SUM(AV29:AV30) -> 32780 | AW31: =SUM(AW29:AW30) -> 34261 | AX31: =SUM(AX29:AX30) -> 38353 | AY31: =SUM(AY29:AY30) -> 42910 | AZ31: =SUM(AZ29:AZ30) -> 46078 | BA31: =SUM(BA29:BA30) -> 52232 | BB31: =SUM(BB29:BB30) -> 62650 | BC31: =SUM(BC29:BC30) -> 65863 | ... BE31: =SUM(BE29:BE30) -> 87831
B32: Gross Profit | C32: =C28-C31 -> 13703 | D32: =D28-D31 -> 15381 | E32: =E28-E31 -> 13795 | F32: =F28-F31 -> 15495 | G32: =G28-G31 -> 14084 | H32: =H28-H31 -> 15925 | I32: =I28-I31 -> 15152 | J32: =J28-J31 -> 17149 | ... AR32: =AR28-AR31 -> 55295 | AV32: =AV28-AV31 -> 58374 | AW32: =AW28-AW31 -> 62310 | AX32: =AX28-AX31 -> 72007 | AY32: =AY28-AY31 -> 82933 | AZ32: =AZ28-AZ31 -> 96937 | BA32: =BA28-BA31 -> 115856 | BB32: =BB28-BB31 -> 135620 | BC32: =BC28-BC31 -> 146052 | ... BE32: =BE28-BE31 -> 193893 | BF32: =BF28*0.7 -> 222843.68 | BG32: =BG28*0.7 -> 245128.05 | BH32: =BH28*0.7 -> 269640.86
B33: R&D | C33: 2962 | D33: 2900 | E33: 2980 | F33: 3146 | G33: 3106 | H33: 3062 | I33: 3355 | J33: 3514 | K33: 3574 | L33: 3504 | M33: 3715 | N33: 3933 | O33: 3977 | P33: 4070 | Q33: 4316 | R33: 4513 | S33: 4565 | T33: 4603 | U33: 4887 | V33: 5214 | W33: 4926 | X33: 4899 | Y33: 5204 | Z33: 5687 | AA33: 5599 | AB33: 5758 | AC33: 6306 | AD33: 6849 | AE33: 6628 | AF33: 6844 | AG33: 6984 | AH33: 6739 | AI33: 6659 | AJ33: 7142 | AK33: 7653 | AL33: 805 | AM33: 7544 | AN33: 7917 | AO33: 8198 | AP33: 8829 | AQ33: 8146 | AR33: 8504 | AV33: 11988 | AW33: 13037 | AX33: 14726 | AY33: 16876 | AZ33: 19269 | BA33: 20716 | BB33: 24512 | BC33: 27195 | BD33: 29510 | BE33: =AM33+AN33+AO33+AP33 -> 32488
