Workbook

Sheet Main
A1: Main
B5: Segment | C5: Product | D5: % | E5: Employees
B6: Cloud | C6: Oracle Applications, Oracle Database and Oracle Middleware software offerings | D6: =(Model!V3+Model!V4)/Model!V7 -> 0.83956119 | E6: 29000 | J6: Price | K6: 338.36
B7: Hardware | C7: Oracle Engineered Systems, servers, storage and industry-specific products, among others. | D7: =Model!V5/Model!V7 -> 0.057891656 | E7: 3000 | J7: S/O | K7: 2805 | L7: Q126
B8: Software | D8: =+Model!V3/Model!V4 -> 7.7510333 | E8: 37000 | J8: MC | K8: =K6*K7 -> 949099.8
J9: Cash | K9: =+Model!K51+Model!K52 -> 11005 | L9: Q126
B10: R&D | E10: 50000 | J10: Debt | K10: =+Model!K61+Model!K66 -> 91315 | L10: Q126
B11: S&M | E11: 31000
B12: G&A | E12: 12000 | J12: EV | K12: =K8-K9+K10 -> 1029409.8
E13: =SUM(E6:E12) -> 162000
B16: Oracle, Java, MySQL, and NetSuite are registered trademarks of Oracle Corporation. NetSuite was the first cloud company—ushering in the new era of cloud computing.

Sheet Model
A1: Main | J1: 45808
C2: Q124 | D2: Q224 | E2: Q324 | F2: Q424 | G2: Q125 | H2: Q225 | I2: Q325 | J2: Q425 | K2: Q126 | L2: Q226 | M2: Q326 | N2: Q426 | O2: Q127 | P2: Q227 | T2: 2024 | U2: 2025 | V2: FY24 | W2: FY25 | X2: FY26 | Y2: FY27 | Z2: FY28 | AA2: FY29 | AB2: FY30 | AC2: FY31 | AD2: FY32 | AE2: FY33 | AF2: FY34 | AG2: FY35 | AH2: FY36 | AI2: FY37 | AJ2: FY38 | AK2: FY39 | AL2: FY40 | AM2: FY41 | AN2: FY42 | AO2: FY43 | AP2: FY44 | AQ2: FY45
B3: Cloud services and license support | C3: 9547 | D3: 9639 | E3: 9963 | F3: 10234 | G3: 10519 | H3: 10806 | I3: 11007 | J3: 11698 | K3: 7186 | V3: 39383 | W3: 44029
B4: Cloud license and on-premise license | C4: 809 | D4: 1178 | E4: 1256 | F4: 1838 | G4: 870 | H4: 1195 | I4: 1129 | J4: 2007 | K4: 5721 | V4: 5081 | W4: 5201
B5: Hardware | C5: 714 | D5: 756 | E5: 754 | F5: 842 | G5: 655 | H5: 728 | I5: 703 | J5: 850 | K5: 670 | V5: 3066 | W5: 2936
B6: Services | C6: 1383 | D6: 1368 | E6: 1307 | F6: 1373 | G6: 1263 | H6: 1330 | I6: 1291 | J6: 1348 | K6: 1349 | V6: 5431 | W6: 5233
B7: Total revenues | C7: =SUM(C3:C6) -> 12453 | D7: =SUM(D3:D6) -> 12941 | E7: =SUM(E3:E6) -> 13280 | F7: =SUM(F3:F6) -> 14287 | G7: =SUM(G3:G6) -> 13307 | H7: =SUM(H3:H6) -> 14059 | I7: =SUM(I3:I6) -> 14130 | J7: =SUM(J3:J6) -> 15903 | ... O7: =SUM(O3:O6) -> 0 | T7: =SUM(F7:I7) -> 55783 | U7: =+J7+15040+16200+16730 -> 63873 | V7: =SUM(V3:V6) -> 52961 | W7: =SUM(W3:W6) -> 57399 | X7: 66760 | Y7: 80050 | Z7: =(Y112*Y113)/0.86 -> 108882.9 | AA7: =(Z112*Z113)/0.87 -> 133904.77 | AB7: =(AA112*AA113)/0.87 -> 166566.53 | AC7: =(AB112*AB113)/0.87 -> 207164.59 | AD7: =(AC112*AC113)/0.88 -> 228269.99 | AE7: =(AD112*AD113)/0.88 -> 254380.96 | AF7: =(AE112*AE113)/0.89 -> 280255.13 | AG7: =(AF112*AF113)/0.89 -> 312227.93 | AH7: =(AG112*AG113)/0.9 -> 343938.36
B8: Cloud services and license support costs | C8: 2179 | D8: 2274 | E8: 2452 | F8: 2522 | G8: 2597 | H8: 2746 | I8: 2882 | J8: 3343 | K8: 3607 | V8: 9427 | W8: 11569
B9: Hardware | C9: 219 | D9: 213 | E9: 217 | F9: 241 | G9: 162 | H9: 172 | I9: 197 | J9: 252 | K9: 178 | V9: 891 | W9: 782
B10: Services | C10: 1212 | D10: 1253 | E10: 1200 | F10: 1160 | G10: 1147 | H10: 1167 | I10: 1116 | J10: 1145 | K10: 1099 | V10: 4825 | W10: 4576
B11: COGS | C11: =SUM(C8:C10) -> 3610 | D11: =SUM(D8:D10) -> 3740 | E11: =SUM(E8:E10) -> 3869 | F11: =SUM(F8:F10) -> 3923 | G11: =SUM(G8:G10) -> 3906 | H11: =SUM(H8:H10) -> 4085 | I11: =SUM(I8:I10) -> 4195 | J11: =SUM(J8:J10) -> 4740 | ... O11: =SUM(O8:O10) -> 0 | V11: =SUM(V8:V10) -> 15143 | W11: =SUM(W8:W10) -> 16927
B12: Gross Profit | C12: =C7-C11 -> 8843 | D12: =D7-D11 -> 9201 | E12: =E7-E11 -> 9411 | F12: =F7-F11 -> 10364 | G12: =G7-G11 -> 9401 | H12: =H7-H11 -> 9974 | I12: =I7-I11 -> 9935 | J12: =J7-J11 -> 11163 | ... O12: =O7-O11 -> 0 | V12: =V7-V11 -> 37818 | W12: =W7-W11 -> 40472
B13: S&M | C13: 2026 | D13: 2093 | E13: 2042 | F13: 2114 | G13: 2036 | H13: 2190 | I13: 2119 | J13: 2306 | K13: 2063 | V13: 8274 | W13: 8651
B14: R&D | C14: 2216 | D14: 2226 | E14: 2248 | F14: 2226 | G14: 2306 | H14: 2471 | I14: 2429 | J14: 2654 | K14: 2491 | V14: 8915 | W14: 9860
B15: G&A | C15: 393 | D15: 375 | E15: 377 | F15: 402 | G15: 358 | H15: 387 | I15: 390 | J15: 467 | K15: 376 | V15: 1548 | W15: 1602
B16: Amortization | C16: 763 | D16: 755 | E16: 749 | F16: 743 | G16: 624 | H16: 591 | I16: 548 | J16: 544 | K16: 420 | V16: 3010 | W16: 2307
B17: Acquisition related and other | C17: 11 | D17: 47 | E17: 155 | F17: 101 | G17: 13 | H17: 31 | I17: 28 | J17: 4 | K17: 13 | V17: 314 | W17: 75
B18: Restructuring | C18: 138 | D18: 83 | E18: 90 | F18: 92 | G18: 73 | H18: 84 | I18: 63 | J18: 79 | K18: 402 | V18: 404 | W18: 299
B19: Operating expenses | C19: =SUM(C13:C18) -> 5547 | D19: =SUM(D13:D18) -> 5579 | E19: =SUM(E13:E18) -> 5661 | F19: =SUM(F13:F18) -> 5678 | G19: =SUM(G13:G18) -> 5410 | H19: =SUM(H13:H18) -> 5754 | I19: =SUM(I13:I18) -> 5577 | J19: =SUM(J13:J18) -> 6054 | ... O19: =SUM(O13:O18) -> 0 | V19: =SUM(V13:V18) -> 22465 | W19: =SUM(W13:W18) -> 22794
B20: Operating Profit | C20: =C12-C19 -> 3296 | D20: =D12-D19 -> 3622 | E20: =E12-E19 -> 3750 | F20: =F12-F19 -> 4686 | G20: =G12-G19 -> 3991 | H20: =H12-H19 -> 4220 | I20: =I12-I19 -> 4358 | J20: =J12-J19 -> 5109 | ... O20: =O12-O19 -> 0 | V20: =V12-V19 -> 15353 | W20: =W12-W19 -> 17678
B21: Interest income | C21: =-872-49 -> -921 | D21: =-888-14 -> -902 | E21: =-876-9 -> -885 | F21: =-878-26 -> -904 | G21: =-842+20 -> -822 | H21: =-866+36 -> -830 | I21: =-892-18 -> -910 | J21: =-978+20 -> -958 | K21: =-923+73 -> -850 | V21: =-3514-98 -> -3612 | W21: =-3578+60 -> -3518
B22: Pretax Income | C22: =C20+C21 -> 2375 | D22: =D20+D21 -> 2720 | E22: =E20+E21 -> 2865 | F22: =F20+F21 -> 3782 | G22: =G20+G21 -> 3169 | H22: =H20+H21 -> 3390 | I22: =I20+I21 -> 3448 | J22: =J20+J21 -> 4151 | ... O22: =O20+O21 -> 0 | V22: =V20+V21 -> 11741 | W22: =W20+W21 -> 14160
B23: Taxes | C23: -45 | D23: 217 | E23: 464 | F23: 639 | G23: 240 | H23: 239 | I23: 512 | J23: 724 | K23: 500 | V23: 1274 | W23: 1717
B24: Net Income | C24: =C22-C23 -> 2420 | D24: =D22-D23 -> 2503 | E24: =E22-E23 -> 2401 | F24: =F22-F23 -> 3143 | G24: =G22-G23 -> 2929 | H24: =H22-H23 -> 3151 | I24: =I22-I23 -> 2936 | J24: =J22-J23 -> 3427 | ... O24: =O22-O23 -> 0 | V24: =V22-V23 -> 10467 | W24: =W22-W23 -> 12443 | X24: 14730 | Y24: 19260 | Z24: =+Z7*Z37 -> 27245.072 | AA24: =+AA7*AA37 -> 34846.381 | AB24: =+AB7*AB37 -> 45079.875 | AC24: =+AC7*AC37 -> 58310.105 | AD24: =+AD7*AD37 -> 65535.601 | AE24: =+AE7*AE37 -> 74492.621 | AF24: =+AF7*AF37 -> 83710.974 | AG24: =+AG7*AG37 -> 95126.329 | AH24: =+AH7*AH37 -> 106883.28 | AI24: =+AH24*(1.01) -> 107952.11 | AJ24: =+AI24*(1.01) -> 109031.64 | AK24: =+AJ24*(1.01) -> 110121.95 | AL24: =+AK24*(1.01) -> 111223.17 | AM24: =+AL24*(1.01) -> 112335.4 | AN24: =+AM24*(1.01) -> 113458.76 | AO24: =+AN24*(1.01) -> 114593.34 | AP24: =+AO24*(1.01) -> 115739.28 | AQ24: =+AP24*(1.01) -> 116896.67 | AR24: =+AQ24*(1+$AL$26) -> 115727.7 | AS24: =+AR24*(1+$AL$26) -> 114570.43 | AT24: =+AS24*(1+$AL$26) -> 113424.72 | AU24: =+AT24*(1+$AL$26) -> 112290.48 | AV24: =+AU24*(1+$AL$26) -> 111167.57 | AW24: =+AV24*(1+$AL$26) -> 110055.9 | AX24: =+AW24*(1+$AL$26) -> 108955.34 | AY24: =+AX24*(1+$AL$26) -> 107865.78 | ... AKN24: =+AKM24*(1+$AL$26) -> 9.8955219
B25: SO | C25: 2728 | D25: 2746 | E25: 2748 | F25: 2753 | G25: 2761 | H25: 2790 | I25: 2799 | J25: 2805 | K25: 2826 | V25: 2753 | W25: 2805
B26: EPS | C26: =C24/C25 -> 0.88709677 | D26: =D24/D25 -> 0.91150765 | E26: =E24/E25 -> 0.87372635 | F26: =F24/F25 -> 1.1416636 | G26: =G24/G25 -> 1.0608475 | H26: =H24/H25 -> 1.1293907 | I26: =I24/I25 -> 1.0489461 | J26: =J24/J25 -> 1.2217469 | ... O26: =O24/O25 -> #DIV/0! | V26: =V24/V25 -> 3.8020341 | W26: =W24/W25 -> 4.4360071 | AK26: Maturity | AL26: -0.01
AK27: Discount | AL27: 0.08
B28: Non-GAAP NI | C28: 3358 | D28: 3762 | E28: 3982 | F28: 4607 | G28: 3964 | H28: 4207 | I28: 4231 | J28: 4881 | K28: 4283 | V28: 15710 | W28: 17284 | AK28: NPV | AL28: =NPV(AL27,Y24:AKN24)+X24+W50 -> 923580.87
B29: Non-GAAP EPS | C29: =C28/C25 -> 1.2309384 | D29: =D28/D25 -> 1.3699927 | E29: =E28/E25 -> 1.4490539 | F29: =F28/F25 -> 1.6734471 | G29: =G28/G25 -> 1.4357117 | H29: =H28/H25 -> 1.5078853 | I29: =I28/I25 -> 1.5116113 | J29: =J28/J25 -> 1.740107 | ... M29: =M28/M25 -> #DIV/0! | V29: =V28/V25 -> 5.706502 | W29: =W28/W25 -> 6.1618538 | AK29: Share | AL29: =+AL28/W25 -> 329.26234
AK30: Current | AL30: =Main!K6 -> 338.36
B31: Cloud % | C31: =SUM(C3:C4)/C7 -> 0.83160684 | D31: =SUM(D3:D4)/D7 -> 0.83587049 | E31: =SUM(E3:E4)/E7 -> 0.84480422 | F31: =SUM(F3:F4)/F7 -> 0.84496395 | G31: =SUM(G3:G4)/G7 -> 0.85586533 | H31: =SUM(H3:H4)/H7 -> 0.8536169 | I31: =SUM(I3:I4)/I7 -> 0.85888181 | J31: =SUM(J3:J4)/J7 -> 0.86178708 | ... M31: =SUM(M3:M4)/M7 -> #DIV/0! | V31: =SUM(V3:V4)/V7 -> 0.83956119 | W31: =SUM(W3:W4)/W7 -> 0.85768045 | AK31: Return | AL31: =AL29/AL30-1 -> -0.026887509
B32: Cloud Y/Y | G32: =SUM(G3:G4)/SUM(C3:C4)-1 -> 0.099748938 | H32: =SUM(H3:H4)/SUM(D3:D4)-1 -> 0.10945734 | I32: =SUM(I3:I4)/SUM(E3:E4)-1 -> 0.08173634 | J32: =SUM(J3:J4)/SUM(F3:F4)-1 -> 0.1352717 | K32: =SUM(K3:K4)/SUM(G3:G4)-1 -> 0.1332865 | L32: =SUM(L3:L4)/SUM(H3:H4)-1 -> -1 | M32: =SUM(M3:M4)/SUM(I3:I4)-1 -> -1 | W32: =SUM(W3:W4)/SUM(V3:V4)-1 -> 0.10718784
B33: Cloud % Y/Y | G33: =(SUM(G3:G4)/G7)/(SUM(C3:C4)/C7)-1 -> 0.029170626 | H33: =(SUM(H3:H4)/H7)/(SUM(D3:D4)/D7)-1 -> 0.021231053 | I33: =(SUM(I3:I4)/I7)/(SUM(E3:E4)/E7)-1 -> 0.016663737 | J33: =(SUM(J3:J4)/J7)/(SUM(F3:F4)/F7)-1 -> 0.01990988 | K33: =(SUM(K3:K4)/K7)/(SUM(G3:G4)/G7)-1 -> 0.01036068 | L33: =(SUM(L3:L4)/L7)/(SUM(H3:H4)/H7)-1 -> #DIV/0! | M33: =(SUM(M3:M4)/M7)/(SUM(I3:I4)/I7)-1 -> #DIV/0! | W33: =(SUM(W3:W4)/W7)/(SUM(V3:V4)/V7)-1 -> 0.021581823
B35: Gross Margin | C35: =C12/C7 -> 0.71011001 | D35: =D12/D7 -> 0.71099606 | E35: =E12/E7 -> 0.70865964 | F35: =F12/F7 -> 0.72541471 | G35: =G12/G7 -> 0.70647028 | H35: =H12/H7 -> 0.70943879 | I35: =I12/I7 -> 0.70311394 | J35: =J12/J7 -> 0.70194303 | ... M35: =M12/M7 -> #DIV/0! | V35: =V12/V7 -> 0.71407262 | W35: =W12/W7 -> 0.70509939
B36: Operating Margin | C36: =C20/C7 -> 0.26467518 | D36: =D20/D7 -> 0.27988563 | E36: =E20/E7 -> 0.28237952 | F36: =F20/F7 -> 0.32799048 | G36: =G20/G7 -> 0.29991734 | H36: =H20/H7 -> 0.3001636 | I36: =I20/I7 -> 0.3084218 | J36: =J20/J7 -> 0.32126014 | ... M36: =M20/M7 -> #DIV/0! | V36: =V20/V7 -> 0.28989256 | W36: =W20/W7 -> 0.30798446
B37: Net Margin | C37: =C24/C7 -> 0.19433068 | D37: =D24/D7 -> 0.19341627 | E37: =E24/E7 -> 0.18079819 | F37: =F24/F7 -> 0.2199902 | G37: =G24/G7 -> 0.22010972 | H37: =H24/H7 -> 0.22412689 | I37: =I24/I7 -> 0.20778485 | J37: =J24/J7 -> 0.21549393 | ... M37: =M24/M7 -> #DIV/0! | V37: =V24/V7 -> 0.197636 | W37: =W24/W7 -> 0.21678078 | X37: =X24/X7 -> 0.2206411 | Y37: =Y24/Y7 -> 0.24059963 | Z37: =Y37*1.04 -> 0.25022361 | AA37: =Z37*1.04 -> 0.26023255 | AB37: =AA37*1.04 -> 0.27064186 | AC37: =AB37*1.04 -> 0.28146753 | AD37: =AC37*1.02 -> 0.28709688 | AE37: =AD37*1.02 -> 0.29283882 | AF37: =AE37*1.02 -> 0.2986956 | AG37: =AF37*1.02 -> 0.30466951 | AH37: =AG37*1.02 -> 0.3107629
B39: Tax Margin | C39: =C23/C22 -> -0.018947368 | D39: =D23/D22 -> 0.079779412 | E39: =E23/E22 -> 0.16195462 | F39: =F23/F22 -> 0.16895822 | G39: =G23/G22 -> 0.07573367 | H39: =H23/H22 -> 0.070501475 | I39: =I23/I22 -> 0.14849188 | J39: =J23/J22 -> 0.1744158 | ... M39: =M23/M22 -> #DIV/0! | V39: =V23/V22 -> 0.10850864 | W39: =W23/W22 -> 0.12125706
B40: R&D Margin | C40: =C14/C12 -> 0.25059369 | D40: =D14/D12 -> 0.24193022 | E40: =E14/E12 -> 0.23886941 | F40: =F14/F12 -> 0.21478194 | G40: =G14/G12 -> 0.24529305 | H40: =H14/H12 -> 0.24774413 | I40: =I14/I12 -> 0.24448918 | J40: =J14/J12 -> 0.23774971 | ... M40: =M14/M12 -> #DIV/0! | V40: =V14/V12 -> 0.23573431 | W40: =W14/W12 -> 0.24362522
B41: S&M Margin | C41: =C13/C12 -> 0.22910777 | D41: =D13/D12 -> 0.22747527 | E41: =E13/E12 -> 0.21698013 | F41: =F13/F12 -> 0.2039753 | G41: =G13/G12 -> 0.21657271 | H41: =H13/H12 -> 0.21957088 | I41: =I13/I12 -> 0.21328636 | J41: =J13/J12 -> 0.20657529 | ... M41: =M13/M12 -> #DIV/0! | V41: =V13/V12 -> 0.21878471 | W41: =W13/W12 -> 0.21375272
B42: G&A Margin | C42: =C15/C12 -> 0.044441931 | D42: =D15/D12 -> 0.04075644 | E42: =E15/E12 -> 0.040059505 | F42: =F15/F12 -> 0.038788113 | G42: =G15/G12 -> 0.038081055 | H42: =H15/H12 -> 0.038800882 | I42: =I15/I12 -> 0.039255159 | J42: =J15/J12 -> 0.041834632 | ... M42: =M15/M12 -> #DIV/0! | V42: =V15/V12 -> 0.040932889 | W42: =W15/W12 -> 0.039582922
...
