Workbook

Sheet Main
K7: Price (€) | L7: 235.85 | M7: 46070 | N7: 147.34
K8: S/O | L8: 786 | M8: Q1 FY26 | N8: =+L8*2 -> 1572
K9: MC | L9: =+L7*L8 -> 185378.1 | N9: =+N7*N8 -> 231618.48
K10: C | L10: =+Model!AA73 -> 15263 | M10: Q1 FY26
K11: D | L11: =+Model!AA93+Model!AA102 -> 56465 | M11: Q1 FY26
K13: EV | L13: =+L9-L10+L11 -> 226580.1

Sheet Model
A1: Main
B2: (in million of €) | C2: Q1 FY20 | D2: Q2 FY20 | E2: Q3 FY20 | F2: Q4 FY20 | G2: Q1 FY21 | H2: Q2 FY21 | I2: Q3 FY21 | J2: Q4 FY21 | K2: Q1 FY22 | L2: Q2 FY22 | M2: Q3 FY22 | N2: Q4 FY22 | O2: Q1 FY23 | P2: Q2 FY23 | Q2: Q3 FY23 | R2: Q4 FY23 | S2: Q1 FY24 | T2: Q2 FY24 | U2: Q3 FY24 | V2: Q4 FY24 | W2: Q1 FY25 | X2: Q2 FY25 | Y2: Q3 FY25 | Z2: Q4 FY25 | AA2: Q1 FY26 | AB2: Q2 FY26 | AC2: Q3 FY26 | AD2: Q4 FY26 | AH2: FY2020 | AI2: FY2021 | AJ2: FY2022 | AK2: FY2023 | AL2: FY2024 | AM2: FY2025 | AN2: FY2026 | AO2: FY2027 | AP2: FY2028 | AQ2: FY2029 | AR2: FY2030
B3: Revenue | C3: 13675 | D3: 13784 | E3: 12979 | F3: 14816 | G3: 14071 | H3: 14665 | I3: 16085 | J3: 17444 | K3: 16497 | L3: 17040 | M3: 17867 | N3: 20573 | O3: 18070 | P3: 19416 | Q3: 18889 | R3: 21393 | S3: 17745 | T3: 18474 | U3: 18900 | V3: 20811 | W3: 18353 | X3: 19757 | Y3: 19377 | Z3: 21427 | AA3: 19139 | AH3: 55254 | AI3: 62265 | AJ3: 71977 | AK3: 74882 | AL3: 75930 | AM3: 78914
B4: Cost of sales | C4: -8688 | D4: -8771 | E4: -8224 | F4: -9683 | G4: -8751 | H4: -9426 | I4: -10213 | J4: -11137 | K4: -10292 | L4: -11300 | M4: -11638 | N4: -12901 | O4: -11104 | P4: -12217 | Q4: -11637 | R4: -13158 | S4: -10707 | T4: -11363 | U4: -11152 | V4: -12885 | W4: -11264 | X4: -12088 | Y4: -11840 | Z4: -13322 | AA4: -11506 | AH4: -35366 | AI4: -39527 | AJ4: -46130 | AK4: -45766 | AL4: -46107 | AM4: -48515
B5: Gross profit | C5: 4987 | D5: 5013 | E5: 4755 | F5: 5133 | G5: 5318 | H5: 5239 | I5: 5872 | J5: 6308 | K5: 6205 | L5: 5741 | M5: 6229 | N5: 7672 | O5: 6967 | P5: 7199 | Q5: 7252 | R5: 8235 | S5: 7038 | T5: 7111 | U5: 7748 | V5: 7926 | W5: 7089 | X5: 7669 | Y5: 7537 | Z5: 8104 | AA5: 7633 | AH5: 19888 | AI5: 22737 | AJ5: 25847 | AK5: 29117 | AL5: 29823 | AM5: 30399
B6: R&D | C6: -1125 | D6: -1159 | E6: -1087 | F6: -1198 | G6: -1064 | H6: -1128 | I6: -1220 | J6: -1447 | K6: -1251 | L6: -1359 | M6: -1400 | N6: -1582 | O6: -1430 | P6: -1528 | Q6: -1542 | R6: -1684 | S6: -1496 | T6: -1567 | U6: -1561 | V6: -1651 | W6: -1545 | X6: -1621 | Y6: -1650 | Z6: -1744 | AA6: -1637 | AH6: -4569 | AI6: -4859 | AJ6: -5591 | AK6: -6113 | AL6: -6276 | AM6: -6559
B7: SG&A | C7: -2840 | D7: -2649 | E7: -2519 | F7: -2674 | G7: -2461 | H7: -2562 | I7: -2940 | J7: -3228 | K7: -2933 | L7: -3081 | M7: -3179 | N7: -3663 | O7: -3349 | P7: -3375 | Q7: -3418 | R7: -3799 | S7: -3373 | T7: -3369 | U7: -3571 | V7: -3671 | W7: -3500 | X7: -3659 | Y7: -3571 | Z7: -4097 | AA7: -3608 | AH7: -10682 | AI7: -11191 | AJ7: -12857 | AK7: -13553 | AL7: -13984 | AM7: -14827
B8: Other operating income | C8: 256 | D8: 74 | E8: 33 | F8: 267 | G8: 122 | H8: 27 | I8: 36 | J8: 51 | K8: 29 | L8: 38 | M8: 833 | N8: 1271 | O8: 172 | P8: 52 | Q8: 126 | R8: 224 | S8: 194 | T8: 74 | U8: 136 | V8: 141 | W8: 105 | X8: 396 | Y8: 362 | Z8: 118 | AA8: 151 | AH8: 630 | AI8: 236 | AJ8: 2171 | AK8: 572 | AL8: 544 | AM8: 981
B9: Other operating expenses | C9: -106 | D9: -57 | E9: -57 | F9: -176 | G9: -181 | H9: -102 | I9: -87 | J9: -61 | K9: -85 | L9: -70 | M9: -52 | N9: -78 | O9: -134 | P9: -126 | Q9: -127 | R9: -68 | S9: -78 | T9: -204 | U9: -139 | V9: -93 | W9: -85 | X9: -118 | Y9: -64 | Z9: -132 | AA9: -45 | AH9: -396 | AI9: -431 | AJ9: -285 | AK9: -447 | AL9: -514 | AM9: -400
B10: Income (loss) from investments accounted for using the equity method, net | C10: 44 | D10: -3 | E10: -84 | F10: -553 | G10: 9 | H10: -29 | I10: -153 | J10: -255 | K10: 239 | L10: 145 | M10: -2814 | N10: 346 | O10: -178 | P10: 1818 | Q10: -533 | R10: -201 | S10: 664 | T10: 72 | U10: 39 | V10: 52 | W10: 90 | X10: 257 | Y10: 36 | Z10: 15 | AA10: 284 | AH10: -596 | AI10: -428 | AJ10: -2085 | AK10: 906 | AL10: 827 | AM10: 397
B11: Interest income | C11: 343 | D11: 488 | E11: 403 | F11: 311 | G11: 317 | H11: 348 | I11: 361 | J11: 415 | K11: 371 | L11: 367 | M11: 419 | N11: 475 | O11: 540 | P11: 578 | Q11: 615 | R11: 673 | S11: 713 | T11: 704 | U11: 703 | V11: 714 | W11: 747 | X11: 706 | Y11: 670 | Z11: 642 | AA11: 686 | AH11: 1545 | AI11: 1441 | AJ11: 1632 | AK11: 2402 | AL11: 2833 | AM11: 2765
B12: Interest expenses | C12: -143 | D12: -312 | E12: -218 | F12: -141 | G12: -165 | H12: -164 | I12: -137 | J12: -178 | K12: -165 | L12: -188 | M12: -160 | N12: -177 | O12: -276 | P12: -348 | Q12: -379 | R12: -370 | S12: -420 | T12: -447 | U12: -447 | V12: -471 | W12: -386 | X12: -370 | Y12: -450 | Z12: -434 | AA12: -435 | AH12: -814 | AI12: -644 | AJ12: -689 | AK12: -1369 | AL12: -1785 | AM12: -1640
B13: Other financial income (expenses), net | C13: 39 | D13: -107 | E13: 122 | F13: 442 | G13: 68 | H13: 355 | I13: -23 | J13: 235 | K13: 37 | L13: 158 | M13: -788 | N13: -394 | O13: -88 | P13: -130 | Q13: -9 | R13: -159 | S13: -24 | T13: -117 | U13: -56 | V13: -44 | W13: -133 | X13: -87 | Y13: 21 | Z13: -88 | AA13: -86 | AH13: 496 | AI13: 635 | AJ13: -987 | AK13: -388 | AL13: -240 | AM13: -287
B14: Income from continuing operations before income taxes | C14: 1457 | D14: 1287 | E14: 1347 | F14: 1411 | G14: 1963 | H14: 1984 | I14: 1708 | J14: 1841 | K14: 2447 | L14: 1750 | M14: -912 | N14: 3869 | O14: 2223 | P14: 4141 | Q14: 1985 | R14: 2851 | S14: 3217 | T14: 2256 | U14: 2852 | V14: 2903 | W14: 2381 | X14: 3173 | Y14: 2890 | Z14: 2385 | AA14: 2944 | AH14: 5502 | AI14: 7496 | AJ14: 7154 | AK14: 11126 | AL14: 11227 | AM14: 10830
... B18: Net income | C18: 1089 | D18: 697 | E18: 535 | F18: 1879 | G18: 1497 | H18: 2390 | I18: 1480 | J18: 1330 | K18: 1796 | L18: 1213 | M18: -1531 | N18: 2913 | O18: 1636 | P18: 3551 | Q18: 1440 | R18: 1902 | S18: 2548 | T18: 2196 | U18: 2133 | V18: 2115 | W18: 3868 | X18: 2439 | Y18: 2243 | Z18: 1837 | AA18: 2222 | AH18: 4200 | AI18: 6697 | AJ18: 4392 | AK18: 8529 | AL18: 8992 | AM18: 10387
B20: Attributable to:
B21: Non-controlling interests | C21: 8 | D21: 44 | E21: -3 | F21: 121 | G21: 121 | H21: 125 | I21: 128 | J21: 163 | K21: 153 | L21: 179 | M21: 125 | N21: 212 | O21: 159 | P21: 74 | Q21: 162 | R21: 184 | S21: 160 | T21: 163 | U21: 154 | V21: 215 | W21: 163 | X21: 189 | Y21: 197 | Z21: 218 | AA21: 192 | AH21: 170 | AI21: 537 | AJ21: 669 | AK21: 579 | AL21: 691 | AM21: 767
B22: Shareholders of Siemens AG | C22: 1081 | D22: 652 | E22: 539 | F22: 1758 | G22: 1377 | H22: 2265 | I22: 1352 | J22: 1167 | K22: 1643 | L22: 1034 | M22: -1655 | N22: 2701 | O22: 1477 | P22: 3477 | Q22: 1278 | R22: 1718 | S22: 2389 | T22: 2033 | U22: 1980 | V22: 1900 | W22: 3705 | X22: 2250 | Y22: 2046 | Z22: 1619 | AA22: 2030 | AH22: 4030 | AI22: 6161 | AJ22: 3723 | AK22: 7949 | AL22: 8301 | AM22: 9620
B24: Basic earnings per share
B25: Income from continuing operations | C25: 1.37 | D25: 1.15 | E25: 1.07 | F25: 1.18 | G25: 1.7 | H25: 1.73 | I25: 1.55 | J25: 1.38 | K25: 2.06 | L25: 1.28 | M25: -2.05 | N25: 3.4 | O25: 1.88 | P25: 4.4 | Q25: 1.57 | R25: 2.18 | S25: 3.05 | T25: 2.33 | U25: 2.54 | V25: 2.49 | W25: 2.08 | X25: 2.86 | Y25: 2.58 | Z25: 2.11 | AA25: 2.61 | AH25: 4.77 | AI25: 6.36 | AJ25: 4.67 | AK25: 10.04 | AL25: 10.42 | AM25: 9.63
B26: Income from discontinued operations | C26: -0.05 | D26: -0.34 | E26: -0.4 | F26: 1.02 | G26: 0.02 | H26: 1.09 | I26: 0.13 | J26: 0.08 | K26: -0.02 | L26: 0.01 | M26: -0.01 | N26: 0 | O26: -0.01 | P26: 0 | Q26: 0.04 | R26: -0.01 | S26: -0.03 | T26: 0.24 | U26: -0.03 | V26: -0.08 | W26: 2.63 | X26: 0 | Y26: 0.03 | Z26: -0.04 | AA26: 0 | AH26: 0.23 | AI26: 1.32 | AJ26: -0.03 | AK26: 0 | AL26: 0.11 | AM26: 2.62
B27: Net income | C27: 1.33 | D27: 0.8 | E27: 0.67 | F27: 2.2 | G27: 1.73 | H27: 2.82 | I27: 1.68 | J27: 1.45 | K27: 2.05 | L27: 1.29 | M27: -2.06 | N27: 3.39 | O27: 1.87 | P27: 4.39 | Q27: 1.61 | R27: 2.17 | S27: 3.03 | T27: 2.57 | U27: 2.51 | V27: 2.42 | W27: 4.71 | X27: 2.86 | Y27: 2.61 | Z27: 2.07 | AA27: 2.6 | AH27: 5 | AI27: 7.68 | AJ27: 4.65 | AK27: 10.04 | AL27: 10.53 | AM27: 12.25
B29: Diluted earnings per share
B30: Income from continuing operations | C30: 1.35 | D30: 1.13 | E30: 1.06 | F30: 1.16 | G30: 1.67 | H30: 1.71 | I30: 1.54 | J30: 1.36 | K30: 2.04 | L30: 1.27 | M30: -2.06 | N30: 3.36 | O30: 1.86 | P30: 4.35 | Q30: 1.55 | R30: 2.15 | S30: 3.01 | T30: 2.3 | U30: 2.51 | V30: 2.46 | W30: 2.06 | X30: 2.83 | Y30: 2.55 | Z30: 2.08 | AA30: 2.58 | AH30: 4.7 | AI30: 6.28 | AJ30: 4.62 | AK30: 9.91 | AL30: 10.27 | AM30: 9.52
B31: Income from discontinued operations | C31: -0.05 | D31: -0.34 | E31: -0.39 | F31: 1.01 | G31: 0.03 | H31: 1.08 | I31: 0.13 | J31: 0.07 | K31: -0.02 | L31: 0.01 | M31: -0.01 | N31: 0 | O31: -0.01 | P31: 0 | Q31: 0.04 | R31: -0.01 | S31: -0.03 | T31: 0.24 | U31: -0.03 | V31: -0.08 | W31: 2.6 | X31: 0 | Y31: 0.03 | Z31: -0.04 | AA31: 0 | AH31: 0.23 | AI31: 1.31 | AJ31: -0.03 | AK31: 0 | AL31: 0.11 | AM31: 2.59
B32: Net income | C32: 1.3 | D32: 0.79 | E32: 0.67 | F32: 2.17 | G32: 1.71 | H32: 2.79 | I32: 1.66 | J32: 1.43 | K32: 2.02 | L32: 1.27 | M32: -2.07 | N32: 3.36 | O32: 1.85 | P32: 4.34 | Q32: 1.59 | R32: 2.14 | S32: 2.99 | T32: 2.54 | U32: 2.48 | V32: 2.38 | W32: 4.66 | X32: 2.83 | Y32: 2.58 | Z32: 2.05 | AA32: 2.58 | AH32: 4.93 | AI32: 7.59 | AJ32: 4.59 | AK32: 9.91 | AL32: 10.38 | AM32: 12.11
B34: Consolidated Statements of Comprehensive Income
B35: Net income | C35: 1089 | D35: 697 | E35: 535 | F35: 1879 | G35: 1497 | H35: 2390 | I35: 1480 | J35: 1330 | K35: 1796 | L35: 1213 | M35: -1531 | N35: 2913 | O35: 1636 | P35: 3551 | Q35: 1440 | R35: 1902 | S35: 2548 | T35: 2196 | U35: 2133 | V35: 2115 | W35: 3868 | X35: 2439 | Y35: 2243 | Z35: 1837 | AA35: 2222 | AH35: 4200 | AI35: 6697 | AJ35: 4392 | AK35: 8529 | AL35: 8992 | AM35: 10387
B37: Remeasurements of defined benefit plans | C37: 322 | D37: 41 | E37: -277 | F37: -347 | G37: 307 | H37: 918 | I37: 679 | J37: 219 | K37: 191 | L37: -27 | M37: 78 | N37: -831 | O37: 305 | P37: 134 | Q37: -542 | R37: -1 | S37: -323 | T37: 529 | U37: 419 | V37: 62 | W37: -83 | X37: 1 | Y37: -33 | Z37: -479 | AA37: 259 | AH37: -261 | AI37: 2123 | AJ37: -589 | AK37: -104 | AL37: 687 | AM37: -594
B38: therein: Income tax effects | C38: -166 | D38: -250 | E38: 319 | F38: 130 | G38: 255 | H38: -311 | I38: -2 | J38: 13 | K38: -93 | L38: -199 | M38: -391 | N38: 123 | O38: -76 | P38: -14 | Q38: 305 | R38: -298 | S38: 290 | T38: -120 | U38: -54 | V38: 296 | W38: 54 | X38: -109 | Y38: -38 | Z38: -525 | AA38: -31 | AH38: 33 | AI38: -45 | AJ38: -560 | AK38: -84 | AL38: 411 | AM38: -618
B39: Remeasurements of equity instruments | C39: 15 | D39: 2 | E39: -12 | F39: 0 | G39: -1 | H39: 18 | I39: -17 | J39: 30 | K39: -4 | L39: -6 | M39: 2 | N39: 9 | O39: -23 | P39: -8 | Q39: 8 | R39: -18 | S39: 122 | T39: 665 | U39: 995 | V39: 1184 | W39: 2352 | X39: 553 | Y39: 1625 | Z39: 2065 | AA39: 959 | AH39: 5 | AI39: 30 | AJ39: 1 | AK39: -41 | AL39: 2966 | AM39: 6595
B40: therein: Income tax effects | C40: -3 | D40: 0 | E40: 0 | F40: 0 | G40: 0 | H40: 0 | I40: 0 | J40: -1 | K40: 0 | L40: -1 | M40: 0 | N40: 0 | O40: 0 | P40: 0 | Q40: 0 | R40: 0 | S40: 0 | T40: 0 | U40: 0 | V40: 0 | W40: -13 | X40: 12 | Y40: 0 | Z40: -61 | AA40: -88 | AH40: -3 | AI40: -1 | AJ40: -1 | AK40: 10 | AL40: 0 | AM40: -61
B41: Income (loss) from investments accounted for using the equity method, net | C41: -3 | D41: -1 | E41: 3 | F41: 18 | G41: 4 | H41: 39 | I41: 7 | J41: 7 | K41: 2 | L41: 40 | M41: 44 | N41: -14 | O41: 1 | P41: -4 | Q41: -3 | R41: 15 | S41: -18 | T41: 0 | U41: 0 | V41: 0 | X41: 0 | Y41: 0 | Z41: 0 | AH41: 17 | AI41: 57 | AJ41: 72 | AK41: 0 | AL41: -18 | AM41: 0
B42: Items that will not be reclassified to profit or loss | C42: 334 | D42: 42 | E42: -287 | F42: -329 | G42: 310 | H42: 975 | I42: 669 | J42: 256 | K42: 188 | L42: 7 | M42: 125 | N42: -835 | O42: 284 | P42: 122 | Q42: -537 | R42: -5 | S42: -218 | T42: 1194 | U42: 1414 | V42: 1246 | W42: 2269 | X42: 554 | Y42: 1592 | Z42: 1586 | AA42: 1218 | AH42: -240 | AI42: 2210 | AJ42: -516 | AK42: -135 | AL42: 3636 | AM42: 6000
B44: Currency translation differences | C44: -846 | D44: -254 | E44: -869 | F44: -836 | G44: -1200 | H44: 1529 | I44: -236 | J44: 1211 | K44: 1110 | L44: 778 | M44: 2567 | N44: 2348 | O44: -4041 | P44: -864 | Q44: -310 | R44: 953 | S44: -1505 | T44: 768 | U44: 439 | V44: -1603 | W44: 2827 | X44: -1775 | Y44: -3506 | Z44: -280 | AA44: -19 | AH44: -2805 | AI44: 1304 | AJ44: 6803 | AK44: -4262 | AL44: -1900 | AM44: -2733
B45: Derivative financial instruments | C45: 27 | D45: -45 | E45: 99 | F45: 67 | G45: -271 | H45: 101 | I45: -29 | J45: -38 | K45: -25 | L45: -69 | M45: 0 | N45: 21 | O45: 223 | P45: 56 | Q45: -112 | R45: -175 | S45: 93 | T45: -10 | U45: -4 | V45: 84 | W45: -228 | X45: 190 | Y45: 129 | Z45: 6 | AA45: -6 | AH45: 148 | AI45: -237 | AJ45: -74 | AK45: -8 | AL45: 163 | AM45: 97
B46: therein: Income tax effects | C46: -19 | D46: 20 | E46: -23 | F46: -16 | G46: 79 | H46: -26 | I46: -37 | J46: 15 | K46: 8 | L46: 33 | M46: 4 | N46: 0 | O46: -98 | P46: -38 | Q46: 52 | R46: 69 | S46: -34 | T46: 14 | U46: -8 | V46: -42 | W46: 93 | X46: -75 | Y46: -46 | Z46: -12 | AA46: 4 | AH46: -38 | AI46: 31 | AJ46: 45 | AK46: -15 | AL46: -69 | AM46: -40
B47: Income (loss) from investments accounted for using the equity method, net | C47: 9 | D47: -42 | E47: -32 | F47: -24 | G47: -9 | H47: 28 | I47: 50 | J47: 19 | K47: 44 | L47: 74 | M47: 166 | N47: 114 | O47: -150 | P47: -22 | Q47: -18 | R47: 29 | S47: -75 | T47: 3 | U47: 6 | V47: -17 | W47: 26 | X47: -3 | Y47: -24 | Z47: -1 | AA47: -5 | AH47: -89 | AI47: 88 | AJ47: 398 | AK47: -161 | AL47: -82 | AM47: -3
B48: Items that may be reclassified subsequently to profit or loss | C48: -812 | D48: -340 | E48: -802 | F48: -792 | G48: -1482 | H48: 1659 | I48: -215 | J48: 1192 | K48: 1128 | L48: 783 | M48: 2733 | N48: 2483 | O48: -3967 | P48: -829 | Q48: -440 | R48: 806 | S48: -1486 | T48: 761 | U48: 442 | V48: -1536 | W48: 2625 | X48: -1588 | Y48: -3401 | Z48: -275 | AA48: -29 | AH48: -2746 | AI48: 1154 | AJ48: 7127 | AK48: -4431 | AL48: -1819 | AM48: -2639
C49: -478 | D49: -298 | E49: -1088 | F49: -1122 | G49: 3364 | H49: 2634 | I49: 453 | J49: 1448 | AH49: -2986
...

Sheet Valuation
C2: Q1 FY20 | D2: Q2 FY20 | E2: Q3 FY20 | F2: Q4 FY20 | G2: Q1 FY21 | H2: Q2 FY21 | I2: Q3 FY21 | J2: Q4 FY21 | K2: Q1 FY22 | L2: Q2 FY22 | M2: Q3 FY22 | N2: Q4 FY22 | O2: Q1 FY23 | P2: Q2 FY23 | Q2: Q3 FY23 | R2: Q4 FY23 | S2: Q1 FY24 | T2: Q2 FY24 | U2: Q3 FY24 | V2: Q4 FY24 | W2: Q1 FY25 | X2: Q2 FY25 | Y2: Q3 FY25 | Z2: Q4 FY25 | AA2: Q1 FY26 | AB2: Q2 FY26 | AC2: Q3 FY26 | AD2: Q4 FY26 | AH2: FY2020 | AI2: FY2021 | AJ2: FY2022 | AK2: FY2023 | AL2: FY2024 | AM2: FY2025 | AN2: FY2026 | AO2: FY2027 | AP2: FY2028 | AQ2: FY2029 | AR2: FY2030
B3: Revenue | C3: =Model!C3 -> 13675 | D3: =Model!D3 -> 13784 | E3: =Model!E3 -> 12979 | F3: =Model!F3 -> 14816 | G3: =Model!G3 -> 14071 | H3: =Model!H3 -> 14665 | I3: =Model!I3 -> 16085 | J3: =Model!J3 -> 17444 | ... AD3: =Model!AD3 -> 0 | AH3: =Model!AH3 -> 55254 | AI3: =Model!AI3 -> 62265 | AJ3: =Model!AJ3 -> 71977 | AK3: =Model!AK3 -> 74882 | AL3: =Model!AL3 -> 75930 | AM3: =Model!AM3 -> 78914 | AN3: =Model!AN3 -> 0 | AO3: =Model!AO3 -> 0
B4: Gross Profit | C4: =+Model!C5 -> 4987 | D4: =+Model!D5 -> 5013 | E4: =+Model!E5 -> 4755 | F4: =+Model!F5 -> 5133 | G4: =+Model!G5 -> 5318 | H4: =+Model!H5 -> 5239 | I4: =+Model!I5 -> 5872 | J4: =+Model!J5 -> 6308 | ... AD4: =+Model!AD5 -> 0 | AH4: =+Model!AH5 -> 19888 | AI4: =+Model!AI5 -> 22737 | AJ4: =+Model!AJ5 -> 25847 | AK4: =+Model!AK5 -> 29117 | AL4: =+Model!AL5 -> 29823 | AM4: =+Model!AM5 -> 30399 | AN4: =+Model!AN5 -> 0 | AO4: =+Model!AO5 -> 0
B5: EBIT | C5: =+C4+Model!C6+Model!C7 -> 1022 | D5: =+D4+Model!D6+Model!D7 -> 1205 | E5: =+E4+Model!E6+Model!E7 -> 1149 | F5: =+F4+Model!F6+Model!F7 -> 1261 | G5: =+G4+Model!G6+Model!G7 -> 1793 | H5: =+H4+Model!H6+Model!H7 -> 1549 | I5: =+I4+Model!I6+Model!I7 -> 1712 | J5: =+J4+Model!J6+Model!J7 -> 1633 | ... AD5: =+AD4+Model!AD6+Model!AD7 -> 0 | AH5: =+AH4+Model!AH6+Model!AH7 -> 4637 | AI5: =+AI4+Model!AI6+Model!AI7 -> 6687 | AJ5: =+AJ4+Model!AJ6+Model!AJ7 -> 7399 | AK5: =+AK4+Model!AK6+Model!AK7 -> 9451 | AL5: =+AL4+Model!AL6+Model!AL7 -> 9563 | AM5: =+AM4+Model!AM6+Model!AM7 -> 9013 | AN5: =+AN4+Model!AN6+Model!AN7 -> 0 | AO5: =+AO4+Model!AO6+Model!AO7 -> 0
B6: Net Income | C6: =Model!C18 -> 1089 | D6: =Model!D18 -> 697 | E6: =Model!E18 -> 535 | F6: =Model!F18 -> 1879 | G6: =Model!G18 -> 1497 | H6: =Model!H18 -> 2390 | I6: =Model!I18 -> 1480 | J6: =Model!J18 -> 1330 | ... AD6: =Model!AD18 -> 0 | AH6: =Model!AH18 -> 4200 | AI6: =Model!AI18 -> 6697 | AJ6: =Model!AJ18 -> 4392 | AK6: =Model!AK18 -> 8529 | AL6: =Model!AL18 -> 8992 | AM6: =Model!AM18 -> 10387 | AN6: =Model!AN18 -> 0 | AO6: =Model!AO18 -> 0
B8: Cash | F8: =Model!F73 -> 14041 | G8: =Model!G73 -> 14016 | H8: =Model!H73 -> 23639 | I8: =Model!I73 -> 10678 | J8: =Model!J73 -> 9545 | K8: =Model!K73 -> 12199 | L8: =Model!L73 -> 9495 | M8: =Model!M73 -> 10097 | ... AD8: =Model!AD73 -> 0 | AH8: =Model!AH73 -> 14041 | AI8: =Model!AI73 -> 9545 | AJ8: =Model!AJ73 -> 10465 | AK8: =Model!AK73 -> 10084 | AL8: =Model!AL73 -> 9156 | AM8: =Model!AM73 -> 14495 | AN8: =Model!AN73 -> 0 | AO8: =Model!AO73 -> 0
B9: Total Assets | F9: =Model!F90 -> 123897 | G9: =Model!G90 -> 121435 | H9: =Model!H90 -> 131658 | I9: =Model!I90 -> 136831 | J9: =Model!J90 -> 139372 | K9: =Model!K90 -> 144409 | L9: =Model!L90 -> 143946 | M9: =Model!M90 -> 145988 | ... AD9: =Model!AD90 -> 0 | AH9: =Model!AH90 -> 123897 | AI9: =Model!AI90 -> 139372 | AJ9: =Model!AJ90 -> 151502 | AK9: =Model!AK90 -> 145071 | AL9: =Model!AL90 -> 147812 | AM9: =Model!AM90 -> 166202 | AN9: =Model!AN90 -> 0 | AO9: =Model!AO90 -> 0
B10: Total Debt | F10: =Model!F93+Model!F102 -> 44567 | G10: =Model!G93+Model!G102 -> 43480 | H10: =Model!H93+Model!H102 -> 52098 | I10: =Model!I93+Model!I102 -> 51111 | J10: =Model!J93+Model!J102 -> 48700 | K10: =Model!K93+Model!K102 -> 51467 | L10: =Model!L93+Model!L102 -> 51753 | M10: =Model!M93+Model!M102 -> 51556 | ... AD10: =Model!AD93+Model!AD102 -> 0 | AH10: =Model!AH93+Model!AH102 -> 44567 | AI10: =Model!AI93+Model!AI102 -> 48700 | AJ10: =Model!AJ93+Model!AJ102 -> 50636 | AK10: =Model!AK93+Model!AK102 -> 46596 | AL10: =Model!AL93+Model!AL102 -> 47919 | AM10: =Model!AM93+Model!AM102 -> 56015 | AN10: =Model!AN93+Model!AN102 -> 0 | AO10: =Model!AO93+Model!AO102 -> 0
B11: Total Liabilities | F11: =+Model!F109 -> 84074 | G11: =+Model!G109 -> 81023 | H11: =+Model!H109 -> 87063 | I11: =+Model!I109 -> 90155 | J11: =+Model!J109 -> 90381 | K11: =+Model!K109 -> 92311 | L11: =+Model!L109 -> 93325 | M11: =+Model!M109 -> 94784 | ... AD11: =+Model!AD109 -> 0 | AH11: =+Model!AH109 -> 84074 | AI11: =+Model!AI109 -> 90381 | AJ11: =+Model!AJ109 -> 96697 | AK11: =+Model!AK109 -> 92019 | AL11: =+Model!AL109 -> 91581 | AM11: =+Model!AM109 -> 97830 | AN11: =+Model!AN109 -> 0 | AO11: =+Model!AO109 -> 0
B12: Equity | F12: =+Model!F118 -> 39823 | G12: =+Model!G118 -> 40409 | H12: =+Model!H118 -> 44595 | I12: =+Model!I118 -> 46676 | J12: =+Model!J118 -> 48991 | K12: =+Model!K118 -> 52098 | L12: =+Model!L118 -> 50621 | M12: =+Model!M118 -> 51204 | ... AD12: =+Model!AD118 -> 0 | AH12: =+Model!AH118 -> 39823 | AI12: =+Model!AI118 -> 48991 | AJ12: =+Model!AJ118 -> 54805 | AK12: =+Model!AK118 -> 53052 | AL12: =+Model!AL118 -> 56231 | AM12: =+Model!AM118 -> 68371 | AN12: =+Model!AN118 -> 0 | AO12: =+Model!AO118 -> 0
B14: CFFO | C14: =+Model!C166 -> 531 | D14: =+Model!D166 -> 669 | E14: =+Model!E166 -> 3020 | F14: =+Model!F166 -> 4642 | G14: =+Model!G166 -> 1312 | H14: =+Model!H166 -> 1594 | I14: =+Model!I166 -> 2692 | J14: =+Model!J166 -> 4398 | ... AD14: =+Model!AD166 -> 0 | AH14: =+Model!AH166 -> 8862 | AI14: =+Model!AI166 -> 9996 | AJ14: =+Model!AJ166 -> 10241 | AK14: =+Model!AK166 -> 12239 | AL14: =+Model!AL166 -> 11665 | AM14: =+Model!AM166 -> 13257 | AN14: =+Model!AN166 -> 0 | AO14: =+Model!AO166 -> 0
B15: CFFI | C15: =+Model!C177 -> -2196 | D15: =+Model!D177 -> -1407 | E15: =+Model!E177 -> -266 | F15: =+Model!F177 -> -1315 | G15: =+Model!G177 -> -448 | H15: =+Model!H177 -> 1071 | I15: =+Model!I177 -> -14501 | J15: =+Model!J177 -> -1616 | ... AD15: =+Model!AD177 -> 0 | AH15: =+Model!AH177 -> -5184 | AI15: =+Model!AI177 -> -15494 | AJ15: =+Model!AJ177 -> -2490 | AK15: =+Model!AK177 -> -3176 | AL15: =+Model!AL177 -> -3282 | AM15: =+Model!AM177 -> -11314 | AN15: =+Model!AN177 -> 0 | AO15: =+Model!AO177 -> 0
B16: CFFF | C16: =+Model!C189 -> 704 | D16: =+Model!D189 -> -672 | E16: =+Model!E189 -> 1918 | F16: =+Model!F189 -> 1222 | G16: =+Model!G189 -> -619 | H16: =+Model!H189 -> 6573 | I16: =+Model!I189 -> -1101 | J16: =+Model!J189 -> -4068 | ... AD16: =+Model!AD189 -> 0 | AH16: =+Model!AH189 -> 3172 | AI16: =+Model!AI189 -> 785 | AJ16: =+Model!AJ189 -> -7502 | AK16: =+Model!AK189 -> -8731 | AL16: =+Model!AL189 -> -8880 | AM16: =+Model!AM189 -> 3641 | AN16: =+Model!AN189 -> 0 | AO16: =+Model!AO189 -> 0
B17: CF | C17: =+Model!C192 -> -1041 | D17: =+Model!D192 -> -1480 | E17: =+Model!E192 -> 4580 | F17: =+Model!F192 -> -396 | G17: =+Model!G192 -> 28 | H17: =+Model!H192 -> 9556 | I17: =+Model!I192 -> -12961 | J17: =+Model!J192 -> -1132 | ... AD17: =+Model!AD192 -> 0 | AH17: =+Model!AH192 -> 1663 | AI17: =+Model!AI192 -> -4509 | AJ17: =+Model!AJ192 -> 927 | AK17: =+Model!AK192 -> -388 | AL17: =+Model!AL192 -> -717 | AM17: =+Model!AM192 -> 5135 | AN17: =+Model!AN192 -> 0 | AO17: =+Model!AO192 -> 0
B19: CapEx | C19: =Model!C168 -> -338 | D19: =Model!D168 -> -342 | E19: =Model!E168 -> -332 | F19: =Model!F168 -> -486 | G19: =Model!G168 -> -329 | H19: =Model!H168 -> -363 | I19: =Model!I168 -> -418 | J19: =Model!J168 -> -620 | ... AD19: =Model!AD168 -> 0 | AH19: =Model!AH168 -> -1498 | AI19: =Model!AI168 -> -1730 | AJ19: =Model!AJ168 -> -2084 | AK19: =Model!AK168 -> -2146 | AL19: =Model!AL168 -> -2088 | AM19: =Model!AM168 -> -2445 | AN19: =Model!AN168 -> 0 | AO19: =Model!AO168 -> 0
B20: Model FCF | C20: =+Model!C199 -> 201 | D20: =+Model!D199 -> 359 | E20: =+Model!E199 -> 2694 | F20: =+Model!F199 -> 4157 | G20: =+Model!G199 -> 1032 | H20: =+Model!H199 -> 1232 | I20: =+Model!I199 -> 2287 | J20: =+Model!J199 -> 3813 | ... AD20: =+Model!AD199 -> 0 | AH20: =+Model!AH199 -> 7411 | AI20: =+Model!AI199 -> 8364 | AJ20: =+Model!AJ199 -> 8433 | AK20: =+Model!AK199 -> 10329 | AL20: =+Model!AL199 -> 9814 | AM20: =+Model!AM199 -> 10998 | AN20: =+Model!AN199 -> 0 | AO20: =+Model!AO199 -> 0
B22: Reported FCF | C22: =+Model!C325 -> -3 | D22: =+Model!D325 -> 685 | E22: =+Model!E325 -> 1920 | F22: =+Model!F325 -> 3750 | G22: =+Model!G325 -> 906 | H22: =+Model!H325 -> 1326 | I22: =+Model!I325 -> 2285 | J22: =+Model!J325 -> 3862 | ... AD22: =+Model!AD325 -> 0 | AH22: =+Model!AH325 -> 6352 | AI22: =+Model!AI325 -> 8379 | AJ22: =+Model!AJ325 -> 8238 | AK22: =+Model!AK325 -> 10146 | AL22: =+Model!AL325 -> 9726 | AM22: =+Model!AM325 -> 11004 | AN22: =+Model!AN325 -> 0 | AO22: =+Model!AO325 -> 0
B24: EBITDA | C24: =Model!C338 -> 1950 | D24: =Model!D338 -> 1952 | E24: =Model!E338 -> 1798 | F24: =Model!F338 -> 1673 | G24: =Model!G338 -> 2454 | H24: =Model!H338 -> 2141 | I24: =Model!I338 -> 2366 | J24: =Model!J338 -> 2178 | ... AD24: =Model!AD338 -> 0 | AH24: =Model!AH338 -> 7373 | AI24: =Model!AI338 -> 9139 | AJ24: =Model!AJ338 -> 10759 | AK24: =Model!AK338 -> 14026 | AL24: =Model!AL338 -> 13577 | AM24: =Model!AM338 -> 13380 | AN24: =Model!AN338 -> 0 | AO24: =Model!AO338 -> 0
B26: Implied Basic S/O | C26: =C6/Model!C27 -> 818.79699 | D26: =D6/Model!D27 -> 871.25 | E26: =E6/Model!E27 -> 798.50746 | F26: =F6/Model!F27 -> 854.09091 | G26: =G6/Model!G27 -> 865.31792 | H26: =H6/Model!H27 -> 847.51773 | I26: =I6/Model!I27 -> 880.95238 | J26: =J6/Model!J27 -> 917.24138 | ... AD26: =AD6/Model!AD27 -> #DIV/0! | AH26: =AH6/Model!AH27 -> 840 | AI26: =AI6/Model!AI27 -> 872.00521 | AJ26: =AJ6/Model!AJ27 -> 944.51613 | AK26: =AK6/Model!AK27 -> 849.50199 | AL26: =AL6/Model!AL27 -> 853.94112 | AM26: =AM6/Model!AM27 -> 847.91837 | AN26: =AN6/Model!AN27 -> #DIV/0! | AO26: =AO6/Model!AO27 -> #DIV/0!
B27: Implied Diluted S/O | C27: =C6/Model!C32 -> 837.69231 | D27: =D6/Model!D32 -> 882.27848 | E27: =E6/Model!E32 -> 798.50746 | F27: =F6/Model!F32 -> 865.89862 | G27: =G6/Model!G32 -> 875.4386 | H27: =H6/Model!H32 -> 856.63082 | I27: =I6/Model!I32 -> 891.56627 | J27: =J6/Model!J32 -> 930.06993 | ... AD27: =AD6/Model!AD32 -> #DIV/0! | AH27: =AH6/Model!AH32 -> 851.92698 | AI27: =AI6/Model!AI32 -> 882.34519 | AJ27: =AJ6/Model!AJ32 -> 956.86275 | AK27: =AK6/Model!AK32 -> 860.64581 | AL27: =AL6/Model!AL32 -> 866.28131 | AM27: =AM6/Model!AM32 -> 857.72089 | AN27: =AN6/Model!AN32 -> #DIV/0! | AO27: =AO6/Model!AO32 -> #DIV/0!
B30: Price | C30: 62.26 | D30: 47.88 | E30: 67.905 | F30: 72.66 | G30: 81.65 | H30: 87.77 | I30: 83.67 | J30: 86.61 | K30: 82.1 | L30: 58.92 | M30: 56.53 | N30: 67.33 | O30: 79.47 | P30: 83.68 | Q30: 81.86 | R30: 79.72 | S30: 91.775 | T30: 95 | U30: 87.22 | V30: 100.55 | W30: 119.24 | X30: 124.62 | Y30: 135.75 | Z30: 134 | AA30: 140
B31: MC | C31: =C26*C30*2 -> 101956.6 | D31: =D26*D30*2 -> 83430.9 | E31: =E26*E30*2 -> 108445.3 | F31: =F26*F30*2 -> 124116.49 | G31: =G26*G30*2 -> 141306.42 | H31: =H26*H30*2 -> 148773.26 | I31: =I26*I30*2 -> 147418.57 | J31: =J26*J30*2 -> 158884.55 | ... AD31: =AD26*AD30*2 -> #DIV/0!
B33: EV | C33: =C31-C8+C10 -> 101956.6 | D33: =D31-D8+D10 -> 83430.9 | E33: =E31-E8+E10 -> 108445.3 | F33: =F31-F8+F10 -> 154642.49 | G33: =G31-G8+G10 -> 170770.42 | H33: =H31-H8+H10 -> 177232.26 | I33: =I31-I8+I10 -> 187851.57 | J33: =J31-J8+J10 -> 198039.55 | ... AD33: =AD31-AD8+AD10 -> #DIV/0!
B36: Trl P/E | C36: 29.551545 | D36: 29.551545 | E36: 29.551545 | F36: =(F31)/SUM(C6:F6) -> 29.551545 | G36: =(G31)/SUM(D6:G6) -> 30.665455 | H36: =(H31)/SUM(E6:H6) -> 23.611056 | I36: =(I31)/SUM(F6:I6) -> 20.344821 | J36: =(J31)/SUM(G6:J6) -> 23.724735 | K36: =(K31)/SUM(H6:K6) -> 20.562496 | L36: =(L31)/SUM(I6:L6) -> 19.042127 | M36: =(M31)/SUM(J6:M6) -> 29.924014 | ... AD36: =(AD31)/SUM(AA6:AD6) -> #DIV/0!
B37: Trl EV/FCF | C37: 20.866616 | D37: 20.866616 | E37: 20.866616 | F37: =F33/SUM(C20:F20) -> 20.866616 | G37: =G33/SUM(D20:G20) -> 20.719536 | H37: =H33/SUM(E20:H20) -> 19.444022 | I37: =I33/SUM(F20:I20) -> 21.572298 | J37: =J33/SUM(G20:J20) -> 23.677613 | K37: =K33/SUM(H20:K20) -> 21.645771 | L37: =L33/SUM(I20:L20) -> 17.8688 | M37: =M33/SUM(J20:M20) -> 14.62707 | ... AD37: =AD33/SUM(AA20:AD20) -> #DIV/0!
B38: Trl EV/EBITDA | C38: 20.974161 | D38: 20.974161 | E38: 20.974161 | F38: =F33/SUM(C24:F24) -> 20.974161 | G38: =G33/SUM(D24:G24) -> 21.679626 | H38: =H33/SUM(E24:H24) -> 21.972758 | I38: =I33/SUM(F24:I24) -> 21.757189 | J38: =J33/SUM(G24:J24) -> 21.669718 | K38: =K33/SUM(H24:K24) -> 18.85924 | L38: =L33/SUM(I24:L24) -> 15.377149 | M38: =M33/SUM(J24:M24) -> 15.522715 | ... AD38: =AD33/SUM(AA24:AD24) -> #DIV/0!
B43: Inventories | F43: =Model!F77+Model!F85 -> 15657 | G43: =Model!G77+Model!G85 -> 15572 | H43: =Model!H77+Model!H85 -> 15803 | I43: =Model!I77+Model!I85 -> 16719 | J43: =Model!J77+Model!J85 -> 16375 | K43: =Model!K77+Model!K85 -> 17437 | L43: =Model!L77+Model!L85 -> 17719 | M43: =Model!M77+Model!M85 -> 15686 | ... AD43: =Model!AD77+Model!AD85 -> 0 | AH43: =Model!AH77+Model!AH85 -> 15657 | AI43: =Model!AI77+Model!AI85 -> 16375 | AJ43: =Model!AJ77+Model!AJ85 -> 15581 | AK43: =Model!AK77+Model!AK85 -> 14562 | AL43: =Model!AL77+Model!AL85 -> 11903 | AM43: =Model!AM77+Model!AM85 -> 11448 | AN43: =Model!AN77+Model!AN85 -> 0 | AO43: =Model!AO77+Model!AO85 -> 0 | ... AQ43: =Model!AQ77+Model!AQ85 -> 0
B44: A/R | F44: =Model!F74 -> 14074 | G44: =Model!G74 -> 13866 | H44: =Model!H74 -> 13951 | I44: =Model!I74 -> 15126 | J44: =Model!J74 -> 15518 | K44: =Model!K74 -> 15916 | L44: =Model!L74 -> 15960 | M44: =Model!M74 -> 16162 | ... AD44: =Model!AD74 -> 0 | AH44: =Model!AH74 -> 14074 | AI44: =Model!AI74 -> 15518 | AJ44: =Model!AJ74 -> 16701 | AK44: =Model!AK74 -> 17405 | AL44: =Model!AL74 -> 16963 | AM44: =Model!AM74 -> 16628 | AN44: =Model!AN74 -> 0 | AO44: =Model!AO74 -> 0 | ... AQ44: =Model!AQ74 -> 0
B45: A/P | F45: =Model!F94 -> 7873 | G45: =Model!G94 -> 7025 | H45: =Model!H94 -> 7274 | I45: =Model!I94 -> 8034 | J45: =Model!J94 -> 8832 | K45: =Model!K94 -> 8486 | L45: =Model!L94 -> 8932 | M45: =Model!M94 -> 9128 | ... AD45: =Model!AD94 -> 0 | AH45: =Model!AH94 -> 7873 | AI45: =Model!AI94 -> 8832 | AJ45: =Model!AJ94 -> 10317 | AK45: =Model!AK94 -> 10130 | AL45: =Model!AL94 -> 8843 | AM45: =Model!AM94 -> 9183 | AN45: =Model!AN94 -> 0 | AO45: =Model!AO94 -> 0 | ... AQ45: =Model!AQ94 -> 0
B46: Working capital, net | F46: =F43+F44-F45 -> 21858 | G46: =G43+G44-G45 -> 22413 | H46: =H43+H44-H45 -> 22480 | I46: =I43+I44-I45 -> 23811 | J46: =J43+J44-J45 -> 23061 | K46: =K43+K44-K45 -> 24867 | L46: =L43+L44-L45 -> 24747 | M46: =M43+M44-M45 -> 22720 | ... AD46: =AD43+AD44-AD45 -> 0 | AH46: =AH43+AH44-AH45 -> 21858 | AI46: =AI43+AI44-AI45 -> 23061 | AJ46: =AJ43+AJ44-AJ45 -> 21965 | AK46: =AK43+AK44-AK45 -> 21837 | AL46: =AL43+AL44-AL45 -> 20023 | AM46: =AM43+AM44-AM45 -> 18893 | AN46: =AN43+AN44-AN45 -> 0 | AO46: =AO43+AO44-AO45 -> 0 | ... AQ46: =AQ43+AQ44-AQ45 -> 0
B47: % of sales TTM | F47: =F46/SUM(C3:F3) -> 0.39559127 | G47: =G46/SUM(D3:G3) -> 0.40274933 | H47: =H46/SUM(E3:H3) -> 0.39765792 | I47: =I46/SUM(F3:I3) -> 0.39926556 | J47: =J46/SUM(G3:J3) -> 0.37036859 | K47: =K46/SUM(H3:K3) -> 0.38439659 | L47: =L46/SUM(I3:L3) -> 0.36899472 | M47: =M46/SUM(J3:M3) -> 0.33000232 | ... AD47: =AD46/SUM(AA3:AD3) -> 0 | AH47: =AH46/AH3 -> 0.39559127 | AI47: =AI46/AI3 -> 0.37036859 | AJ47: =AJ46/AJ3 -> 0.30516693 | AK47: =AK46/AK3 -> 0.29161881 | AL47: =AL46/AL3 -> 0.26370341 | AM47: =AM46/AM3 -> 0.23941253 | AN47: =AN46/AN3 -> #DIV/0! | AO47: =AO46/AO3 -> #DIV/0! | ... AQ47: =AQ46/AQ3 -> #DIV/0!
B48: Change in working capital | G48: =G46-F46 -> 555 | H48: =H46-G46 -> 67 | I48: =I46-H46 -> 1331 | J48: =J46-I46 -> -750 | K48: =K46-J46 -> 1806 | L48: =L46-K46 -> -120 | M48: =M46-L46 -> -2027 | N48: =N46-M46 -> -755 | ... AD48: =AD46-AC46 -> 0 | AI48: =AI46-AH46 -> 1203 | AJ48: =AJ46-AI46 -> -1096 | AK48: =AK46-AJ46 -> -128 | AL48: =AL46-AK46 -> -1814 | AM48: =AM46-AL46 -> -1130 | AN48: =AN46-AM46 -> -18893 | AO48: =AO46-AN46 -> 0 | AP48: =AP46-AO46 -> 0 | AQ48: =AQ46-AP46 -> 0
B50: Days inventories on hand TTM | F50: =365/((-SUM(Model!C4:G4))/Valuation!F43) -> 129.53748 | G50: =365/((-SUM(Model!D4:H4))/((Valuation!G43+F43)/2)) -> 127.06036 | H50: =365/((-SUM(Model!E4:I4))/((Valuation!H43+G43)/2)) -> 123.67837 | I50: =365/((-SUM(Model!F4:J4))/((Valuation!I43+H43)/2)) -> 120.61095 | J50: =365/((-SUM(Model!G4:K4))/((Valuation!J43+I43)/2)) -> 121.23196 | K50: =365/((-SUM(Model!H4:L4))/((Valuation!K43+J43)/2)) -> 117.83322 | L50: =365/((-SUM(Model!I4:M4))/((Valuation!L43+K43)/2)) -> 117.55167 | M50: =365/((-SUM(Model!J4:N4))/((Valuation!M43+L43)/2)) -> 106.45408 | N50: =365/((-SUM(Model!K4:O4))/((Valuation!N43+M43)/2)) -> 99.698218 | ... AD50: =365/((-SUM(Model!AA4:AE4))/((Valuation!AD43+AC43)/2)) -> #DIV/0! | AH50: =365/(-Model!AH4/Valuation!AH43) -> 161.59037 | AI50: =365/(-Model!AI4/((Valuation!AI43+AH43)/2)) -> 147.89486 | AJ50: =365/(-Model!AJ4/((Valuation!AJ43+AI43)/2)) -> 126.42467 | AK50: =365/(-Model!AK4/((Valuation!AK43+AJ43)/2)) -> 120.20053 | AL50: =365/(-Model!AL4/((Valuation!AL43+AK43)/2)) -> 104.75335 | AM50: =365/(-Model!AM4/((Valuation!AM43+AL43)/2)) -> 87.839998 | AN50: =365/(-Model!AN4/((Valuation!AN43+AM43)/2)) -> #DIV/0! | AO50: =365/(-Model!AO4/((Valuation!AO43+AN43)/2)) -> #DIV/0! | AP50: =365/(-Model!AP4/((Valuation!AP43+AO43)/2)) -> #DIV/0! | AQ50: =365/(-Model!AQ4/((Valuation!AQ43+AP43)/2)) -> #DIV/0!
B51: Days sales outstanding TTM | F51: =365/(SUM(C3:F3)/F44) -> 92.970826 | G51: =365/(SUM(D3:G3)/((G44+F44)/2)) -> 91.627134 | H51: =365/(SUM(E3:H3)/((H44+G44)/2)) -> 89.8021 | I51: =365/(SUM(F3:I3)/((I44+H44)/2)) -> 88.980876 | J51: =365/(SUM(G3:J3)/((J44+I44)/2)) -> 89.818196 | K51: =365/(SUM(H3:K3)/((K44+J44)/2)) -> 88.678564 | L51: =365/(SUM(I3:L3)/((L44+K44)/2)) -> 86.740972 | M51: =365/(SUM(J3:M3)/((M44+L44)/2)) -> 85.147935 | N51: =365/(SUM(K3:N3)/((N44+M44)/2)) -> 83.325194 | ... AD51: =365/(SUM(AA3:AD3)/((AD44+AC44)/2)) -> #DIV/0! | AH51: =365/(AH3/AH44) -> 92.970826 | AI51: =365/(AI3/((AI44+AH44)/2)) -> 86.734763 | AJ51: =365/(AJ3/((AJ44+AI44)/2)) -> 81.692311 | AK51: =365/(AK3/((AK44+AJ44)/2)) -> 83.122045 | AL51: =365/(AL3/((AL44+AK44)/2)) -> 82.604504 | AM51: =365/(AM3/((AM44+AL44)/2)) -> 77.684029 | AN51: =365/(AN3/((AN44+AM44)/2)) -> #DIV/0! | AO51: =365/(AO3/((AO44+AN44)/2)) -> #DIV/0! | AP51: =365/(AP3/((AP44+AO44)/2)) -> #DIV/0! | AQ51: =365/(AQ3/((AQ44+AP44)/2)) -> #DIV/0!
B52: Days payable outstanding TTM | F52: =365/((-SUM(Model!C4:G4))/F45) -> 65.136909 | G52: =365/((-SUM(Model!D4:H4))/((Valuation!G45+F45)/2)) -> 60.614982 | H52: =365/((-SUM(Model!E4:I4))/((Valuation!H45+G45)/2)) -> 56.365801 | I52: =365/((-SUM(Model!F4:J4))/((Valuation!I45+H45)/2)) -> 56.771185 | J52: =365/((-SUM(Model!G4:K4))/((Valuation!J45+I45)/2)) -> 61.78456 | K52: =365/((-SUM(Model!H4:L4))/((Valuation!K45+J45)/2)) -> 60.35241 | L52: =365/((-SUM(Model!I4:M4))/((Valuation!L45+K45)/2)) -> 58.240839 | M52: =365/((-SUM(Model!J4:N4))/((Valuation!M45+L45)/2)) -> 57.553084 | N52: =365/((-SUM(Model!K4:O4))/((Valuation!N45+M45)/2)) -> 62.00249 | ... AD52: =365/((-SUM(Model!AA4:AE4))/((Valuation!AD45+AC45)/2)) -> #DIV/0! | AH52: =365/(-Model!AH4/Valuation!AH45) -> 81.254453 | AI52: =365/(-Model!AI4/((Valuation!AI45+AH45)/2)) -> 77.128608 | AJ52: =365/(-Model!AJ4/((Valuation!AJ45+AI45)/2)) -> 75.757479 | AK52: =365/(-Model!AK4/((Valuation!AK45+AJ45)/2)) -> 81.53602 | AL52: =365/(-Model!AL4/((Valuation!AL45+AK45)/2)) -> 75.098629 | AM52: =365/(-Model!AM4/((Valuation!AM45+AL45)/2)) -> 67.808822 | AN52: =365/(-Model!AN4/((Valuation!AN45+AM45)/2)) -> #DIV/0! | AO52: =365/(-Model!AO4/((Valuation!AO45+AN45)/2)) -> #DIV/0! | AP52: =365/(-Model!AP4/((Valuation!AP45+AO45)/2)) -> #DIV/0! | AQ52: =365/(-Model!AQ4/((Valuation!AQ45+AP45)/2)) -> #DIV/0!
B53: Cash Conversion Cycle | F53: =F50+F51-F52 -> 157.3714 | G53: =G50+G51-G52 -> 158.07251 | H53: =H50+H51-H52 -> 157.11467 | I53: =I50+I51-I52 -> 152.82064 | J53: =J50+J51-J52 -> 149.2656 | K53: =K50+K51-K52 -> 146.15937 | L53: =L50+L51-L52 -> 146.0518 | M53: =M50+M51-M52 -> 134.04894 | ... AD53: =AD50+AD51-AD52 -> #DIV/0! | AH53: =AH50+AH51-AH52 -> 173.30674 | AI53: =AI50+AI51-AI52 -> 157.50101 | AJ53: =AJ50+AJ51-AJ52 -> 132.3595 | AK53: =AK50+AK51-AK52 -> 121.78656 | AL53: =AL50+AL51-AL52 -> 112.25922 | AM53: =AM50+AM51-AM52 -> 97.715205 | AN53: =AN50+AN51-AN52 -> #DIV/0! | AO53: =AO50+AO51-AO52 -> #DIV/0! | ... AQ53: =AQ50+AQ51-AQ52 -> #DIV/0!

Sheet Norge Ownership
E2: Company | F2: Value | G2: Currency | H2: Rate | I2: USD | J2: Ownership % | K2: Country | L2: Sector
E3: Siemens AG | F3: 40757194248 | G3: NOK | H3: 9.6305 | I3: =F3/$H$3 -> 4.2320953e+09 | J3: 0.018 | K3: Germany | L3: Industrials
E4: Siemens Energy AG | F4: 23721468884 | G4: NOK | I4: =F4/$H$3 -> 2.4631607e+09 | J4: 0.0193 | K4: Germany | L4: Energy
E5: Siemens Healthcare AG | F5: 12471723386 | G5: NOK | I5: =F5/$H$3 -> 1.2950235e+09 | J5: 0.0208 | K5: Germany | L5: Healthcare
E6: General Electric Co | F6: 41916805908 | G6: NOK | I6: =F6/$H$3 -> 4.3525057e+09 | J6: 0.0128 | K6: United States | L6: Industrials
E7: GE Vernova Inc | F7: 21824505506 | G7: NOK | I7: =F7/$H$3 -> 2.2661861e+09 | J7: 0.0122 | K7: United States | L7: Industrials
E8: Schneider Electric SE | F8: 36763709310 | G8: NOK | I8: =F8/$H$3 -> 3.8174248e+09 | J8: 0.0229 | K8: France | L8: Industrials
E9: ABB Ltd | F9: 21558767704 | G9: NOK | I9: =F9/$H$3 -> 2.2385928e+09 | J9: 0.0155 | K9: Switzerland | L9: Industrials
E10: Rockwell Automation Inc | F10: 5200185686 | G10: NOK | I10: =F10/$H$3 -> 5.3997048e+08 | J10: 0.0118 | K10: United States | L10: Industrials
E11: Emerson Electric Co | F11: 9454991822 | G11: NOK | I11: =F11/$H$3 -> 9.817758e+08 | J11: 0.0126 | K11: United States | L11: Industrials
E12: Mitsubishi Electric Corp | F12: 10116783439 | G12: NOK | I12: =F12/$H$3 -> 1.0504941e+09 | J12: 0.0162 | K12: Japan | L12: Industrials
E13: Panasonic Holdings Corp | F13: 4921305417 | G13: NOK | I13: =F13/$H$3 -> 5.1101245e+08 | J13: 0.0154 | K13: Japan | L13: Consumer Discretionary
E14: Hitachi Ltd | F14: 23796328080 | G14: NOK | I14: =F14/$H$3 -> 2.4709338e+09 | J14: 0.0165 | K14: Japan | L14: Industrials
E15: Toshiba TEC Corp | F15: 26060746 | G15: NOK | I15: =F15/$H$3 -> 2706063.7 | J15: 0.0026 | K15: Japan | L15: Technology
... E18: thyssenkrupp AG | F18: 934836496 | G18: NOK | I18: =F18/$H$3 -> 97070401 | J18: 0.0137 | K18: Germany | L18: Industrials
