Workbook

Sheet Main
A1: SaaS
Q4: Q1 FY27 Guidance | U4: FY27 Guidance
I5: Price | J5: 19.78 | M5: 1Yβ | N5: 1.544 | P5: Revenue | Q5: 253 | R5: 255 | U5: 1099 | V5: 1118
I6: S/O | J6: =+FS!Q21/1000 -> 167.407 | K6: Q3FY26 | M6: US 1-YR | N6: 3.607 | P6: Non-GAAP EBIT | Q6: 32 | R6: 34 | U6: 129 | V6: 137
I7: MC | J7: =J5*J6 -> 3311.3105 | M7: E[M] | N7: 0.2 | P7: Margin | Q7: =Q6/Q5 -> 0.12648221 | R7: =R6/R5 -> 0.13333333 | U7: =U6/U5 -> 0.11737944 | V7: =V6/V5 -> 0.12254025
I8: Cash | J8: =+FS!Q50/1000 -> 1204.308 | K8: Q3FY26 | M8: E[GTLB] | N8: =N6/100+N5*(N7-N6/100) -> 0.28917792 | P8: Diluted WASO | R8: 173 | V8: 175
I9: Debt | J9: 0 | K9: Q3FY26 | P9: Non-GAAP EPS | Q9: 0.2 | R9: 0.21 | U9: 0.76 | V9: 0.8
P10: Implied Non-GAAP NI | Q10: =+Q9*R8 -> 34.6 | R10: =R9*R8 -> 36.33 | U10: =U9*V8 -> 133 | V10: =+V9*V8 -> 140
I11: EV | J11: =J7-J8+J94 -> 2107.0025 | P11: Net Margin | Q11: =Q10/Q5 -> 0.13675889 | R11: =R10/R5 -> 0.14247059 | U11: =U10/U5 -> 0.12101911 | V11: =V10/V5 -> 0.12522361
J14: =1000/J5 -> 50.556117
J15: =J14/J6 -> 0.30199524

Sheet FS
A1: Main | B1: 45802
B2: INCOME STATEMENT | C2: Q123 | D2: Q223 | E2: Q323 | F2: Q423 | G2: Q124 | H2: Q224 | I2: Q324 | J2: Q424 | K2: Q125 | L2: Q225 | M2: Q325 | N2: Q425 | O2: Q126 | P2: Q226 | Q2: Q326 | R2: Q426 | S2: Q127 | T2: Q227 | U2: Q327 | V2: Q427 | W2: Q128 | X2: Q228 | Y2: Q328 | Z2: Q428 | AC2: 2023 | AD2: 2024 | AE2: 2025 | AF2: 2026 | AG2: 2027 | AH2: 2028 | AI2: 2029 | AJ2: 2030 | AK2: 2031 | AL2: 2032 | AM2: 2033 | AN2: 2034 | AO2: 2035 | AP2: 2036 | AQ2: 2037 | AR2: 2038 | AS2: 2039 | AT2: 2040 | AU2: 2041 | AV2: 2042 | AW2: 2043 | AX2: 2044 | AY2: 2045 | AZ2: 2046 | BA2: 2047 | BB2: 2048 | BC2: 2049 | BD2: 2050 | BE2: 2051 | BF2: 2052 | BG2: 2053 | BH2: 2054 | BI2: 2055 | BJ2: 2056 | BK2: 2057 | BL2: 2058 | BM2: 2059 | BN2: 2060 | BO2: 2061 | BP2: 2062 | BQ2: 2063 | BR2: 2064 | BS2: 2065 | BT2: 2066 | BU2: 2067 | BV2: 2068 | BW2: 2069 | BX2: 2070 | BY2: 2071 | BZ2: 2072 | CA2: 2073 | CB2: 2074 | CC2: 2075 | CD2: 2076 | CE2: 2077 | CF2: 2078 | CG2: 2079 | CH2: 2080 | CI2: 2081 | CJ2: 2082 | CK2: 2083 | CL2: 2084 | CM2: 2085 | CN2: 2086 | CO2: 2087 | CP2: 2088 | CQ2: 2089 | CR2: 2090 | CS2: 2091 | CT2: 2092 | CU2: 2093 | CV2: 2094 | CW2: 2095 | CX2: 2096 | CY2: 2097 | CZ2: 2098 | DA2: 2099 | DB2: 2100 | DC2: 2101 | DD2: 2102 | DE2: 2103 | DF2: 2104 | DG2: 2105 | DH2: 2106 | DI2: 2107 | DJ2: 2108 | DK2: 2109 | DL2: 2110 | DM2: 2111 | DN2: 2112 | DO2: 2113 | DP2: 2114 | DQ2: 2115 | DR2: 2116 | DS2: 2117 | DT2: 2118 | DU2: 2119 | DV2: 2120 | DW2: 2121 | DX2: 2122 | DY2: 2123 | DZ2: 2124 | EA2: 2125 | EB2: 2126 | EC2: 2127 | ED2: 2128 | EE2: 2129 | EF2: 2130 | EG2: 2131 | EH2: 2132 | EI2: 2133 | EJ2: 2134 | EK2: 2135 | EL2: 2136 | EM2: 2137 | EN2: 2138 | EO2: 2139 | EP2: 2140 | EQ2: 2141 | ER2: 2142 | ES2: 2143 | ET2: 2144 | EU2: 2145
B3: Subscription | C3: 76923 | D3: 88936 | E3: 98435 | F3: 105055 | G3: 111191 | H3: 122096 | I3: 130993 | J3: 142026 | K3: 151179 | L3: 163181 | M3: 175257 | N3: 185562 | O3: 194481 | P3: 212684 | Q3: 223262 | R3: 234277 | AC3: 369349 | AD3: 506306 | AE3: 675179
B4: License | C4: 10484 | D4: 12105 | E4: 14546 | F4: 17852 | G4: 15687 | H4: 17485 | I4: 18675 | J4: 21753 | K4: 18008 | L4: 19403 | M4: 20790 | N4: 25869 | O4: 20028 | P4: 23276 | Q4: 21091 | R4: 26125 | AC4: 54987 | AD4: 73600 | AE4: 84070
B5: Revenue | C5: =+C3+C4 -> 87407 | D5: =+D3+D4 -> 101041 | E5: =+E3+E4 -> 112981 | F5: =+F3+F4 -> 122907 | G5: =+G3+G4 -> 126878 | H5: =+H3+H4 -> 139581 | I5: =+I3+I4 -> 149668 | J5: =+J3+J4 -> 163779 | ... R5: =+R3+R4 -> 260402 | S5: 255000 | T5: 277000 | U5: 293000 | V5: 311000 | W5: 323000 | X5: =T5*1.2 -> 332400 | Y5: =U5*1.2 -> 351600 | Z5: =V5*1.2 -> 373200 | AC5: =+AC3+AC4 -> 424336 | AD5: =+AD3+AD4 -> 579906 | AE5: =+AE3+AE4 -> 759249 | AF5: =SUM(O5:R5) -> 955224 | AG5: =SUM(S5:V5) -> 1136000 | AH5: =SUM(W5:Z5) -> 1380200 | AI5: =AH5*1.15 -> 1587230 | AJ5: =AI5*1.15 -> 1825314.5 | AK5: =AJ5*1.1 -> 2007845.9 | AL5: =AK5*1.1 -> 2208630.5 | AM5: =AL5*1.1 -> 2429493.6 | AN5: =AM5*1.1 -> 2672443 | AO5: =AN5*1.1 -> 2939687.3 | AP5: =AO5*1.05 -> 3086671.6 | AQ5: =AP5*1.05 -> 3241005.2 | AR5: =AQ5*1.05 -> 3403055.5 | AS5: =AR5*1.05 -> 3573208.2 | AT5: =AS5*1.05 -> 3751868.6 | AU5: =AT5*1.05 -> 3939462.1 | AV5: =AU5*1.05 -> 4136435.2 | AW5: =AV5*1.05 -> 4343256.9 | ... AY5: =AX5*1.05 -> 4788440.8
B6: Subscription Cost | C6: 7933 | D6: 10671 | E6: 11113 | F6: 11124 | G6: 10891 | H6: 10871 | I6: 11559 | J6: 12165 | K6: 13839 | L6: 16630 | M6: 17170 | N6: 17277 | O6: 19268 | P6: 21753 | Q6: 25184 | R6: 28297 | AC6: 40841 | AD6: 45486 | AE6: 64916
B7: License Cost | C7: 1915 | D7: 2359 | E7: 3451 | F7: 3114 | G7: 3048 | H7: 3825 | I7: 3525 | J7: 3824 | K7: 4937 | L7: 4740 | M7: 4955 | N7: 5592 | O7: 5767 | P7: 6752 | Q7: 7037 | R7: 6685 | AC7: 10839 | AD7: 14222 | AE7: 20224
B8: COGS | C8: =+C6+C7 -> 9848 | D8: =+D6+D7 -> 13030 | E8: =+E6+E7 -> 14564 | F8: =+F6+F7 -> 14238 | G8: =+G6+G7 -> 13939 | H8: =+H6+H7 -> 14696 | I8: =+I6+I7 -> 15084 | J8: =+J6+J7 -> 15989 | ... T8: =+T6+T7 -> 0 | AC8: =+AC6+AC7 -> 51680 | AD8: =+AD6+AD7 -> 59708 | AE8: =+AE6+AE7 -> 85140
B9: Gross Profit | C9: =+C5-C8 -> 77559 | D9: =+D5-D8 -> 88011 | E9: =+E5-E8 -> 98417 | F9: =+F5-F8 -> 108669 | G9: =+G5-G8 -> 112939 | H9: =+H5-H8 -> 124885 | I9: =+I5-I8 -> 134584 | J9: =+J5-J8 -> 147790 | ... T9: =+T5-T8 -> 277000 | AC9: =+AC5-AC8 -> 372656 | AD9: =+AD5-AD8 -> 520198 | AE9: =+AE5-AE8 -> 674109 | AF9: =+AF5*0.89 -> 850149.36 | AG9: =+AG5*0.89 -> 1011040 | AH9: =+AH5*0.89 -> 1228378 | AI9: =+AI5*0.89 -> 1412634.7 | AJ9: =+AJ5*0.89 -> 1624529.9 | AK9: =+AK5*0.89 -> 1786982.9 | AL9: =+AL5*0.89 -> 1965681.2 | AM9: =+AM5*0.89 -> 2162249.3 | ... AY9: =+AY5*0.89 -> 4261712.3
B10: S&M | C10: 66710 | D10: 80689 | E10: 81080 | F10: 81513 | G10: 86537 | H10: 92116 | I10: 86978 | J10: 90762 | K10: 92424 | L10: 97778 | M10: 95340 | N10: 98753 | O10: 107587 | P10: 109583 | Q10: 104974 | R10: 112581 | AC10: 309992 | AD10: 356393 | AE10: 384295 | AF10: =AF9*0.27 -> 229540.33 | AG10: =AG9*0.27 -> 272980.8 | AH10: =+AH9*0.22 -> 270243.16 | AI10: =+AI9*0.2 -> 282526.94 | AJ10: =+AJ9*0.15 -> 243679.49 | AK10: =+AK9*0.15 -> 268047.43 | AL10: =+AL9*0.15 -> 294852.18 | AM10: =+AM9*0.15 -> 324337.4 | AN10: =+AN9*0.15 -> 356771.14 | AO10: =+AO9*0.15 -> 392448.25 | AP10: =+AP9*0.15 -> 412070.66 | AQ10: =+AQ9*0.15 -> 432674.19 | ... AY10: =+AY9*0.15 -> 639256.84
B11: R&D | C11: 31830 | D11: 39520 | E11: 41113 | F11: 43680 | G11: 50387 | H11: 49007 | I11: 49058 | J11: 52388 | K11: 54140 | L11: 61273 | M11: 61354 | N11: 62885 | O11: 65410 | P11: 71488 | Q11: 68715 | R11: 68961 | AC11: 156143 | AD11: 200840 | AE11: 239652 | AF11: =AF9*0.3 -> 255044.81 | AG11: =AG9*0.3 -> 303312 | AH11: =AH9*0.3 -> 368513.4 | AI11: =AI9*0.3 -> 423790.41 | AJ11: =AJ9*0.3 -> 487358.97 | AK11: =AK9*0.3 -> 536094.87 | AL11: =AL9*0.3 -> 589704.36 | AM11: =AM9*0.3 -> 648674.79 | ... AY11: =AY9*0.3 -> 1278513.7
B12: G&A | C12: 21892 | D12: 33104 | E12: 33186 | F12: 29750 | G12: 34248 | H12: 37819 | I12: 38815 | J12: 39523 | K12: 57487 | L12: 43168 | M12: 45960 | N12: 42370 | O12: 51087 | P12: 44735 | Q12: 50799 | R12: 49042 | AC12: 117932 | AD12: 150405 | AE12: 192877 | AF12: =AF9*0.29 -> 246543.31 | AG12: =AG9*0.29 -> 293201.6 | AH12: =AH9*0.22 -> 270243.16 | AI12: =AI9*0.2 -> 282526.94 | AJ12: =AJ9*0.15 -> 243679.49 | AK12: =AK9*0.15 -> 268047.43 | AL12: =AL9*0.15 -> 294852.18 | AM12: =AM9*0.15 -> 324337.4 | AN12: =AN9*0.15 -> 356771.14 | AO12: =AO9*0.15 -> 392448.25 | AP12: =AP9*0.15 -> 412070.66 | AQ12: =AQ9*0.15 -> 432674.19 | ... AY12: =AY9*0.15 -> 639256.84
B13: Operating Expenses | C13: =+C10+C11+C12 -> 120432 | D13: =+D10+D11+D12 -> 153313 | E13: =+E10+E11+E12 -> 155379 | F13: =+F10+F11+F12 -> 154943 | G13: =+G10+G11+G12 -> 171172 | H13: =+H10+H11+H12 -> 178942 | I13: =+I10+I11+I12 -> 174851 | J13: =+J10+J11+J12 -> 182673 | ... T13: =+T10+T11+T12 -> 0 | AC13: =+AC10+AC11+AC12 -> 584067 | AD13: =+AD10+AD11+AD12 -> 707638 | AE13: =+AE10+AE11+AE12 -> 816824 | AF13: =+AF10+AF11+AF12 -> 731128.45 | AG13: =+AG10+AG11+AG12 -> 869494.4 | AH13: =+AH10+AH11+AH12 -> 908999.72 | AI13: =+AI10+AI11+AI12 -> 988844.29 | AJ13: =+AJ10+AJ11+AJ12 -> 974717.94 | ... AY13: =+AY10+AY11+AY12 -> 2557027.4
B14: Operating Profit/Loss | C14: =+C9-C13 -> -42873 | D14: =+D9-D13 -> -65302 | E14: =+E9-E13 -> -56962 | F14: =+F9-F13 -> -46274 | G14: =+G9-G13 -> -58233 | H14: =+H9-H13 -> -54057 | I14: =+I9-I13 -> -40267 | J14: =+J9-J13 -> -34883 | ... T14: =+T9-T13 -> 277000 | AC14: =AC9-AC13 -> -211411 | AD14: =AD9-AD13 -> -187440 | AE14: =AE9-AE13 -> -142715 | AF14: =AF9-AF13 -> 119020.91 | AG14: =AG9-AG13 -> 141545.6 | AH14: =AH9-AH13 -> 319378.28 | AI14: =AI9-AI13 -> 423790.41 | AJ14: =AJ9-AJ13 -> 649811.96 | ... AY14: =AY9-AY13 -> 1704684.9
B15: Interest Income | C15: 526 | D15: 3064 | E15: 4657 | F15: 6249 | G15: 7315 | H15: 9112 | I15: 10874 | J15: 11813 | K15: 12030 | L15: 12827 | M15: 12586 | N15: 10292 | O15: 10862 | P15: 11511 | Q15: 11704 | R15: 11630 | AC15: 14496 | AD15: 39114 | AE15: 47735
B16: Other Income | C16: 18448 | D16: 1500 | E16: 2661 | F16: -1024 | G16: 253 | H16: -1330 | I16: 569 | J16: -11451 | K16: -567 | L16: 1032 | M16: 4992 | N16: 4017 | O16: -9971 | P16: -911 | Q16: -6334 | R16: -6075 | AC16: 21621 | AD16: -12241 | AE16: 9187
B17: Pre Tax Income | C17: =+C14+C15+C16 -> -23899 | D17: =+D14+D15+D16 -> -60738 | E17: =+E14+E15+E16 -> -49644 | F17: =+F14+F15+F16 -> -41049 | G17: =+G14+G15+G16 -> -50665 | H17: =+H14+H15+H16 -> -46275 | I17: =+I14+I15+I16 -> -28824 | J17: =+J14+J15+J16 -> -34521 | ... T17: =+T14+T15+T16 -> 277000 | AC17: =+AC14+AC15+AC16 -> -175294 | AD17: =+AD14+AD15+AD16 -> -160567 | AE17: =+AE14+AE15+AE16 -> -85793 | AF17: =+(O50*0.04)+AF14 -> 163214.19 | AG17: =+($O$50*0.04)+AF14 -> 163214.19 | AH17: =+($O$50*0.04)+AG14 -> 185738.88 | AI17: =+($O$50*0.04)+AH14 -> 363571.56 | AJ17: =+($O$50*0.04)+AI14 -> 467983.69 | AK17: =+($O$50*0.04)+AJ14 -> 694005.24 | AL17: =+($O$50*0.04)+AK14 -> 758986.44 | AM17: =+($O$50*0.04)+AL14 -> 830465.75 | AN17: =+($O$50*0.04)+AM14 -> 909093 | ... AY17: =+($O$50*0.04)+AX14 -> 1667702.7
B18: Stake in Other Businesses | C18: -203 | D18: -816 | E18: -756 | F18: -693 | G18: -748 | H18: -917 | I18: -743 | J18: -1416 | K18: 0 | L18: 0 | M18: 0 | N18: 0 | O18: 0 | P18: 0 | Q18: 0 | R18: 0 | AC18: -2468 | AD18: -3824 | AE18: 0
B19: Taxes | C19: 2511 | D19: -57 | E19: 65 | F19: 379 | G19: 1486 | H19: 4016 | I19: 256788 | J19: 2035 | K19: 12710 | L19: -39420 | M19: -39421 | N19: -11344 | O19: 2539 | P19: 2245 | Q19: 1811 | R19: 3904 | AC19: 4030 | AD19: 265145 | AE19: -76674 | AF19: =+AF17*0.2 -> 32642.838 | AG19: =+AG17*0.2 -> 32642.838 | AH19: =+AH17*0.2 -> 37147.776 | AI19: =+AI17*0.2 -> 72714.312 | AJ19: =+AJ17*0.2 -> 93596.738 | AK19: =+AK17*0.2 -> 138801.05 | AL19: =+AL17*0.2 -> 151797.29 | AM19: =+AM17*0.2 -> 166093.15 | ... AY19: =+AY17*0.2 -> 333540.54
B20: Net Income/Loss | C20: =C17+C18-C19 -> -26613 | D20: =D17+D18-D19 -> -61497 | E20: =E17+E18-E19 -> -50465 | F20: =F17+F18-F19 -> -42121 | G20: =G17+G18-G19 -> -52899 | H20: =H17+H18-H19 -> -51208 | I20: =I17+I18-I19 -> -286355 | J20: =J17+J18-J19 -> -37972 | ... T20: =T17+T18-T19 -> 277000 | U20: -17000 | V20: -10200 | W20: -20440 | AC20: =AC17+AC18-AC19 -> -181792 | AD20: =AD17+AD18-AD19 -> -429536 | AE20: =AE17+AE18-AE19 -> -9119 | AF20: =+AF21*AF22 -> 129375 | AG20: =AG17-AG19 -> 130571.35 | AH20: =AH17-AH19 -> 148591.1 | AI20: =AI17-AI19 -> 290857.25 | AJ20: =AJ17-AJ19 -> 374386.95 | AK20: =AK17-AK19 -> 555204.19 | AL20: =AL17-AL19 -> 607189.15 | AM20: =AM17-AM19 -> 664372.6 | AN20: =AN17-AN19 -> 727274.4 | ... AY20: =AY17-AY19 -> 1334162.2 | AZ20: =AY20*(1+$BA$26) -> 1307478.9 | BA20: =AZ20*(1+$BA$26) -> 1281329.4 | BB20: =BA20*(1+$BA$26) -> 1255702.8 | BC20: =BB20*(1+$BA$26) -> 1230588.7 | BD20: =BC20*(1+$BA$26) -> 1205976.9 | BE20: =BD20*(1+$BA$26) -> 1181857.4 | BF20: =BE20*(1+$BA$26) -> 1158220.3 | BG20: =BF20*(1+$BA$26) -> 1135055.8 | ... WO20: =WN20*(1+$BA$26) -> 15.640951
B21: S/O | C21: 146643 | D21: 147797 | E21: 148883 | F21: 150133 | G21: 151692 | H21: 153644 | I21: 155123 | J21: 156601 | K21: 158157 | L21: 159677 | M21: 161317 | N21: 163055 | O21: 164491 | P21: 165953 | Q21: 167407 | R21: 169231 | AC21: 148407 | AD21: 154283 | AE21: 160580 | AF21: 172500
B22: EPS | C22: =+C20/C21 -> -0.18148156 | D22: =+D20/D21 -> -0.41609099 | E22: =+E20/E21 -> -0.33895744 | F22: =+F20/F21 -> -0.28055791 | G22: =+G20/G21 -> -0.34872637 | H22: =+H20/H21 -> -0.33328994 | I22: =+I20/I21 -> -1.8459867 | J22: =+J20/J21 -> -0.2424761 | ... T22: =+T20/T21 -> #DIV/0! | AC22: =AC20/AC21 -> -1.2249557 | AD22: =AD20/AD21 -> -2.7840786 | AE22: =AE20/AE21 -> -0.056787894 | AF22: 0.75
B23: Non-GAAP Net Income | H23: 1866 | I23: 14446 | J23: 25044 | K23: 4474 | L23: 24522 | M23: 39145 | N23: 56700 | O23: 29350 | P23: 40927 | Q23: 43518 | AD23: 32598 | AE23: 124841 | AF23: =+AF21*0.75 -> 129375
B24: Non-GAAP EPS | H24: =+H23/H21 -> 0.012144958 | I24: =+I23/I21 -> 0.0931261 | J24: =+J23/J21 -> 0.15992235 | K24: =+K23/K21 -> 0.028288346 | L24: =+L23/L21 -> 0.15357252 | M24: =+M23/M21 -> 0.24265886 | N24: =+N23/N21 -> 0.34773543 | O24: =+O23/O21 -> 0.17842921 | ... T24: =+T23/T21 -> #DIV/0! | AD24: =+AD23/AD21 -> 0.21128705 | AE24: =+AE23/AE21 -> 0.77743804
AZ26: Maturity | BA26: -0.02
B27: Gross Margin | C27: =+C9/C5 -> 0.88733168 | D27: =+D9/D5 -> 0.87104245 | E27: =+E9/E5 -> 0.87109337 | F27: =+F9/F5 -> 0.88415631 | G27: =+G9/G5 -> 0.89013856 | H27: =+H9/H5 -> 0.89471346 | I27: =+I9/I5 -> 0.89921693 | J27: =+J9/J5 -> 0.90237454 | ... R27: =+R9/R5 -> 0.86566155 | AC27: =+AC9/AC5 -> 0.87820972 | AD27: =+AD9/AD5 -> 0.89703849 | AE27: =+AE9/AE5 -> 0.88786288 | AZ27: Discount | BA27: 0.09
B28: Operating Margin | C28: =C14/C5 -> -0.49049847 | D28: =D14/D5 -> -0.6462921 | E28: =E14/E5 -> -0.50417327 | F28: =F14/F5 -> -0.37649605 | G28: =G14/G5 -> -0.45896846 | H28: =H14/H5 -> -0.3872805 | I28: =I14/I5 -> -0.26904215 | J28: =J14/J5 -> -0.21298823 | ... R28: =R14/R5 -> -0.019830877 | AC28: =AC14/AC5 -> -0.49821604 | AD28: =AD14/AD5 -> -0.3232248 | AE28: =AE14/AE5 -> -0.18796864 | AZ28: NPV | BA28: =NPV(BA27,AG20:WO20)+AF20+O50 -> 9209270.9
B29: Net Margin | C29: =+C20/C5 -> -0.30447218 | D29: =+D20/D5 -> -0.60863412 | E29: =+E20/E5 -> -0.44666802 | F29: =+F20/F5 -> -0.34270627 | G29: =+G20/G5 -> -0.41692807 | H29: =+H20/H5 -> -0.36686942 | I29: =+I20/I5 -> -1.913268 | J29: =+J20/J5 -> -0.23184902 | ... R29: =+R20/R5 -> -0.01349068 | AC29: =+AC20/AC5 -> -0.42841522 | AD29: =+AD20/AD5 -> -0.74069935 | AE29: =+AE20/AE5 -> -0.012010553 | AZ29: Share | BA29: =BA28/170000 -> 54.172182
B30: Effective Tax Rate | C30: =+C19/(C17+C18) -> -0.10418223 | D30: =+D19/(D17+D18) -> 0.00092601618 | E30: =+E19/(E17+E18) -> -0.0012896825 | F30: =+F19/(F17+F18) -> -0.0090795841 | G30: =+G19/(G17+G18) -> -0.028903196 | H30: =+H19/(H17+H18) -> -0.085099169 | I30: =+I19/(I17+I18) -> -8.6849528 | J30: =+J19/(J17+J18) -> -0.056626875 | ... R30: =+R19/(R17+R18) -> 9.9846547 | AC30: =+AC19/(AC17+AC18) -> -0.022670762 | AD30: =+AD19/(AD17+AD18) -> -1.6128924 | AE30: =+AE19/(AE17+AE18) -> 0.89370928 | AZ30: Current | BA30: 40.6
B31: S&M Margin | C31: =+(C10)/C9 -> 0.86011939 | D31: =+(D10)/D9 -> 0.91680585 | E31: =+(E10)/E9 -> 0.82384141 | F31: =+(F10)/F9 -> 0.75010353 | G31: =+(G10)/G9 -> 0.76622779 | H31: =+(H10)/H9 -> 0.7376066 | I31: =+(I10)/I9 -> 0.64627296 | J31: =+(J10)/J9 -> 0.61412815 | ... R31: =+(R10)/R9 -> 0.49942773 | AC31: =+(AC10)/AC9 -> 0.83184492 | AD31: =+(AD10)/AD9 -> 0.68511028 | AE31: =+(AE10)/AE9 -> 0.57007843 | AZ31: Return | BA31: =BA29/BA30-1 -> 0.33429019
B32: R&D Margin | C32: =+C11/C9 -> 0.41039725 | D32: =+D11/D9 -> 0.44903478 | E32: =+E11/E9 -> 0.41774287 | F32: =+F11/F9 -> 0.40195456 | G32: =+G11/G9 -> 0.44614349 | H32: =+H11/H9 -> 0.39241702 | I32: =+I11/I9 -> 0.36451584 | J32: =+J11/J9 -> 0.35447595 | ... R32: =+R11/R9 -> 0.30592228 | AC32: =+AC11/AC9 -> 0.41900036 | AD32: =+AD11/AD9 -> 0.38608376 | AE32: =+AE11/AE9 -> 0.35550927
B33: G&A Margin | C33: =+(C12)/C9 -> 0.28226254 | D33: =+(D12)/D9 -> 0.3761348 | E33: =+(E12)/E9 -> 0.33719784 | F33: =+(F12)/F9 -> 0.27376713 | G33: =+(G12)/G9 -> 0.30324334 | H33: =+(H12)/H9 -> 0.3028306 | I33: =+(I12)/I9 -> 0.28840724 | J33: =+(J12)/J9 -> 0.26742675 | ... R33: =+(R12)/R9 -> 0.21755834 | AC33: =+(AC12)/AC9 -> 0.31646344 | AD33: =+(AD12)/AD9 -> 0.28913029 | AE33: =+(AE12)/AE9 -> 0.28612138
B34: Interest Margin | C34: =+(C15+C16)/C14 -> -0.44256292 | D34: =+(D15+D16)/D14 -> -0.069890662 | E34: =+(E15+E16)/E14 -> -0.12847161 | F34: =+(F15+F16)/F14 -> -0.11291438 | G34: =+(G15+G16)/G14 -> -0.12996068 | H34: =+(H15+H16)/H14 -> -0.14395915 | I34: =+(I15+I16)/I14 -> -0.28417811 | J34: =+(J15+J16)/J14 -> -0.010377548 | ... R34: =+(R15+R16)/R14 -> -1.0757165 | AC34: =+(AC15+AC16)/AC14 -> -0.17083785 | AD34: =+(AD15+AD16)/AD14 -> -0.14336854 | AE34: =+(AE15+AE16)/AE14 -> -0.39885086
B35: Non-GAAP Net Margin | H35: =H23/H5 -> 0.013368582 | I35: =I23/I5 -> 0.096520298 | J35: =J23/J5 -> 0.15291338 | K35: =K23/K5 -> 0.026444112 | L35: =L23/L5 -> 0.13430531 | M35: =M23/M5 -> 0.19967151 | N35: =N23/N5 -> 0.2681726 | O35: =O23/O5 -> 0.1368241 | ... R35: =R23/R5 -> 0 | AD35: =+AD23/AD5 -> 0.056212559 | AE35: =+AE23/AE5 -> 0.16442695 | AF35: =+AF23/AF5 -> 0.13543944
B37: Revenue to S&M | C37: =C5/C10 -> 1.3102533 | D37: =D5/D10 -> 1.2522277 | E37: =E5/E10 -> 1.3934509 | F37: =F5/F10 -> 1.5078208 | G37: =G5/G10 -> 1.4661705 | H37: =H5/H10 -> 1.5152742 | I37: =I5/I10 -> 1.720757 | J37: =J5/J10 -> 1.8044887 | ... R37: =R5/R10 -> 2.3130191
B39: EV/Revenue | AC39: =[1]Main!$O$21*1000/AC5 -> 15.719871 | AD39: =[1]Main!$O$21*1000/AD5 -> 11.502738 | AE39: =[1]Main!$O$21*1000/AE5 -> 8.7856645
B41: S&M y/y | G41: =G10/C10-1 -> 0.29721181 | H41: =H10/D10-1 -> 0.14161782 | I41: =I10/E10-1 -> 0.07274297 | J41: =J10/F10-1 -> 0.11346656 | K41: =K10/G10-1 -> 0.068028704 | L41: =L10/H10-1 -> 0.061465978 | M41: =M10/I10-1 -> 0.096139254 | N41: =N10/J10-1 -> 0.088043454 | ... R41: =R10/N10-1 -> 0.14002613 | AD41: =AD10/AC10-1 -> 0.14968451 | AE41: =AE10/AD10-1 -> 0.078289978
B42: R&D y/y | G42: =G11/C11-1 -> 0.58300346 | H42: =H11/D11-1 -> 0.24005567 | I42: =I11/E11-1 -> 0.19324788 | J42: =J11/F11-1 -> 0.19935897 | K42: =K11/G11-1 -> 0.074483498 | L42: =L11/H11-1 -> 0.25029077 | M42: =M11/I11-1 -> 0.2506421 | N42: =N11/J11-1 -> 0.20037031 | ... R42: =R11/N11-1 -> 0.096620816 | AD42: =AD11/AC11-1 -> 0.28625683 | AE42: =AE11/AD11-1 -> 0.19324836
B43: G&A y/y | G43: =G12/C12-1 -> 0.56440709 | H43: =H12/D12-1 -> 0.14242992 | I43: =I12/E12-1 -> 0.16961972 | J43: =J12/F12-1 -> 0.3285042 | K43: =K12/G12-1 -> 0.67855057 | L43: =L12/H12-1 -> 0.14143684 | M43: =M12/I12-1 -> 0.18407832 | N43: =N12/J12-1 -> 0.072034006 | ... R43: =R12/N12-1 -> 0.15746991 | AD43: =AD12/AC12-1 -> 0.27535359 | AE43: =AE12/AD12-1 -> 0.28238423
B44: Operating Expenses y/y | G44: =G13/C13-1 -> 0.42131659 | H44: =H13/D13-1 -> 0.16716782 | I44: =I13/E13-1 -> 0.12531938 | J44: =J13/F13-1 -> 0.17896904 | K44: =K13/G13-1 -> 0.19208165 | L44: =L13/H13-1 -> 0.13008126 | M44: =M13/I13-1 -> 0.15900967 | N44: =N13/J13-1 -> 0.1167934 | ... R44: =R13/N13-1 -> 0.1302694
...

Sheet FA
C2: 2021 | D2: 2022 | E2: 2023 | F2: 2024 | G2: 2025 | H2: 2026 | I2: 2027
B3: Employees | C3: 1350 | D3: 1630 | E3: 2170 | F3: 2130 | G3: 2375
B4: Revenue | C4: 152180 | D4: 252653 | E4: =FS!AC5 -> 424336 | F4: =FS!AD5 -> 579906 | G4: =FS!AE5 -> 759249
B5: Revenue/Employee | C5: =C4/C3 -> 112.72593 | D5: =D4/D3 -> 155.00184 | E5: =E4/E3 -> 195.54654 | F5: =F4/F3 -> 272.25634 | G5: =G4/G3 -> 319.68379
B7: Employee Growth Rate | D7: =D3/C3-1 -> 0.20740741 | E7: =E3/D3-1 -> 0.33128834 | F7: =F3/E3-1 -> -0.01843318 | G7: =G3/F3-1 -> 0.11502347
B8: R/E y/y | D8: =D5/C5-1 -> 0.37503276 | E8: =E5/D5-1 -> 0.26157562 | F8: =F5/E5-1 -> 0.39228407 | G8: =G5/F5-1 -> 0.17420146
B13: ARR - Annual Recurring Revenue (Monthly recurring revenue ("MRR") multiplied by 12.)
B14: Customer base
C15: Q423 | D15: Q124 | E15: Q224 | F15: Q324 | G15: Q424 | H15: Q125 | I15: Q225 | J15: Q325 | K15: Q425 | L15: Q126 | M15: Q226 | N15: Q326 | O15: Q426
B16: $5,000+ ARR | C16: 7002 | D16: 7406 | E16: 7815 | F16: 8175 | G16: 8602 | H16: 8976 | I16: 9314 | J16: 9519 | K16: 9893 | L16: 10104 | M16: 10338 | N16: 10475 | O16: 10682
B17: $100,000+ ARR | C17: 697 | D17: 760 | E17: 810 | F17: 874 | G17: 955 | H17: 1025 | I17: 1076 | J17: 1144 | K17: 1229 | L17: 1288 | M17: 1344 | N17: 1405 | O17: 1456
B18: $1,000,000+ ARR | C18: 63 | G18: 96 | K18: 123 | O18: 155
B20: $5,000+ ARR q/q | D20: =D16/C16-1 -> 0.057697801 | E20: =E16/D16-1 -> 0.055225493 | F20: =F16/E16-1 -> 0.046065259 | G20: =G16/F16-1 -> 0.052232416 | H20: =H16/G16-1 -> 0.043478261 | I20: =I16/H16-1 -> 0.037655971 | J20: =J16/I16-1 -> 0.022009878 | K20: =K16/J16-1 -> 0.039289841 | ... O20: =O16/N16-1 -> 0.019761337
B21: $100,000+ ARR q/q | D21: =D17/C17-1 -> 0.090387374 | E21: =E17/D17-1 -> 0.065789474 | F21: =F17/E17-1 -> 0.079012346 | G21: =G17/F17-1 -> 0.092677346 | H21: =H17/G17-1 -> 0.073298429 | I21: =I17/H17-1 -> 0.049756098 | J21: =J17/I17-1 -> 0.063197026 | K21: =K17/J17-1 -> 0.074300699 | ... O21: =O17/N17-1 -> 0.036298932
B22: $1m y/y | G22: =G18/C18-1 -> 0.52380952 | K22: =K18/G18-1 -> 0.28125 | O22: =O18/K18-1 -> 0.2601626
B23: $5,000+ ARR y/y | G23: =G16/C16-1 -> 0.22850614 | H23: =H16/D16-1 -> 0.21199028 | I23: =I16/E16-1 -> 0.19181062 | J23: =J16/F16-1 -> 0.16440367 | K23: =K16/G16-1 -> 0.15008138 | L23: =L16/H16-1 -> 0.12566845 | M23: =M16/I16-1 -> 0.10994202 | N23: =N16/J16-1 -> 0.10043072 | O23: =O16/K16-1 -> 0.079753361
B24: $100,000+ ARR y/y | G24: =G17/C17-1 -> 0.37015782 | H24: =H17/D17-1 -> 0.34868421 | I24: =I17/E17-1 -> 0.32839506 | J24: =J17/F17-1 -> 0.30892449 | K24: =K17/G17-1 -> 0.28691099 | L24: =L17/H17-1 -> 0.25658537 | M24: =M17/I17-1 -> 0.24907063 | N24: =N17/J17-1 -> 0.22814685 | O24: =O17/K17-1 -> 0.18470301
A26: Total value of all future revenue from existing contracts that a company is obligated to fulfill
B27: RPO - Remaining Performance Obligation | L27: 955.1 | M27: 988.2 | N27: 1000 | O27: 1100
B28: cRPO - Current Remaining Performance Obligation | L28: 584.8 | M28: 621.6 | N28: 659.1 | O28: 719.4
B29: RPO QoQ | M29: =M27/L27-1 -> 0.034656057 | N29: =N27/M27-1 -> 0.011940903 | O29: =O27/N27-1 -> 0.1
B30: cRP QoQ | M30: =M28/L28-1 -> 0.062927497 | N30: =N28/M28-1 -> 0.060328185 | O30: =O28/N28-1 -> 0.091488393
B32: $ retention rate | O32: 1.18

Sheet Segments
B2: Metric | C2: Value (Date)
B3: Registered users (free-tier) | C3: >50 million (Apr 30, 2025)
B6: Company | C6: Headquarters | D6: Market Cap / Valuation | E6: Employees
B7: Sigma Defense | C7: Perry, GA, USA | D7: Private (Valuation N/A) | E7: 900
B8: CACI International | C8: Reston, VA, USA | D8: ~$10.15B (May 2025) (NASDAQ: CACI) | E8: 24000
B9: Southwest Airlines | C9: Dallas, TX, USA | D9: ~$18.07B (May 2025) (NYSE: LUV) | E9: 72,450 (2024)
B10: Nasdaq, Inc. | C10: New York, NY, USA | D10: ~$47.65B (May 2025) (Nasdaq: NDAQ) | E10: 9162
B11: Deutsche Telekom | C11: Bonn, Germany | D11: ~€166.5B (May 2025) (FWB: DTE) | E11: 199652
B12: Siemens AG | C12: Munich, Germany | D12: ~$196.2B (May 2025) (Xetra: SIE) | E12: 327000
B13: UBS Group AG | C13: Zurich, Switzerland | D13: ~$101.8B (as reported) (NYSE: UBS) | E13: 108648
B14: Hilti AG | C14: Schaan, Liechtenstein | D14: Private (family-owned) | E14: 32000
B15: Fujitsu Ltd | C15: Kawasaki, Kanagawa, Japan | D15: ~$41.04B (May 2025) (OTCM: FJTSY) | E15: 113000
B16: Fanatics, Inc. | C16: New York, NY, USA (inc. Jacksonville, FL) | D16: ~$31B (Dec 2023) (private) | E16: 22000
B17: Crédit Agricole SA | C17: Paris, France | D17: ~$56.34B (as reported) (EPA: ACA) | E17: 80518
B18: Airbus SE | C18: Toulouse, France | D18: ~$140.56B (May 2025) (EPA: AIR) | E18: 147,893 (2023)
B23: Feature Area | C23: GitHub | D23: GitLab | E23: Bitbucket (Atlassian)
B24: Deployment Model | C24: SaaS-first, then self-hosted (Enterprise) | D24: Self-hosted-first, then SaaS | E24: Primarily Cloud-based
B25: Open Source Status | C25: Not open-source (contributes to OSS) | D25: Fully open-source | E25: Not open-source
B26: Tech Stack | C26: Ruby on Rails + MySQL | D26: Ruby on Rails + Go + PostgreSQL | E26: Integrated with Atlassian suite (Jira, Confluence)
B27: Repository Management | C27: Pioneered forks & pull requests | D27: Merge requests, fork functionality | E27: Collaborative code repos, strong Jira integration
B28: CI/CD Capabilities | C28: GitHub Actions (strong 3rd-party ecosystem, more runtime envs) | D28: Pioneered built-in CI/CD & Auto DevOps (multi-project pipelines, canary deployments) | E28: Bitbucket Pipelines, robust automation with Jira
B29: Security | C29: Advanced Security (CodeQL, code/secret scanning) | D29: Pioneered DevSecOps (SAST, DAST, Dependency/Secret/IaC Scanning, Fuzz Testing) | E29: Integrates with security tools (e.g., Snyk)
B30: Project Management | C30: Projects & Issues (many prefer Jira) | D30: Issues, Epics, Boards (developer-centric) | E30: Jira (leading specialized tool)
B31: AI Capabilities | C31: GitHub Copilot (code suggestions, faster task completion) | D31: GitLab Duo (code suggestions, chat, vulnerability explanations, CI/CD troubleshooting) | E31: Rovo (new AI for teamwork)

Sheet Comp.
AZ1: In millions
AZ2: Q2FY26 R Cons. | BA2: 227 | BC2: FY26 R Cons. | BD2: 942
AZ3: Actual | BA3: 236 | BC3: Actual | BD3: 942
AZ4: Beat | BA4: =BA3/BA2-1 -> 0.039647577 | BC4: Beat | BD4: =BD3/BD2-1 -> 0
AZ5: Q2FY26 EPS Cons. | BA5: 0.17 | BC5: FY26 EPS Cons. | BD5: 0.75
G6: TEAM | H6: Q122 | I6: Q222 | J6: Q322 | K6: Q422 | L6: Q123 | M6: Q223 | N6: Q323 | O6: Q423 | P6: Q124 | Q6: Q224 | R6: Q324 | S6: Q424 | T6: Q125 | U6: Q225 | V6: Q325 | W6: Q425 | AA6: Q324 | AB6: Q325 | AC6: % | AE6: Q424 | AF6: Q425 | AG6: % | AH6: Guidance | AI6: % | AJ6: Beat | AM6: R | AN6: EPS | AQ6: Q126 | AT6: FY22 | AU6: FY23 | AV6: FY24 | AW6: FY25 | AX6: FY26 | AZ6: Actual | BA6: 0.24 | BC6: Actual | BD6: 0.83
G7: Revenue | H7: 614 | I7: 688.5 | J7: 740.5 | K7: 759.8 | L7: 807.4 | M7: 872.7 | N7: 915.5 | O7: 939.1 | P7: 977.8 | Q7: 1060.1 | R7: 1189.1 | S7: 1131.6 | T7: 1187.8 | U7: 1286.5 | V7: 1356.7 | W7: 1384.344 | Z7: Cloud | AA7: 703036 | AB7: 880429 | AC7: =AB7/AA7-1 -> 0.25232421 | AE7: 738006 | AF7: 927730 | AG7: =AF7/AE7-1 -> 0.2570765 | AH7: =AE7*1.23 -> 907747.38 | AI7: =AH7/AE7-1 -> 0.23 | AJ7: =AF7/AH7-1 -> 0.022013415 | AL7: Proj. | AM7: 1359 | AN7: 0.83 | AP7: Guidance | AQ7: 1395-1403 | AT7: =SUM(H7:K7) -> 2802.8 | AU7: =SUM(L7:O7) -> 3534.7 | AV7: =SUM(P7:S7) -> 4358.6 | AW7: =SUM(T7:W7) -> 5215.344 | AX7: =AW7*1.18 -> 6154.1059 | AZ7: Beat | BA7: =BA6/BA5-1 -> 0.41176471 | BC7: Beat | BD7: =BD6/BD5-1 -> 0.10666667
G8: COGS | H8: 96.3 | I8: 110.2 | J8: 116.1 | K8: 130.4 | L8: 139.4 | M8: 155.9 | N8: 168.7 | O8: 169.8 | P8: 178 | Q8: 194.5 | R8: 213.4 | S8: 217.5 | T8: 217.6 | U8: 223.1 | V8: 219.7 | Z8: DataCenter | AA8: 364134 | AB8: 388516 | AC8: =AB8/AA8-1 -> 0.066958867 | AE8: 326663 | AF8: 380776 | AG8: =AF8/AE8-1 -> 0.1656539 | AH8: =+AE8*1.165 -> 380562.4 | AI8: =AH8/AE8-1 -> 0.165 | AJ8: =AF8/AH8-1 -> 0.00056128772 | AL8: Act. | AM8: 1384.344 | AP8: Prev. Guidance | AQ8: 1410 | AZ8: Q2FY26 OpInc Cons. | BA8: 24 | BC8: FY26 OpInc Cons. | BD8: 121
G9: Gross Profit | H9: 517.8 | I9: 578.3 | J9: 624.4 | K9: 629.4 | L9: 668 | M9: 716.8 | N9: 746.8 | O9: 769.3 | P9: 799.7 | Q9: 865.6 | R9: 975.7 | S9: 914.1 | T9: 970.2 | U9: 1063.3 | V9: 1137 | Z9: Server | AA9: 29720 | AC9: =AB9/AA9-1 -> -1 | AU9: =AU7/AT7-1 -> 0.26113173 | AV9: =AV7/AU7-1 -> 0.23308909 | AW9: =AW7/AV7-1 -> 0.19656403 | AX9: =AX7/AW7-1 -> 0.18 | AZ9: Actual | BA9: 39.6 | BC9: Actual | BD9: 136
G10: SG&A Expense | H10: 89.8 | I10: 115.7 | J10: 115 | K10: 131.7 | L10: 142.9 | M10: 156.1 | N10: 165.1 | O10: 142.2 | P10: 143.3 | Q10: 157.3 | R10: 157.6 | S10: 152.3 | T10: 146.6 | U10: 168.7 | V10: 168.3 | Z10: Marketplance | AA10: 92238 | AB10: 87771 | AC10: =AB10/AA10-1 -> -0.048429064 | AE10: 66921 | AF10: 75838 | AG10: =AF10/AE10-1 -> 0.13324666 | AH10: =+AE10*1 -> 66921 | AI10: =AH10/AE10-1 -> 0 | AJ10: =AF10/AH10-1 -> 0.13324666 | AL10: Beat | AM10: =AM8/AM7-1 -> 0.018649007 | AN10: =AN8/AN7-1 -> -1 | AZ10: Beat | BA10: =BA9/BA8-1 -> 0.65 | BC10: Beat | BD10: =BD9/BD8-1 -> 0.12396694
G11: Net Income | H11: -411.2 | I11: -22.3 | J11: 4.7 | K11: -90.6 | L11: -13.7 | M11: -205 | N11: -209 | O11: -59 | P11: -31.9 | Q11: -84.5 | R11: 12.8 | S11: -196.9 | T11: -123.8 | U11: -38.2 | V11: -70.8 | W11: -60.4 | Z11: Total | AA11: =SUM(AA7:AA10) -> 1189128 | AB11: =SUM(AB7:AB10) -> 1356716 | AC11: =AB11/AA11-1 -> 0.14093352 | AE11: =SUM(AE7:AE10) -> 1131590 | AF11: =SUM(AF7:AF10) -> 1384344 | AG11: =AF11/AE11-1 -> 0.22336182 | AH11: =AE11*1.19 -> 1346592.1 | AI11: =AH11/AE11-1 -> 0.19 | AJ11: =AF11/AH11-1 -> 0.028035141 | AZ11: Q3FY26 R Guid. Cons. | BA11: 241
G12: EPS | T12: -0.48 | U12: -0.15 | V12: -0.27 | AZ12: Actual | BA12: 239
AZ13: Beat | BA13: =BA12/BA11-1 -> -0.0082987552
G14: Revenue to SG&A | H14: =H7/H10 -> 6.8374165 | I14: =I7/I10 -> 5.9507347 | J14: =J7/J10 -> 6.4391304 | K14: =K7/K10 -> 5.7691724 | L14: =L7/L10 -> 5.650105 | M14: =M7/M10 -> 5.590647 | N14: =N7/N10 -> 5.5451242 | O14: =O7/O10 -> 6.6040788 | ... V14: =V7/V10 -> 8.0612002 | AZ14: Q3FY26 EPS Guid. Cons | BA14: 0.19
AZ15: Actual | BA15: 0.2
G16: R Y/Y | L16: =L7/H7-1 -> 0.31498371 | M16: =M7/I7-1 -> 0.26753813 | N16: =N7/J7-1 -> 0.23632681 | O16: =O7/K7-1 -> 0.23598315 | P16: =P7/L7-1 -> 0.21104781 | Q16: =Q7/M7-1 -> 0.21473588 | R16: =R7/N7-1 -> 0.29885309 | S16: =S7/O7-1 -> 0.20498349 | ... W16: =W7/S7-1 -> 0.22335101 | AZ16: Beat | BA16: =BA15/BA14-1 -> 0.052631579
G17: R Q/Q | I17: =I7/H7-1 -> 0.1213355 | J17: =J7/I7-1 -> 0.075526507 | K17: =K7/J7-1 -> 0.026063471 | L17: =L7/K7-1 -> 0.062648065 | M17: =M7/L7-1 -> 0.080876889 | N17: =N7/M7-1 -> 0.049043199 | O17: =O7/N7-1 -> 0.025778263 | P17: =P7/O7-1 -> 0.041209669 | ... W17: =W7/V7-1 -> 0.020375912 | AZ17: Q3FY26 OpInc Cons. | BA17: 30
G18: NI Y/Y | L18: =L11/H11-1 -> -0.96668288 | M18: =M11/I11-1 -> 8.1928251 | N18: =N11/J11-1 -> -45.468085 | O18: =O11/K11-1 -> -0.34878587 | P18: =P11/L11-1 -> 1.3284672 | Q18: =Q11/M11-1 -> -0.58780488 | R18: =R11/N11-1 -> -1.061244 | S18: =S11/O11-1 -> 2.3372881 | ... W18: =W11/S11-1 -> -0.6932453 | AZ18: Actual | BA18: 32
G19: NI Q/Q | I19: =I11/H11-1 -> -0.94576848 | J19: =J11/I11-1 -> -1.2107623 | K19: =K11/J11-1 -> -20.276596 | L19: =L11/K11-1 -> -0.84878587 | M19: =M11/L11-1 -> 13.963504 | N19: =N11/M11-1 -> 0.019512195 | O19: =O11/N11-1 -> -0.71770335 | P19: =P11/O11-1 -> -0.45932203 | ... W19: =W11/V11-1 -> -0.14689266 | AZ19: Beat | BA19: =BA18/BA17-1 -> 0.066666667
G22: PEGA | H22: Q210 | I22: Q310 | J22: Q111 | K22: Q211 | L22: Q311 | M22: Q411 | N22: Q112 | O22: Q212 | P22: Q312 | Q22: Q412 | R22: Q113 | S22: Q213 | T22: Q313 | U22: Q413 | V22: Q114 | W22: Q214 | X22: Q314 | Y22: Q414 | Z22: Q115 | AA22: Q215 | AB22: Q315 | AC22: Q415 | AD22: Q116 | AE22: Q216 | AF22: Q316 | AG22: Q416 | AH22: Q117 | AI22: Q217 | AJ22: Q317 | AK22: Q417 | AL22: Q118 | AM22: Q218 | AN22: Q318 | AO22: Q418 | AP22: Q119 | AQ22: Q219 | AR22: Q319 | AS22: Q419 | AT22: Q120 | AU22: Q220 | AV22: Q320 | AW22: Q420 | AX22: Q121 | AY22: Q221 | AZ22: Q321 | BA22: Q421 | BB22: Q122 | BC22: Q222 | BD22: Q322 | BE22: Q422 | BF22: Q123 | BG22: Q223 | BH22: Q323 | BI22: Q423 | BJ22: Q124 | BK22: Q224 | BL22: Q324 | BM22: Q424 | BN22: Q125 | BO22: Q225
G23: Revenue | H23: 82.2 | I23: 90 | J23: 102.4 | K23: 103.5 | L23: 95.5 | M23: 115.3 | N23: 111.2 | O23: 105.1 | P23: 101.7 | Q23: 143.8 | R23: 116.2 | S23: 117.3 | T23: 122 | U23: 153.4 | V23: 140.5 | W23: 143 | X23: 137.6 | Y23: 168.9 | Z23: 153.9 | AA23: 162 | AB23: 162.4 | AC23: 204.4 | AD23: 178.9 | AE23: 189 | AF23: 182.8 | AG23: 211.6 | AH23: 256.3 | AI23: 186.6 | AJ23: 191 | AK23: 254.6 | AL23: 235.2 | AM23: 196.8 | AN23: 203.3 | AO23: 256.4 | AP23: 212.5 | AQ23: 205.6 | AR23: 216.7 | AS23: 276.5 | AT23: 265.6 | AU23: 227.4 | AV23: 226 | AW23: 298.6 | AX23: 313.5 | AY23: 325.7 | AZ23: 256.3 | BA23: 316.2 | BB23: 376.3 | BC23: 274.3 | BD23: 270.7 | BE23: 396.5 | BF23: 325.5 | BG23: 298.3 | BH23: 334.6 | BI23: 474.2 | BJ23: 330.1 | BK23: 351.2 | BL23: 325 | BM23: 490.8 | BN23: 475.6 | BO23: 384.5
G24: COGS | H24: 31.3 | I24: 35 | J24: 40 | K24: 40.4 | L24: 41.8 | M24: 42.6 | N24: 41.5 | O24: 40 | P24: 37.7 | Q24: 38.2 | R24: 37.7 | S24: 37.9 | T24: 38.1 | U24: 43.8 | V24: 45.9 | W24: 46.7 | X24: 46.4 | Y24: 46.1 | Z24: 50.1 | AA24: 54.8 | AB24: 55.4 | AC24: 53.2 | AD24: 56.5 | AE24: 60.1 | AF24: 60.4 | AG24: 62.2 | AH24: 68.1 | AI24: 0 | AJ24: 0 | AK24: 211.6 | AL24: 75.6 | AM24: 73.8 | AN24: 74.4 | AO24: 77.9 | AP24: 74.4 | AQ24: 77.1 | AR24: 80.9 | AS24: 77.6 | AT24: 79.5 | AU24: 76.7 | AV24: 77.8 | AW24: 76.9 | AX24: 82.4 | AY24: 84.5 | AZ24: 84.2 | BA24: 85.2 | BB24: 88.2 | BC24: 95.1 | BD24: 93 | BE24: 92.3 | BF24: 97.9 | BG24: 96.1 | BH24: 93.8 | BI24: 90.6 | BJ24: 94.7 | BK24: 96.9 | BL24: 96.7 | BM24: 102.4 | BN24: 102.4 | BO24: 109.6
G25: Gross Profit | H25: 51 | I25: 55 | J25: 62.3 | K25: 63.1 | L25: 53.7 | M25: 72.7 | N25: 69.6 | O25: 65.1 | P25: 64 | Q25: 105.6 | R25: 78.6 | S25: 79.4 | T25: 83.9 | U25: 109.6 | V25: 94.6 | W25: 96.3 | X25: 91.2 | Y25: 122.8 | Z25: 103.9 | AA25: 107.2 | AB25: 107 | AC25: 151.2 | AD25: 122.3 | AE25: 128.9 | AF25: 122.4 | AG25: 149.4 | AH25: 188.2 | AI25: 186.6 | AJ25: 191 | AK25: 43 | AL25: 159.6 | AM25: 123 | AN25: 128.8 | AO25: 178.4 | AP25: 138.1 | AQ25: 128.5 | AR25: 135.8 | AS25: 198.9 | AT25: 186.1 | AU25: 150.7 | AV25: 148.2 | AW25: 221.7 | AX25: 231.1 | AY25: 241.2 | AZ25: 172 | BA25: 231 | BB25: 288.1 | BC25: 179.2 | BD25: 177.7 | BE25: 304.2 | BF25: 227.5 | BG25: 202.1 | BH25: 240.9 | BI25: 383.6 | BJ25: 235.5 | BK25: 254.2 | BL25: 228.3 | BM25: 388.5 | BN25: 373.2 | BO25: 274.9
G26: SG&A Expense | H26: 6.7 | I26: 6.4 | J26: 7.1 | K26: 6.8 | L26: 7.2 | M26: 7 | N26: 6.3 | O26: 7.7 | P26: 7.2 | Q26: 7.7 | R26: 6.8 | S26: 7.3 | T26: 7.1 | U26: 8.4 | V26: 9.3 | W26: 10.2 | X26: 8.8 | Y26: 9.1 | Z26: 6.3 | AA26: 10.2 | AB26: 9.6 | AC26: 10.6 | AD26: 11 | AE26: 11.3 | AF26: 11.7 | AG26: 11.9 | AH26: 12.3 | AI26: 12.7 | AJ26: 13.1 | AK26: 14 | AL26: 16.5 | AM26: 10.2 | AN26: 12.1 | AO26: 12.9 | AP26: 12.7 | AQ26: 14.2 | AR26: 14.8 | AS26: 14.9 | AT26: 15.6 | AU26: 15.7 | AV26: 17.9 | AW26: 18.3 | AX26: 18.3 | AY26: 19.2 | AZ26: 20.2 | BA26: 25.9 | BB26: 35.8 | BC26: 32.7 | BD26: 26 | BE26: 23.2 | BF26: 23.1 | BG26: 23.5 | BH26: 27.3 | BI26: 22.8 | BJ26: 23.5 | BK26: 25.4 | BL26: 35.7 | BM26: 28.2 | BN26: 33.8 | BO26: 31.8
G28: Revenue to SG&A | H28: =H23/H26 -> 12.268657 | I28: =I23/I26 -> 14.0625 | J28: =J23/J26 -> 14.422535 | K28: =K23/K26 -> 15.220588 | L28: =L23/L26 -> 13.263889 | M28: =M23/M26 -> 16.471429 | N28: =N23/N26 -> 17.650794 | O28: =O23/O26 -> 13.649351 | ... BO28: =BO23/BO26 -> 12.091195

Sheet Sentiment
F23: 01.01.2015-06.06.2025 | O23: 06.06.2025-07.28.2025
B24: Company | C24: Avg_Sentiment | D24: Std_Sentiment | E24: Min_Sentiment | F24: Max_Sentiment | G24: Latest_SMA7 | H24: Latest_SMA30 | I24: Latest_SMA100 | J24: Total_Posts | K24: Avg_Daily_Posts | L24: Days_Analyzed | O24: Company | P24: Avg_Sentiment | Q24: Std_Sentiment | R24: Min_Sentiment | S24: Max_Sentiment | T24: Latest_SMA7 | U24: Latest_SMA30 | V24: Latest_SMA100 | W24: Total_Posts | X24: Avg_Daily_Posts | Y24: Days_Analyzed
B25: GitLab | C25: 0.535 | D25: 0.5535 | E25: -0.9986 | F25: 1 | G25: 0.6645 | H25: 0.4223 | I25: 0.5124 | J25: 1739 | K25: 2.422 | L25: 718 | O25: GitLab | P25: 0.5958 | Q25: 0.3447 | R25: -0.3211 | S25: 0.9966 | T25: 0.6202 | U25: 0.6585 | V25: 0.5958 | W25: 212 | X25: 4.24 | Y25: 50
