Workbook

Sheet Main
A1: SaaS
I10: P | J10: 661.8 | K10: 45896
I11: S/O | J11: =Model!AI31 -> 279
I12: MC | J12: =+J10*J11 -> 184642.2
I13: C | J13: =Model!R70+Model!R71+Model!R77 -> 4646 | K13: Q4FY25
I14: D | J14: =Model!R85+Model!R91 -> 5973 | K14: Q4FY25
I16: EV | J16: =J12-J13+J14 -> 185969.2
I18: P/E | J18: =J12/Model!AI30 -> 47.723494
I19: EV/E | J19: =J16/Model!AI30 -> 48.066477
I20: P/S | J20: =J12/Model!AI13 -> 9.8052254
I21: EV/S | J21: =J16/Model!AI13 -> 9.8756943
I22: Fwd FY26 P/E | J22: =$J$12/Model!AJ30 -> 41.731012
I23: Fwd FY26 P/S | J23: =$J$16/Model!AJ13 -> 8.7779288
I24: Fwd FY27 P/E | J24: =$J$12/Model!AK30 -> 34.772542
I25: Fwd FY27 P/S | J25: =$J$16/Model!AK13 -> 7.8072712

Sheet Model
A1: Main | R1: 45869
C2: Q1FY22 | D2: Q2FY22 | E2: Q3FY22 | F2: Q4FY22 | G2: Q1FY23 | H2: Q2FY23 | I2: Q3FY23 | J2: Q4FY23 | K2: Q1FY24 | L2: Q2FY24 | M2: Q3FY24 | N2: Q4FY24 | O2: Q1FY25 | P2: Q2FY25 | Q2: Q3FY25 | R2: Q4FY25 | S2: Q1FY26 | T2: Q2FY26 | U2: Q3FY26 | V2: Q4FY26 | W2: Q1FY27 | X2: Q2FY27 | Y2: Q3FY27 | Z2: Q4FY27 | AE2: FY21 | AF2: FY22 | AG2: FY23 | AH2: FY24 | AI2: FY25 | AJ2: FY26 | AK2: FY27 | AL2: FY28 | AM2: FY29 | AN2: FY30 | AO2: FY31 | AP2: FY32 | AQ2: FY33 | AR2: FY34 | AS2: FY35 | AT2: FY36 | AU2: FY37 | AV2: FY38 | AW2: FY39 | AX2: FY40 | AY2: FY41 | AZ2: FY42 | BA2: FY43 | BB2: FY44 | BC2: FY45
B3: QuickBooks Online Accounting | G3: 668 | H3: 696 | I3: 723 | J3: 762 | K3: 798 | L3: 826 | M3: 860 | N3: 895 | O3: 965 | P3: 1008 | Q3: 1044 | R3: 1103 | AG3: 2849 | AH3: 3379 | AI3: 4120
B4: Online Services | G4: 681 | H4: 695 | I4: 745 | J4: 789 | K4: 820 | L4: 862 | M4: 894 | N4: 937 | O4: 978 | P4: 1030 | Q4: 1059 | R4: 1115 | AG4: 2910 | AH4: 3513 | AI4: 4182
B5: Total Online Ecosystem | C5: =SUM(C3:C4) -> 0 | D5: =SUM(D3:D4) -> 0 | E5: =SUM(E3:E4) -> 0 | F5: =SUM(F3:F4) -> 0 | G5: =SUM(G3:G4) -> 1349 | H5: =SUM(H3:H4) -> 1391 | I5: =SUM(I3:I4) -> 1468 | J5: =SUM(J3:J4) -> 1551 | ... S5: =SUM(S3:S4) -> 0 | AE5: =SUM(AE3:AE4) -> 0 | AF5: =SUM(AF3:AF4) -> 0 | AG5: =SUM(AG3:AG4) -> 5759 | AH5: =SUM(AH3:AH4) -> 6892 | AI5: =SUM(AI3:AI4) -> 8302
B6: QuickBooks Desktop Accounting | G6: 375 | H6: 228 | I6: 292 | J6: 316 | K6: 467 | L6: 291 | M6: 363 | N6: 454 | O6: 329 | P6: 355 | Q6: 476 | R6: 512 | AG6: 1211 | AH6: 1575 | AI6: 1672
B7: Desktop Services and Supplies | G7: 264 | H7: 278 | I7: 261 | J7: 265 | K7: 259 | L7: 266 | M7: 270 | N7: 271 | O7: 272 | P7: 278 | Q7: 270 | R7: 283 | AG7: 1068 | AH7: 1066 | AI7: 1103
B8: Total Desktop Ecosystem | C8: =SUM(C6:C7) -> 0 | D8: =SUM(D6:D7) -> 0 | E8: =SUM(E6:E7) -> 0 | F8: =SUM(F6:F7) -> 0 | G8: =SUM(G6:G7) -> 639 | H8: =SUM(H6:H7) -> 506 | I8: =SUM(I6:I7) -> 553 | J8: =SUM(J6:J7) -> 581 | ... S8: =SUM(S6:S7) -> 0 | AE8: =SUM(AE6:AE7) -> 0 | AF8: =SUM(AF6:AF7) -> 0 | AG8: =SUM(AG6:AG7) -> 2279 | AH8: =SUM(AH6:AH7) -> 2641 | AI8: =SUM(AI6:AI7) -> 2775
B9: Global Business Solutions | C9: =C5+C8 -> 0 | D9: =D5+D8 -> 0 | E9: =E5+E8 -> 0 | F9: =F5+F8 -> 0 | G9: =G5+G8 -> 1988 | H9: =H5+H8 -> 1897 | I9: =I5+I8 -> 2021 | J9: =J5+J8 -> 2132 | ... S9: =S5+S8 -> 0 | AE9: =AE5+AE8 -> 0 | AF9: =AF5+AF8 -> 0 | AG9: =AG5+AG8 -> 8038 | AH9: =AH5+AH8 -> 9533 | AI9: =AI5+AI8 -> 11077
B10: Consumer | G10: 150 | H10: 516 | I10: 3341 | J10: 128 | K10: 187 | L10: 492 | M10: 3653 | N10: 113 | O10: 176 | P10: 509 | Q10: 4048 | R10: 137 | AG10: 4135 | AH10: 4445 | AI10: 4870
B11: Credit Karma | G11: 425 | H11: 375 | I11: 410 | J11: 424 | K11: 405 | L11: 375 | M11: 443 | N11: 485 | O11: 524 | P11: 511 | Q11: 579 | R11: 649 | AG11: 1634 | AH11: 1708 | AI11: 2263
B12: ProTax | G12: 34 | H12: 253 | I12: 246 | J12: 28 | K12: 42 | L12: 274 | M12: 254 | N12: 29 | O12: 39 | P12: 272 | Q12: 278 | R12: 32 | AG12: 561 | AH12: 599 | AI12: 621
B13: Total Revenues | C13: =SUM(C9:C12) -> 0 | D13: =SUM(D9:D12) -> 0 | E13: =SUM(E9:E12) -> 0 | F13: =SUM(F9:F12) -> 0 | G13: =SUM(G9:G12) -> 2597 | H13: =SUM(H9:H12) -> 3041 | I13: =SUM(I9:I12) -> 6018 | J13: =SUM(J9:J12) -> 2712 | ... S13: =SUM(S9:S12) -> 0 | AE13: =SUM(AE9:AE12) -> 0 | AF13: =SUM(AF9:AF12) -> 0 | AG13: =SUM(AG9:AG12) -> 14368 | AH13: =SUM(AH9:AH12) -> 16285 | AI13: =SUM(AI9:AI12) -> 18831 | AJ13: 21186 | AK13: 23820
B14: Service costs | N14: 733 | R14: 834 | AH14: 3250 | AI14: 3624
B15: Product costs | N15: 14 | R15: 16 | AH15: 69 | AI15: 68
B16: COGS | C16: =SUM(C14:C15) -> 0 | D16: =SUM(D14:D15) -> 0 | E16: =SUM(E14:E15) -> 0 | F16: =SUM(F14:F15) -> 0 | G16: =SUM(G14:G15) -> 0 | H16: =SUM(H14:H15) -> 0 | I16: =SUM(I14:I15) -> 0 | J16: =SUM(J14:J15) -> 0 | ... S16: =SUM(S14:S15) -> 0 | AE16: =SUM(AE14:AE15) -> 0 | AF16: =SUM(AF14:AF15) -> 0 | AG16: =SUM(AG14:AG15) -> 0 | AH16: =SUM(AH14:AH15) -> 3319 | AI16: =SUM(AI14:AI15) -> 3692
B17: Gross Profit | C17: =C13-C16 -> 0 | D17: =D13-D16 -> 0 | E17: =E13-E16 -> 0 | F17: =F13-F16 -> 0 | G17: =G13-G16 -> 2597 | H17: =H13-H16 -> 3041 | I17: =I13-I16 -> 6018 | J17: =J13-J16 -> 2712 | ... S17: =S13-S16 -> 0 | AE17: =AE13-AE16 -> 0 | AF17: =AF13-AF16 -> 0 | AG17: =AG13-AG16 -> 14368 | AH17: =AH13-AH16 -> 12966 | AI17: =AI13-AI16 -> 15139
B18: Amortization on acquisitions | N18: 36 | R18: 44 | AH18: 146 | AI18: 156
B19: S&M | N19: 1104 | R19: 1251 | AH19: 4312 | AI19: 5035
B20: R&D | N20: 725 | R20: 801 | AH20: 2754 | AI20: 2928
B21: G&A | N21: 377 | R21: 424 | AH21: 1418 | AI21: 1601
B22: Amortization on intangibles | N22: 123 | R22: 121 | AH22: 483 | AI22: 481
B23: Restructuring | N23: 223 | R23: 1 | AH23: 223 | AI23: 15
B24: OpEx | C24: =SUM(C18:C23) -> 0 | D24: =SUM(D18:D23) -> 0 | E24: =SUM(E18:E23) -> 0 | F24: =SUM(F18:F23) -> 0 | G24: =SUM(G18:G23) -> 0 | H24: =SUM(H18:H23) -> 0 | I24: =SUM(I18:I23) -> 0 | J24: =SUM(J18:J23) -> 0 | ... S24: =SUM(S18:S23) -> 0 | AE24: =SUM(AE18:AE23) -> 0 | AF24: =SUM(AF18:AF23) -> 0 | AG24: =SUM(AG18:AG23) -> 0 | AH24: =SUM(AH18:AH23) -> 9336 | AI24: =SUM(AI18:AI23) -> 10216
B25: OpInc | C25: =C17-C24 -> 0 | D25: =D17-D24 -> 0 | E25: =E17-E24 -> 0 | F25: =F17-F24 -> 0 | G25: =G17-G24 -> 2597 | H25: =H17-H24 -> 3041 | I25: =I17-I24 -> 6018 | J25: =J17-J24 -> 2712 | ... S25: =S17-S24 -> 0 | AE25: =AE17-AE24 -> 0 | AF25: =AF17-AF24 -> 0 | AG25: =AG17-AG24 -> 14368 | AH25: =AH17-AH24 -> 3630 | AI25: =AI17-AI24 -> 4923
B26: Interest expense | G26: -49 | H26: -65 | I26: -66 | J26: -68 | K26: -65 | L26: -57 | M26: -60 | N26: -60 | O26: -60 | P26: -60 | Q26: -68 | R26: -59 | AG26: -248 | AH26: -242 | AI26: -247
B27: Interest income | G27: 5 | H27: 23 | I27: 22 | J27: 46 | K27: 22 | L27: 42 | M27: 27 | N27: 71 | O27: 2 | P27: 38 | Q27: 32 | R27: 86 | AG27: 96 | AH27: 162 | AI27: 158
B28: Pretax Income | C28: =C25+C26+C27 -> 0 | D28: =D25+D26+D27 -> 0 | E28: =E25+E26+E27 -> 0 | F28: =F25+F26+F27 -> 0 | G28: =G25+G26+G27 -> 2553 | H28: =H25+H26+H27 -> 2999 | I28: =I25+I26+I27 -> 5974 | J28: =J25+J26+J27 -> 2690 | ... S28: =S25+S26+S27 -> 0 | AE28: =AE25+AE26+AE27 -> 0 | AF28: =AF25+AF26+AF27 -> 0 | AG28: =AG25+AG26+AG27 -> 14216 | AH28: =AH25+AH26+AH27 -> 3550 | AI28: =AI25+AI26+AI27 -> 4834
B29: Taxes | N29: -120 | R29: -15 | AH29: 587 | AI29: 965
B30: Net Income | C30: =+C28-C29 -> 0 | D30: =+D28-D29 -> 0 | E30: =+E28-E29 -> 0 | F30: =+F28-F29 -> 0 | G30: =+G28-G29 -> 2553 | H30: =+H28-H29 -> 2999 | I30: =+I28-I29 -> 5974 | J30: =+J28-J29 -> 2690 | ... S30: =+S28-S29 -> 0 | AE30: =+AE28-AE29 -> 0 | AF30: =+AF28-AF29 -> 0 | AG30: =+AG28-AG29 -> 14216 | AH30: =+AH28-AH29 -> 2963 | AI30: =+AI28-AI29 -> 3869 | AJ30: 4424.58 | AK30: 5310
B31: S/O | G31: 281 | H31: 281 | I31: 281 | J31: 280 | K31: 280 | L31: 280 | M31: 280 | N31: 280 | O31: 280 | P31: 280 | Q31: 280 | R31: 279 | AG31: 281 | AH31: 280 | AI31: 279 | AJ31: 279 | AK31: 279
B32: EPS | C32: =+C30/C31 -> #DIV/0! | D32: =+D30/D31 -> #DIV/0! | E32: =+E30/E31 -> #DIV/0! | F32: =+F30/F31 -> #DIV/0! | G32: =+G30/G31 -> 9.0854093 | H32: =+H30/H31 -> 10.672598 | I32: =+I30/I31 -> 21.259786 | J32: =+J30/J31 -> 9.6071429 | ... S32: =+S30/S31 -> #DIV/0! | AE32: =+AE30/AE31 -> #DIV/0! | AF32: =+AF30/AF31 -> #DIV/0! | AG32: =+AG30/AG31 -> 50.590747 | AH32: =+AH30/AH31 -> 10.582143 | AI32: =+AI30/AI31 -> 13.867384 | AJ32: =+AJ30/AJ31 -> 15.85871 | AK32: =+AK30/AK31 -> 19.032258
B35: Gross Margin | N35: =N17/N13 -> 0.76538945 | R35: =R17/R13 -> 0.77812582 | S35: =S17/S13 -> #DIV/0!
B36: Op. Margin | N36: =N25/N13 -> -0.047424623 | R36: =R25/R13 -> 0.088488645 | S36: =S25/S13 -> #DIV/0!
B37: Tax Margin | N37: =N29/N28 -> 0.85714286 | R37: =R29/R28 -> -0.040983607 | S37: =S29/S28 -> #DIV/0!
B38: Net Margin | N38: =N30/N13 -> -0.006281407 | R38: =R30/R13 -> 0.09945184 | S38: =S30/S13 -> #DIV/0!
B40: YoY Growth
B41: QuickBooks Online Accounting | K41: =K3/G3-1 -> 0.19461078 | L41: =L3/H3-1 -> 0.18678161 | M41: =M3/I3-1 -> 0.18948824 | N41: =N3/J3-1 -> 0.17454068 | O41: =O3/K3-1 -> 0.20927318 | P41: =P3/L3-1 -> 0.22033898 | Q41: =Q3/M3-1 -> 0.21395349 | R41: =R3/N3-1 -> 0.23240223 | S41: =S3/O3-1 -> -1
B42: Online Services | K42: =K4/G4-1 -> 0.2041116 | L42: =L4/H4-1 -> 0.24028777 | M42: =M4/I4-1 -> 0.2 | N42: =N4/J4-1 -> 0.18757921 | O42: =O4/K4-1 -> 0.19268293 | P42: =P4/L4-1 -> 0.19489559 | Q42: =Q4/M4-1 -> 0.18456376 | R42: =R4/N4-1 -> 0.18996798 | S42: =S4/O4-1 -> -1
B43: Total Online Ecosystem | K43: =K5/G5-1 -> 0.19940697 | L43: =L5/H5-1 -> 0.21351546 | M43: =M5/I5-1 -> 0.19482289 | N43: =N5/J5-1 -> 0.18117344 | O43: =O5/K5-1 -> 0.20086527 | P43: =P5/L5-1 -> 0.20734597 | Q43: =Q5/M5-1 -> 0.19897377 | R43: =R5/N5-1 -> 0.21069869 | S43: =S5/O5-1 -> -1
...
