Workbook

Sheet Main
A1: Model
I6: Price | J6: 183.95 | K6: 46080 | N6: Cons. | O6: 46050
I7: S/O | J7: =+Model!U19 -> 24327 | K7: Q426 | N7: Beat | O7: =Model!T8/O6-1 -> 0.01504886
I8: MC | J8: =+J7*J6 -> 4474951.6
I9: Cash | J9: =+Model!U39 -> 60608 | K9: Q426 | N9: EPS Cons. | O9: 1.01
I10: Debt | J10: =+Model!U52+Model!U53 -> 8467 | K10: Q426 | N10: Beat | O10: =Model!T20/O9-1 -> 0.069306931
I12: EV | J12: =J8-J9+J10 -> 4422810.6 | N12: Guidance cons. | O12: 53430
N13: Beat | O13: =Model!U8/O12-1 -> 0.066928692

Sheet Model
A1: Main | S1: 45774
C2: Q122 | D2: Q222 | E2: Q322 | F2: Q422 | G2: Q123 | H2: Q223 | I2: Q323 | J2: Q423 | K2: Q124 | L2: Q224 | M2: Q324 | N2: Q424 | O2: Q125 | P2: Q225 | Q2: Q325 | R2: Q425 | S2: Q126 | T2: Q226 | U2: Q326 | V2: Q426 | W2: Q127 | X2: Q227 | AA2: 2022 | AB2: 2023 | AC2: 2024 | AD2: 2025 | AE2: 2026 | AF2: 2027
B3: Data Center | C3: 2048 | D3: 2366 | E3: 2936 | F3: 3263 | G3: 3750 | H3: 3806 | I3: 3833 | J3: 3616 | K3: 4284 | L3: 10323 | M3: 14514 | N3: 18404 | O3: 22563 | P3: 26272 | Q3: 30771 | R3: 35580 | S3: 39112 | T3: 41096 | U3: 51215 | V3: 62314 | AA3: =C3+D3+E3+F3 -> 10613 | AB3: =+G3+H3+I3+J3 -> 15005 | AC3: =K3+L3+M3+N3 -> 47525 | AD3: =O3+P3+Q3+R3 -> 115186 | AE3: =SUM(S3:V3) -> 193737
B4: Gaming | C4: 2760 | D4: 3061 | E4: 3221 | F4: 3420 | G4: 3620 | H4: 2042 | I4: 1574 | J4: 1831 | K4: 2240 | L4: 2486 | M4: 2856 | N4: 2865 | O4: 2647 | P4: 2880 | Q4: 3279 | R4: 2544 | S4: 3763 | T4: 4287 | U4: 4265 | V4: 3727 | AA4: =C4+D4+E4+F4 -> 12462 | AB4: =+G4+H4+I4+J4 -> 9067 | AC4: =K4+L4+M4+N4 -> 10447 | AD4: =O4+P4+Q4+R4 -> 11350 | AE4: =SUM(S4:V4) -> 16042
B5: Visualization | C5: 372 | D5: 519 | E5: 577 | F5: 643 | G5: 622 | H5: 496 | I5: 200 | J5: 226 | K5: 295 | L5: 379 | M5: 416 | N5: 463 | O5: 427 | P5: 454 | Q5: 486 | R5: 511 | S5: 509 | T5: 601 | U5: 760 | V5: 1321 | AA5: =C5+D5+E5+F5 -> 2111 | AB5: =+G5+H5+I5+J5 -> 1544 | AC5: =K5+L5+M5+N5 -> 1553 | AD5: =O5+P5+Q5+R5 -> 1878 | AE5: =SUM(S5:V5) -> 3191
B6: Auto | C6: 154 | D6: 152 | E6: 135 | F6: 125 | G6: 138 | H6: 220 | I6: 251 | J6: 294 | K6: 296 | L6: 253 | M6: 261 | N6: 281 | O6: 329 | P6: 346 | Q6: 449 | R6: 570 | S6: 567 | T6: 586 | U6: 592 | V6: 604 | AA6: =C6+D6+E6+F6 -> 566 | AB6: =+G6+H6+I6+J6 -> 903 | AC6: =K6+L6+M6+N6 -> 1091 | AD6: =O6+P6+Q6+R6 -> 1694 | AE6: =SUM(S6:V6) -> 2349
B7: OEM & Other | C7: 327 | D7: 409 | E7: 234 | F7: 192 | G7: 158 | H7: 140 | I7: 73 | J7: 84 | K7: 77 | L7: 66 | M7: 73 | N7: 90 | O7: 78 | P7: 88 | Q7: 97 | R7: 126 | S7: 111 | T7: 173 | U7: 174 | V7: 161 | AA7: =C7+D7+E7+F7 -> 1162 | AB7: =+G7+H7+I7+J7 -> 455 | AC7: =K7+L7+M7+N7 -> 306 | AD7: =O7+P7+Q7+R7 -> 389 | AE7: =SUM(S7:V7) -> 619
B8: Revenue | C8: =SUM(C3:C7) -> 5661 | D8: =SUM(D3:D7) -> 6507 | E8: =SUM(E3:E7) -> 7103 | F8: =SUM(F3:F7) -> 7643 | G8: =SUM(G3:G7) -> 8288 | H8: =SUM(H3:H7) -> 6704 | I8: =SUM(I3:I7) -> 5931 | J8: =SUM(J3:J7) -> 6051 | ... X8: =SUM(X3:X7) -> 0 | AA8: =C8+D8+E8+F8 -> 26914 | AB8: =+G8+H8+I8+J8 -> 26974 | AC8: =K8+L8+M8+N8 -> 60922 | AD8: =O8+P8+Q8+R8 -> 130497 | AE8: =SUM(AE3:AE7) -> 215938 | AF8: 253590
B9: COGS | K9: 2544 | L9: 4045 | M9: 4720 | N9: 5312 | O9: 5638 | P9: 7466 | Q9: 8926 | R9: 10608 | S9: 17394 | T9: 12890 | U9: 15157 | V9: 17034 | AC9: =K9+L9+M9+N9 -> 16621 | AD9: =O9+P9+Q9+R9 -> 32638 | AE9: =SUM(S9:V9) -> 62475
B10: Gross Profit | C10: =C8-C9 -> 5661 | D10: =D8-D9 -> 6507 | E10: =E8-E9 -> 7103 | F10: =F8-F9 -> 7643 | G10: =G8-G9 -> 8288 | H10: =H8-H9 -> 6704 | I10: =I8-I9 -> 5931 | J10: =J8-J9 -> 6051 | ... X10: =X8-X9 -> 0 | AC10: =AC8-AC9 -> 44301 | AD10: =AD8-AD9 -> 97859 | AE10: =AE8-AE9 -> 153463 | AF10: =AF8-AF9 -> 253590
B11: R&D | K11: 1875 | L11: 2040 | M11: 2294 | N11: 2465 | O11: 2720 | P11: 3090 | Q11: 3390 | R11: 3714 | S11: 3989 | T11: 4291 | U11: 4705 | V11: 5512 | AC11: =K11+L11+M11+N11 -> 8674 | AD11: =O11+P11+Q11+R11 -> 12914 | AE11: =SUM(S11:V11) -> 18497
B12: SG&A | K12: 633 | L12: 622 | M12: 689 | N12: 711 | O12: 777 | P12: 842 | Q12: 897 | R12: 975 | S12: 1041 | T12: 1122 | U12: 1134 | V12: 1282 | AC12: =K12+L12+M12+N12 -> 2655 | AD12: =O12+P12+Q12+R12 -> 3491 | AE12: =SUM(S12:V12) -> 4579
B13: Operating expenses | C13: =+C12+C11 -> 0 | D13: =+D12+D11 -> 0 | E13: =+E12+E11 -> 0 | F13: =+F12+F11 -> 0 | G13: =+G12+G11 -> 0 | H13: =+H12+H11 -> 0 | I13: =+I12+I11 -> 0 | J13: =+J12+J11 -> 0 | ... X13: =+X12+X11 -> 0 | AC13: =+AC12+AC11 -> 11329 | AD13: =+AD12+AD11 -> 16405 | AE13: =+AE12+AE11 -> 23076 | AF13: =+AF12+AF11 -> 0
B14: Operating profit | C14: =C10-C13 -> 5661 | D14: =D10-D13 -> 6507 | E14: =E10-E13 -> 7103 | F14: =F10-F13 -> 7643 | G14: =G10-G13 -> 8288 | H14: =H10-H13 -> 6704 | I14: =I10-I13 -> 5931 | J14: =J10-J13 -> 6051 | ... S14: =S10-S13 -> 21638 | T14: 28440 | U14: =U10-U13 -> 36010 | V14: =V10-V13 -> 44299 | W14: =W10-W13 -> 0 | X14: =X10-X13 -> 0 | AC14: =AC10-AC13 -> 32972 | AD14: =AD10-AD13 -> 81454 | AE14: =AE10-AE13 -> 130387 | AF14: =AF10-AF13 -> 253590
B15: Interest income | K15: =150-66-15 -> 69 | L15: =187-65+59 -> 181 | M15: =234-63-66 -> 105 | N15: =294-63+260 -> 491 | O15: =359-64+75 -> 370 | P15: =444-61+189 -> 572 | Q15: =472-61+36 -> 447 | R15: =511-61+733 -> 1183 | S15: =515-63-180 -> 272 | T15: =592-62+2236 -> 2766 | U15: =624-61+1363 -> 1926 | V15: 6098 | AC15: =K15+L15+M15+N15 -> 846 | AD15: =O15+P15+Q15+R15 -> 2572 | AE15: =SUM(S15:V15) -> 11062
B16: Pretax income | C16: =C14+C15 -> 5661 | D16: =D14+D15 -> 6507 | E16: =E14+E15 -> 7103 | F16: =F14+F15 -> 7643 | G16: =G14+G15 -> 8288 | H16: =H14+H15 -> 6704 | I16: =I14+I15 -> 5931 | J16: =J14+J15 -> 6051 | ... X16: =X14+X15 -> 0 | AC16: =AC14+AC15 -> 33818 | AD16: =AD14+AD15 -> 84026 | AE16: =AE14+AE15 -> 141449 | AF16: =AF14+AF15 -> 253590
B17: Taxes | K17: 166 | L17: 793 | M17: 1279 | N17: 1821 | O17: 2398 | P17: 2615 | Q17: 3007 | R17: 3126 | S17: 3135 | T17: 4784 | U17: 6026 | V17: 7437 | AC17: =K17+L17+M17+N17 -> 4059 | AD17: =O17+P17+Q17+R17 -> 11146 | AE17: =SUM(S17:V17) -> 21382
B18: Net Income | C18: =C16-C17 -> 5661 | D18: =D16-D17 -> 6507 | E18: =E16-E17 -> 7103 | F18: =F16-F17 -> 7643 | G18: =G16-G17 -> 8288 | H18: =H16-H17 -> 6704 | I18: =I16-I17 -> 5931 | J18: =J16-J17 -> 6051 | ... X18: =X16-X17 -> 0 | AC18: =AC16-AC17 -> 29759 | AD18: =AD16-AD17 -> 72880 | AE18: =AE16-AE17 -> 120067 | AF18: =AF16-AF17 -> 253590
B19: S/O | K19: 24700 | L19: 24729 | M19: 24680 | N19: 24660 | O19: 24620 | P19: 24578 | Q19: 24533 | R19: 24489 | S19: 24441 | T19: 24366 | U19: 24327 | V19: 24304 | AC19: 24660 | AD19: 24489 | AE19: =V19 -> 24304 | AF19: =AF18/AF20 -> #DIV/0!
B20: EPS | C20: =C18/C19 -> #DIV/0! | D20: =D18/D19 -> #DIV/0! | E20: =E18/E19 -> #DIV/0! | F20: =F18/F19 -> #DIV/0! | G20: =G18/G19 -> #DIV/0! | H20: =H18/H19 -> #DIV/0! | I20: =I18/I19 -> #DIV/0! | J20: =J18/J19 -> #DIV/0! | ... S20: =S18/S19 -> 0.76817642 | T20: 1.08 | U20: =U18/U19 -> 1.3117113 | V20: =V18/V19 -> 1.7676103 | W20: =W18/W19 -> #DIV/0! | X20: =X18/X19 -> #DIV/0! | AC20: =AC18/AC19 -> 1.2067721 | AD20: =AD18/AD19 -> 2.9760301 | AE20: =AE18/AE19 -> 4.9402156
B23: Gross Margin | K23: =K10/K8 -> 0.64627364 | L23: =L10/L8 -> 0.70052565 | M23: =M10/M8 -> 0.73951435 | N23: =N10/N8 -> 0.75967063 | O23: =O10/O8 -> 0.7835202 | P23: =P10/P8 -> 0.75146471 | Q23: =Q10/Q8 -> 0.74556753 | R23: =R10/R8 -> 0.73028908 | ... X23: =X10/X8 -> #DIV/0! | AC23: =AC10/AC8 -> 0.72717573 | AD23: =AD10/AD8 -> 0.74989463 | AE23: =AE10/AE8 -> 0.71068084 | AF23: =AF10/AF8 -> 1
B24: Operating Margin | K24: =K14/K8 -> 0.29755284 | L24: =L14/L8 -> 0.50344266 | M24: =M14/M8 -> 0.57488962 | N24: =N14/N8 -> 0.61597973 | O24: =O14/O8 -> 0.64924743 | P24: =P14/P8 -> 0.62057257 | Q24: =Q14/Q8 -> 0.62336811 | R24: =R14/R8 -> 0.61107015 | ... X24: =X14/X8 -> #DIV/0! | AC24: =AC14/AC8 -> 0.54121664 | AD24: =AD14/AD8 -> 0.62418293 | AE24: =AE14/AE8 -> 0.60381684 | AF24: =AF14/AF8 -> 1
B25: Net Margin | K25: =K18/K8 -> 0.28406563 | L25: =L18/L8 -> 0.45813282 | M25: =M18/M8 -> 0.51009934 | N25: =N18/N8 -> 0.5558069 | O25: =O18/O8 -> 0.5713792 | P25: =P18/P8 -> 0.55256325 | Q25: =Q18/Q8 -> 0.55039621 | R25: =R18/R8 -> 0.56166891 | ... X25: =X18/X8 -> #DIV/0! | AC25: =AC18/AC8 -> 0.48847707 | AD25: =AD18/AD8 -> 0.55848027 | AE25: =AE18/AE8 -> 0.55602534 | AF25: =AF18/AF8 -> 1
B27: R&D Margin | K27: =K11/K10 -> 0.40339931 | L27: =L11/L10 -> 0.21559924 | M27: =M11/M10 -> 0.17119403 | N27: =N11/N10 -> 0.14680484 | O27: =O11/O10 -> 0.13329413 | P27: =P11/P10 -> 0.13688314 | Q27: =Q11/Q10 -> 0.12960697 | R27: =R11/R10 -> 0.12930404 | ... X27: =X11/X10 -> #DIV/0! | AC27: =AC11/AC10 -> 0.19579693 | AD27: =AD11/AD10 -> 0.13196538 | AE27: =AE11/AE10 -> 0.12053068 | AF27: =AF11/AF10 -> 0
B28: SG&A Margin | K28: =K12/K10 -> 0.13618761 | L28: =L12/L10 -> 0.065736631 | M28: =M12/M10 -> 0.05141791 | N28: =N12/N10 -> 0.042344113 | O28: =O12/O10 -> 0.038077036 | P28: =P12/P10 -> 0.037299548 | Q28: =Q12/Q10 -> 0.034294235 | R28: =R12/R10 -> 0.033944922 | ... X28: =X12/X10 -> #DIV/0! | AC28: =AC12/AC10 -> 0.059930927 | AD28: =AD12/AD10 -> 0.035673776 | AE28: =AE12/AE10 -> 0.029837811 | AF28: =AF12/AF10 -> 0
B29: Effective tax rate | K29: =K17/K16 -> 0.075147125 | L29: =L17/L16 -> 0.11359404 | M29: =M17/M16 -> 0.12155484 | N29: =N17/N16 -> 0.129094 | O29: =O17/O16 -> 0.13878118 | P29: =P17/P16 -> 0.13609868 | Q29: =Q17/Q16 -> 0.13474637 | R29: =R17/R16 -> 0.12396399 | ... X29: =X17/X16 -> #DIV/0! | AC29: =AC17/AC16 -> 0.12002484 | AD29: =AD17/AD16 -> 0.13264942 | AE29: =AE17/AE16 -> 0.15116402 | AF29: =AF17/AF16 -> 0
B30: Interest Margin | K30: =K15/K14 -> 0.032242991 | L30: =L15/L14 -> 0.026617647 | M30: =M15/M14 -> 0.010079677 | N30: =N15/N14 -> 0.036063166 | O30: =O15/O14 -> 0.021881838 | P30: =P15/P14 -> 0.030683403 | Q30: =Q15/Q14 -> 0.020439892 | R30: =R15/R14 -> 0.049221936 | ... X30: =X15/X14 -> #DIV/0! | AC30: =AC15/AC14 -> 0.025658134 | AD30: =AD15/AD14 -> 0.031576104 | AE30: =AE15/AE14 -> 0.084839746 | AF30: =AF15/AF14 -> 0
B32: Revenue Y/Y | G32: =G8/C8-1 -> 0.46405229 | H32: =H8/D8-1 -> 0.030275088 | I32: =I8/E8-1 -> -0.1650007 | J32: =J8/F8-1 -> -0.20829517 | K32: =K8/G8-1 -> -0.13223938 | L32: =L8/H8-1 -> 1.0147673 | M32: =M8/I8-1 -> 2.055134 | N32: =N8/J8-1 -> 2.6527847 | ... X32: =X8/T8-1 -> -1 | AB32: =AB8/AA8-1 -> 0.002229323 | AC32: =AC8/AB8-1 -> 1.2585453 | AD32: =AD8/AC8-1 -> 1.1420341 | AE32: =AE8/AD8-1 -> 0.65473536 | AF32: =AF8/AE8-1 -> 0.17436486
B33: Data Center Y/Y | G33: =G3/C3-1 -> 0.83105469 | H33: =H3/D3-1 -> 0.60862215 | I33: =I3/E3-1 -> 0.30551771 | J33: =J3/F3-1 -> 0.10818265 | K33: =K3/G3-1 -> 0.1424 | L33: =L3/H3-1 -> 1.7122964 | M33: =M3/I3-1 -> 2.7865901 | N33: =N3/J3-1 -> 4.0896018 | ... X33: =X3/T3-1 -> -1 | AB33: =AB3/AA3-1 -> 0.41383209 | AC33: =AC3/AB3-1 -> 2.1672776 | AD33: =AD3/AC3-1 -> 1.4236928 | AE33: =AE3/AD3-1 -> 0.6819492 | AF33: =AF3/AE3-1 -> -1
B34: Gaming Y/Y | G34: =G4/C4-1 -> 0.3115942 | H34: =H4/D4-1 -> -0.33289775 | I34: =I4/E4-1 -> -0.51133188 | J34: =J4/F4-1 -> -0.46461988 | K34: =K4/G4-1 -> -0.38121547 | L34: =L4/H4-1 -> 0.21743389 | M34: =M4/I4-1 -> 0.81448539 | N34: =N4/J4-1 -> 0.56471873 | ... X34: =X4/T4-1 -> -1 | AB34: =AB4/AA4-1 -> -0.27242818 | AC34: =AC4/AB4-1 -> 0.15220029 | AD34: =AD4/AC4-1 -> 0.086436298 | AE34: =AE4/AD4-1 -> 0.41339207 | AF34: =AF4/AE4-1 -> -1
B38: Net Cash | N38: =+N39-N52-N53 -> 16275 | O38: =+O39-O52-O53 -> 21728 | P38: =+P39-P52-P53 -> 26339 | Q38: =+Q39-Q52-Q53 -> 30025 | R38: =+R39-R52-R53 -> 34747 | S38: =+S39-S52-S53 -> 45227 | T38: =+T39-T52-T53 -> 48325 | U38: =+U39-U52-U53 -> 52141 | ... X38: =+X39-X52-X53 -> 0 | AC38: =+AC39-AC52-AC53 -> 16275 | AD38: =+AD39-AD52-AD53 -> 34747 | AE38: =+AE39-AE52-AE53 -> 54088
B39: Cash | N39: 25984 | O39: 31438 | P39: 34800 | Q39: 38487 | R39: 43210 | S39: 53691 | T39: 56791 | U39: =11486+49122 -> 60608 | V39: 62556 | AC39: 25984 | AD39: 43210 | AE39: 62556
B40: A/R | N40: 9999 | O40: 12365 | P40: 14132 | Q40: 17693 | R40: 23065 | S40: 22132 | T40: 27808 | U40: 33391 | V40: 38466 | AC40: 9999 | AD40: 23065 | AE40: 38466
B41: Inventories | N41: 5282 | O41: 5864 | P41: 6675 | Q41: 7654 | R41: 10080 | S41: 11333 | T41: 14962 | U41: 19754 | V41: 21403 | AC41: 5282 | AD41: 10080 | AE41: 21403
B42: Prepaids | N42: 3080 | O42: 4062 | P42: 4026 | Q42: 3806 | R42: 3771 | S42: 2779 | T42: 2658 | U42: 2709 | V42: 3180 | AC42: 3080 | AD42: 3771 | AE42: 3180
B43: PP&A | N43: 3914 | O43: 4006 | P43: 4885 | Q43: 5343 | R43: 6283 | S43: 7136 | T43: 9141 | U43: 9780 | V43: 10383 | AC43: 3914 | AD43: 6283 | AE43: 10383
B44: Leases | N44: 1346 | O44: 1532 | P44: 1556 | Q44: 1755 | R44: 1793 | S44: 1810 | T44: 2084 | U44: 2281 | V44: 2867 | AC44: 1346 | AD44: 1793 | AE44: 2867
B45: Goodwill | N45: 4430 | O45: 4453 | P45: 4622 | Q45: 4724 | R45: 5188 | S45: 5498 | T45: 5755 | U45: 6261 | V45: 20832 | AC45: 4430 | AD45: 5188 | AE45: 20832
B46: Intangibles | N46: 1112 | O46: 986 | P46: 952 | Q46: 838 | R46: 807 | S46: 769 | T46: 755 | U46: 936 | V46: 3306 | AC46: 1112 | AD46: 807 | AE46: 3306
B47: Deferred income tax | N47: 6081 | O47: 7798 | P47: 9578 | Q47: 10276 | R47: 10979 | S47: 13318 | T47: 13570 | U47: 13674 | V47: 13258 | AC47: 6081 | AD47: 10979 | AE47: 13258
...
