Workbook

Sheet Main
J6: P | K6: 51.22
J7: S/O | K7: =Model!L30/1000 -> 170.776
J8: MC | K8: =K6*K7 -> 8747.1467
J9: Cash | K9: =(Model!L55+Model!L56)/1000 -> 411.567
J10: Debt | K10: =+Model!L68/1000 -> 0
J12: EV | K12: =+K8-K9+K10 -> 8335.5797

Sheet Model
A1: Main | C1: ($ thousands)
C2: Q123 | D2: Q223 | E2: Q323 | F2: Q423 | G2: Q124 | H2: Q224 | I2: Q324 | J2: Q424 | K2: Q125 | L2: Q225 | M2: Q325 | N2: Q425 | O2: Q126 | P2: Q226 | Q2: Q326 | R2: Q426 | S2: Q127 | T2: Q227 | U2: Q327 | V2: Q427 | Y2: 2022 | Z2: 2023 | AA2: 2024 | AB2: 2025 | AC2: 2026 | AD2: 2027 | AE2: 2028 | AF2: 2029 | AG2: 2030 | AH2: 2031 | AI2: 2032 | AJ2: 2033 | AK2: 2034 | AL2: 2035 | AM2: 2036 | AN2: 2037 | AO2: 2038 | AP2: 2039 | AQ2: 2040 | AR2: 2041 | AS2: 2042 | AT2: 2043 | AU2: 2044 | AV2: 2045 | AW2: 2046 | AX2: 2047 | AY2: 2048 | AZ2: 2049 | BA2: 2050 | BB2: 2051 | BC2: 2052 | BD2: 2053 | BE2: 2054 | BF2: 2055 | BG2: 2056 | BH2: 2057 | BI2: 2058 | BJ2: 2059 | BK2: 2060
B3: Pega Cloud | C3: 107879 | D3: 115063 | E3: 118040 | F3: 120346 | G3: 130902 | H3: 134086 | I3: 144108 | J3: 149638 | K3: 151123 | L3: 166743 | Y3: 384271 | Z3: 461328 | AA3: 558734 | AB3: =0.4*AB9 -> 682458
B4: Maintenance | C4: 79630 | D4: 82042 | E4: 83538 | F4: 86646 | G4: 81001 | H4: 80344 | I4: 80702 | J4: 81257 | K4: 76368 | L4: 79271 | Y4: 317564 | Z4: 331856 | AA4: 323304
B5: Subscription services | C5: =SUM(C3:C4) -> 187509 | D5: =SUM(D3:D4) -> 197105 | E5: =SUM(E3:E4) -> 201578 | F5: =SUM(F3:F4) -> 206992 | G5: =SUM(G3:G4) -> 211903 | H5: =SUM(H3:H4) -> 214430 | I5: =SUM(I3:I4) -> 224810 | J5: =SUM(J3:J4) -> 230895 | ... L5: =SUM(L3:L4) -> 246014 | Y5: =SUM(Y3:Y4) -> 701835 | Z5: =SUM(Z3:Z4) -> 793184 | AA5: =SUM(AA3:AA4) -> 882038 | AB5: =SUM(AB3:AB4) -> 682458
B6: Subscription license | C6: 84527 | D6: 41197 | E6: 74342 | F6: 207559 | G6: 63338 | H6: 84647 | I6: 45420 | J6: 204697 | K6: 186555 | L6: 79963 | Y6: 366063 | Z6: 407625 | AA6: 398102
B7: Consulting | C7: 53033 | D7: 58387 | E7: 55976 | F7: 54310 | G7: 54047 | H7: 52040 | I7: 54364 | J7: 52822 | K7: 60421 | L7: 57824 | Y7: 230654 | Z7: 221706 | AA7: 213273
B8: Perpetual license | C8: 403 | D8: 1579 | E8: 2747 | F8: 5372 | G8: 859 | H8: 36 | I8: 456 | J8: 2416 | K8: 1166 | L8: 711 | Y8: 19293 | Z8: 10101 | AA8: 3767
B9: Total revenue | C9: =SUM(C5:C8) -> 325472 | D9: =SUM(D5:D8) -> 298268 | E9: =SUM(E5:E8) -> 334643 | F9: =SUM(F5:F8) -> 474233 | G9: =SUM(G5:G8) -> 330147 | H9: =SUM(H5:H8) -> 351153 | I9: =SUM(I5:I8) -> 325050 | J9: =SUM(J5:J8) -> 490830 | ... L9: =SUM(L5:L8) -> 384512 | M9: 352000 | N9: 494000 | O9: 478000 | P9: 412000 | Q9: 392000 | R9: 533000 | S9: 505000 | T9: 452000 | U9: =Q9*(1+U43) -> 431200 | V9: =R9*(1+V43) -> 580970 | Y9: =SUM(Y5:Y8) -> 1317845 | Z9: =SUM(Z5:Z8) -> 1432616 | AA9: =SUM(AA5:AA8) -> 1497180 | AB9: =+K9+L9+M9+N9 -> 1706145 | AC9: =+O9+P9+Q9+R9 -> 1815000 | AD9: =S9+T9+U9+V9 -> 1969170 | AE9: =AD9*(1+AE43) -> 2107011.9 | AF9: =AE9*(1+AF43) -> 2254502.7 | AG9: =AF9*(1+AG43) -> 2412317.9 | AH9: =AG9*(1+AH43) -> 2581180.2 | AI9: =AH9*(1+AI43) -> 2761862.8 | AJ9: =AI9*(1+AJ43) -> 2955193.2 | AK9: =AJ9*(1+AK43) -> 3162056.7 | AL9: =AK9*(1+AL43) -> 3383400.7 | ... AV9: =AU9*(1+AV43) -> 5457358.8
B10: Subscription services | C10: 36864 | D10: 36783 | E10: 35906 | F10: 34697 | G10: 35824 | H10: 36238 | I10: 36868 | J10: 40988 | K10: 38128 | L10: 41510 | Y10: 138736 | Z10: 144250 | AA10: 149918
B11: Subscription license | C11: 719 | D11: 623 | E11: 629 | F11: 635 | G11: 643 | H11: 477 | I11: 384 | J11: 384 | K11: 386 | L11: 360 | Y11: 2642 | Z11: 2606 | AA11: 1888
B12: Consulting | C12: 60348 | D12: 58710 | E12: 57204 | F12: 55298 | G12: 58182 | H12: 60231 | I12: 59451 | J12: 60978 | K12: 63934 | L12: 67700 | Y12: 227082 | Z12: 231560 | AA12: 238842
B13: Perpetual license | C13: 3 | D13: 24 | E13: 24 | F13: 16 | G13: 9 | I13: 3 | J13: 5 | K13: 2 | L13: 4 | Y13: 175 | Z13: 67 | AA13: 17
B14: Total cost | C14: =SUM(C10:C13) -> 97934 | D14: =SUM(D10:D13) -> 96140 | E14: =SUM(E10:E13) -> 93763 | F14: =SUM(F10:F13) -> 90646 | G14: =SUM(G10:G13) -> 94658 | H14: =SUM(H10:H13) -> 96946 | I14: =SUM(I10:I13) -> 96706 | J14: =SUM(J10:J13) -> 102355 | ... L14: =SUM(L10:L13) -> 109574 | Y14: =SUM(Y10:Y13) -> 368635 | Z14: =SUM(Z10:Z13) -> 378483 | AA14: =SUM(AA10:AA13) -> 390665 | AB14: =SUM(AB10:AB13) -> 0
B15: Gross Profit | C15: =C9-C14 -> 227538 | D15: =D9-D14 -> 202128 | E15: =E9-E14 -> 240880 | F15: =F9-F14 -> 383587 | G15: =G9-G14 -> 235489 | H15: =H9-H14 -> 254207 | I15: =I9-I14 -> 228344 | J15: =J9-J14 -> 388475 | ... L15: =L9-L14 -> 274938 | Y15: =Y9-Y14 -> 949210 | Z15: =Z9-Z14 -> 1054133 | AA15: =AA9-AA14 -> 1106515 | AB15: =AB9-AB14 -> 1706145
B16: S&M | C16: 149797 | D16: 143858 | E16: 131598 | F16: 133924 | G16: 127695 | H16: 139761 | I16: 127669 | J16: 139655 | K16: 138069 | L16: 147131 | Y16: 624789 | Z16: 559177 | AA16: 534780
B17: R&D | C17: 75376 | D17: 73931 | E17: 74955 | F17: 71250 | G17: 72113 | H17: 75425 | I17: 74157 | J17: 76379 | K17: 74286 | L17: 78784 | Y17: 294349 | Z17: 295512 | AA17: 298074
B18: G&A | C18: 23110 | D18: 23462 | E18: 27321 | F18: 22850 | G18: 23527 | H18: 25420 | I18: 35694 | J18: 28207 | K18: 33828 | L18: 31788 | Y18: 117734 | Z18: 96743 | AA18: 112848
B19: Litigation | G19: 32403 | AA19: 32403
B20: Restructuring | C20: 1461 | D20: 2167 | E20: 17822 | F20: 297 | G20: 163 | H20: 635 | I20: 2485 | J20: 1245 | K20: 11 | L20: -44 | Y20: 21743 | Z20: 21747 | AA20: 4528
B21: Operating expenses | C21: =SUM(C16:C20) -> 249744 | D21: =SUM(D16:D20) -> 243418 | E21: =SUM(E16:E20) -> 251696 | F21: =SUM(F16:F20) -> 228321 | G21: =SUM(G16:G20) -> 255901 | H21: =SUM(H16:H20) -> 241241 | I21: =SUM(I16:I20) -> 240005 | J21: =SUM(J16:J20) -> 245486 | ... L21: =SUM(L16:L20) -> 257659 | Y21: =SUM(Y16:Y20) -> 1058615 | Z21: =SUM(Z16:Z20) -> 973179 | AA21: =SUM(AA16:AA20) -> 982633 | AB21: =SUM(AB16:AB20) -> 0
B22: Operating profit | C22: =C15-C21 -> -22206 | D22: =D15-D21 -> -41290 | E22: =E15-E21 -> -10816 | F22: =F15-F21 -> 155266 | G22: =G15-G21 -> -20412 | H22: =H15-H21 -> 12966 | I22: =I15-I21 -> -11661 | J22: =J15-J21 -> 142989 | ... L22: =L15-L21 -> 17279 | Y22: =Y15-Y21 -> -109405 | Z22: =Z15-Z21 -> 80954 | AA22: =AA15-AA21 -> 123882 | AB22: =AB15-AB21 -> 1706145
B23: FX | C23: -2675 | D23: -3290 | E23: 1994 | F23: -1271 | G23: -3262 | H23: 437 | I23: -4405 | J23: 6318 | K23: -5325 | L23: -14008 | Y23: 4560 | Z23: -5242 | AA23: -912
B24: Interest income | C24: 1485 | D24: 1814 | E24: 2532 | F24: 3428 | G24: 5281 | H24: 6785 | I24: 6769 | J24: 6944 | K24: 5335 | L24: 3248 | Y24: 1643 | Z24: 9259 | AA24: 25779
B25: Interest expense | C25: -1918 | D25: -1778 | E25: -1533 | F25: -1647 | G25: -1752 | H25: -1656 | I25: -1639 | J25: -1788 | K25: -1027 | L25: -1 | Y25: -7792 | Z25: -6876 | AA25: -6835
B26: Other income | C26: =3206+6583 -> 9789 | D26: =-1361+5702 -> 4341 | E26: =-2294+6383 -> 4089 | F26: =-899+25 -> -874 | G26: =3299+1684 -> 4983 | H26: -3277 | I26: -689 | J26: =4-299 -> -295 | K26: =-223+561 -> 338 | L26: 18729 | Y26: =-57382+6579 -> -50803 | Z26: =-1348+18693 -> 17345 | AA26: =-663+1385 -> 722
B27: Pretax income | C27: =C22+SUM(C23:C26) -> -15525 | D27: =D22+SUM(D23:D26) -> -40203 | E27: =E22+SUM(E23:E26) -> -3734 | F27: =F22+SUM(F23:F26) -> 154902 | G27: =G22+SUM(G23:G26) -> -15162 | H27: =H22+SUM(H23:H26) -> 15255 | I27: =I22+SUM(I23:I26) -> -11625 | J27: =J22+SUM(J23:J26) -> 154168 | ... L27: =L22+SUM(L23:L26) -> 25247 | Y27: =Y22+SUM(Y23:Y26) -> -161797 | Z27: =Z22+SUM(Z23:Z26) -> 95440 | AA27: =AA22+SUM(AA23:AA26) -> 142636 | AB27: =AB22+SUM(AB23:AB26) -> 1706145
B28: Taxes | C28: 5249 | D28: 6601 | E28: 3545 | F28: 12237 | G28: -3038 | H28: 8642 | I28: 2765 | J28: 35078 | K28: 40888 | L28: -4830 | Y28: 183785 | Z28: 27632 | AA28: 43447
B29: Net Income | C29: =C27-C28 -> -20774 | D29: =D27-D28 -> -46804 | E29: =E27-E28 -> -7279 | F29: =F27-F28 -> 142665 | G29: =G27-G28 -> -12124 | H29: =H27-H28 -> 6613 | I29: =I27-I28 -> -14390 | J29: =J27-J28 -> 119090 | ... L29: =L27-L28 -> 30077 | M29: -280 | N29: 106000 | O29: 84000 | P29: 30340 | Q29: 10210 | R29: 125000 | S29: 73120 | T29: 42000 | U29: 15180 | V29: 143000 | Y29: =Y27-Y28 -> -345582 | Z29: =Z27-Z28 -> 67808 | AA29: =AA27-AA28 -> 99189 | AB29: =+K29+L29+M29+N29 -> 221219 | AC29: =+O29+P29+Q29+R29 -> 249550 | AD29: =S29+T29+U29+V29 -> 273300 | AE29: =AE9*(AE40) -> 294981.67 | AF29: =AF9*(AF40) -> 320139.39 | AG29: =AG9*(AG40) -> 349786.1 | AH29: =AH9*(AH40) -> 379433.49 | AI29: =AI9*(AI40) -> 411517.56 | AJ29: =AJ9*(AJ40) -> 443278.98 | AK29: =AK9*(AK40) -> 474308.51 | AL29: =AL9*(AL40) -> 507510.1 | ... AV29: =AV9*(AV40) -> 818603.81 | AW29: =AV29*(1-$AZ$32) -> 794045.7 | AX29: =AW29*(1-$AZ$32) -> 770224.33 | AY29: =AX29*(1-$AZ$32) -> 747117.6 | AZ29: =AY29*(1-$AZ$32) -> 724704.07 | BA29: =AZ29*(1-$AZ$32) -> 702962.95 | BB29: =BA29*(1-$AZ$32) -> 681874.06 | BC29: =BB29*(1-$AZ$32) -> 661417.84 | BD29: =BC29*(1-$AZ$32) -> 641575.3 | ... OP29: =OO29*(1-$AZ$32) -> 15.043699
B30: S/O | C30: 82604 | D30: 83039 | E30: 83336 | F30: 83654 | G30: 84266 | H30: 170314 | I30: 85625 | J30: 86000 | K30: 85902 | L30: 170776 | Y30: 81947 | Z30: 83162 | AA30: 85265
B31: EPS | C31: =C29/C30 -> -0.25148903 | D31: =D29/D30 -> -0.56363877 | E31: =E29/E30 -> -0.087345205 | F31: =F29/F30 -> 1.7054176 | G31: =G29/G30 -> -0.14387772 | H31: =H29/H30 -> 0.038828282 | I31: =I29/I30 -> -0.16805839 | J31: =J29/J30 -> 1.3847674 | ... L31: =L29/L30 -> 0.1761196 | Y31: =Y29/Y30 -> -4.2171403 | Z31: =Z29/Z30 -> 0.81537241 | AA31: =AA29/AA30 -> 1.1633026 | AB31: =AB29/AB30 -> #DIV/0! | AY31: NI Model | BC31: FCF Model
AY32: Maturity | AZ32: 0.03 | BC32: Maturity | BD32: 0.03
AY33: Discount | AZ33: 0.115 | BC33: Discount | BD33: 0.115
AY34: NPV | AZ34: =NPV(AZ33,AC29:OP29)+AB29+L54 -> 4511495.4 | BC34: NPV | BD34: =NPV(BD33,AC107:OP107)+AB107+L54 -> 9084927.1
B35: Gross margin | C35: =C15/C9 -> 0.69910161 | D35: =D15/D9 -> 0.67767243 | E35: =E15/E9 -> 0.71981186 | F35: =F15/F9 -> 0.80885767 | G35: =G15/G9 -> 0.71328529 | H35: =H15/H9 -> 0.72392091 | I35: =I15/I9 -> 0.70248885 | J35: =J15/J9 -> 0.79146548 | ... L35: =L15/L9 -> 0.715031 | Y35: =Y15/Y9 -> 0.72027439 | Z35: =Z15/Z9 -> 0.73580988 | AA35: =AA15/AA9 -> 0.73906611 | AY35: Share | AZ35: =AZ34/L30 -> 26.41762 | BC35: Share | BD35: =BD34/L30 -> 53.197915
B36: S&M margin | C36: =C16/C15 -> 0.65833839 | D36: =D16/D15 -> 0.71171733 | E36: =E16/E15 -> 0.54632182 | F36: =F16/F15 -> 0.34913592 | G36: =G16/G15 -> 0.54225463 | H36: =H16/H15 -> 0.5497921 | I36: =I16/I15 -> 0.55910819 | J36: =J16/J15 -> 0.35949546 | ... L36: =L16/L15 -> 0.53514247 | Y36: =Y16/Y15 -> 0.65821999 | Z36: =Z16/Z15 -> 0.53046153 | AA36: =AA16/AA15 -> 0.48330118 | AY36: Current | AZ36: =Main!K6 -> 51.22 | BC36: Current | BD36: =Main!K6 -> 51.22
B37: R&D margin | C37: =C17/C15 -> 0.33126774 | D37: =D17/D15 -> 0.36576328 | E37: =E17/E15 -> 0.31117154 | F37: =F17/F15 -> 0.18574665 | G37: =G17/G15 -> 0.30622662 | H37: =H17/H15 -> 0.29670701 | I37: =I17/I15 -> 0.32476001 | J37: =J17/J15 -> 0.19661239 | ... L37: =L17/L15 -> 0.28655188 | Y37: =Y17/Y15 -> 0.31009892 | Z37: =Z17/Z15 -> 0.28033654 | AA37: =AA17/AA15 -> 0.26938089 | AY37: Return | AZ37: =AZ35/AZ36-1 -> -0.48423234 | BC37: Return | BD37: =BD35/BD36-1 -> 0.038616068
B38: Operating margin | C38: =C22/C9 -> -0.068227067 | D38: =D22/D9 -> -0.13843255 | E38: =E22/E9 -> -0.032321011 | F38: =F22/F9 -> 0.32740446 | G38: =G22/G9 -> -0.061827004 | H38: =H22/H9 -> 0.036924076 | I38: =I22/I9 -> -0.035874481 | J38: =J22/J9 -> 0.29132082 | ... L38: =L22/L9 -> 0.044937479 | Y38: =Y22/Y9 -> -0.083018109 | Z38: =Z22/Z9 -> 0.056507815 | AA38: =AA22/AA9 -> 0.082743558
B39: Interest margin | C39: =SUM(C23:C26)/C22 -> -0.30086463 | D39: =SUM(D23:D26)/D22 -> -0.026325987 | E39: =SUM(E23:E26)/E22 -> -0.65477071 | F39: =SUM(F23:F26)/F22 -> -0.0023443639 | G39: =SUM(G23:G26)/G22 -> -0.25720165 | H39: =SUM(H23:H26)/H22 -> 0.17653864 | I39: =SUM(I23:I26)/I22 -> -0.0030872138 | J39: =SUM(J23:J26)/J22 -> 0.078180839 | ... L39: =SUM(L23:L26)/L22 -> 0.4611378 | Y39: =SUM(Y23:Y26)/Y22 -> 0.47888122 | Z39: =SUM(Z23:Z26)/Z22 -> 0.17894113 | AA39: =SUM(AA23:AA26)/AA22 -> 0.151386
B40: Net margin | C40: =C29/C9 -> -0.063827303 | D40: =D29/D9 -> -0.15691928 | E40: =E29/E9 -> -0.021751538 | F40: =F29/F9 -> 0.30083313 | G40: =G29/G9 -> -0.036723035 | H40: =H29/H9 -> 0.018832247 | I40: =I29/I9 -> -0.044270112 | J40: =J29/J9 -> 0.24262983 | ... L40: =L29/L9 -> 0.078221226 | Y40: =Y29/Y9 -> -0.26223266 | Z40: =Z29/Z9 -> 0.047331595 | AA40: =AA29/AA9 -> 0.066250551 | AB40: =AB29/AB9 -> 0.12966014 | AC40: =AC29/AC9 -> 0.13749311 | AD40: =AD29/AD9 -> 0.13878944 | AE40: 0.14 | AF40: 0.142 | AG40: 0.145 | AH40: 0.147 | AI40: 0.149 | AJ40: 0.15 | AK40: 0.15 | AL40: 0.15 | AM40: 0.15 | AN40: 0.15 | AO40: 0.15 | AP40: 0.15 | AQ40: 0.15 | AR40: 0.15 | AS40: 0.15 | AT40: 0.15 | AU40: 0.15 | AV40: 0.15
...
