Workbook

Sheet Main
A1: Tech
I6: P | J6: 137.65 | K6: 46061
I7: S/O | J7: =+Model!V18/1000 -> 2386.904 | K7: Q425
I8: MC | J8: =J6*J7 -> 328557.34
I9: Cash | J9: =+(Model!V36+Model!V37)/1000 -> 7177.143 | K9: Q425
I10: Debt | J10: 0 | K10: Q425
I12: EV | J12: =J8-J9+J10 -> 321380.19

Sheet Model
A1: Main | K1: ($ thousands)
C2: Q121 | D2: Q221 | E2: Q321 | F2: Q421 | G2: Q122 | H2: Q222 | I2: Q322 | J2: Q422 | K2: Q123 | L2: Q223 | M2: Q323 | N2: Q423 | O2: Q124 | P2: Q224 | Q2: Q324 | R2: Q424 | S2: Q125 | T2: Q225 | U2: Q325 | V2: Q425 | W2: Q126 | X2: Q226 | Y2: Q326 | Z2: Q426 | AC2: 2018 | AD2: 2019 | AE2: 2020 | AF2: 2021 | AG2: 2022 | AH2: 2023 | AI2: 2024 | AJ2: 2025 | AK2: 2026 | AL2: 2027 | AM2: 2028 | AN2: 2029 | AO2: 2030 | AP2: 2031 | AQ2: 2032 | AR2: 2033 | AS2: 2034 | AT2: 2035
B3: Revenue | C3: 341200 | D3: 375600 | E3: 392100 | F3: 432900 | G3: 446400 | H3: 473000 | I3: 477900 | J3: 508600 | K3: 525186 | L3: 533317 | M3: 558159 | N3: =AH3-SUM(K3:M3) -> 608350 | O3: 634338 | P3: 678134 | Q3: 725516 | R3: 827519 | S3: 883855 | T3: 1003697 | U3: 1181092 | V3: 1406802 | W3: 1536000 | AC3: 595409 | AD3: 742555 | AE3: 1092673 | AF3: 1541889 | AG3: 1905871 | AH3: 2225012 | AI3: 2865507 | AJ3: =SUM(S3:V3) -> 4475446 | AK3: 7198000
B4: COGS | C4: 74100 | D4: 90900 | E4: 86800 | F4: 87600 | G4: 94400 | H4: 102200 | I4: 107600 | J4: 104300 | K4: 107645 | L4: 106899 | M4: 107922 | N4: =AH4-SUM(K4:M4) -> 108639 | O4: 116256 | P4: 128562 | Q4: 146639 | R4: 174533 | S4: 172970 | T4: 192934 | U4: 207307 | V4: 215966 | AC4: 165401 | AD4: 242373 | AE4: 352547 | AF4: 339404 | AG4: 408549 | AH4: 431105 | AI4: 565990 | AJ4: =SUM(S4:V4) -> 789177
B5: Gross Profit | C5: =C3-C4 -> 267100 | D5: =D3-D4 -> 284700 | E5: =E3-E4 -> 305300 | F5: =F3-F4 -> 345300 | G5: =G3-G4 -> 352000 | H5: =H3-H4 -> 370800 | I5: =I3-I4 -> 370300 | J5: =J3-J4 -> 404300 | ... Z5: =Z3-Z4 -> 0 | AC5: =AC3-AC4 -> 430008 | AD5: =AD3-AD4 -> 500182 | AE5: =AE3-AE4 -> 740126 | AF5: =AF3-AF4 -> 1202485 | AG5: =AG3-AG4 -> 1497322 | AH5: =AH3-AH4 -> 1793907 | AI5: =AI3-AI4 -> 2299517 | AJ5: =AJ3-AJ4 -> 3686269
B6: S&M | K6: 187093 | L6: 184163 | M6: 176373 | N6: =AH6-SUM(K6:M6) -> 197363 | O6: 193177 | P6: 196809 | Q6: 209474 | R6: 288295 | S6: 236309 | T6: 243788 | U6: 274636 | V6: 302126 | AC6: 461762 | AD6: 450120 | AE6: 683701 | AF6: 614512 | AG6: 702511 | AH6: 744992 | AI6: 887755 | AJ6: =SUM(S6:V6) -> 1056859
B7: R&D | C7: 98500 | D7: 110500 | E7: 94300 | F7: 84200 | G7: 88600 | H7: 88200 | I7: 100900 | J7: 82000 | K7: 90100 | L7: 99533 | M7: 105708 | N7: =AH7-SUM(K7:M7) -> 109283 | O7: 110040 | P7: 108781 | Q7: 117555 | R7: 171502 | S7: 134889 | T7: 135043 | U7: 144191 | V7: 143554 | AC7: 285451 | AD7: 305563 | AE7: 560660 | AF7: 387487 | AG7: 359679 | AH7: 404624 | AI7: 507878 | AJ7: =SUM(S7:V7) -> 557677
B8: G&M | K8: 136233 | L8: 132648 | M8: 128173 | N8: =AH8-SUM(K8:M8) -> 127271 | O8: 133984 | P8: 138643 | Q8: 138708 | R8: 182146 | S8: 163639 | T8: 162615 | U8: 161702 | V8: 169762 | AC8: 306235 | AD8: 320943 | AE8: 669444 | AF8: 611532 | AG8: 596333 | AH8: 524325 | AI8: 593481 | AJ8: =SUM(S8:V8) -> 657718
B9: Operating expenses | C9: 381100 | D9: 430900 | E9: 397300 | F9: 404200 | G9: 391400 | H9: 412500 | I9: 432500 | J9: 422100 | K9: =SUM(K6:K8) -> 413426 | L9: =SUM(L6:L8) -> 416344 | M9: =SUM(M6:M8) -> 410254 | N9: =SUM(N6:N8) -> 433917 | O9: =SUM(O6:O8) -> 437201 | P9: =SUM(P6:P8) -> 444233 | Q9: =SUM(Q6:Q8) -> 465737 | R9: =SUM(R6:R8) -> 641943 | ... Z9: =SUM(Z6:Z8) -> 0 | AC9: =SUM(AC6:AC8) -> 1053448 | AD9: =SUM(AD6:AD8) -> 1076626 | AE9: =SUM(AE6:AE8) -> 1913805 | AF9: =SUM(AF6:AF8) -> 1613531 | AG9: =SUM(AG6:AG8) -> 1658523 | AH9: =SUM(AH6:AH8) -> 1673941 | AI9: =SUM(AI6:AI8) -> 1989114 | AJ9: =SUM(AJ6:AJ8) -> 2272254
B10: Operating income | C10: =C5-C9 -> -114000 | D10: =D5-D9 -> -146200 | E10: =E5-E9 -> -92000 | F10: =F5-F9 -> -58900 | G10: =G5-G9 -> -39400 | H10: =H5-H9 -> -41700 | I10: =I5-I9 -> -62200 | J10: =J5-J9 -> -17800 | ... Z10: =Z5-Z9 -> 0 | AC10: =AC5-AC9 -> -623440 | AD10: =AD5-AD9 -> -576444 | AE10: =AE5-AE9 -> -1173679 | AF10: =AF5-AF9 -> -411046 | AG10: =AG5-AG9 -> -161201 | AH10: =AH5-AH9 -> 119966 | AI10: =AI5-AI9 -> 310403 | AJ10: =AJ5-AJ9 -> 1414015
B11: Interest income | K11: 20853 | L11: 30310 | M11: 36864 | N11: =AH11-SUM(K11:M11) -> 44545 | O11: 43352 | P11: 46593 | Q11: 52120 | R11: 54727 | S11: 50441 | T11: 56255 | U11: 59762 | V11: 62723 | AC11: 10500 | AD11: 15090 | AE11: 4680 | AF11: 1607 | AG11: 20309 | AH11: 132572 | AI11: 196792 | AJ11: =SUM(S11:V11) -> 229181
B12: Interest expense | K12: -4136 | L12: -10341 | M12: 3122 | N12: =AH12-SUM(K12:M12) -> -4092 | O12: -13507 | P12: -11173 | Q12: -8110 | R12: 14768 | S12: -3173 | T12: 6596 | U12: 27483 | V12: -16734 | AC12: =-3440+48093-2638 -> 42015 | AD12: =-3061-3-2853 -> -5917 | AE12: =-14139+4111 -> -10028 | AF12: =-3640-75415 -> -79055 | AG12: -220135 | AH12: -15447 | AI12: -18022 | AJ12: =SUM(S12:V12) -> 14172
B13: Pretax income | C13: -120400 | D13: -144200 | E13: -100700 | F13: -123200 | G13: -99400 | H13: -176700 | I13: -122800 | J13: 37800 | K13: =K10+K11+K12 -> 20832 | L13: =L10+L11+L12 -> 30043 | M13: =M10+M11+M12 -> 79969 | N13: =N10+N11+N12 -> 106247 | O13: =O10+O11+O12 -> 110726 | P13: =P10+P11+P12 -> 140759 | Q13: =Q10+Q11+Q12 -> 157150 | R13: =R10+R11+R12 -> 80538 | ... Z13: =Z10+Z11+Z12 -> 0 | AC13: =AC10+AC11+AC12 -> -570925 | AD13: =AD10+AD11+AD12 -> -567271 | AE13: =AE10+AE11+AE12 -> -1179027 | AF13: =AF10+AF11+AF12 -> -488494 | AG13: =AG10+AG11+AG12 -> -361027 | AH13: =AH10+AH11+AH12 -> 237091 | AI13: =AI10+AI11+AI12 -> 489173 | AJ13: =AJ10+AJ11+AJ12 -> 1657368
B14: Taxes | C14: 3100 | D14: -5700 | E14: 1400 | F14: 3300 | G14: 200 | H14: 2600 | I14: 1100 | J14: 4400 | K14: 1681 | L14: 2171 | M14: 6530 | N14: =AH14-SUM(K14:M14) -> 9334 | O14: 4655 | P14: 5189 | Q14: 7809 | R14: 3602 | S14: 5599 | T14: 3596 | U14: 3753 | V14: 9776 | AC14: 9102 | AD14: 12375 | AE14: -12636 | AF14: 31885 | AG14: 10067 | AH14: 19716 | AI14: 21255 | AJ14: =SUM(S14:V14) -> 22724
B15: Net Income | C15: =C13-C14 -> -123500 | D15: =D13-D14 -> -138500 | E15: =E13-E14 -> -102100 | F15: =F13-F14 -> -126500 | G15: =G13-G14 -> -99600 | H15: =H13-H14 -> -179300 | I15: =I13-I14 -> -123900 | J15: =J13-J14 -> 33400 | ... Z15: =Z13-Z14 -> 0 | AC15: =AC13-AC14 -> -580027 | AD15: =AD13-AD14 -> -579646 | AE15: =AE13-AE14 -> -1166391 | AF15: =AF13-AF14 -> -520379 | AG15: =AG13-AG14 -> -371094 | AH15: =AH13-AH14 -> 217375 | AI15: =AI13-AI14 -> 467918 | AJ15: =AJ13-AJ14 -> 1634644
B16: Less: noncontrolling | K16: 2349 | L16: -255 | M16: 1934 | N16: =AH16-SUM(K16:M16) -> 3522 | O16: 541 | P16: 1444 | Q16: 5816 | R16: -2073 | S16: 3686 | T16: 1845 | U16: 1149 | V16: 2931 | AC16: 18098 | AD16: 8481 | AG16: 2611 | AH16: 7550 | AI16: 5728 | AJ16: =SUM(S16:V16) -> 9611
B17: Net income attributable to Palantir | C17: =C15-C16 -> -123500 | D17: =D15-D16 -> -138500 | E17: =E15-E16 -> -102100 | F17: =F15-F16 -> -126500 | G17: =G15-G16 -> -99600 | H17: =H15-H16 -> -179300 | I17: =I15-I16 -> -123900 | J17: =J15-J16 -> 33400 | ... Z17: =Z15-Z16 -> 0 | AC17: =AC15-AC16 -> -598125 | AD17: =AD15-AD16 -> -588127 | AE17: =AE15-AE16 -> -1166391 | AF17: =AF15-AF16 -> -520379 | AG17: =AG15-AG16 -> -373705 | AH17: =AH15-AH16 -> 209825 | AI17: =AI15-AI16 -> 462190 | AJ17: =AJ15-AJ16 -> 1625033 | AK17: 1460000 | AL17: =+AK17*1.33 -> 1941800
B18: S/O | C18: =C17/C19 -> 1764285.7 | D18: 1923617 | E18: 1923617 | F18: 1923617 | G18: =G17/G19 -> 1992000 | H18: =H17/H19 -> 1992222.2 | I18: 2063793 | J18: 2063793 | K18: 2107780 | L18: 2131224 | M18: 2162530 | N18: 2147446 | O18: 2213545 | P18: 2231592 | Q18: 2250032 | R18: 2250163 | S18: 2348679 | T18: 2365196 | U18: 2377167 | V18: 2386904 | AC18: 537280.39 | AD18: 576958.56 | AE18: 977722 | AF18: 1923617 | AG18: 2063793 | AH18: 2147446 | AI18: 2250163 | AJ18: 2386904
B19: EPS | C19: -0.07 | D19: =D17/D18 -> -0.07199978 | E19: =E17/E18 -> -0.053077094 | F19: =F17/F18 -> -0.065761532 | G19: -0.05 | H19: -0.09 | I19: -0.06 | J19: =J17/J18 -> 0.016183794 | K19: =K17/K18 -> 0.0079714202 | L19: =L17/L18 -> 0.01319758 | M19: =M17/M18 -> 0.033065437 | N19: =N17/N18 -> 0.043489336 | O19: =O17/O18 -> 0.047674658 | P19: =P17/P18 -> 0.060103281 | Q19: =Q17/Q18 -> 0.063787982 | ... Z19: =Z17/Z18 -> #DIV/0! | AC19: =AC17/AC18 -> -1.1132455 | AD19: =AD17/AD18 -> -1.0193574 | AE19: =AE17/AE18 -> -1.1929679 | AF19: =AF17/AF18 -> -0.27052111 | AG19: =AG17/AG18 -> -0.18107678 | AH19: =AH17/AH18 -> 0.097709093 | AI19: =AI17/AI18 -> 0.2054029 | AJ19: =AJ17/AJ18 -> 0.68081205 | AK19: 0.83
B22: Gross margin | C22: =C5/C3 -> 0.78282532 | D22: =D5/D3 -> 0.75798722 | E22: =E5/E3 -> 0.7786279 | F22: =F5/F3 -> 0.7976438 | G22: =G5/G3 -> 0.78853047 | H22: =H5/H3 -> 0.78393235 | I22: =I5/I3 -> 0.77484829 | J22: =J5/J3 -> 0.79492725 | ... Z22: =Z5/Z3 -> #DIV/0! | AC22: =AC5/AC3 -> 0.72220608 | AD22: =AD5/AD3 -> 0.6735959 | AE22: =AE5/AE3 -> 0.67735361 | AF22: =AF5/AF3 -> 0.7798778 | AG22: =AG5/AG3 -> 0.78563659 | AH22: =AH5/AH3 -> 0.80624599 | AI22: =AI5/AI3 -> 0.80248172 | AJ22: =AJ5/AJ3 -> 0.82366517 | ... AL22: =AL5/AL3 -> #DIV/0!
B23: S&M margin | C23: =C6/C$5 -> 0 | D23: =D6/D$5 -> 0 | E23: =E6/E$5 -> 0 | F23: =F6/F$5 -> 0 | G23: =G6/G$5 -> 0 | H23: =H6/H$5 -> 0 | I23: =I6/I$5 -> 0 | J23: =J6/J$5 -> 0 | ... Z23: =Z6/Z$5 -> #DIV/0! | AC23: =AC6/AC$5 -> 1.0738451 | AD23: =AD6/AD$5 -> 0.89991243 | AE23: =AE6/AE$5 -> 0.92376298 | AF23: =AF6/AF$5 -> 0.51103506 | AG23: =AG6/AG$5 -> 0.46917831 | AH23: =AH6/AH$5 -> 0.4152902 | AI23: =AI6/AI$5 -> 0.38606151 | AJ23: =AJ6/AJ$5 -> 0.28670154 | ... AL23: =AL6/AL$5 -> #DIV/0!
B24: R&D margin | C24: =C7/C$5 -> 0.36877574 | D24: =D7/D$5 -> 0.38812785 | E24: =E7/E$5 -> 0.30887651 | F24: =F7/F$5 -> 0.24384593 | G24: =G7/G$5 -> 0.25170455 | H24: =H7/H$5 -> 0.23786408 | I24: =I7/I$5 -> 0.27248177 | J24: =J7/J$5 -> 0.20281969 | ... Z24: =Z7/Z$5 -> #DIV/0! | AC24: =AC7/AC$5 -> 0.66382718 | AD24: =AD7/AD$5 -> 0.61090363 | AE24: =AE7/AE$5 -> 0.75751967 | AF24: =AF7/AF$5 -> 0.32223853 | AG24: =AG7/AG$5 -> 0.24021486 | AH24: =AH7/AH$5 -> 0.22555461 | AI24: =AI7/AI$5 -> 0.2208629 | AJ24: =AJ7/AJ$5 -> 0.15128494 | ... AL24: =AL7/AL$5 -> #DIV/0!
B25: G&M margin | C25: =C8/C$5 -> 0 | D25: =D8/D$5 -> 0 | E25: =E8/E$5 -> 0 | F25: =F8/F$5 -> 0 | G25: =G8/G$5 -> 0 | H25: =H8/H$5 -> 0 | I25: =I8/I$5 -> 0 | J25: =J8/J$5 -> 0 | ... Z25: =Z8/Z$5 -> #DIV/0! | AC25: =AC8/AC$5 -> 0.71216117 | AD25: =AD8/AD$5 -> 0.64165244 | AE25: =AE8/AE$5 -> 0.90450004 | AF25: =AF8/AF$5 -> 0.50855686 | AG25: =AG8/AG$5 -> 0.39826637 | AH25: =AH8/AH$5 -> 0.29228104 | AI25: =AI8/AI$5 -> 0.25808942 | AJ25: =AJ8/AJ$5 -> 0.17842377 | ... AL25: =AL8/AL$5 -> #DIV/0!
B26: Operating margin | C26: =C10/C3 -> -0.33411489 | D26: =D10/D3 -> -0.38924388 | E26: =E10/E3 -> -0.23463402 | F26: =F10/F3 -> -0.13605914 | G26: =G10/G3 -> -0.088261649 | H26: =H10/H3 -> -0.088160677 | I26: =I10/I3 -> -0.13015275 | J26: =J10/J3 -> -0.034998034 | ... Z26: =Z10/Z3 -> #DIV/0! | AC26: =AC10/AC3 -> -1.0470786 | AD26: =AD10/AD3 -> -0.77629805 | AE26: =AE10/AE3 -> -1.0741356 | AF26: =AF10/AF3 -> -0.26658599 | AG26: =AG10/AG3 -> -0.084581275 | AH26: =AH10/AH3 -> 0.053917013 | AI26: =AI10/AI3 -> 0.10832394 | AJ26: =AJ10/AJ3 -> 0.31594952 | ... AL26: =AL10/AL3 -> #DIV/0!
B27: Interest margin | C27: =(C11+C12)/C10 -> 0 | D27: =(D11+D12)/D10 -> 0 | E27: =(E11+E12)/E10 -> 0 | F27: =(F11+F12)/F10 -> 0 | G27: =(G11+G12)/G10 -> 0 | H27: =(H11+H12)/H10 -> 0 | I27: =(I11+I12)/I10 -> 0 | J27: =(J11+J12)/J10 -> 0 | ... Z27: =(Z11+Z12)/Z10 -> #DIV/0! | AC27: =(AC11+AC12)/AC10 -> -0.084234249 | AD27: =(AD11+AD12)/AD10 -> -0.015913081 | AE27: =(AE11+AE12)/AE10 -> 0.0045566122 | AF27: =(AF11+AF12)/AF10 -> 0.18841687 | AG27: =(AG11+AG12)/AG10 -> 1.2396077 | AH27: =(AH11+AH12)/AH10 -> 0.97631829 | AI27: =(AI11+AI12)/AI10 -> 0.57592871 | AJ27: =(AJ11+AJ12)/AJ10 -> 0.17210072 | ... AL27: =(AL11+AL12)/AL10 -> #DIV/0!
B28: Tax margin | C28: =C14/C13 -> -0.025747508 | D28: =D14/D13 -> 0.039528433 | E28: =E14/E13 -> -0.013902681 | F28: =F14/F13 -> -0.026785714 | G28: =G14/G13 -> -0.0020120724 | H28: =H14/H13 -> -0.014714205 | I28: =I14/I13 -> -0.0089576547 | J28: =J14/J13 -> 0.11640212 | ... Z28: =Z14/Z13 -> #DIV/0! | AC28: =AC14/AC13 -> -0.015942549 | AD28: =AD14/AD13 -> -0.02181497 | AE28: =AE14/AE13 -> 0.010717312 | AF28: =AF14/AF13 -> -0.06527204 | AG28: =AG14/AG13 -> -0.027884341 | AH28: =AH14/AH13 -> 0.083157944 | AI28: =AI14/AI13 -> 0.043450885 | AJ28: =AJ14/AJ13 -> 0.013710896 | ... AL28: =AL14/AL13 -> #DIV/0!
B29: Net margin | C29: =C17/C3 -> -0.3619578 | D29: =D17/D3 -> -0.36874334 | E29: =E17/E3 -> -0.26039276 | F29: =F17/F3 -> -0.29221529 | G29: =G17/G3 -> -0.22311828 | H29: =H17/H3 -> -0.37906977 | I29: =I17/I3 -> -0.25925926 | J29: =J17/J3 -> 0.065670468 | ... Z29: =Z17/Z3 -> #DIV/0! | AC29: =AC17/AC3 -> -1.0045616 | AD29: =AD17/AD3 -> -0.79203157 | AE29: =AE17/AE3 -> -1.0674657 | AF29: =AF17/AF3 -> -0.33749446 | AG29: =AG17/AG3 -> -0.19608095 | AH29: =AH17/AH3 -> 0.094302862 | AI29: =AI17/AI3 -> 0.16129432 | AJ29: =AJ17/AJ3 -> 0.36309968 | ... AL29: =AL17/AL3 -> #DIV/0!
B31: Revenue Y/Y | G31: =G3/C3-1 -> 0.30832356 | H31: =H3/D3-1 -> 0.25931842 | I31: =I3/E3-1 -> 0.21882173 | J31: =J3/F3-1 -> 0.17486717 | K31: =K3/G3-1 -> 0.17649194 | L31: =L3/H3-1 -> 0.12752008 | M31: =M3/I3-1 -> 0.16794099 | N31: =N3/J3-1 -> 0.19612662 | ... Z31: =Z3/V3-1 -> -1 | AD31: =AD3/AC3-1 -> 0.24713432 | AE31: =AE3/AD3-1 -> 0.47150447 | AF31: =AF3/AE3-1 -> 0.41111659 | AG31: =AG3/AF3-1 -> 0.23606239 | AH31: =AH3/AG3-1 -> 0.16745152 | AI31: =AI3/AH3-1 -> 0.28786137 | AJ31: =AJ3/AI3-1 -> 0.56183391 | AK31: =AK3/AJ3-1 -> 0.60833133 | AL31: =AL3/AK3-1 -> -1
B35: Net Cash | F35: =F36+F37 -> 2601067 | G35: =G36+G37 -> 0 | H35: =H36+H37 -> 0 | I35: =I36+I37 -> 0 | J35: =J36+J37 -> 2662470 | K35: =K36+K37 -> 0 | L35: =L36+L37 -> 0 | M35: =M36+M37 -> 0 | ... Z35: =Z36+Z37 -> 0 | AC35: =AC36+AC37 -> 1284335 | AD35: =AD36+AD37-AD52 -> 988522 | AE35: =AE36+AE37-AE52 -> 1925853 | AF35: =AF36+AF37 -> 2601067 | AG35: =AG36+AG37 -> 2662470 | AH35: =AH36+AH37 -> 3674179 | AI35: =AI36+AI37 -> 5229987 | AJ35: =AJ36+AJ37 -> 7177143 | AK35: =AK36+AK37 -> 0 | AL35: =AL36+AL37 -> 0
B36: Cash | F36: =2290674+36628+39612 -> 2366914 | J36: =2598540+16244+12551 -> 2627335 | N36: 831047 | O36: 520388 | P36: 512659 | Q36: 768710 | R36: 2098524 | S36: 993464 | T36: 929547 | U36: 1615967 | V36: 1423896 | AC36: =1116342+10484+140009+17500 -> 1284335 | AD36: =1079154+52099+270709+26145 -> 1428107 | AE36: =2011323+37285+79538 -> 2128146 | AF36: =2290674+36628+39612 -> 2366914 | AG36: =2598540+16244+12551 -> 2627335 | AH36: 831047 | AI36: 2098524 | AJ36: 1423896
B37: Securities | F37: 234153 | J37: 35135 | N37: 2843132 | O37: 3347512 | P37: 3485800 | Q37: 3795949 | R37: 3131463 | S37: 4437225 | T37: 5070875 | U37: 4821850 | V37: 5753247 | AF37: 234153 | AG37: 35135 | AH37: 2843132 | AI37: 3131463 | AJ37: 5753247
B38: A/R | F38: 190923 | J38: 258346 | N38: 364784 | O38: 486986 | P38: 659339 | Q38: 668110 | R38: 575048 | S38: 725205 | T38: 747484 | U38: 1005910 | V38: 1042065 | AC38: 19187 | AD38: 50315 | AE38: 156932 | AF38: 190923 | AG38: 258346 | AH38: 364784 | AI38: 575048 | AJ38: 1042065
B39: Prepaids | F39: 110872 | J39: 133312 | N39: 99655 | O39: 81178 | P39: 115712 | Q39: 119193 | R39: 129254 | S39: 126705 | T39: 142487 | U39: 142429 | V39: 139066 | AC39: 74063 | AD39: 32585 | AE39: 51889 | AF39: 110872 | AG39: 133312 | AH39: 99655 | AI39: 129254 | AJ39: 139066
B40: PP&A | F40: 31304 | J40: 69170 | N40: 47758 | O40: 46906 | P40: 43483 | Q40: 40345 | R40: 39638 | S40: 39669 | T40: 43523 | U40: 45706 | V40: 51960 | AC40: 30034 | AD40: 31589 | AE40: 29541 | AF40: 31304 | AG40: 69170 | AH40: 47758 | AI40: 39638 | AJ40: 51960
B41: Operating lease ROU | F41: 216898 | J41: 200240 | N41: 182863 | O41: 173707 | P41: 213453 | Q41: 211570 | R41: 200740 | S41: 209348 | T41: 203474 | U41: 204315 | V41: 200105 | AE41: 217075 | AF41: 216898 | AG41: 200240 | AH41: 182863 | AI41: 200740 | AJ41: 200105
B42: Other assets | F42: 96386 | J42: 137701 | N42: 153186 | O42: 150402 | P42: 161434 | Q42: 164220 | R42: 166217 | S42: 205301 | T42: 228298 | U42: 277783 | V42: 290153 | AC42: 23346 | AD42: 51429 | AE42: 106921 | AF42: 96386 | AG42: 137701 | AH42: 153186 | AI42: 166217 | AJ42: 290153
B43: Total assets | F43: =SUM(F36:F42) -> 3247450 | G43: =SUM(G36:G42) -> 0 | H43: =SUM(H36:H42) -> 0 | I43: =SUM(I36:I42) -> 0 | J43: =SUM(J36:J42) -> 3461239 | K43: =SUM(K36:K42) -> 0 | L43: =SUM(L36:L42) -> 0 | M43: =SUM(M36:M42) -> 0 | ... Z43: =SUM(Z36:Z42) -> 0 | AC43: =SUM(AC36:AC42) -> 1430965 | AD43: =SUM(AD36:AD42) -> 1594025 | AE43: =SUM(AE36:AE42) -> 2690504 | AF43: =SUM(AF36:AF42) -> 3247450 | AG43: =SUM(AG36:AG42) -> 3461239 | AH43: =SUM(AH36:AH42) -> 4522425 | AI43: =SUM(AI36:AI42) -> 6340884 | AJ43: =SUM(AJ36:AJ42) -> 8900492 | ... AL43: =SUM(AL36:AL42) -> 0
B44: A/P | F44: 74907 | J44: 44788 | N44: 12122 | O44: 35634 | P44: 67345 | Q44: 27021 | R44: 103 | S44: 2330 | T44: 10774 | U44: 67503 | V44: 8064 | AC44: 27399 | AD44: 51735 | AE44: 16358 | AF44: 74907 | AG44: 44788 | AH44: 12122 | AI44: 103 | AJ44: 8064
B45: Accrued liabilities | F45: 155806 | J45: 172715 | N45: 222991 | O45: 206034 | P45: 195489 | Q45: 265244 | R45: 427046 | S45: 371061 | T45: 393623 | U45: 381737 | V45: 355624 | AC45: 123745 | AD45: 126620 | AE45: 158546 | AF45: 155806 | AG45: 172715 | AH45: 222991 | AI45: 427046 | AJ45: 355624
B46: Deferred revenue | F46: 227816 | J46: 183350 | N46: 246901 | O46: 237195 | P46: 278441 | Q46: 236608 | R46: 259624 | S46: 318556 | T46: 376784 | U46: 316722 | V46: 408963 | AC46: 239116 | AD46: 186105 | AE46: 189520 | AF46: 227816 | AG46: 183350 | AH46: 246901 | AI46: 259624 | AJ46: 408963
...
