Workbook

Sheet Main
I7: Price | J7: 33.74
I8: S/O | J8: =+Model!N21/1000000 -> 417.566
I9: MC | J9: =J7*J8 -> 14088.677
I10: C | J10: =(Model!N39+Model!N40)/1000000 -> 1691.045
I11: D | J11: =Model!N52/1000000 -> 2233.255
I13: EV | J13: =+J9+J11-J10 -> 14630.887
H14: EV/Last 4Q Sales | J14: =J13/((Model!N5+Model!M5+Model!L5+Model!K5)/1000000) -> 8.2216317
H15: EV/Last 4Q Adj. EBITDA | J15: =J13/((Model!G130+Model!F130+Model!E130+Model!D130)/1000000) -> 51.717522
H16: EV/Last 4Q FCF | J16: =J13/((Model!N123+Model!M123+Model!L123+Model!K123)/1000000) -> 41.223636

Sheet Model
C2: Q322 | D2: Q422 | E2: Q123 | F2: Q223 | G2: Q323 | H2: Q423 | I2: Q124 | J2: Q224 | K2: Q324 | L2: Q424 | M2: Q125 | N2: Q225 | O2: Q325 | P2: Q425 | Q2: Q126 | R2: Q226 | S2: Q326 | T2: Q426 | Y2: 2023 | Z2: 2024 | AA2: 2025
B3: Create Solutions | C3: 189178000 | D3: 197762000 | E3: 187369000 | F3: 193110000 | G3: 188900000 | H3: 289795000 | I3: 163670000 | J3: 150777000 | K3: 147369000 | L3: 152150000 | M3: 150378000 | N3: 153782000 | Y3: 859174000 | Z3: 613966000
B4: Grow Solutions | C4: 133703000 | D4: 253212000 | E4: 312992000 | F4: 340368000 | G4: 355310000 | H4: 319473000 | I4: 296710000 | J4: 298482000 | K4: 299148000 | L4: 304949000 | M4: 284622000 | N4: 287162000 | Y4: 1328143000 | Z4: 1199289000
B5: Total Revenue | C5: =SUM(C3:C4) -> 322881000 | D5: =SUM(D3:D4) -> 450974000 | E5: =SUM(E3:E4) -> 500361000 | F5: =SUM(F3:F4) -> 533478000 | G5: =SUM(G3:G4) -> 544210000 | H5: =SUM(H3:H4) -> 609268000 | I5: =SUM(I3:I4) -> 460380000 | J5: =SUM(J3:J4) -> 449259000 | ... T5: =SUM(T3:T4) -> 0 | Y5: =SUM(Y3:Y4) -> 2187317000 | Z5: =SUM(Z3:Z4) -> 1813255000 | AA5: =SUM(AA3:AA4) -> 0
B6: COGS | C6: 111903000 | D6: 139928000 | E6: 161964000 | F6: 158827000 | G6: 151349000 | H6: 261582000 | I6: 144387000 | J6: 108875000 | K6: 112054000 | L6: 115537000 | M6: 113957000 | N6: 114211000 | Y6: 733722000 | Z6: 480853000
B7: Gross Profit | C7: =C5-C6 -> 210978000 | D7: =D5-D6 -> 311046000 | E7: =E5-E6 -> 338397000 | F7: =F5-F6 -> 374651000 | G7: =G5-G6 -> 392861000 | H7: =H5-H6 -> 347686000 | I7: =I5-I6 -> 315993000 | J7: =J5-J6 -> 340384000 | ... T7: =T5-T6 -> 0 | Y7: =Y5-Y6 -> 1453595000 | Z7: =Z5-Z6 -> 1332402000 | AA7: =AA5-AA6 -> 0
B8: R&D | C8: 248380000 | D8: 274111000 | E8: 280480000 | F8: 267955000 | G8: 240003000 | H8: 265150000 | I8: 282728000 | J8: 208935000 | K8: 215197000 | L8: 217970000 | M8: 220625000 | N8: 214807000 | Y8: 1053588000 | Z8: 924830000
B9: S&M | C9: 109639000 | D9: 183470000 | E9: 216127000 | F9: 209131000 | G9: 194000000 | H9: 215367000 | I9: 230625000 | J9: 169854000 | K9: 176423000 | L9: 175747000 | M9: 162013000 | N9: 161513000 | Y9: 834625000 | Z9: 752649000
B10: G&A | C10: 92585000 | D10: 127225000 | E10: 96774000 | F10: 89017000 | G10: 86256000 | H10: 126129000 | I10: 177569000 | J10: 91015000 | K10: 69989000 | L10: 71499000 | M10: 66340000 | N10: 69165000 | Y10: 398176000 | Z10: 410072000
B11: OpEx | C11: =SUM(C8:C10) -> 450604000 | D11: =SUM(D8:D10) -> 584806000 | E11: =SUM(E8:E10) -> 593381000 | F11: =SUM(F8:F10) -> 566103000 | G11: =SUM(G8:G10) -> 520259000 | H11: =SUM(H8:H10) -> 606646000 | I11: =SUM(I8:I10) -> 690922000 | J11: =SUM(J8:J10) -> 469804000 | ... T11: =SUM(T8:T10) -> 0 | Y11: =SUM(Y8:Y10) -> 2286389000 | Z11: =SUM(Z8:Z10) -> 2087551000 | AA11: =SUM(AA8:AA10) -> 0
B12: OpInc | C12: =C7-C11 -> -239626000 | D12: =D7-D11 -> -273760000 | E12: =E7-E11 -> -254984000 | F12: =F7-F11 -> -191452000 | G12: =G7-G11 -> -127398000 | H12: =H7-H11 -> -258960000 | I12: =I7-I11 -> -374929000 | J12: =J7-J11 -> -129420000 | ... T12: =T7-T11 -> 0 | Y12: =Y7-Y11 -> -832794000 | Z12: =Z7-Z11 -> -755149000 | AA12: =AA7-AA11 -> 0
B13: IntExp | C13: -1135000 | D13: -4035000 | E13: -6129000 | F13: -6142000 | G13: -6154000 | H13: -6155000 | I13: -6035000 | J13: -5829000 | K13: -5839000 | L13: -5839000 | M13: -5891000 | N13: -6030000 | Y13: -24580000 | Z13: -23542000
B14: IntInc & Other | C14: 2208000 | D14: 7101000 | E14: 13615000 | F14: 9061000 | G14: 16013000 | H14: 20840000 | I14: 76643000 | J14: 10457000 | K14: 15350000 | L14: 9108000 | M14: 58111000 | N14: 19837000 | Y14: 59529000 | Z14: 111558000
B15: Pretax Income | C15: =C12+C13+C14 -> -238553000 | D15: =D12+D13+D14 -> -270694000 | E15: =E12+E13+E14 -> -247498000 | F15: =F12+F13+F14 -> -188533000 | G15: =G12+G13+G14 -> -117539000 | H15: =H12+H13+H14 -> -244275000 | I15: =I12+I13+I14 -> -304321000 | J15: =J12+J13+J14 -> -124792000 | ... T15: =T12+T13+T14 -> 0 | Y15: =Y12+Y13+Y14 -> -797845000 | Z15: =Z12+Z13+Z14 -> -667133000 | AA15: =AA12+AA13+AA14 -> 0
B16: Taxes | C16: 11468000 | D16: 17060000 | E16: 6205000 | F16: 4791000 | G16: 7771000 | H16: 9710000 | I16: -12843000 | J16: 946000 | K16: 6913000 | L16: 2138000 | M16: 2192000 | N16: 2420000 | Y16: 28477000 | Z16: -2846000
B17: Net Income | C17: =C15-C16 -> -250021000 | D17: =D15-D16 -> -287754000 | E17: =E15-E16 -> -253703000 | F17: =F15-F16 -> -193324000 | G17: =G15-G16 -> -125310000 | H17: =H15-H16 -> -253985000 | I17: =I15-I16 -> -291478000 | J17: =J15-J16 -> -125738000 | ... T17: =T15-T16 -> 0 | Y17: =Y15-Y16 -> -826322000 | Z17: =Z15-Z16 -> -664287000 | AA17: =AA15-AA16 -> 0
B18: Noncontrolling | C18: 0 | D18: -1296000 | E18: -672000 | F18: -1164000 | G18: -1239000 | H18: -1236000 | I18: -404000 | J18: -164000 | K18: 191000 | L18: 204000 | M18: -265000 | N18: 1433000 | Y18: -4311000 | Z18: -173000
B19: Adj. | C19: 0 | D19: 2870000 | E19: 0 | F19: 0 | G19: 0 | H19: 0 | I19: 0 | J19: 0 | K19: 0 | L19: 0 | M19: 0 | N19: 0 | Y19: 0 | Z19: 0
B20: Net Income attributable to Unity | C20: =+C17-C18-C19 -> -250021000 | D20: =+D17-D18-D19 -> -289328000 | E20: =+E17-E18-E19 -> -253031000 | F20: =+F17-F18-F19 -> -192160000 | G20: =+G17-G18-G19 -> -124071000 | H20: =+H17-H18-H19 -> -252749000 | I20: =+I17-I18-I19 -> -291074000 | J20: =+J17-J18-J19 -> -125574000 | ... T20: =+T17-T18-T19 -> 0 | Y20: =+Y17-Y18-Y19 -> -822011000 | Z20: =+Z17-Z18-Z19 -> -664114000 | AA20: =+AA17-AA18-AA19 -> 0
B21: Basic | C21: 299062000 | D21: 351264000 | E21: 375909000 | F21: 380355000 | G21: 383674000 | H21: 381788000 | I21: 387151000 | J21: 392537000 | K21: 398810000 | L21: 405172000 | M21: 411852000 | N21: 417566000 | Y21: 380457000 | Z21: 395951000
B22: Diluted | C22: 299062000 | D22: 351264000 | E22: 375909000 | F22: 380355000 | G22: 383674000 | H22: 381788000 | I22: 387151000 | J22: 392537000 | K22: 398810000 | L22: 405172000 | M22: 411852000 | N22: 417566000 | Y22: 380457000 | Z22: 395951000
B23: EPS Basic | C23: =C20/C21 -> -0.83601728 | D23: =D20/D21 -> -0.82367678 | E23: =E20/E21 -> -0.6731177 | F23: =F20/F21 -> -0.50521224 | G23: =G20/G21 -> -0.3233761 | H23: =H20/H21 -> -0.662014 | I23: =I20/I21 -> -0.75183585 | J23: =J20/J21 -> -0.3199036 | ... T23: =T20/T21 -> #DIV/0! | Y23: =Y20/Y21 -> -2.1605885 | Z23: =Z20/Z21 -> -1.6772631 | AA23: =AA20/AA21 -> #DIV/0!
B24: EPS Diluted | C24: =C20/C22 -> -0.83601728 | D24: =D20/D22 -> -0.82367678 | E24: =E20/E22 -> -0.6731177 | F24: =F20/F22 -> -0.50521224 | G24: =G20/G22 -> -0.3233761 | H24: =H20/H22 -> -0.662014 | I24: =I20/I22 -> -0.75183585 | J24: =J20/J22 -> -0.3199036 | ... T24: =T20/T22 -> #DIV/0! | Y24: =Y20/Y22 -> -2.1605885 | Z24: =Z20/Z22 -> -1.6772631 | AA24: =AA20/AA22 -> #DIV/0!
B27: Gross Margin | C27: =C7/C5 -> 0.6534234 | D27: =D7/D5 -> 0.68972047 | E27: =E7/E5 -> 0.67630571 | F27: =F7/F5 -> 0.70228013 | G27: =G7/G5 -> 0.72189228 | H27: =H7/H5 -> 0.57066184 | I27: =I7/I5 -> 0.6863743 | J27: =J7/J5 -> 0.7576565 | ... T27: =T7/T5 -> #DIV/0! | Y27: =Y7/Y5 -> 0.66455617 | Z27: =Z7/Z5 -> 0.73481226 | AA27: =AA7/AA5 -> #DIV/0!
B28: Op Margin | C28: =C12/C5 -> -0.74214958 | D28: =D12/D5 -> -0.60704165 | E28: =E12/E5 -> -0.50960007 | F28: =F12/F5 -> -0.35887516 | G28: =G12/G5 -> -0.23409713 | H28: =H12/H5 -> -0.42503463 | I28: =I12/I5 -> -0.81439029 | J28: =J12/J5 -> -0.28807436 | ... T28: =T12/T5 -> #DIV/0! | Y28: =Y12/Y5 -> -0.38073768 | Z28: =Z12/Z5 -> -0.41646045 | AA28: =AA12/AA5 -> #DIV/0!
B29: Tax Margin | C29: =C16/C15 -> -0.048073175 | D29: =D16/D15 -> -0.063023192 | E29: =E16/E15 -> -0.02507091 | F29: =F16/F15 -> -0.025411997 | G29: =G16/G15 -> -0.066114226 | H29: =H16/H15 -> -0.039750281 | I29: =I16/I15 -> 0.042202148 | J29: =J16/J15 -> -0.0075806141 | ... T29: =T16/T15 -> #DIV/0! | Y29: =Y16/Y15 -> -0.035692396 | Z29: =Z16/Z15 -> 0.0042660159 | AA29: =AA16/AA15 -> #DIV/0!
B30: Net Margin | C30: =C17/C5 -> -0.77434411 | D30: =D17/D5 -> -0.63807226 | E30: =E17/E5 -> -0.50703992 | F30: =F17/F5 -> -0.3623842 | G30: =G17/G5 -> -0.23026038 | H30: =H17/H5 -> -0.4168691 | I30: =I17/I5 -> -0.63312481 | J30: =J17/J5 -> -0.27987864 | ... T30: =T17/T5 -> #DIV/0! | Y30: =Y17/Y5 -> -0.3777788 | Z30: =Z17/Z5 -> -0.36635057 | AA30: =AA17/AA5 -> #DIV/0!
B32: Create YoY | G32: =G3/D3-1 -> -0.04481144 | H32: =H3/E3-1 -> 0.54665393 | I32: =I3/F3-1 -> -0.15245197 | J32: =J3/G3-1 -> -0.20181578 | K32: =K3/H3-1 -> -0.49147156 | L32: =L3/I3-1 -> -0.070385532 | M32: =M3/J3-1 -> -0.0026462922 | N32: =N3/K3-1 -> 0.043516615 | ... T32: =T3/Q3-1 -> #DIV/0! | Z32: =Z3/Y3-1 -> -0.2853997 | AA32: =AA3/Z3-1 -> -1
B33: Grow YoY | G33: =G4/D4-1 -> 0.40321154 | H33: =H4/E4-1 -> 0.0207066 | I33: =I4/F4-1 -> -0.12826705 | J33: =J4/G4-1 -> -0.15993921 | K33: =K4/H4-1 -> -0.0636204 | L33: =L4/I4-1 -> 0.027767854 | M33: =M4/J4-1 -> -0.046434961 | N33: =N4/K4-1 -> -0.040067124 | ... T33: =T4/Q4-1 -> #DIV/0! | Z33: =Z4/Y4-1 -> -0.097018167 | AA33: =AA4/Z4-1 -> -1
B34: Revenue YoY | G34: =G5/D5-1 -> 0.20674363 | H34: =H5/E5-1 -> 0.21765685 | I34: =I5/F5-1 -> -0.13702158 | J34: =J5/G5-1 -> -0.17447493 | K34: =K5/H5-1 -> -0.26712547 | L34: =L5/I5-1 -> -0.0071267214 | M34: =M5/J5-1 -> -0.03173893 | N34: =N5/K5-1 -> -0.012481048 | ... T34: =T5/Q5-1 -> #DIV/0! | Z34: =Z5/Y5-1 -> -0.17101408 | AA34: =AA5/Z5-1 -> -1
B38: Net Cash | C38: =C39+C40-C52 -> -20300000 | D38: =D39+D40-D52 -> -1120376000 | E38: =E39+E40-E52 -> -1114354000 | F38: =F39+F40-F52 -> -1068516000 | G38: =G39+G40-G52 -> -1203432000 | H38: =H39+H40-H52 -> -1121425000 | I38: =I39+I40-I52 -> -1056453000 | J38: =J39+J40-J52 -> -969288000 | ... T38: =T39+T40-T52 -> 0 | Y38: =Y39+Y40-Y52 -> -1121425000 | Z38: =Z39+Z40-Z52 -> -721250000 | AA38: =AA39+AA40-AA52 -> 0
B39: Cash | C39: 1239337000 | D39: 1485084000 | E39: 1593946000 | F39: 1640926000 | G39: 1507164000 | H39: 1590325000 | I39: 1179962000 | J39: 1267957000 | K39: 1405276000 | L39: 1517672000 | M39: 1541170000 | N39: 1691045000 | Y39: 1590325000 | Z39: 1517672000
B40: Short-term investments | C40: 446766000 | D40: 101711000 | E40: 0 | F40: 0 | G40: 0 | H40: 0 | I40: 0 | J40: 0 | K40: 0 | L40: 0 | M40: 0 | N40: 0 | Y40: 0 | Z40: 0
B41: A/R | C41: 316337000 | D41: 633775000 | E41: 612763000 | F41: 632032000 | G41: 604743000 | H41: 611723000 | I41: 621184000 | J41: 573220000 | K41: 576436000 | L41: 573884000 | M41: 552958000 | N41: 596560000 | Y41: 611723000 | Z41: 573884000
B42: Prepaids & Other | C42: 81960000 | D42: 144070000 | E42: 136653000 | F42: 121406000 | G42: 120758000 | H42: 122843000 | I42: 140092000 | J42: 142889000 | K42: 134656000 | L42: 133795000 | M42: 144514000 | N42: 120171000 | Y42: 122843000 | Z42: 133795000
B43: PP&A | C43: 112458000 | D43: 121863000 | E43: 129050000 | F43: 135387000 | G43: 140807000 | H43: 140887000 | I43: 122783000 | J43: 112080000 | K43: 108085000 | L43: 98819000 | M43: 89972000 | N43: 82426000 | Y43: 140887000 | Z43: 98819000
B44: Goodwill | C44: 1657863000 | D44: 3200955000 | E44: 3200955000 | F44: 3200955000 | G44: 3202116000 | H44: 3166304000 | I44: 3166304000 | J44: 3166304000 | K44: 3166304000 | L44: 3166304000 | M44: 3166304000 | N44: 3166304000 | Y44: 3166304000 | Z44: 3166304000
B45: Intangible assets | C45: 724926000 | D45: 1922234000 | E45: 1824313000 | F45: 1725438000 | G45: 1626392000 | H45: 1406745000 | I45: 1318787000 | J45: 1230716000 | K45: 1154699000 | L45: 1066235000 | M45: 980584000 | N45: 894367000 | Y45: 1406745000 | Z45: 1066235000
B46: Other assets | C46: 147514000 | D46: 224293000 | E46: 237053000 | F46: 230702000 | G46: 223703000 | H46: 204614000 | I46: 204151000 | J46: 190568000 | K46: 180399000 | L46: 180698000 | M46: 170453000 | N46: 165551000 | Y46: 204614000 | Z46: 180698000
B47: Total Assets | C47: =SUM(C39:C46) -> 4727161000 | D47: =SUM(D39:D46) -> 7833985000 | E47: =SUM(E39:E46) -> 7734733000 | F47: =SUM(F39:F46) -> 7686846000 | G47: =SUM(G39:G46) -> 7425683000 | H47: =SUM(H39:H46) -> 7243441000 | I47: =SUM(I39:I46) -> 6753263000 | J47: =SUM(J39:J46) -> 6683734000 | ... T47: =SUM(T39:T46) -> 0 | Y47: =SUM(Y39:Y46) -> 7243441000 | Z47: =SUM(Z39:Z46) -> 6737407000 | AA47: =SUM(AA39:AA46) -> 0
...
